Workbook
Name Region: #REF!
Name Region: #REF!
Name Region: #REF!
Name Region: #REF!

Sheet 說明頁_更新版
A1: ID | B1: Action | C1: Remark
A2: 1 | B2: A-M欄及BM-BP欄照理來說不會更動只會新增
A3: 2 | B3: 檔名的部分請像這樣 "Rebate and Spending report Supplier’s name_2025 01"，勿加上其他說明，若有V2版本請寫 "Rebate and Spending report Supplier’s name_2025 01_V2"
A4: 3 | B4: 請全年度都放在同一個tab，Summary也是Q1-Q4都放在一起，若有更新的年度請一樣要加上對應的Summary
A5: 4 | B5: Title相關規範請看右方所示, 請按照此欄位進行填寫, 勿更改資料次序 *上面也附上Example, 參考的顏色表以及Mason的PDF instruction | C5: A欄位:打上年度，新年度記得要更新
C6: B欄位: SPM, 請填全名, ex Benson Chen, 而不是Benson，若SPM有異動也請更新
C7: C 欄位: 一律填自己公司名稱
C8: D欄位: 請照上方指示, 勿自創提詞, 須注意只有NB和DT才會有Consumer/Commercial之分, F欄位是Peripheral則D和E都是填Peripheral
C9: E欄位 : 請照上方指示, 勿自創提詞
C10: F欄位 : Peripheral只需填寫Peripheral
C11: G欄位 : 已更新到2025
C12: H欄位 : -請一定不能空白此欄位，不然後面的數字都會讀不到 -如果多個platforms共用同keyboard, 請用 '/' 去 group這些platforms，大小寫沒關係。 -請Platform name請跟LTF一模一樣，像是有些後面會加上尺寸也請加上( BAYMAX14/LUISA14/BAYMAXW14/BAYMAX13/BAYMAX13X) -請用"/"來 Grouping 不同 Platform (e.g. ANDAZ/ABU) ，勿用其他符號，錯誤範例如:ANDAZ&ABU
C13: I欄位 : 請照上方指示, 勿自創提詞
C14: J欄位 : 如果沒有Size，則填寫"NA/"，請不要只寫"NA"
C15: K欄 : -要注意勿將 Color grouping 在一起，像是Jet Black/Soft Grey，若有n個顏色需分成n筆資料去填 -如果沒有Color，則填寫"NA/"，請注意不要只寫"NA" -Color 需確保填寫正確，如 SEAFOAM TEAL PEARL 需完整打出來，避免填成 SEAFOAM TEAL -請確保在顏色中間加上空格，大小寫沒關係。 -關於灰色，請使用“Grey” 而非“Gray” -Color 欄位需保持正常format，像是 PERFORMANCE BLUE OPAQUE 請避免填成 PERFORMANCE BLUE OPAQUE-RGB -針對CNB Gaming，關於Numpad及RGB方面請遵照以下方式及右方的說明 : RGB Per Key W Numpad_Soft Grey RGB Per Key W/O Numpad_Soft Grey 1 Zone W Numpad_Soft Grey, 1 Zone Red W Numpad_Soft Grey 4 Zone RGB W Numpad_Soft Grey 1 Zone W/O Numpad_Soft Grey, 1 Zone Red W/O Numpad_Soft Grey 4 Zone RGB W/O Numpad_Soft Grey 1 Zone RGB W Numpad_Soft Grey 1 Zone RGB W/O Numpad_Soft Grey
C16: L欄 : 請照上方指示，勿自創提詞，注意NMC更新為Thailand/Vietnam
C17: M欄 : 請照上方指示填寫對應ODM，勿自創提詞或簡寫。若發生ODM不存在於上方的情況，請勿寫上OTHERS，需參照在contract中寫的ODM或Regional site名稱
... C22: BP欄 : 如果有HP Part#就填上，如果沒有的話就填上ODM Part# (語言別的部分可以屏蔽並用星號代替，除非有語言別會造成價格不同的情況才需列出語言別的部分)
A23: 5 | B23: 當月出貨的所有品項都必須填上, 即使rebate=0的項目, 定義為FCS之後, EOL前的platform 當月出貨都需要寫上(也就是不含service part)
A24: 6 | B24: 每個月10日固定上傳此份rebate and spending report，請注意目前的Share point已經與財務共用，因此有任何要更新的地方都請通知Jenny並且上傳V2/V3…版本，且舊檔案勿刪除
A25: 7 | B25: 在上傳此份檔案前針對數字的部分需再三確認，因為這些數字會直接當作日後開發票的金額
A26: 8 | B26: excel欄位有相乘的部分 (rebate amount), 請不要直接在公式以外做數字上的調整, 沒有邏輯性的數字, 程式會偵測異常
A27: 9 | B27: Summary_1不能有任何註記, 需要呈現最真實的數字, Summary_2貴司可有一些註記符號, 或是rebate抵扣等地紀錄是能夠被容許的

Sheet FY23 Summary_1
B3: Supplier's name | C3: 2022 11 | D3: 2022 12 | E3: 2023 01 | F3: Total Q1
B4: Rebate amount | C4: ='FY23'!AO1 -> 571985.43 | D4: ='FY23'!AQ1 -> 502301.86 | E4: ='FY23'!AS1 -> 478294.01 | F4: =SUM(C4:E4) -> 1552581.3
B5: E&O reduction | C5: 0 | D5: 0 | E5: 0 | F5: =SUM(C5:E5) -> 0
B6: Complexity reduction | C6: 0 | D6: 0 | E6: 0 | F6: =SUM(C6:E6) -> 0 | H6: 1. 新增Summary_1, 原先的Summary重新命名為Summary_2
B7: Total amount | C7: =SUM(C4:C6) -> 571985.43 | D7: =SUM(D4:D6) -> 502301.86 | E7: =SUM(E4:E6) -> 478294.01 | F7: =SUM(F4:F6) -> 1552581.3
H8: 2.黃色部位為貴司名稱, 請整份報告都跟檔名貴司名稱撰寫方式一致
B10: Supplier's name | C10: 2023 02 | D10: 2023 03 | E10: 2023 04 | F10: Total Q2 | H10: 3. 這些欄位一定要固定, B3-B28, C3-C28, D3-D28, E3-E28, F3-F28都有賦予定義
B11: Rebate amount | C11: ='FY23'!AU1 -> 527397.12 | D11: ='FY23'!AW1 -> 775016.34 | E11: ='FY23'!AY1 -> 683472.59 | F11: =SUM(C11:E11) -> 1985886.1
B12: E&O reduction | C12: 0 | D12: 0 | E12: 0 | F12: =SUM(C12:E12) -> 0 | H12: 4. Rebate amount 指得是summary_2的page金額 (就是我們一直以來收集的金額)
B13: Complexity reduction | C13: 0 | D13: 0 | E13: 0 | F13: =SUM(C13:E13) -> 0
B14: Total amount | C14: =SUM(C11:C13) -> 527397.12 | D14: =SUM(D11:D13) -> 775016.34 | E14: =SUM(E11:E13) -> 683472.59 | F14: =SUM(F11:F13) -> 1985886.1 | H14: 5. 新增 E&O reduction 及complexity reduction品項, 先留足空間
H15: 若目前還未有此款項存在都先填0
B17: Supplier's name | C17: 2023 05 | D17: 2023 06 | E17: 2023 07 | F17: Total Q3 | H17: 6. 金額都放未經調整後的真實數字, 分析才具意義
B18: Rebate amount | C18: ='FY23'!BA1 -> 949563.11 | D18: ='FY23'!BC1 -> 844037.71 | E18: ='FY23'!BE1 -> 805668.24 | F18: =SUM(C18:E18) -> 2599269.1
B19: E&O reduction | C19: 2052.51 | D19: 0 | E19: 0 | F19: =SUM(C19:E19) -> 2052.51
B20: Complexity reduction | C20: 0 | D20: 0 | E20: 0 | F20: =SUM(C20:E20) -> 0
B21: Total amount | C21: =SUM(C18:C20) -> 951615.62 | D21: =SUM(D18:D20) -> 844037.71 | E21: =SUM(E18:E20) -> 805668.24 | F21: =SUM(F18:F20) -> 2601321.6
B24: Supplier's name | C24: 2023 08 | D24: 2023 09 | E24: 2023 10 | F24: Total Q4
B25: Rebate amount | C25: ='FY23'!BG1 -> 967501.49 | D25: ='FY23'!BI1 -> 1083624.8 | E25: ='FY23'!BK1 -> 744433.43 | F25: =SUM(C25:E25) -> 2795559.7
B26: E&O reduction | C26: 0 | D26: 0 | E26: 0 | F26: =SUM(C26:E26) -> 0
B27: Complexity reduction | C27: 0 | D27: 0 | E27: 0 | F27: =SUM(C27:E27) -> 0
B28: Total amount | C28: =SUM(C25:C27) -> 967501.49 | D28: =SUM(D25:D27) -> 1083624.8 | E28: =SUM(E25:E27) -> 744433.43 | F28: =SUM(F25:F27) -> 2795559.7

Sheet FY23 Summary_2
B3: Q1 Actual by Segment
C4: Segment | D4: 44866 | E4: 44896 | F4: 44927 | G4: Total Rebate in Q1 2023 (US$)
B5: CMIT Input Devices | C5: 200 series (6U) | D5: =SUM('FY23'!AO$77:AO$116)*0.25 -> 62925.182 | E5: =SUM('FY23'!AQ77:AQ116)*0.25 -> 59669.115 | F5: =SUM('FY23'!AS77:AS116)*0.25 -> 50134.382 | G5: =SUM(D5:F5) -> 172728.68
C6: 400 series (S) | D6: =SUM('FY23'!AO$6:AO$13) -> 0 | E6: =SUM('FY23'!AQ6:AQ13) -> 0 | F6: =SUM('FY23'!AS6:AS13) -> 0 | G6: =SUM(D6:F6) -> 0
C7: 600 series (B) | D7: =SUM('FY23'!AO$14:AO$19) -> 0 | E7: =SUM('FY23'!AQ14:AQ19) -> 0 | F7: =SUM('FY23'!AS14:AS19) -> 0 | G7: =SUM(D7:F7) -> 0
C8: 800 series (P) | D8: =SUM('FY23'!AO$20:AO$30) -> 0 | E8: =SUM('FY23'!AQ20:AQ30) -> 0 | F8: =SUM('FY23'!AS20:AS30) -> 0 | G8: =SUM(D8:F8) -> 0
C9: 1000 series (M | D9: =SUM('FY23'!AO$31:AO$34) -> 0 | E9: =SUM('FY23'!AQ31:AQ34) -> 0 | F9: =SUM('FY23'!AS31:AS34) -> 0 | G9: =SUM(D9:F9) -> 0
C10: MWS (Workstation) | D10: =SUM('FY23'!AO$39:AO$40) -> 81120 | E10: =SUM('FY23'!AQ39:AQ40) -> 73696 | F10: =SUM('FY23'!AS39:AS40) -> 96408 | G10: =SUM(D10:F10) -> 251224
C11: Soft Keyboard | D11: =SUM('FY23'!AO$41:AO$44) -> 0 | E11: =SUM('FY23'!AQ41:AQ44) -> 0 | F11: =SUM('FY23'!AS41:AS44) -> 0 | G11: =SUM(D11:F11) -> 0
C12: Chrome Book | D12: =SUM('FY23'!AO$45:AO$64)*0.7 -> 38115 | E12: =SUM('FY23'!AQ45:AQ64)*0.7 -> 25414.41 | F12: =SUM('FY23'!AS45:AS64)*0.7 -> 10162.95 | G12: =SUM(D12:F12) -> 73692.36
C13: Clickpad | D13: =SUM('FY23'!AO$35:AO$36) -> 0 | E13: =SUM('FY23'!AQ35:AQ36) -> 0 | F13: =SUM('FY23'!AS35:AS36) -> 0 | G13: =SUM(D13:F13) -> 0
C14: Education | D14: =SUM('FY23'!AO$37:AO$38) -> 7372 | E14: =SUM('FY23'!AQ37:AQ38) -> 3944 | F14: =SUM('FY23'!AS37:AS38) -> 7364 | G14: =SUM(D14:F14) -> 18680
C15: Peripherals/AMO | G15: =SUM(D15:F15) -> 0
C16: Desktop | D16: =SUM('FY23'!AO$65:AO$76) -> 36310.22 | E16: =SUM('FY23'!AQ65:AQ76) -> 29354.7 | F16: =SUM('FY23'!AS65:AS76) -> 28409.28 | G16: =SUM(D16:F16) -> 94074.2
B17: Consumer Input Devices | C17: OPP | D17: =SUM('FY23'!AO$77:AO$116)*0.75 -> 188775.55 | E17: =SUM('FY23'!AQ77:AQ116)*0.75 -> 179007.35 | F17: =SUM('FY23'!AS77:AS116)*0.75 -> 150403.15 | G17: =SUM(D17:F17) -> 518186.04
C18: Chrome Book | D18: =SUM('FY23'!AO$45:AO$64)*0.3 -> 16335 | E18: =SUM('FY23'!AQ45:AQ64)*0.3 -> 10891.89 | F18: =SUM('FY23'!AS45:AS64)*0.3 -> 4355.55 | G18: =SUM(D18:F18) -> 31582.44
C19: Pavillion | D19: =SUM('FY23'!AO$126:AO$167) -> 90287.58 | E19: =SUM('FY23'!AQ126:AQ167) -> 78366.4 | F19: =SUM('FY23'!AS126:AS167) -> 69603.3 | G19: =SUM(D19:F19) -> 238257.28
C20: Spectre | D20: =SUM('FY23'!AO$168:AO$170) -> 0 | E20: =SUM('FY23'!AQ168:AQ170) -> 0 | F20: =SUM('FY23'!AS168:AS170) -> 0 | G20: =SUM(D20:F20) -> 0
C21: Envy | D21: =SUM('FY23'!AO$171:AO$182) -> 33195.6 | E21: =SUM('FY23'!AQ171:AQ182) -> 16676 | F21: =SUM('FY23'!AS171:AS182) -> 47115.5 | G21: =SUM(D21:F21) -> 96987.1
C22: Stream | D22: =SUM('FY23'!AO$183:AO$184) -> 5459.3 | E22: =SUM('FY23'!AQ183:AQ184) -> 5236 | F22: =SUM('FY23'!AS183:AS184) -> 7280 | G22: =SUM(D22:F22) -> 17975.3
C23: Omen | D23: =SUM('FY23'!AO$185:AO$210) -> 12090 | E23: =SUM('FY23'!AQ185:AQ210) -> 20046 | F23: =SUM('FY23'!AS185:AS210) -> 6940 | G23: =SUM(D23:F23) -> 39076
C24: Peripherals/AMO | G24: =SUM(D24:F24) -> 0
C25: Desktop | D25: =SUM('FY23'!AO$211:AO$227) -> 0 | E25: =SUM('FY23'!AQ211:AQ227) -> 0 | F25: =SUM('FY23'!AS211:AS227) -> 117.9 | G25: =SUM(D25:F25) -> 117.9
G26: =SUM(G5:G25) -> 1552581.3
B28: Q1 Actual by Segment
C29: Supplier | D29: 44866 | E29: 44896 | F29: 44927 | G29: Total Rebate in Q1 2023 (US$)
B30: Input Devices | C30: Acrox
C31: Chicony
C32: Darfon | D32: =SUM(D5:D25) -> 571985.43 | E32: =SUM(E5:E25) -> 502301.86 | F32: =SUM(F5:F25) -> 478294.01 | G32: =SUM(D32:F32) -> 1552581.3
C33: Liteon
C34: Primax
C35: Sunrex
F36: Total Rebate Amount
B39: Q2 Actual by Segment
C40: Segment | D40: 44958 | E40: 44986 | F40: 45017 | G40: Total Rebate in Q2 2023 (US$)
B41: CMIT Input Devices | C41: 200 series (6U) | D41: =SUM('FY23'!AU$77:AU$116)*0.25 -> 47471.27 | E41: =SUM('FY23'!AW$77:AW$116)*0.25 -> 98625.165 | F41: =SUM('FY23'!AY$77:AY$116)*0.25 -> 72830.137 | G41: =SUM(D41:F41) -> 218926.57
C42: 400 series (S) | D42: =SUM('FY23'!AU$6:AU$13) -> 0 | E42: =SUM('FY23'!AW$6:AW$13) -> 0 | F42: =SUM('FY23'!AY$6:AY$13) -> 0 | G42: =SUM(D42:F42) -> 0
C43: 600 series (B) | D43: =SUM('FY23'!AU$14:AU$19) -> 0 | E43: =SUM('FY23'!AW$14:AW$19) -> 0 | F43: =SUM('FY23'!AY$14:AY$19) -> 0 | G43: =SUM(D43:F43) -> 0
C44: 800 series (P) | D44: =SUM('FY23'!AU$20:AU$30) -> 0 | E44: =SUM('FY23'!AW$20:AW$30) -> 0 | F44: =SUM('FY23'!AY$20:AY$30) -> 0 | G44: =SUM(D44:F44) -> 0
C45: 1000 series (M | D45: =SUM('FY23'!AU$31:AU$34) -> 0 | E45: =SUM('FY23'!AW$31:AW$34) -> 0 | F45: =SUM('FY23'!AY$31:AY$34) -> 0 | G45: =SUM(D45:F45) -> 0
...

Sheet FY23
D1: Consumer/Commercial/ Peripheral | E1: NB/DT/Peripheral | G1: 2020/2021/2022 | H1: Remove Size/Color, define Platform naming Hagrid/Hedwig/Granger/Ashmore/Ramla (follow naming rule of product list) | I1: NBL KB/BL KB/Mouse /Combo/Clickpad/Others | J1: NA/ | K1: NA/ | L1: (E China/W China/S China/NMC) | M1: COMPAL/ QUANTA /INVENTEC /WISTRON/ FOXCONN/ OTHERS | AO1: =SUM(AO3:AO986) -> 571985.43 | AQ1: =SUM(AQ3:AQ986) -> 502301.86 | AS1: =SUM(AS3:AS986) -> 478294.01 | AU1: =SUM(AU3:AU986) -> 527397.12 | AW1: =SUM(AW3:AW986) -> 775016.34 | AY1: =SUM(AY3:AY986) -> 683472.59 | BA1: =SUM(BA3:BA986) -> 949563.11 | BC1: =SUM(BC3:BC986) -> 844037.71 | BE1: =SUM(BE3:BE986) -> 805668.24 | BG1: =SUM(BG3:BG986) -> 967501.49 | BI1: =SUM(BI3:BI986) -> 1083624.8 | BK1: =SUM(BK3:BK986) -> 744433.43
A2: FY23 | B2: SPM (Project Owner) | C2: GTK Suppliers | D2: Category | E2: Segment | F2: Series | G2: Production Year | H2: Platforms | I2: Product | J2: Size | K2: Color | L2: Location | M2: ODM | N2: The lowest unit table price (ODM cost) | O2: Table Price Nov | P2: Table Price Dec | Q2: Table Price Jan | R2: Table Price Feb | S2: Table Price Mar | T2: Table Price Apr | U2: Table Price May | V2: Table Price Jun | W2: Table Price Jul | X2: Table Price Aug | Y2: Table Price Sep | Z2: Table Price Oct | AA2: The lowest unit rebate cost | AB2: Unit Rebate Nov | AC2: Unit Rebate Dec | AD2: Unit Rebate Jan | AE2: Unit Rebate Feb | AF2: Unit Rebate Mar | AG2: Unit Rebate Apr | AH2: Unit Rebate May | AI2: Unit Rebate Jun | AJ2: Unit Rebate Jul | AK2: Unit Rebate Aug | AL2: Unit Rebate Sep | AM2: Unit Rebate Oct | AN2: Nov Q'ty | AO2: Nov Rebate Amount | AP2: Dec Q'ty | AQ2: Dec Rebate Amount | AR2: Jan Q'ty | AS2: Jan Rebate Amount | AT2: Feb Q'ty | AU2: Feb Rebate Amount | AV2: Mar Q'ty | AW2: Mar Rebate Amount | AX2: Apr Q'ty | AY2: Apr Rebate Amount | AZ2: May Q'ty | BA2: May Rebate Amount | BB2: Jun Q'ty | BC2: Jun Rebate Amount | BD2: Jul Q'ty | BE2: Jul Rebate Amount | BF2: Aug Q'ty | BG2: Aug Rebate Amount | BH2: Sep Q'ty | BI2: Sep Rebate Amount | BJ2: Oct Q'ty | BK2: Oct Rebate Amount | BL2: Supplier Part# | BM2: Comment
A3: FY23 | D3: Commercial | F3: 200 | AO3: =AB3*AN3 -> 0 | AQ3: =AC3*AP3 -> 0 | AS3: =AD3*AR3 -> 0 | AU3: =AE3*AT3 -> 0 | AW3: =AF3*AV3 -> 0 | AY3: =AG3*AX3 -> 0 | BA3: =AH3*AZ3 -> 0 | BC3: =AI3*BB3 -> 0 | BE3: =AJ3*BD3 -> 0 | BG3: =AK3*BF3 -> 0 | BI3: =AL3*BH3 -> 0 | BK3: =AM3*BJ3 -> 0
A4: FY23 | AO4: =AB4*AN4 -> 0 | AQ4: =AC4*AP4 -> 0 | AS4: =AD4*AR4 -> 0 | AU4: =AE4*AT4 -> 0 | AW4: =AF4*AV4 -> 0 | AY4: =AG4*AX4 -> 0 | BA4: =AH4*AZ4 -> 0 | BC4: =AI4*BB4 -> 0 | BE4: =AJ4*BD4 -> 0 | BG4: =AK4*BF4 -> 0 | BI4: =AL4*BH4 -> 0 | BK4: =AM4*BJ4 -> 0
A5: FY23 | AO5: =AB5*AN5 -> 0 | AQ5: =AC5*AP5 -> 0 | AS5: =AD5*AR5 -> 0 | AU5: =AE5*AT5 -> 0 | AW5: =AF5*AV5 -> 0 | AY5: =AG5*AX5 -> 0 | BA5: =AH5*AZ5 -> 0 | BC5: =AI5*BB5 -> 0 | BE5: =AJ5*BD5 -> 0 | BG5: =AK5*BF5 -> 0 | BI5: =AL5*BH5 -> 0 | BK5: =AM5*BJ5 -> 0
A6: FY23 | F6: 400 | AO6: =AB6*AN6 -> 0 | AQ6: =AC6*AP6 -> 0 | AS6: =AD6*AR6 -> 0 | AU6: =AE6*AT6 -> 0 | AW6: =AF6*AV6 -> 0 | AY6: =AG6*AX6 -> 0 | BA6: =AH6*AZ6 -> 0 | BC6: =AI6*BB6 -> 0 | BE6: =AJ6*BD6 -> 0 | BG6: =AK6*BF6 -> 0 | BI6: =AL6*BH6 -> 0 | BK6: =AM6*BJ6 -> 0
A7: FY23 | AO7: =AB7*AN7 -> 0 | AQ7: =AC7*AP7 -> 0 | AS7: =AD7*AR7 -> 0 | AU7: =AE7*AT7 -> 0 | AW7: =AF7*AV7 -> 0 | AY7: =AG7*AX7 -> 0 | BA7: =AH7*AZ7 -> 0 | BC7: =AI7*BB7 -> 0 | BE7: =AJ7*BD7 -> 0 | BG7: =AK7*BF7 -> 0 | BI7: =AL7*BH7 -> 0 | BK7: =AM7*BJ7 -> 0
A8: FY23 | AO8: =AB8*AN8 -> 0 | AQ8: =AC8*AP8 -> 0 | AS8: =AD8*AR8 -> 0 | AU8: =AE8*AT8 -> 0 | AW8: =AF8*AV8 -> 0 | AY8: =AG8*AX8 -> 0 | BA8: =AH8*AZ8 -> 0 | BC8: =AI8*BB8 -> 0 | BE8: =AJ8*BD8 -> 0 | BG8: =AK8*BF8 -> 0 | BI8: =AL8*BH8 -> 0 | BK8: =AM8*BJ8 -> 0
A9: FY23 | AO9: =AB9*AN9 -> 0 | AQ9: =AC9*AP9 -> 0 | AS9: =AD9*AR9 -> 0 | AU9: =AE9*AT9 -> 0 | AW9: =AF9*AV9 -> 0 | AY9: =AG9*AX9 -> 0 | BA9: =AH9*AZ9 -> 0 | BC9: =AI9*BB9 -> 0 | BE9: =AJ9*BD9 -> 0 | BG9: =AK9*BF9 -> 0 | BI9: =AL9*BH9 -> 0 | BK9: =AM9*BJ9 -> 0
A10: FY23 | AO10: =AB10*AN10 -> 0 | AQ10: =AC10*AP10 -> 0 | AS10: =AD10*AR10 -> 0 | AU10: =AE10*AT10 -> 0 | AW10: =AF10*AV10 -> 0 | AY10: =AG10*AX10 -> 0 | BA10: =AH10*AZ10 -> 0 | BC10: =AI10*BB10 -> 0 | BE10: =AJ10*BD10 -> 0 | BG10: =AK10*BF10 -> 0 | BI10: =AL10*BH10 -> 0 | BK10: =AM10*BJ10 -> 0
A11: FY23 | AO11: =AB11*AN11 -> 0 | AQ11: =AC11*AP11 -> 0 | AS11: =AD11*AR11 -> 0 | AU11: =AE11*AT11 -> 0 | AW11: =AF11*AV11 -> 0 | AY11: =AG11*AX11 -> 0 | BA11: =AH11*AZ11 -> 0 | BC11: =AI11*BB11 -> 0 | BE11: =AJ11*BD11 -> 0 | BG11: =AK11*BF11 -> 0 | BI11: =AL11*BH11 -> 0 | BK11: =AM11*BJ11 -> 0
A12: FY23 | AO12: =AB12*AN12 -> 0 | AQ12: =AC12*AP12 -> 0 | AS12: =AD12*AR12 -> 0 | AU12: =AE12*AT12 -> 0 | AW12: =AF12*AV12 -> 0 | AY12: =AG12*AX12 -> 0 | BA12: =AH12*AZ12 -> 0 | BC12: =AI12*BB12 -> 0 | BE12: =AJ12*BD12 -> 0 | BG12: =AK12*BF12 -> 0 | BI12: =AL12*BH12 -> 0 | BK12: =AM12*BJ12 -> 0
A13: FY23 | AO13: =AB13*AN13 -> 0 | AQ13: =AC13*AP13 -> 0 | AS13: =AD13*AR13 -> 0 | AU13: =AE13*AT13 -> 0 | AW13: =AF13*AV13 -> 0 | AY13: =AG13*AX13 -> 0 | BA13: =AH13*AZ13 -> 0 | BC13: =AI13*BB13 -> 0 | BE13: =AJ13*BD13 -> 0 | BG13: =AK13*BF13 -> 0 | BI13: =AL13*BH13 -> 0 | BK13: =AM13*BJ13 -> 0
A14: FY23 | F14: 600 | AO14: =AB14*AN14 -> 0 | AQ14: =AC14*AP14 -> 0 | AS14: =AD14*AR14 -> 0 | AU14: =AE14*AT14 -> 0 | AW14: =AF14*AV14 -> 0 | AY14: =AG14*AX14 -> 0 | BA14: =AH14*AZ14 -> 0 | BC14: =AI14*BB14 -> 0 | BE14: =AJ14*BD14 -> 0 | BG14: =AK14*BF14 -> 0 | BI14: =AL14*BH14 -> 0 | BK14: =AM14*BJ14 -> 0
A15: FY23 | AO15: =AB15*AN15 -> 0 | AQ15: =AC15*AP15 -> 0 | AS15: =AD15*AR15 -> 0 | AU15: =AE15*AT15 -> 0 | AW15: =AF15*AV15 -> 0 | AY15: =AG15*AX15 -> 0 | BA15: =AH15*AZ15 -> 0 | BC15: =AI15*BB15 -> 0 | BE15: =AJ15*BD15 -> 0 | BG15: =AK15*BF15 -> 0 | BI15: =AL15*BH15 -> 0 | BK15: =AM15*BJ15 -> 0
A16: FY23 | AO16: =AB16*AN16 -> 0 | AQ16: =AC16*AP16 -> 0 | AS16: =AD16*AR16 -> 0 | AU16: =AE16*AT16 -> 0 | AW16: =AF16*AV16 -> 0 | AY16: =AG16*AX16 -> 0 | BA16: =AH16*AZ16 -> 0 | BC16: =AI16*BB16 -> 0 | BE16: =AJ16*BD16 -> 0 | BG16: =AK16*BF16 -> 0 | BI16: =AL16*BH16 -> 0 | BK16: =AM16*BJ16 -> 0
A17: FY23 | AO17: =AB17*AN17 -> 0 | AQ17: =AC17*AP17 -> 0 | AS17: =AD17*AR17 -> 0 | AU17: =AE17*AT17 -> 0 | AW17: =AF17*AV17 -> 0 | AY17: =AG17*AX17 -> 0 | BA17: =AH17*AZ17 -> 0 | BC17: =AI17*BB17 -> 0 | BE17: =AJ17*BD17 -> 0 | BG17: =AK17*BF17 -> 0 | BI17: =AL17*BH17 -> 0 | BK17: =AM17*BJ17 -> 0
A18: FY23 | AO18: =AB18*AN18 -> 0 | AQ18: =AC18*AP18 -> 0 | AS18: =AD18*AR18 -> 0 | AU18: =AE18*AT18 -> 0 | AW18: =AF18*AV18 -> 0 | AY18: =AG18*AX18 -> 0 | BA18: =AH18*AZ18 -> 0 | BC18: =AI18*BB18 -> 0 | BE18: =AJ18*BD18 -> 0 | BG18: =AK18*BF18 -> 0 | BI18: =AL18*BH18 -> 0 | BK18: =AM18*BJ18 -> 0
A19: FY23 | AO19: =AB19*AN19 -> 0 | AQ19: =AC19*AP19 -> 0 | AS19: =AD19*AR19 -> 0 | AU19: =AE19*AT19 -> 0 | AW19: =AF19*AV19 -> 0 | AY19: =AG19*AX19 -> 0 | BA19: =AH19*AZ19 -> 0 | BC19: =AI19*BB19 -> 0 | BE19: =AJ19*BD19 -> 0 | BG19: =AK19*BF19 -> 0 | BI19: =AL19*BH19 -> 0 | BK19: =AM19*BJ19 -> 0
A20: FY23 | F20: 800 | AO20: =AB20*AN20 -> 0 | AQ20: =AC20*AP20 -> 0 | AS20: =AD20*AR20 -> 0 | AU20: =AE20*AT20 -> 0 | AW20: =AF20*AV20 -> 0 | AY20: =AG20*AX20 -> 0 | BA20: =AH20*AZ20 -> 0 | BC20: =AI20*BB20 -> 0 | BE20: =AJ20*BD20 -> 0 | BG20: =AK20*BF20 -> 0 | BI20: =AL20*BH20 -> 0 | BK20: =AM20*BJ20 -> 0
A21: FY23 | AO21: =AB21*AN21 -> 0 | AQ21: =AC21*AP21 -> 0 | AS21: =AD21*AR21 -> 0 | AU21: =AE21*AT21 -> 0 | AW21: =AF21*AV21 -> 0 | AY21: =AG21*AX21 -> 0 | BA21: =AH21*AZ21 -> 0 | BC21: =AI21*BB21 -> 0 | BE21: =AJ21*BD21 -> 0 | BG21: =AK21*BF21 -> 0 | BI21: =AL21*BH21 -> 0 | BK21: =AM21*BJ21 -> 0
A22: FY23 | AO22: =AB22*AN22 -> 0 | AQ22: =AC22*AP22 -> 0 | AS22: =AD22*AR22 -> 0 | AU22: =AE22*AT22 -> 0 | AW22: =AF22*AV22 -> 0 | AY22: =AG22*AX22 -> 0 | BA22: =AH22*AZ22 -> 0 | BC22: =AI22*BB22 -> 0 | BE22: =AJ22*BD22 -> 0 | BG22: =AK22*BF22 -> 0 | BI22: =AL22*BH22 -> 0 | BK22: =AM22*BJ22 -> 0
A23: FY23 | AO23: =AB23*AN23 -> 0 | AQ23: =AC23*AP23 -> 0 | AS23: =AD23*AR23 -> 0 | AU23: =AE23*AT23 -> 0 | AW23: =AF23*AV23 -> 0 | AY23: =AG23*AX23 -> 0 | BA23: =AH23*AZ23 -> 0 | BC23: =AI23*BB23 -> 0 | BE23: =AJ23*BD23 -> 0 | BG23: =AK23*BF23 -> 0 | BI23: =AL23*BH23 -> 0 | BK23: =AM23*BJ23 -> 0
A24: FY23 | AO24: =AB24*AN24 -> 0 | AQ24: =AC24*AP24 -> 0 | AS24: =AD24*AR24 -> 0 | AU24: =AE24*AT24 -> 0 | AW24: =AF24*AV24 -> 0 | AY24: =AG24*AX24 -> 0 | BA24: =AH24*AZ24 -> 0 | BC24: =AI24*BB24 -> 0 | BE24: =AJ24*BD24 -> 0 | BG24: =AK24*BF24 -> 0 | BI24: =AL24*BH24 -> 0 | BK24: =AM24*BJ24 -> 0
A25: FY23 | AO25: =AB25*AN25 -> 0 | AQ25: =AC25*AP25 -> 0 | AS25: =AD25*AR25 -> 0 | AU25: =AE25*AT25 -> 0 | AW25: =AF25*AV25 -> 0 | AY25: =AG25*AX25 -> 0 | BA25: =AH25*AZ25 -> 0 | BC25: =AI25*BB25 -> 0 | BE25: =AJ25*BD25 -> 0 | BG25: =AK25*BF25 -> 0 | BI25: =AL25*BH25 -> 0 | BK25: =AM25*BJ25 -> 0
A26: FY23 | AO26: =AB26*AN26 -> 0 | AQ26: =AC26*AP26 -> 0 | AS26: =AD26*AR26 -> 0 | AU26: =AE26*AT26 -> 0 | AW26: =AF26*AV26 -> 0 | AY26: =AG26*AX26 -> 0 | BA26: =AH26*AZ26 -> 0 | BC26: =AI26*BB26 -> 0 | BE26: =AJ26*BD26 -> 0 | BG26: =AK26*BF26 -> 0 | BI26: =AL26*BH26 -> 0 | BK26: =AM26*BJ26 -> 0
A27: FY23 | AO27: =AB27*AN27 -> 0 | AQ27: =AC27*AP27 -> 0 | AS27: =AD27*AR27 -> 0 | AU27: =AE27*AT27 -> 0 | AW27: =AF27*AV27 -> 0 | AY27: =AG27*AX27 -> 0 | BA27: =AH27*AZ27 -> 0 | BC27: =AI27*BB27 -> 0 | BE27: =AJ27*BD27 -> 0 | BG27: =AK27*BF27 -> 0 | BI27: =AL27*BH27 -> 0 | BK27: =AM27*BJ27 -> 0
A28: FY23 | AO28: =AB28*AN28 -> 0 | AQ28: =AC28*AP28 -> 0 | AS28: =AD28*AR28 -> 0 | AU28: =AE28*AT28 -> 0 | AW28: =AF28*AV28 -> 0 | AY28: =AG28*AX28 -> 0 | BA28: =AH28*AZ28 -> 0 | BC28: =AI28*BB28 -> 0 | BE28: =AJ28*BD28 -> 0 | BG28: =AK28*BF28 -> 0 | BI28: =AL28*BH28 -> 0 | BK28: =AM28*BJ28 -> 0
A29: FY23 | AO29: =AB29*AN29 -> 0 | AQ29: =AC29*AP29 -> 0 | AS29: =AD29*AR29 -> 0 | AU29: =AE29*AT29 -> 0 | AW29: =AF29*AV29 -> 0 | AY29: =AG29*AX29 -> 0 | BA29: =AH29*AZ29 -> 0 | BC29: =AI29*BB29 -> 0 | BE29: =AJ29*BD29 -> 0 | BG29: =AK29*BF29 -> 0 | BI29: =AL29*BH29 -> 0 | BK29: =AM29*BJ29 -> 0
A30: FY23 | AO30: =AB30*AN30 -> 0 | AQ30: =AC30*AP30 -> 0 | AS30: =AD30*AR30 -> 0 | AU30: =AE30*AT30 -> 0 | AW30: =AF30*AV30 -> 0 | AY30: =AG30*AX30 -> 0 | BA30: =AH30*AZ30 -> 0 | BC30: =AI30*BB30 -> 0 | BE30: =AJ30*BD30 -> 0 | BG30: =AK30*BF30 -> 0 | BI30: =AL30*BH30 -> 0 | BK30: =AM30*BJ30 -> 0
A31: FY23 | F31: 1000 | AO31: =AB31*AN31 -> 0 | AQ31: =AC31*AP31 -> 0 | AS31: =AD31*AR31 -> 0 | AU31: =AE31*AT31 -> 0 | AW31: =AF31*AV31 -> 0 | AY31: =AG31*AX31 -> 0 | BA31: =AH31*AZ31 -> 0 | BC31: =AI31*BB31 -> 0 | BE31: =AJ31*BD31 -> 0 | BG31: =AK31*BF31 -> 0 | BI31: =AL31*BH31 -> 0 | BK31: =AM31*BJ31 -> 0
A32: FY23 | AO32: =AB32*AN32 -> 0 | AQ32: =AC32*AP32 -> 0 | AS32: =AD32*AR32 -> 0 | AU32: =AE32*AT32 -> 0 | AW32: =AF32*AV32 -> 0 | AY32: =AG32*AX32 -> 0 | BA32: =AH32*AZ32 -> 0 | BC32: =AI32*BB32 -> 0 | BE32: =AJ32*BD32 -> 0 | BG32: =AK32*BF32 -> 0 | BI32: =AL32*BH32 -> 0 | BK32: =AM32*BJ32 -> 0
A33: FY23 | AO33: =AB33*AN33 -> 0 | AQ33: =AC33*AP33 -> 0 | AS33: =AD33*AR33 -> 0 | AU33: =AE33*AT33 -> 0 | AW33: =AF33*AV33 -> 0 | AY33: =AG33*AX33 -> 0 | BA33: =AH33*AZ33 -> 0 | BC33: =AI33*BB33 -> 0 | BE33: =AJ33*BD33 -> 0 | BG33: =AK33*BF33 -> 0 | BI33: =AL33*BH33 -> 0 | BK33: =AM33*BJ33 -> 0
A34: FY23 | AO34: =AB34*AN34 -> 0 | AQ34: =AC34*AP34 -> 0 | AS34: =AD34*AR34 -> 0 | AU34: =AE34*AT34 -> 0 | AW34: =AF34*AV34 -> 0 | AY34: =AG34*AX34 -> 0 | BA34: =AH34*AZ34 -> 0 | BC34: =AI34*BB34 -> 0 | BE34: =AJ34*BD34 -> 0 | BG34: =AK34*BF34 -> 0 | BI34: =AL34*BH34 -> 0 | BK34: =AM34*BJ34 -> 0
A35: FY23 | F35: Clickpad | AO35: =AB35*AN35 -> 0 | AQ35: =AC35*AP35 -> 0 | AS35: =AD35*AR35 -> 0 | AU35: =AE35*AT35 -> 0 | AW35: =AF35*AV35 -> 0 | AY35: =AG35*AX35 -> 0 | BA35: =AH35*AZ35 -> 0 | BC35: =AI35*BB35 -> 0 | BE35: =AJ35*BD35 -> 0 | BG35: =AK35*BF35 -> 0 | BI35: =AL35*BH35 -> 0 | BK35: =AM35*BJ35 -> 0
A36: FY23 | AO36: =AB36*AN36 -> 0 | AQ36: =AC36*AP36 -> 0 | AS36: =AD36*AR36 -> 0 | AU36: =AE36*AT36 -> 0 | AW36: =AF36*AV36 -> 0 | AY36: =AG36*AX36 -> 0 | BA36: =AH36*AZ36 -> 0 | BC36: =AI36*BB36 -> 0 | BE36: =AJ36*BD36 -> 0 | BG36: =AK36*BF36 -> 0 | BI36: =AL36*BH36 -> 0 | BK36: =AM36*BJ36 -> 0
A37: FY23 | B37: Iris Huang | C37: Darfon | E37: NB | F37: Education | G37: 2022 | H37: ANOLE1/ARIZONA | I37: NBL KB | J37: 11 | K37: Jet Black/Jellyfish Blue | L37: W China | M37: INVENTEC | N37: 4.8 | O37: 4.8 | P37: 4.8 | Q37: 4.8 | R37: 4.8 | S37: 4.8 | T37: 4.8 | U37: 4.8 | V37: 4.8 | W37: 4.8 | X37: 4.8 | Y37: 4.8 | Z37: 4.8 | AA37: 0.8 | AB37: 0.8 | AC37: 0.8 | AD37: 0.8 | AE37: 1.26 | AF37: 1.26 | AG37: 1.26 | AH37: 1.26 | AI37: 1.26 | AJ37: 1.26 | AK37: 1.26 | AL37: 1.26 | AM37: 1.26 | AN37: 9080 | AO37: =AB37*AN37 -> 7264 | AP37: 4480 | AQ37: =AC37*AP37 -> 3584 | AR37: 8440 | AS37: =AD37*AR37 -> 6752 | AT37: 25480 | AU37: =AE37*AT37 -> 32104.8 | AV37: 41537 | AW37: =AF37*AV37 -> 52336.62 | AX37: 23118 | AY37: =AG37*AX37 -> 29128.68 | AZ37: 32640 | BA37: =AH37*AZ37 -> 41126.4 | BB37: 19480 | BC37: =AI37*BB37 -> 24544.8 | BD37: 15098 | BE37: =AJ37*BD37 -> 19023.48 | BF37: 12840 | BG37: =AK37*BF37 -> 16178.4 | BH37: 34040 | BI37: =AL37*BH37 -> 42890.4 | BJ37: 14360 | BK37: =AM37*BJ37 -> 18093.6
A38: FY23 | B38: Iris Huang | C38: Darfon | E38: NB | G38: 2022 | H38: ARCLIGHT1 | I38: NBL KB | J38: 14 | K38: Jet Black | L38: W China | M38: INVENTEC | N38: 4.9 | O38: 4.9 | P38: 4.9 | Q38: 4.9 | R38: 4.9 | S38: 4.9 | T38: 4.9 | U38: 4.9 | V38: 4.9 | W38: 4.9 | X38: 4.9 | Y38: 4.9 | Z38: 4.9 | AA38: 0.9 | AB38: 0.9 | AC38: 0.9 | AD38: 0.9 | AE38: 1.36 | AF38: 1.36 | AG38: 1.36 | AH38: 1.36 | AI38: 1.36 | AJ38: 1.36 | AK38: 1.36 | AL38: 1.36 | AM38: 1.36 | AN38: 120 | AO38: =AB38*AN38 -> 108 | AP38: 400 | AQ38: =AC38*AP38 -> 360 | AR38: 680 | AS38: =AD38*AR38 -> 612 | AT38: 360 | AU38: =AE38*AT38 -> 489.6 | AV38: 8160 | AW38: =AF38*AV38 -> 11097.6 | AX38: 2520 | AY38: =AG38*AX38 -> 3427.2 | AZ38: 14320 | BA38: =AH38*AZ38 -> 19475.2 | BB38: 2758 | BC38: =AI38*BB38 -> 3750.88 | BD38: 1760 | BE38: =AJ38*BD38 -> 2393.6 | BF38: 560 | BG38: =AK38*BF38 -> 761.6 | BH38: 9200 | BI38: =AL38*BH38 -> 12512 | BJ38: 2200 | BK38: =AM38*BJ38 -> 2992
A39: FY23 | B39: Iris Huang | C39: Darfon | E39: NB | F39: MWS (Workstation) | G39: 2020 | H39: VALERIAN | I39: BL KB | J39: 15 | K39: Flint | L39: E China | M39: COMPAL | N39: 23.61 | O39: 23.61 | P39: 23.61 | Q39: 23.61 | R39: 23.61 | S39: 23.61 | T39: 23.61 | U39: 23.61 | V39: 23.61 | W39: 23.61 | X39: 23.61 | Y39: 23.61 | Z39: 23.61 | AA39: 8 | AB39: 8 | AC39: 8 | AD39: 8 | AE39: 8.81 | AF39: 8.81 | AG39: 8.81 | AH39: 8.81 | AI39: 8.81 | AJ39: 8.81 | AK39: 8.81 | AL39: 8.81 | AM39: 8.81 | AN39: 7991 | AO39: =AB39*AN39 -> 63928 | AP39: 6647 | AQ39: =AC39*AP39 -> 53176 | AR39: 9343 | AS39: =AD39*AR39 -> 74744 | AT39: 10202 | AU39: =AE39*AT39 -> 89879.62 | AV39: 4395 | AW39: =AF39*AV39 -> 38719.95 | AX39: 2268 | AY39: =AG39*AX39 -> 19981.08 | AZ39: 4298 | BA39: =AH39*AZ39 -> 37865.38 | BB39: 558 | BC39: =AI39*BB39 -> 4915.98 | BD39: 600 | BE39: =AJ39*BD39 -> 5286 | BF39: 313 | BG39: =AK39*BF39 -> 2757.53 | BH39: 480 | BI39: =AL39*BH39 -> 4228.8 | BJ39: 80 | BK39: =AM39*BJ39 -> 704.8
A40: FY23 | B40: Iris Huang | C40: Darfon | E40: NB | G40: 2020 | H40: ALDER | I40: BL KB | J40: 17 | K40: Flint | L40: E China | M40: COMPAL | N40: 24.21 | O40: 24.21 | P40: 24.21 | Q40: 24.21 | R40: 24.21 | S40: 24.21 | T40: 24.21 | U40: 24.21 | V40: 24.21 | W40: 24.21 | X40: 24.21 | Y40: 24.21 | Z40: 24.21 | AA40: 8 | AB40: 8 | AC40: 8 | AD40: 8 | AE40: 9.01 | AF40: 9.01 | AG40: 9.01 | AH40: 9.01 | AI40: 9.01 | AJ40: 9.01 | AK40: 9.01 | AL40: 9.01 | AM40: 9.01 | AN40: 2149 | AO40: =AB40*AN40 -> 17192 | AP40: 2565 | AQ40: =AC40*AP40 -> 20520 | AR40: 2708 | AS40: =AD40*AR40 -> 21664 | AT40: 3440 | AU40: =AE40*AT40 -> 30994.4 | AV40: 4257 | AW40: =AF40*AV40 -> 38355.57 | AX40: 1295 | AY40: =AG40*AX40 -> 11667.95 | AZ40: 1193 | BA40: =AH40*AZ40 -> 10748.93 | BB40: 830 | BC40: =AI40*BB40 -> 7478.3 | BD40: 80 | BE40: =AJ40*BD40 -> 720.8 | BF40: 387 | BG40: =AK40*BF40 -> 3486.87 | BH40: 40 | BI40: =AL40*BH40 -> 360.4 | BK40: =AM40*BJ40 -> 0
...

Sheet FY24 Summary_1
B3: Supplier's name | C3: 2023 11 | D3: 2023 12 | E3: 2024 01 | F3: Total Q1
B4: Rebate amount | C4: =SUM('FY24'!AP1) -> 632724.29 | D4: =SUM('FY24'!AR1) -> 1177587 | E4: =SUM('FY24'!AT1) -> 780271.42 | F4: =SUM(C4:E4) -> 2590582.7
B5: E&O reduction | C5: 0 | D5: 4611.43 | E5: 8106.08 | F5: =SUM(C5:E5) -> 12717.51
B6: Complexity reduction | C6: 0 | D6: 0 | E6: 0 | F6: =SUM(C6:E6) -> 0 | H6: 1. 新增Summary_1, 原先的Summary重新命名為Summary_2
B7: Total amount | C7: =SUM(C4:C6) -> 632724.29 | D7: =SUM(D4:D6) -> 1182198.4 | E7: =SUM(E4:E6) -> 788377.5 | F7: =SUM(F4:F6) -> 2603300.2
H8: 2.黃色部位為貴司名稱, 請整份報告都跟檔名貴司名稱撰寫方式一致
B10: Supplier's name | C10: 2024 02 | D10: 2024 03 | E10: 2024 04 | F10: Total Q2 | H10: 3. 這些欄位一定要固定, B3-B28, C3-C28, D3-D28, E3-E28, F3-F28都有賦予定義
B11: Rebate amount | C11: =SUM('FY24'!AV1) -> 721055.04 | D11: =SUM('FY24'!AX1) -> 1269953.2 | E11: =SUM('FY24'!AZ1) -> 1100883.6 | F11: =SUM(C11:E11) -> 3091891.8
B12: E&O reduction | C12: 0 | D12: 0 | E12: 0 | F12: =SUM(C12:E12) -> 0 | H12: 4. Rebate amount 指得是summary_2的page金額 (就是我們一直以來收集的金額)
B13: Complexity reduction | C13: 0 | D13: 0 | E13: 0 | F13: =SUM(C13:E13) -> 0
B14: Total amount | C14: =SUM(C11:C13) -> 721055.04 | D14: =SUM(D11:D13) -> 1269953.2 | E14: =SUM(E11:E13) -> 1100883.6 | F14: =SUM(F11:F13) -> 3091891.8 | H14: 5. 新增 E&O reduction 及complexity reduction品項, 先留足空間
H15: 若目前還未有此款項存在都先填0
B17: Supplier's name | C17: 2024 05 | D17: 2024 06 | E17: 2024 07 | F17: Total Q3 | H17: 6. 金額都放未經調整後的真實數字, 分析才具意義
B18: Rebate amount | C18: =SUM('FY24'!BB1) -> 1454500.9 | D18: =SUM('FY24'!BD1) -> 1487747.3 | E18: =SUM('FY24'!BF1) -> 1179453.1 | F18: =SUM(C18:E18) -> 4121701.3
B19: E&O reduction | C19: 0 | D19: 0 | E19: 130797.29 | F19: =SUM(C19:E19) -> 130797.29
B20: Complexity reduction | C20: 0 | D20: 0 | E20: 0 | F20: =SUM(C20:E20) -> 0
B21: Total amount | C21: =SUM(C18:C20) -> 1454500.9 | D21: =SUM(D18:D20) -> 1487747.3 | E21: =SUM(E18:E20) -> 1310250.3 | F21: =SUM(F18:F20) -> 4252498.6
B24: Supplier's name | C24: 2024 08 | D24: 2024 09 | E24: 2024 10 | F24: Total Q4
B25: Rebate amount | C25: =SUM('FY24'!BH1) -> 1424994.8 | D25: =SUM('FY24'!BJ1) -> 1735007.2 | E25: =SUM('FY24'!BL1) -> 1374350.6 | F25: =SUM(C25:E25) -> 4534352.7
B26: E&O reduction | C26: 0 | D26: 0 | E26: 0 | F26: =SUM(C26:E26) -> 0
B27: Complexity reduction | C27: 0 | D27: 0 | E27: 0 | F27: =SUM(C27:E27) -> 0
B28: Total amount | C28: =SUM(C25:C27) -> 1424994.8 | D28: =SUM(D25:D27) -> 1735007.2 | E28: =SUM(E25:E27) -> 1374350.6 | F28: =SUM(F25:F27) -> 4534352.7

Sheet FY24 Summary_2
B3: Q1 Actual by Segment
C4: Segment | D4: 45231 | E4: 45261 | F4: 45292 | G4: Total Rebate in Q1 2024 (US$)
B5: CMIT Input Devices | C5: 200 series (6U) | D5: =SUM('FY24'!AP$149:AP$193)*0.25 -> 73703.9 | E5: =SUM('FY24'!AR149:AR193)*0.25 -> 72614.775 | F5: =SUM('FY24'!AT149:AT193)*0.25 -> 64714.575 | G5: =SUM(D5:F5) -> 211033.25
C6: 400 /600 series (S/B) | D6: =SUM('FY24'!AP$6:AP$13) -> 0 | E6: =SUM('FY24'!AR6:AR13) -> 0 | F6: =SUM('FY24'!AT6:AT13) -> 0 | G6: =SUM(D6:F6) -> 0
C7: 800 series (P) | D7: =SUM('FY24'!AP$14:AP$24) -> 0 | E7: =SUM('FY24'!AR14:AR24) -> 0 | F7: =SUM('FY24'!AT14:AT24) -> 0 | G7: =SUM(D7:F7) -> 0
C8: 1000 series (M | D8: =SUM('FY24'!AP$25:AP$28) -> 0 | E8: =SUM('FY24'!AR25:AR28) -> 0 | F8: =SUM('FY24'!AT25:AT28) -> 0 | G8: =SUM(D8:F8) -> 0
C9: MWS (Workstation) | D9: =SUM('FY24'!AP$33:AP$34) -> 0 | E9: =SUM('FY24'!AR33:AR34) -> 0 | F9: =SUM('FY24'!AT33:AT34) -> 0 | G9: =SUM(D9:F9) -> 0
C10: Soft Keyboard | D10: =SUM('FY24'!AP$35:AP$38) -> 0 | E10: =SUM('FY24'!AR35:AR38) -> 0 | F10: =SUM('FY24'!AT35:AT38) -> 0 | G10: =SUM(D10:F10) -> 0
C11: Chrome Book | D11: =SUM('FY24'!AP$39:AP$52)*0.7 -> 8512 | E11: =SUM('FY24'!AR39:AR52)*0.7 -> 43094.1 | F11: =SUM('FY24'!AT39:AT52)*0.7 -> 22919.4 | G11: =SUM(D11:F11) -> 74525.5
C12: Clickpad | D12: =SUM('FY24'!AP$29:AP$30) -> 0 | E12: =SUM('FY24'!AR29:AR30) -> 0 | F12: =SUM('FY24'!AT29:AT30) -> 0 | G12: =SUM(D12:F12) -> 0
C13: Education | D13: =SUM('FY24'!AP$31:AP$32) -> 10450.22 | E13: =SUM('FY24'!AR31:AR32) -> 5550.4 | F13: =SUM('FY24'!AT31:AT32) -> 19585.6 | G13: =SUM(D13:F13) -> 35586.22
C14: Peripherals/AMO | G14: =SUM(D14:F14) -> 0
C15: Desktop | D15: =SUM('FY24'!AP$53:AP$61) -> 34155.08 | E15: =SUM('FY24'!AR53:AR61) -> 42030.76 | F15: =SUM('FY24'!AT53:AT61) -> 19579.38 | G15: =SUM(D15:F15) -> 95765.22
B16: Consumer Input Devices | C16: OPP | D16: =SUM('FY24'!AP$149:AP$193)*0.75+SUM('FY24'!AP62:AP76) -> 337364.59 | E16: =SUM('FY24'!AR149:AR193)*0.75+SUM('FY24'!AR62:AR76) -> 587172.04 | F16: =SUM('FY24'!AT149:AT193)*0.75+SUM('FY24'!AT62:AT76) -> 306257.72 | G16: =SUM(D16:F16) -> 1230794.4
C17: Chrome Book | D17: =SUM('FY24'!AP$39:AP$52)*0.3 -> 3648 | E17: =SUM('FY24'!AR39:AR52)*0.3 -> 18468.9 | F17: =SUM('FY24'!AT39:AT52)*0.3 -> 9822.6 | G17: =SUM(D17:F17) -> 31939.5
C18: Pavillion | D18: =SUM('FY24'!AP$86:AP$105) -> 61540 | E18: =SUM('FY24'!AR86:AR105) -> 214380 | F18: =SUM('FY24'!AT86:AT105) -> 120854 | G18: =SUM(D18:F18) -> 396774
C19: Spectre | D19: =SUM('FY24'!AP$106:AP$108) -> 0 | E19: =SUM('FY24'!AR106:AR108) -> 0 | F19: =SUM('FY24'!AT106:AT108) -> 13088.4 | G19: =SUM(D19:F19) -> 13088.4
C20: Envy | D20: =SUM('FY24'!AP$109:AP$116) -> 49680 | E20: =SUM('FY24'!AR109:AR116) -> 92880 | F20: =SUM('FY24'!AT109:AT116) -> 59295 | G20: =SUM(D20:F20) -> 201855
C21: Stream | D21: =SUM('FY24'!AP$117:AP$118) -> 9296 | E21: =SUM('FY24'!AR117:AR118) -> 3332 | F21: =SUM('FY24'!AT117:AT118) -> 4676 | G21: =SUM(D21:F21) -> 17304
C22: Omen | D22: =SUM('FY24'!AP$119:AP$130) -> 44374.5 | E22: =SUM('FY24'!AR119:AR130) -> 98064 | F22: =SUM('FY24'!AT119:AT130) -> 139258 | G22: =SUM(D22:F22) -> 281696.5
C23: Peripherals/AMO | D23: =SUM('FY24'!AP138:AP148) -> 0 | E23: =SUM('FY24'!AR138:AR148) -> 0 | F23: =SUM('FY24'!AT138:AT148) -> 220.74 | G23: =SUM(D23:F23) -> 220.74
C24: Desktop | D24: =SUM('FY24'!AP$131:AP$137) -> 0 | E24: =SUM('FY24'!AR131:AR137) -> 0 | F24: =SUM('FY24'!AT131:AT137) -> 0 | G24: =SUM(D24:F24) -> 0
G25: =SUM(G5:G24) -> 2590582.7
B27: Q1 Actual by Segment
C28: Supplier | D28: 45231 | E28: 45261 | F28: 45292 | G28: Total Rebate in Q1 2024 (US$)
B29: Input Devices | C29: Acrox
C30: Chicony
C31: Darfon | D31: =SUM(D5:D24) -> 632724.29 | E31: =SUM(E5:E24) -> 1177587 | F31: =SUM(F5:F24) -> 780271.42 | G31: =SUM(D31:F31) -> 2590582.7
C32: Liteon
C33: Primax
C34: Sunrex
F35: Total Rebate Amount | G35: =SUM(G29:G34) -> 2590582.7
B38: Q2 Actual by Segment
C39: Segment | D39: 45323 | E39: 45352 | F39: 45383 | G39: Total Rebate in Q2 2024 (US$)
B40: CMIT Input Devices | C40: 200 series (6U) | D40: =SUM('FY24'!AV$149:AV$193)*0.25 -> 62797.335 | E40: =SUM('FY24'!AX$149:AX$193)*0.25 -> 69902.598 | F40: =SUM('FY24'!AZ$149:AZ$193)*0.25 -> 70753.725 | G40: =SUM(D40:F40) -> 203453.66
C41: 400 /600 series (S/B) | D41: =SUM('FY24'!AV$6:AV$13) -> 0 | E41: =SUM('FY24'!AX$6:AX$13) -> 0 | F41: =SUM('FY24'!AZ$6:AZ$13) -> 91014.8 | G41: =SUM(D41:F41) -> 91014.8
C42: 800 series (P) | D42: =SUM('FY24'!AV$14:AV$24) -> 0 | E42: =SUM('FY24'!AX$14:AX$24) -> 0 | F42: =SUM('FY24'!AZ$14:AZ$24) -> 0 | G42: =SUM(D42:F42) -> 0
C43: 1000 series (M | D43: =SUM('FY24'!AV$25:AV$28) -> 0 | E43: =SUM('FY24'!AX$25:AX$28) -> 0 | F43: =SUM('FY24'!AZ$25:AZ$28) -> 0 | G43: =SUM(D43:F43) -> 0
C44: MWS (Workstation) | D44: =SUM('FY24'!AV$33:AV$34) -> 0 | E44: =SUM('FY24'!AX$33:AX$34) -> 0 | F44: =SUM('FY24'!AZ$33:AZ$34) -> 0 | G44: =SUM(D44:F44) -> 0
C45: Soft Keyboard | D45: =SUM('FY24'!AV$35:AV$38) -> 0 | E45: =SUM('FY24'!AX$35:AX$38) -> 0 | F45: =SUM('FY24'!AZ$35:AZ$38) -> 0 | G45: =SUM(D45:F45) -> 0
...

Sheet FY24
D1: Consumer/Commercial/ Peripheral | E1: NB/DT/Peripheral | G1: 2020/2021/2022 | H1: Remove Size/Color, define Platform naming Hagrid/Hedwig/Granger/Ashmore/Ramla (follow naming rule of product list) | I1: NBL KB/BL KB/Mouse /Combo/Clickpad/Others | J1: NA/ | K1: NA/ | L1: (E China/W China/S China/NMC) | M1: COMPAL/ QUANTA /INVENTEC /WISTRON/ FOXCONN/ OTHERS | AP1: =SUM(AP3:AP922) -> 632724.29 | AR1: =SUM(AR3:AR922) -> 1177587 | AT1: =SUM(AT3:AT922) -> 780271.42 | AV1: =SUM(AV3:AV922) -> 721055.04 | AX1: =SUM(AX3:AX922) -> 1269953.2 | AZ1: =SUM(AZ3:AZ922) -> 1100883.6 | BB1: =SUM(BB3:BB922) -> 1454500.9 | BD1: =SUM(BD3:BD922) -> 1487747.3 | BF1: =SUM(BF3:BF922) -> 1179453.1 | BH1: =SUM(BH3:BH922) -> 1424994.8 | BJ1: =SUM(BJ3:BJ922) -> 1735007.2 | BL1: =SUM(BL3:BL922) -> 1374350.6 | BO1: NA/EMEA/APJ
A2: FY24 | B2: SPM (Project Owner) | C2: GTK Suppliers | D2: Category | E2: Segment | F2: Series | G2: Production Year | H2: Platforms | I2: Product | J2: Size | K2: Color | L2: Location | M2: ODM | N2: RFQ Final Cost | O2: The lowest unit table price (ODM cost) | P2: Table Price Nov | Q2: Table Price Dec | R2: Table Price Jan | S2: Table Price Feb | T2: Table Price Mar | U2: Table Price Apr | V2: Table Price May | W2: Table Price Jun | X2: Table Price Jul | Y2: Table Price Aug | Z2: Table Price Sep | AA2: Table Price Oct | AB2: The lowest unit rebate cost | AC2: Unit Rebate Nov | AD2: Unit Rebate Dec | AE2: Unit Rebate Jan | AF2: Unit Rebate Feb | AG2: Unit Rebate Mar | AH2: Unit Rebate Apr | AI2: Unit Rebate May | AJ2: Unit Rebate Jun | AK2: Unit Rebate Jul | AL2: Unit Rebate Aug | AM2: Unit Rebate Sep | AN2: Unit Rebate Oct | AO2: Nov Q'ty | AP2: Nov Rebate Amount | AQ2: Dec Q'ty | AR2: Dec Rebate Amount | AS2: Jan Q'ty | AT2: Jan Rebate Amount | AU2: Feb Q'ty | AV2: Feb Rebate Amount | AW2: Mar Q'ty | AX2: Mar Rebate Amount | AY2: Apr Q'ty | AZ2: Apr Rebate Amount | BA2: May Q'ty | BB2: May Rebate Amount | BC2: Jun Q'ty | BD2: Jun Rebate Amount | BE2: Jul Q'ty | BF2: Jul Rebate Amount | BG2: Aug Q'ty | BH2: Aug Rebate Amount | BI2: Sep Q'ty | BJ2: Sep Rebate Amount | BK2: Oct Q'ty | BL2: Oct Rebate Amount | BM2: Supplier Part# | BN2: Comment | BO2: Region
A3: FY24 | D3: Commercial | F3: 200 | AP3: =AC3*AO3 -> 0 | AR3: =AD3*AQ3 -> 0 | AT3: =AE3*AS3 -> 0 | AV3: =AF3*AU3 -> 0 | AX3: =AG3*AW3 -> 0 | AZ3: =AH3*AY3 -> 0 | BB3: =AI3*BA3 -> 0 | BD3: =AJ3*BC3 -> 0 | BF3: =AK3*BE3 -> 0 | BH3: =AL3*BG3 -> 0 | BJ3: =AM3*BI3 -> 0 | BL3: =AN3*BK3 -> 0
A4: FY24 | AP4: =AC4*AO4 -> 0 | AR4: =AD4*AQ4 -> 0 | AT4: =AE4*AS4 -> 0 | AV4: =AF4*AU4 -> 0 | AX4: =AG4*AW4 -> 0 | AZ4: =AH4*AY4 -> 0 | BB4: =AI4*BA4 -> 0 | BD4: =AJ4*BC4 -> 0 | BF4: =AK4*BE4 -> 0 | BH4: =AL4*BG4 -> 0 | BJ4: =AM4*BI4 -> 0 | BL4: =AN4*BK4 -> 0
A5: FY24 | AP5: =AC5*AO5 -> 0 | AR5: =AD5*AQ5 -> 0 | AT5: =AE5*AS5 -> 0 | AV5: =AF5*AU5 -> 0 | AX5: =AG5*AW5 -> 0 | AZ5: =AH5*AY5 -> 0 | BB5: =AI5*BA5 -> 0 | BD5: =AJ5*BC5 -> 0 | BF5: =AK5*BE5 -> 0 | BH5: =AL5*BG5 -> 0 | BJ5: =AM5*BI5 -> 0 | BL5: =AN5*BK5 -> 0
A6: FY24 | B6: Sandy Lu | C6: Darfon | E6: NB | F6: 400/600 | G6: 2024 | H6: Olaf/Rex | I6: NBL KB | J6: 16 | K6: Soft Grey | L6: W China | M6: Quanta | N6: 3.25 | O6: 4.43 | P6: 4.52 | Q6: 4.52 | R6: 4.52 | S6: 4.52 | T6: 4.52 | U6: 4.52 | V6: 4.43 | W6: 4.43 | X6: 4.43 | Y6: 4.43 | Z6: 4.43 | AA6: 4.43 | AB6: 1.18 | AC6: 1.27 | AD6: 1.27 | AE6: 1.27 | AF6: 1.27 | AG6: 1.27 | AH6: 1.27 | AI6: 1.18 | AJ6: 1.18 | AK6: 1.18 | AL6: 1.18 | AM6: 1.18 | AN6: 1.18 | AP6: =AC6*AO6 -> 0 | AR6: =AD6*AQ6 -> 0 | AT6: =AE6*AS6 -> 0 | AV6: =AF6*AU6 -> 0 | AX6: =AG6*AW6 -> 0 | AY6: 680 | AZ6: =AH6*AY6 -> 863.6 | BA6: 7200 | BB6: =AI6*BA6 -> 8496 | BC6: 10800 | BD6: =AJ6*BC6 -> 12744 | BE6: 4160 | BF6: =AK6*BE6 -> 4908.8 | BG6: 11640 | BH6: =AL6*BG6 -> 13735.2 | BI6: 11240 | BJ6: =AM6*BI6 -> 13263.2 | BK6: 13919 | BL6: =AN6*BK6 -> 16424.42
A7: FY24 | B7: Sandy Lu | C7: Darfon | E7: NB | G7: 2024 | H7: Olaf/Rex | I7: BL KB | J7: 16 | K7: Soft Grey | L7: W China | M7: Quanta | N7: 8.99 | O7: 13.63 | P7: 15.58 | Q7: 15.58 | R7: 15.58 | S7: 15.58 | T7: 15.58 | U7: 15.58 | V7: 13.63 | W7: 13.63 | X7: 13.63 | Y7: 13.63 | Z7: 13.63 | AA7: 13.63 | AB7: 4.64 | AC7: 6.59 | AD7: 6.59 | AE7: 6.59 | AF7: 6.59 | AG7: 6.59 | AH7: 6.59 | AI7: 4.64 | AJ7: 4.64 | AK7: 4.64 | AL7: 4.64 | AM7: 4.64 | AN7: 4.64 | AP7: =AC7*AO7 -> 0 | AR7: =AD7*AQ7 -> 0 | AT7: =AE7*AS7 -> 0 | AV7: =AF7*AU7 -> 0 | AX7: =AG7*AW7 -> 0 | AY7: 13680 | AZ7: =AH7*AY7 -> 90151.2 | BA7: 32080 | BB7: =AI7*BA7 -> 148851.2 | BC7: 53320 | BD7: =AJ7*BC7 -> 247404.8 | BE7: 22680 | BF7: =AK7*BE7 -> 105235.2 | BG7: 20400 | BH7: =AL7*BG7 -> 94656 | BI7: 42040 | BJ7: =AM7*BI7 -> 195065.6 | BK7: 46357 | BL7: =AN7*BK7 -> 215096.48
A8: FY24 | AP8: =AC8*AO8 -> 0 | AR8: =AD8*AQ8 -> 0 | AT8: =AE8*AS8 -> 0 | AV8: =AF8*AU8 -> 0 | AX8: =AG8*AW8 -> 0 | AZ8: =AH8*AY8 -> 0 | BB8: =AI8*BA8 -> 0 | BD8: =AJ8*BC8 -> 0 | BF8: =AK8*BE8 -> 0 | BH8: =AL8*BG8 -> 0 | BJ8: =AM8*BI8 -> 0 | BL8: =AN8*BK8 -> 0
A9: FY24 | AP9: =AC9*AO9 -> 0 | AR9: =AD9*AQ9 -> 0 | AT9: =AE9*AS9 -> 0 | AV9: =AF9*AU9 -> 0 | AX9: =AG9*AW9 -> 0 | AZ9: =AH9*AY9 -> 0 | BB9: =AI9*BA9 -> 0 | BD9: =AJ9*BC9 -> 0 | BF9: =AK9*BE9 -> 0 | BH9: =AL9*BG9 -> 0 | BJ9: =AM9*BI9 -> 0 | BL9: =AN9*BK9 -> 0
A10: FY24 | AP10: =AC10*AO10 -> 0 | AR10: =AD10*AQ10 -> 0 | AT10: =AE10*AS10 -> 0 | AV10: =AF10*AU10 -> 0 | AX10: =AG10*AW10 -> 0 | AZ10: =AH10*AY10 -> 0 | BB10: =AI10*BA10 -> 0 | BD10: =AJ10*BC10 -> 0 | BF10: =AK10*BE10 -> 0 | BH10: =AL10*BG10 -> 0 | BJ10: =AM10*BI10 -> 0 | BL10: =AN10*BK10 -> 0
A11: FY24 | AP11: =AC11*AO11 -> 0 | AR11: =AD11*AQ11 -> 0 | AT11: =AE11*AS11 -> 0 | AV11: =AF11*AU11 -> 0 | AX11: =AG11*AW11 -> 0 | AZ11: =AH11*AY11 -> 0 | BB11: =AI11*BA11 -> 0 | BD11: =AJ11*BC11 -> 0 | BF11: =AK11*BE11 -> 0 | BH11: =AL11*BG11 -> 0 | BJ11: =AM11*BI11 -> 0 | BL11: =AN11*BK11 -> 0
A12: FY24 | AP12: =AC12*AO12 -> 0 | AR12: =AD12*AQ12 -> 0 | AT12: =AE12*AS12 -> 0 | AV12: =AF12*AU12 -> 0 | AX12: =AG12*AW12 -> 0 | AZ12: =AH12*AY12 -> 0 | BB12: =AI12*BA12 -> 0 | BD12: =AJ12*BC12 -> 0 | BF12: =AK12*BE12 -> 0 | BH12: =AL12*BG12 -> 0 | BJ12: =AM12*BI12 -> 0 | BL12: =AN12*BK12 -> 0
A13: FY24 | AP13: =AC13*AO13 -> 0 | AR13: =AD13*AQ13 -> 0 | AT13: =AE13*AS13 -> 0 | AV13: =AF13*AU13 -> 0 | AX13: =AG13*AW13 -> 0 | AZ13: =AH13*AY13 -> 0 | BB13: =AI13*BA13 -> 0 | BD13: =AJ13*BC13 -> 0 | BF13: =AK13*BE13 -> 0 | BH13: =AL13*BG13 -> 0 | BJ13: =AM13*BI13 -> 0 | BL13: =AN13*BK13 -> 0
A14: FY24 | F14: 800 | AP14: =AC14*AO14 -> 0 | AR14: =AD14*AQ14 -> 0 | AT14: =AE14*AS14 -> 0 | AV14: =AF14*AU14 -> 0 | AX14: =AG14*AW14 -> 0 | AZ14: =AH14*AY14 -> 0 | BB14: =AI14*BA14 -> 0 | BD14: =AJ14*BC14 -> 0 | BF14: =AK14*BE14 -> 0 | BH14: =AL14*BG14 -> 0 | BJ14: =AM14*BI14 -> 0 | BL14: =AN14*BK14 -> 0
A15: FY24 | AP15: =AC15*AO15 -> 0 | AR15: =AD15*AQ15 -> 0 | AT15: =AE15*AS15 -> 0 | AV15: =AF15*AU15 -> 0 | AX15: =AG15*AW15 -> 0 | AZ15: =AH15*AY15 -> 0 | BB15: =AI15*BA15 -> 0 | BD15: =AJ15*BC15 -> 0 | BF15: =AK15*BE15 -> 0 | BH15: =AL15*BG15 -> 0 | BJ15: =AM15*BI15 -> 0 | BL15: =AN15*BK15 -> 0
A16: FY24 | AP16: =AC16*AO16 -> 0 | AR16: =AD16*AQ16 -> 0 | AT16: =AE16*AS16 -> 0 | AV16: =AF16*AU16 -> 0 | AX16: =AG16*AW16 -> 0 | AZ16: =AH16*AY16 -> 0 | BB16: =AI16*BA16 -> 0 | BD16: =AJ16*BC16 -> 0 | BF16: =AK16*BE16 -> 0 | BH16: =AL16*BG16 -> 0 | BJ16: =AM16*BI16 -> 0 | BL16: =AN16*BK16 -> 0
A17: FY24 | AP17: =AC17*AO17 -> 0 | AR17: =AD17*AQ17 -> 0 | AT17: =AE17*AS17 -> 0 | AV17: =AF17*AU17 -> 0 | AX17: =AG17*AW17 -> 0 | AZ17: =AH17*AY17 -> 0 | BB17: =AI17*BA17 -> 0 | BD17: =AJ17*BC17 -> 0 | BF17: =AK17*BE17 -> 0 | BH17: =AL17*BG17 -> 0 | BJ17: =AM17*BI17 -> 0 | BL17: =AN17*BK17 -> 0
A18: FY24 | AP18: =AC18*AO18 -> 0 | AR18: =AD18*AQ18 -> 0 | AT18: =AE18*AS18 -> 0 | AV18: =AF18*AU18 -> 0 | AX18: =AG18*AW18 -> 0 | AZ18: =AH18*AY18 -> 0 | BB18: =AI18*BA18 -> 0 | BD18: =AJ18*BC18 -> 0 | BF18: =AK18*BE18 -> 0 | BH18: =AL18*BG18 -> 0 | BJ18: =AM18*BI18 -> 0 | BL18: =AN18*BK18 -> 0
A19: FY24 | AP19: =AC19*AO19 -> 0 | AR19: =AD19*AQ19 -> 0 | AT19: =AE19*AS19 -> 0 | AV19: =AF19*AU19 -> 0 | AX19: =AG19*AW19 -> 0 | AZ19: =AH19*AY19 -> 0 | BB19: =AI19*BA19 -> 0 | BD19: =AJ19*BC19 -> 0 | BF19: =AK19*BE19 -> 0 | BH19: =AL19*BG19 -> 0 | BJ19: =AM19*BI19 -> 0 | BL19: =AN19*BK19 -> 0
A20: FY24 | AP20: =AC20*AO20 -> 0 | AR20: =AD20*AQ20 -> 0 | AT20: =AE20*AS20 -> 0 | AV20: =AF20*AU20 -> 0 | AX20: =AG20*AW20 -> 0 | AZ20: =AH20*AY20 -> 0 | BB20: =AI20*BA20 -> 0 | BD20: =AJ20*BC20 -> 0 | BF20: =AK20*BE20 -> 0 | BH20: =AL20*BG20 -> 0 | BJ20: =AM20*BI20 -> 0 | BL20: =AN20*BK20 -> 0
A21: FY24 | AP21: =AC21*AO21 -> 0 | AR21: =AD21*AQ21 -> 0 | AT21: =AE21*AS21 -> 0 | AV21: =AF21*AU21 -> 0 | AX21: =AG21*AW21 -> 0 | AZ21: =AH21*AY21 -> 0 | BB21: =AI21*BA21 -> 0 | BD21: =AJ21*BC21 -> 0 | BF21: =AK21*BE21 -> 0 | BH21: =AL21*BG21 -> 0 | BJ21: =AM21*BI21 -> 0 | BL21: =AN21*BK21 -> 0
A22: FY24 | AP22: =AC22*AO22 -> 0 | AR22: =AD22*AQ22 -> 0 | AT22: =AE22*AS22 -> 0 | AV22: =AF22*AU22 -> 0 | AX22: =AG22*AW22 -> 0 | AZ22: =AH22*AY22 -> 0 | BB22: =AI22*BA22 -> 0 | BD22: =AJ22*BC22 -> 0 | BF22: =AK22*BE22 -> 0 | BH22: =AL22*BG22 -> 0 | BJ22: =AM22*BI22 -> 0 | BL22: =AN22*BK22 -> 0
A23: FY24 | AP23: =AC23*AO23 -> 0 | AR23: =AD23*AQ23 -> 0 | AT23: =AE23*AS23 -> 0 | AV23: =AF23*AU23 -> 0 | AX23: =AG23*AW23 -> 0 | AZ23: =AH23*AY23 -> 0 | BB23: =AI23*BA23 -> 0 | BD23: =AJ23*BC23 -> 0 | BF23: =AK23*BE23 -> 0 | BH23: =AL23*BG23 -> 0 | BJ23: =AM23*BI23 -> 0 | BL23: =AN23*BK23 -> 0
A24: FY24 | AP24: =AC24*AO24 -> 0 | AR24: =AD24*AQ24 -> 0 | AT24: =AE24*AS24 -> 0 | AV24: =AF24*AU24 -> 0 | AX24: =AG24*AW24 -> 0 | AZ24: =AH24*AY24 -> 0 | BB24: =AI24*BA24 -> 0 | BD24: =AJ24*BC24 -> 0 | BF24: =AK24*BE24 -> 0 | BH24: =AL24*BG24 -> 0 | BJ24: =AM24*BI24 -> 0 | BL24: =AN24*BK24 -> 0
A25: FY24 | B25: Sandy Lu | C25: Darfon | F25: 1000 | G25: 2024 | H25: Ernesto | I25: BL KB | J25: 14 | K25: Soft Grey | L25: W China | M25: INVENTEC | N25: 9.45 | O25: 15.66 | P25: 15.66 | Q25: 15.66 | R25: 15.66 | S25: 15.66 | T25: 15.66 | U25: 15.66 | V25: 15.66 | W25: 15.66 | X25: 15.66 | Y25: 15.66 | Z25: 15.66 | AA25: 15.66 | AB25: 6.21 | AC25: 6.21 | AD25: 6.21 | AE25: 6.21 | AF25: 6.21 | AG25: 6.21 | AH25: 6.21 | AI25: 6.21 | AJ25: 6.21 | AK25: 6.21 | AL25: 6.21 | AM25: 6.21 | AN25: 6.21 | AP25: =AC25*AO25 -> 0 | AR25: =AD25*AQ25 -> 0 | AT25: =AE25*AS25 -> 0 | AV25: =AF25*AU25 -> 0 | AX25: =AG25*AW25 -> 0 | AZ25: =AH25*AY25 -> 0 | BA25: 2320 | BB25: =AI25*BA25 -> 14407.2 | BC25: 4867 | BD25: =AJ25*BC25 -> 30224.07 | BE25: 3398 | BF25: =AK25*BE25 -> 21101.58 | BG25: 5080 | BH25: =AL25*BG25 -> 31546.8 | BI25: 10092 | BJ25: =AM25*BI25 -> 62671.32 | BK25: 11710 | BL25: =AN25*BK25 -> 72719.1
A26: FY24 | AP26: =AC26*AO26 -> 0 | AR26: =AD26*AQ26 -> 0 | AT26: =AE26*AS26 -> 0 | AV26: =AF26*AU26 -> 0 | AX26: =AG26*AW26 -> 0 | AZ26: =AH26*AY26 -> 0 | BB26: =AI26*BA26 -> 0 | BD26: =AJ26*BC26 -> 0 | BF26: =AK26*BE26 -> 0 | BH26: =AL26*BG26 -> 0 | BJ26: =AM26*BI26 -> 0 | BL26: =AN26*BK26 -> 0
A27: FY24 | AP27: =AC27*AO27 -> 0 | AR27: =AD27*AQ27 -> 0 | AT27: =AE27*AS27 -> 0 | AV27: =AF27*AU27 -> 0 | AX27: =AG27*AW27 -> 0 | AZ27: =AH27*AY27 -> 0 | BB27: =AI27*BA27 -> 0 | BD27: =AJ27*BC27 -> 0 | BF27: =AK27*BE27 -> 0 | BH27: =AL27*BG27 -> 0 | BJ27: =AM27*BI27 -> 0 | BL27: =AN27*BK27 -> 0
A28: FY24 | AP28: =AC28*AO28 -> 0 | AR28: =AD28*AQ28 -> 0 | AT28: =AE28*AS28 -> 0 | AV28: =AF28*AU28 -> 0 | AX28: =AG28*AW28 -> 0 | AZ28: =AH28*AY28 -> 0 | BB28: =AI28*BA28 -> 0 | BD28: =AJ28*BC28 -> 0 | BF28: =AK28*BE28 -> 0 | BH28: =AL28*BG28 -> 0 | BJ28: =AM28*BI28 -> 0 | BL28: =AN28*BK28 -> 0
A29: FY24 | F29: Clickpad | AP29: =AC29*AO29 -> 0 | AR29: =AD29*AQ29 -> 0 | AT29: =AE29*AS29 -> 0 | AV29: =AF29*AU29 -> 0 | AX29: =AG29*AW29 -> 0 | AZ29: =AH29*AY29 -> 0 | BB29: =AI29*BA29 -> 0 | BD29: =AJ29*BC29 -> 0 | BF29: =AK29*BE29 -> 0 | BH29: =AL29*BG29 -> 0 | BJ29: =AM29*BI29 -> 0 | BL29: =AN29*BK29 -> 0
A30: FY24 | AP30: =AC30*AO30 -> 0 | AR30: =AD30*AQ30 -> 0 | AT30: =AE30*AS30 -> 0 | AV30: =AF30*AU30 -> 0 | AX30: =AG30*AW30 -> 0 | AZ30: =AH30*AY30 -> 0 | BB30: =AI30*BA30 -> 0 | BD30: =AJ30*BC30 -> 0 | BF30: =AK30*BE30 -> 0 | BH30: =AL30*BG30 -> 0 | BJ30: =AM30*BI30 -> 0 | BL30: =AN30*BK30 -> 0
A31: FY24 | B31: Sandy Lu | C31: Darfon | E31: NB | F31: Education | G31: 2022 | H31: ANOLE1/ANOLE2/ARIZONA | I31: NBL KB | J31: 11 | K31: Jet Black/Jellyfish Blue | L31: W China | M31: INVENTEC | N31: 3.15 | O31: 4.8 | P31: 4.8 | Q31: 4.8 | R31: 4.8 | S31: 4.8 | T31: 4.8 | U31: 4.8 | V31: 4.8 | W31: 4.8 | X31: 4.8 | Y31: 4.8 | Z31: 4.8 | AA31: 4.8 | AB31: 1.26 | AC31: 1.26 | AD31: 1.26 | AE31: 1.26 | AF31: 1.26 | AG31: 1.26 | AH31: 1.26 | AI31: 1.36 | AJ31: 1.36 | AK31: 1.36 | AL31: 1.36 | AM31: 1.36 | AN31: 1.36 | AO31: 6365 | AP31: =AC31*AO31 -> 8019.9 | AQ31: 2160 | AR31: =AD31*AQ31 -> 2721.6 | AS31: 7600 | AT31: =AE31*AS31 -> 9576 | AU31: 14360 | AV31: =AF31*AU31 -> 18093.6 | AW31: 33558 | AX31: =AG31*AW31 -> 42283.08 | AY31: 29560 | AZ31: =AH31*AY31 -> 37245.6 | BA31: 22840 | BB31: =AI31*BA31 -> 31062.4 | BC31: 12358 | BD31: =AJ31*BC31 -> 16806.88 | BE31: 9320 | BF31: =AK31*BE31 -> 12675.2 | BG31: 14501 | BH31: =AL31*BG31 -> 19721.36 | BI31: 32948 | BJ31: =AM31*BI31 -> 44809.28 | BK31: 4160 | BL31: =AN31*BK31 -> 5657.6
A32: FY24 | B32: Sandy Lu | C32: Darfon | E32: NB | G32: 2022 | H32: ARCLIGHT1/ARCLIGHT2 | I32: NBL KB | J32: 14 | K32: Jet Black | L32: W China | M32: INVENTEC | N32: 3.15 | O32: 4.9 | P32: 4.9 | Q32: 4.9 | R32: 4.9 | S32: 4.9 | T32: 4.9 | U32: 4.9 | V32: 4.9 | W32: 4.9 | X32: 4.9 | Y32: 4.9 | Z32: 4.9 | AA32: 4.9 | AB32: 1.36 | AC32: 1.36 | AD32: 1.36 | AE32: 1.36 | AF32: 1.36 | AG32: 1.36 | AH32: 1.36 | AI32: 1.5 | AJ32: 1.5 | AK32: 1.5 | AL32: 1.5 | AM32: 1.5 | AN32: 1.5 | AO32: 1787 | AP32: =AC32*AO32 -> 2430.32 | AQ32: 2080 | AR32: =AD32*AQ32 -> 2828.8 | AS32: 7360 | AT32: =AE32*AS32 -> 10009.6 | AU32: 760 | AV32: =AF32*AU32 -> 1033.6 | AW32: 5480 | AX32: =AG32*AW32 -> 7452.8 | AY32: 4040 | AZ32: =AH32*AY32 -> 5494.4 | BA32: 14760 | BB32: =AI32*BA32 -> 22140 | BC32: 2160 | BD32: =AJ32*BC32 -> 3240 | BE32: 16000 | BF32: =AK32*BE32 -> 24000 | BG32: 2440 | BH32: =AL32*BG32 -> 3660 | BI32: 3120 | BJ32: =AM32*BI32 -> 4680 | BK32: 6200 | BL32: =AN32*BK32 -> 9300
A33: FY24 | F33: MWS (Workstation) | AP33: =AC33*AO33 -> 0 | AR33: =AD33*AQ33 -> 0 | AT33: =AE33*AS33 -> 0 | AV33: =AF33*AU33 -> 0 | AX33: =AG33*AW33 -> 0 | AZ33: =AH33*AY33 -> 0 | BB33: =AI33*BA33 -> 0 | BD33: =AJ33*BC33 -> 0 | BF33: =AK33*BE33 -> 0 | BH33: =AL33*BG33 -> 0 | BJ33: =AM33*BI33 -> 0 | BL33: =AN33*BK33 -> 0
A34: FY24 | AP34: =AC34*AO34 -> 0 | AR34: =AD34*AQ34 -> 0 | AT34: =AE34*AS34 -> 0 | AV34: =AF34*AU34 -> 0 | AX34: =AG34*AW34 -> 0 | AZ34: =AH34*AY34 -> 0 | BB34: =AI34*BA34 -> 0 | BD34: =AJ34*BC34 -> 0 | BF34: =AK34*BE34 -> 0 | BH34: =AL34*BG34 -> 0 | BJ34: =AM34*BI34 -> 0 | BL34: =AN34*BK34 -> 0
A35: FY24 | F35: Soft Keyboard | AP35: =AC35*AO35 -> 0 | AR35: =AD35*AQ35 -> 0 | AT35: =AE35*AS35 -> 0 | AV35: =AF35*AU35 -> 0 | AX35: =AG35*AW35 -> 0 | AZ35: =AH35*AY35 -> 0 | BB35: =AI35*BA35 -> 0 | BD35: =AJ35*BC35 -> 0 | BF35: =AK35*BE35 -> 0 | BH35: =AL35*BG35 -> 0 | BJ35: =AM35*BI35 -> 0 | BL35: =AN35*BK35 -> 0
A36: FY24 | AP36: =AC36*AO36 -> 0 | AR36: =AD36*AQ36 -> 0 | AT36: =AE36*AS36 -> 0 | AV36: =AF36*AU36 -> 0 | AX36: =AG36*AW36 -> 0 | AZ36: =AH36*AY36 -> 0 | BB36: =AI36*BA36 -> 0 | BD36: =AJ36*BC36 -> 0 | BF36: =AK36*BE36 -> 0 | BH36: =AL36*BG36 -> 0 | BJ36: =AM36*BI36 -> 0 | BL36: =AN36*BK36 -> 0
A37: FY24 | AP37: =AC37*AO37 -> 0 | AR37: =AD37*AQ37 -> 0 | AT37: =AE37*AS37 -> 0 | AV37: =AF37*AU37 -> 0 | AX37: =AG37*AW37 -> 0 | AZ37: =AH37*AY37 -> 0 | BB37: =AI37*BA37 -> 0 | BD37: =AJ37*BC37 -> 0 | BF37: =AK37*BE37 -> 0 | BH37: =AL37*BG37 -> 0 | BJ37: =AM37*BI37 -> 0 | BL37: =AN37*BK37 -> 0
A38: FY24 | AP38: =AC38*AO38 -> 0 | AR38: =AD38*AQ38 -> 0 | AT38: =AE38*AS38 -> 0 | AV38: =AF38*AU38 -> 0 | AX38: =AG38*AW38 -> 0 | AZ38: =AH38*AY38 -> 0 | BB38: =AI38*BA38 -> 0 | BD38: =AJ38*BC38 -> 0 | BF38: =AK38*BE38 -> 0 | BH38: =AL38*BG38 -> 0 | BJ38: =AM38*BI38 -> 0 | BL38: =AN38*BK38 -> 0
A39: FY24 | B39: Benson Chen | C39: Darfon | E39: NB | F39: Chromebook | G39: 2020 | H39: BULBUL/BULBULM6 | I39: NBL KB | J39: 14 | K39: Chalkboard Gray | L39: W China | M39: QUANTA | N39: 2.9 | O39: 3.5 | P39: 3.5 | Q39: 3.5 | R39: 3.5 | S39: 3.5 | T39: 3.5 | U39: 3.5 | V39: 3.5 | W39: 3.5 | X39: 3.5 | Y39: 3.5 | Z39: 3.5 | AA39: 3.5 | AB39: 0.5 | AC39: 0.5 | AD39: 0.5 | AE39: 0.6 | AF39: 0.6 | AG39: 0.6 | AH39: 0.6 | AI39: 0.6 | AJ39: 0.6 | AK39: 0.6 | AL39: 0.6 | AM39: 0.6 | AN39: 0.6 | AO39: 11840 | AP39: =AC39*AO39 -> 5920 | AQ39: 41720 | AR39: =AD39*AQ39 -> 20860 | AS39: 5800 | AT39: =AE39*AS39 -> 3480 | AU39: 28560 | AV39: =AF39*AU39 -> 17136 | AW39: 16120 | AX39: =AG39*AW39 -> 9672 | AY39: 37673 | AZ39: =AH39*AY39 -> 22603.8 | BA39: 52920 | BB39: =AI39*BA39 -> 31752 | BC39: 29960 | BD39: =AJ39*BC39 -> 17976 | BE39: 32840 | BF39: =AK39*BE39 -> 19704 | BH39: =AL39*BG39 -> 0 | BI39: 12280 | BJ39: =AM39*BI39 -> 7368 | BK39: 26760 | BL39: =AN39*BK39 -> 16056
A40: FY24 | B40: Benson Chen | C40: Darfon | E40: NB | G40: 2020 | H40: BULBUL/BULBULM6 | I40: BL KB | J40: 14 | K40: Chalkboard Gray | L40: W China | M40: QUANTA | N40: 9 | O40: 12.15 | P40: 12.15 | Q40: 12.15 | R40: 12.15 | S40: 12.15 | T40: 12.15 | U40: 12.15 | V40: 12.15 | W40: 12.15 | X40: 12.15 | Y40: 12.15 | Z40: 12.15 | AA40: 12.15 | AB40: 2 | AC40: 2 | AD40: 2 | AE40: 3.15 | AF40: 3.15 | AG40: 3.15 | AH40: 3.15 | AI40: 3.15 | AJ40: 3.15 | AK40: 3.15 | AL40: 3.15 | AM40: 3.15 | AN40: 3.15 | AO40: 120 | AP40: =AC40*AO40 -> 240 | AQ40: 840 | AR40: =AD40*AQ40 -> 1680 | AT40: =AE40*AS40 -> 0 | AV40: =AF40*AU40 -> 0 | AX40: =AG40*AW40 -> 0 | AZ40: =AH40*AY40 -> 0 | BB40: =AI40*BA40 -> 0 | BC40: 120 | BD40: =AJ40*BC40 -> 378 | BE40: 360 | BF40: =AK40*BE40 -> 1134 | BH40: =AL40*BG40 -> 0 | BJ40: =AM40*BI40 -> 0 | BL40: =AN40*BK40 -> 0
...

Sheet FY25 Summary_1
B3: Supplier's name | C3: 2024 11 | D3: 2024 12 | E3: 2025 01 | F3: Total Q1
B4: Rebate amount | C4: =SUM('FY25'!AP1) -> 575736.99 | D4: =SUM('FY25'!AR1) -> 899411.86 | E4: =SUM('FY25'!AT1) -> 489460.9 | F4: =SUM(C4:E4) -> 1964609.8
B5: E&O reduction | C5: 0 | D5: 0 | E5: 10388.4 | F5: =SUM(C5:E5) -> 10388.4
B6: Complexity reduction | C6: 0 | D6: 0 | E6: 0 | F6: =SUM(C6:E6) -> 0 | H6: 1. 新增Summary_1, 原先的Summary重新命名為Summary_2
B7: Total amount | C7: =SUM(C4:C6) -> 575736.99 | D7: =SUM(D4:D6) -> 899411.86 | E7: =SUM(E4:E6) -> 499849.3 | F7: =SUM(F4:F6) -> 1974998.2
H8: 2.黃色部位為貴司名稱, 請整份報告都跟檔名貴司名稱撰寫方式一致
B10: Supplier's name | C10: 2025 02 | D10: 2025 03 | E10: 2025 04 | F10: Total Q2 | H10: 3. 這些欄位一定要固定, B3-B28, C3-C28, D3-D28, E3-E28, F3-F28都有賦予定義
B11: Rebate amount | C11: =SUM('FY25'!AV1) -> 596846.92 | D11: =SUM('FY25'!AX1) -> 1117691.8 | E11: =SUM('FY25'!AZ1) -> 1039626.5 | F11: =SUM(C11:E11) -> 2754165.2
B12: E&O reduction | C12: 0 | D12: 32832.89 | E12: 0 | F12: =SUM(C12:E12) -> 32832.89 | H12: 4. Rebate amount 指得是summary_2的page金額 (就是我們一直以來收集的金額)
B13: Complexity reduction | C13: 0 | D13: 0 | E13: 0 | F13: =SUM(C13:E13) -> 0
B14: Total amount | C14: =SUM(C11:C13) -> 596846.92 | D14: =SUM(D11:D13) -> 1150524.7 | E14: =SUM(E11:E13) -> 1039626.5 | F14: =SUM(F11:F13) -> 2786998.1 | H14: 5. 新增 E&O reduction 及complexity reduction品項, 先留足空間
H15: 若目前還未有此款項存在都先填0
B17: Supplier's name | C17: 2025 05 | D17: 2025 06 | E17: 2025 07 | F17: Total Q3 | H17: 6. 金額都放未經調整後的真實數字, 分析才具意義
B18: Rebate amount | C18: =SUM('FY25'!BB1) -> 1064109.8 | D18: =SUM('FY25'!BD1) -> 1157504.3 | E18: =SUM('FY25'!BF1) -> 1112718.7 | F18: =SUM(C18:E18) -> 3334332.8
B19: E&O reduction | C19: 0 | D19: 91172.63 | E19: 28639.79 | F19: =SUM(C19:E19) -> 119812.42
B20: Complexity reduction | C20: 0 | D20: 0 | E20: 0 | F20: =SUM(C20:E20) -> 0
B21: Total amount | C21: =SUM(C18:C20) -> 1064109.8 | D21: =SUM(D18:D20) -> 1248676.9 | E21: =SUM(E18:E20) -> 1141358.5 | F21: =SUM(F18:F20) -> 3454145.2
B24: Supplier's name | C24: 2025 08 | D24: 2025 09 | E24: 2025 10 | F24: Total Q4
B25: Rebate amount | C25: =SUM('FY25'!BH1) -> 1064241.9 | D25: =SUM('FY25'!BJ1) -> 1166386.9 | E25: =SUM('FY25'!BL1) -> 825994.7 | F25: =SUM(C25:E25) -> 3056623.5
B26: E&O reduction | C26: 0 | D26: 0 | E26: 21143.37 | F26: =SUM(C26:E26) -> 21143.37
B27: Complexity reduction | C27: 0 | D27: 0 | E27: 0 | F27: =SUM(C27:E27) -> 0
B28: Total amount | C28: =SUM(C25:C27) -> 1064241.9 | D28: =SUM(D25:D27) -> 1166386.9 | E28: =SUM(E25:E27) -> 847138.07 | F28: =SUM(F25:F27) -> 3077766.9

Sheet FY25 Summary_2
B3: Q1 Actual by Segment
C4: Segment | D4: 45597 | E4: 45627 | F4: 45658 | G4: Total Rebate in Q1 2025 (US$)
B5: CMIT Input Devices | C5: 200 series (6U) | D5: =SUM('FY25'!AP$276:AP$374)*0.25 -> 48492.525 | E5: =SUM('FY25'!AR276:AR374)*0.25 -> 123738.69 | F5: =SUM('FY25'!AT276:AT374)*0.25 -> 53862.763 | G5: =SUM(D5:F5) -> 226093.98
C6: 400 /600 series (S/B) | D6: =SUM('FY25'!AP$6:AP$19) -> 55790.12 | E6: =SUM('FY25'!AR6:AR19) -> 81240.88 | F6: =SUM('FY25'!AT6:AT19) -> 60397.35 | G6: =SUM(D6:F6) -> 197428.35
C7: 800 series (P) | D7: =SUM('FY25'!AP$20:AP$39) -> 0 | E7: =SUM('FY25'!AR20:AR39) -> 0 | F7: =SUM('FY25'!AT20:AT39) -> 0 | G7: =SUM(D7:F7) -> 0
C8: 1000 series (M | D8: =SUM('FY25'!AP$40:AP$48) -> 25741.76 | E8: =SUM('FY25'!AR40:AR48) -> 26996.3 | F8: =SUM('FY25'!AT40:AT48) -> 23963.98 | G8: =SUM(D8:F8) -> 76702.04
C9: MWS (Workstation) | D9: =SUM('FY25'!AP$66:AP$67) -> 0 | E9: =SUM('FY25'!AR66:AR67) -> 0 | F9: =SUM('FY25'!AT66:AT67) -> 0 | G9: =SUM(D9:F9) -> 0
C10: Soft Keyboard | D10: =SUM('FY25'!AP$68:AP$71) -> 0 | E10: =SUM('FY25'!AR68:AR71) -> 0 | F10: =SUM('FY25'!AT68:AT71) -> 0 | G10: =SUM(D10:F10) -> 0
C11: Chrome Book | D11: =SUM('FY25'!AP$72:AP$102)*0.7 -> 27914.04 | E11: =SUM('FY25'!AR72:AR102)*0.7 -> 26084.296 | F11: =SUM('FY25'!AT72:AT102)*0.7 -> 27566.42 | G11: =SUM(D11:F11) -> 81564.756
C12: Clickpad | D12: =SUM('FY25'!AP$49:AP$50) -> 0 | E12: =SUM('FY25'!AR49:AR50) -> 0 | F12: =SUM('FY25'!AT49:AT50) -> 0 | G12: =SUM(D12:F12) -> 0
C13: Education | D13: =SUM('FY25'!AP$51:AP$65) -> 3261.41 | E13: =SUM('FY25'!AR51:AR65) -> 25590.67 | F13: =SUM('FY25'!AT51:AT65) -> 3931.6 | G13: =SUM(D13:F13) -> 32783.68
C14: Peripherals/AMO | G14: =SUM(D14:F14) -> 0
C15: Desktop | D15: =SUM('FY25'!AP$103:AP$169) -> 110410.42 | E15: =SUM('FY25'!AR103:AR169) -> 114374.58 | F15: =SUM('FY25'!AT103:AT169) -> 82016.6 | G15: =SUM(D15:F15) -> 306801.6
B16: Consumer Input Devices | C16: OPP | D16: =SUM('FY25'!AP$276:AP$374)*0.75+SUM('FY25'!AP170:AP181) -> 148306.58 | E16: =SUM('FY25'!AR276:AR374)*0.75+SUM('FY25'!AR170:AR181) -> 371240.06 | F16: =SUM('FY25'!AT276:AT374)*0.75+SUM('FY25'!AT170:AT181) -> 161660.29 | G16: =SUM(D16:F16) -> 681206.93
C17: Chrome Book | D17: =SUM('FY25'!AP$72:AP$102)*0.3 -> 11963.16 | E17: =SUM('FY25'!AR72:AR102)*0.3 -> 11178.984 | F17: =SUM('FY25'!AT72:AT102)*0.3 -> 11814.18 | G17: =SUM(D17:F17) -> 34956.324
C18: Pavillion | D18: =SUM('FY25'!AP$186:AP$203) -> 63652.5 | E18: =SUM('FY25'!AR186:AR203) -> 52516.3 | F18: =SUM('FY25'!AT186:AT203) -> 18281.8 | G18: =SUM(D18:F18) -> 134450.6
C19: Spectre | D19: =SUM('FY25'!AP$204:AP$206) -> 9884 | E19: =SUM('FY25'!AR204:AR206) -> 12520 | F19: =SUM('FY25'!AT204:AT206) -> 10750 | G19: =SUM(D19:F19) -> 33154
C20: Envy | D20: =SUM('FY25'!AP$207:AP$221) -> 9421.2 | E20: =SUM('FY25'!AR207:AR221) -> 14851.2 | F20: =SUM('FY25'!AT207:AT221) -> 11228.1 | G20: =SUM(D20:F20) -> 35500.5
C21: Stream | D21: =SUM('FY25'!AP$222:AP$223) -> 0 | E21: =SUM('FY25'!AR222:AR223) -> 0 | F21: =SUM('FY25'!AT222:AT223) -> 0 | G21: =SUM(D21:F21) -> 0
C22: Omen | D22: =SUM('FY25'!AP$224:AP$249) -> 59494.8 | E22: =SUM('FY25'!AR224:AR249) -> 39003.1 | F22: =SUM('FY25'!AT224:AT249) -> 23515.5 | G22: =SUM(D22:F22) -> 122013.4
C23: Peripherals/AMO | D23: =SUM('FY25'!AP257:AP275) -> 1404.48 | E23: =SUM('FY25'!AR257:AR275) -> 76.8 | F23: =SUM('FY25'!AT257:AT275) -> 472.32 | G23: =SUM(D23:F23) -> 1953.6
C24: Desktop | D24: =SUM('FY25'!AP$250:AP$256) -> 0 | E24: =SUM('FY25'!AR250:AR256) -> 0 | F24: =SUM('FY25'!AT250:AT256) -> 0 | G24: =SUM(D24:F24) -> 0
G25: =SUM(G5:G24) -> 1964609.8
B27: Q1 Actual by Segment
C28: Supplier | D28: 45597 | E28: 45627 | F28: 45658 | G28: Total Rebate in Q1 2025 (US$)
B29: Input Devices | C29: Acrox
C30: Chicony
C31: Darfon | D31: =SUM(D5:D24) -> 575736.99 | E31: =SUM(E5:E24) -> 899411.86 | F31: =SUM(F5:F24) -> 489460.9 | G31: =SUM(D31:F31) -> 1964609.8
C32: Liteon
C33: Primax
C34: Sunrex
F35: Total Rebate Amount | G35: =SUM(G29:G34) -> 1964609.8
B38: Q2 Actual by Segment
C39: Segment | D39: 45689 | E39: 45717 | F39: 45748 | G39: Total Rebate in Q2 2025 (US$)
B40: CMIT Input Devices | C40: 200 series (6U) | D40: =SUM('FY25'!AV$276:AV$374)*0.25 -> 64072.163 | E40: =SUM('FY25'!AX$276:AX$374)*0.25 -> 136038.8 | F40: =SUM('FY25'!AZ$276:AZ$374)*0.25 -> 72675.888 | G40: =SUM(D40:F40) -> 272786.85
C41: 400 /600 series (S/B) | D41: =SUM('FY25'!AV$6:AV$19) -> 48888.85 | E41: =SUM('FY25'!AX$6:AX$19) -> 105022.95 | F41: =SUM('FY25'!AZ$6:AZ$19) -> 65178.91 | G41: =SUM(D41:F41) -> 219090.71
C42: 800 series (P) | D42: =SUM('FY25'!AV$20:AV$39) -> 0 | E42: =SUM('FY25'!AX$20:AX$39) -> 27744.5 | F42: =SUM('FY25'!AZ$20:AZ$39) -> 86587.6 | G42: =SUM(D42:F42) -> 114332.1
C43: 1000 series (M | D43: =SUM('FY25'!AV$40:AV$48) -> 37234.5 | E43: =SUM('FY25'!AX$40:AX$48) -> 31167.8 | F43: =SUM('FY25'!AZ$40:AZ$48) -> 40765.34 | G43: =SUM(D43:F43) -> 109167.64
C44: MWS (Workstation) | D44: =SUM('FY25'!AV$66:AV$67) -> 0 | E44: =SUM('FY25'!AX$66:AX$67) -> 0 | F44: =SUM('FY25'!AZ$66:AZ$67) -> 0 | G44: =SUM(D44:F44) -> 0
C45: Soft Keyboard | D45: =SUM('FY25'!AV$68:AV$71) -> 0 | E45: =SUM('FY25'!AX$68:AX$71) -> 0 | F45: =SUM('FY25'!AZ$68:AZ$71) -> 0 | G45: =SUM(D45:F45) -> 0
...

Sheet FY25
D1: Consumer/Commercial/ Peripheral | E1: NB/DT/Peripheral | G1: 2009/2010/….2023/2024/2025 | H1: Platform name please strictly follow the LTF | I1: NBL KB/BL KB/Mouse /Combo/Clickpad/Dongle | J1: If no Size, fill in "NA/" | K1: If no Color, fill in "NA/" | L1: E China/W China/S China/Thailand/Vietnam | M1: COMPAL/QUANTA/INVENTEC/WISTRON/FOXCONN *If the ODM is not listed above, do not write 'OTHERS'. Please refer to the ODM or Regional site name as stated in the contract. | AP1: =SUM(AP3:AP1103) -> 575736.99 | AR1: =SUM(AR3:AR1103) -> 899411.86 | AT1: =SUM(AT3:AT1103) -> 489460.9 | AV1: =SUM(AV3:AV1103) -> 596846.92 | AX1: =SUM(AX3:AX1103) -> 1117691.8 | AZ1: =SUM(AZ3:AZ1103) -> 1039626.5 | BB1: =SUM(BB3:BB1103) -> 1064109.8 | BD1: =SUM(BD3:BD1103) -> 1157504.3 | BF1: =SUM(BF3:BF1103) -> 1112718.7 | BH1: =SUM(BH3:BH1103) -> 1064241.9 | BJ1: =SUM(BJ3:BJ1103) -> 1166386.9 | BL1: =SUM(BL3:BL1103) -> 825994.7 | BM1: Please fill in your supplier part# | BN1: Do not fill in ODM or Supplier part# at this column | BO1: APJ/EMEA/NA/ODM | BP1: If you don't have hp part#, pls fill in ODM part# without localization
