Workbook
Name Region: #REF!

Sheet 工作表6 (2)
A3: 加總 - Aug Q'ty
A4: Platforms | B4: Comment | C4: Supplier Part# | D4: Table Price Aug | E4: 合計
A5: Brac | B5: Flextronics CZ | C5: 18H24AA#AC3 | D5: 9.01 | E5: 21280
C6: 1Y4D0AA#AC3 | D6: 9.16 | E6: 0
C7: 1Y4D0UT#AC3 | D7: 9.16 | E7: 25800
B8: Flextronics CZ 合計 | E8: 47080
B9: Foxconn Indy | C9: 1Y4D0AA#ABA | D9: 8.86 | E9: 0
C10: 1Y4D0AA#ABC | D10: 8.84 | E10: 0
C11: 1Y4D0UT#ABA | D11: 8.86 | E11: 6400
C12: 1Y4D0UT#ABC | D12: 8.84 | E12: 0
B13: Foxconn Indy 合計 | E13: 6400
B14: Foxconn LH | C14: 18H24AA#AB1 | D14: 8.85 | E14: 0
C15: 18H24AA#ABA | D15: 8.85 | E15: 23040
C16: 18H24AA#ABM | D16: 8.87 | E16: 3840
C17: 18H24AA#AC4 | D17: 8.87 | E17: 11520
C18: 18H24AA#UUF | D18: 8.85 | E18: 7680
C19: 1Y4D0AA#AB1 | D19: 9 | E19: 0
C20: 1Y4D0AA#ABM | D20: 9.02 | E20: 0
C21: 1Y4D0AA#AC4 | D21: 9.02 | E21: 0
C22: 1Y4D0AA#UUF | D22: 9 | E22: 0
C23: 1Y4D0UT#AB1 | D23: 9 | E23: 0
C24: 1Y4D0UT#ABM | D24: 9.02 | E24: 5120
C25: 1Y4D0UT#AC4 | D25: 9.02 | E25: 0
C26: 1Y4D0UT#UUF | D26: 9 | E26: 5120
B27: Foxconn LH 合計 | E27: 56320
B28: QUANTA | C28: M40045-161 | D28: 9.72 | E28: 4320
B29: QUANTA 合計 | E29: 4320
A30: Brac 合計 | E30: 114120
A31: 總計 | E31: 114120

Sheet 說明頁_更新版
A1: ID | B1: Action | C1: Remark
A2: 1 | B2: A-M欄及BM-BP欄照理來說不會更動只會新增
A3: 2 | B3: 檔名的部分請像這樣 "Rebate and Spending report Supplier’s name_2025 01"，勿加上其他說明，若有V2版本請寫 "Rebate and Spending report Supplier’s name_2025 01_V2"
A4: 3 | B4: 請全年度都放在同一個tab，Summary也是Q1-Q4都放在一起，若有更新的年度請一樣要加上對應的Summary
A5: 4 | B5: Title相關規範請看右方所示, 請按照此欄位進行填寫, 勿更改資料次序 *上面也附上Example, 參考的顏色表以及Mason的PDF instruction | C5: A欄位:打上年度，新年度記得要更新
C6: B欄位: SPM, 請填全名, ex Benson Chen, 而不是Benson，若SPM有異動也請更新
C7: C 欄位: 一律填自己公司名稱
C8: D欄位: 請照上方指示, 勿自創提詞, 須注意只有NB和DT才會有Consumer/Commercial之分, F欄位是Peripheral則D和E都是填Peripheral
C9: E欄位 : 請照上方指示, 勿自創提詞
C10: F欄位 : Peripheral只需填寫Peripheral
C11: G欄位 : 已更新到2025
C12: H欄位 : -請一定不能空白此欄位，不然後面的數字都會讀不到 -如果多個platforms共用同keyboard, 請用 '/' 去 group這些platforms，大小寫沒關係。 -請Platform name請跟LTF一模一樣，像是有些後面會加上尺寸也請加上( BAYMAX14/LUISA14/BAYMAXW14/BAYMAX13/BAYMAX13X) -請用"/"來 Grouping 不同 Platform (e.g. ANDAZ/ABU) ，勿用其他符號，錯誤範例如:ANDAZ&ABU
C13: I欄位 : 請照上方指示, 勿自創提詞
C14: J欄位 : 如果沒有Size，則填寫"NA/"，請注意不要只寫"NA"
C15: K欄 : -要注意勿將 Color grouping 在一起，像是Jet Black/Soft Grey，若有n個顏色需分成n筆資料去填 -如果沒有Color，則填寫"NA/"，請注意不要只寫"NA" -Color 需確保填寫正確，如 SEAFOAM TEAL PEARL 需完整打出來，避免填成 SEAFOAM TEAL -請確保在顏色中間加上空格，大小寫沒關係。 -關於灰色，請使用“Grey” 而非“Gray” -有些顏色後面可能需加上國家，請用"_"的方式加上，像是 : Pike Silver_JP, Ash Silver_INDIA。 -Color 欄位需保持正常format，像是 PERFORMANCE BLUE OPAQUE 請避免填成 PERFORMANCE BLUE OPAQUE-RGB -針對CNB Gaming，關於Numpad及RGB方面請遵照以下方式及右方的說明 : RGB Per Key_Soft Grey 1 Zone W Numpad_Soft Grey, 1 Zone Red W Numpad_Soft Grey 4 Zone RGB W Numpad_Soft Grey 1 Zone W/O Numpad_Soft Grey, 1 Zone Red W/O Numpad_Soft Grey 4 Zone RGB W/O Numpad_Soft Grey 1 Zone RGB W Numpad_Soft Grey 1 Zone RGB W/O Numpad_Soft Grey
C16: L欄 : 請照上方指示，勿自創提詞，注意NMC更新為Thailand/Vietnam
C17: M欄 : 請照上方指示，勿自創提詞或簡寫，後面多加 Site 等
... C22: BP欄 : 新增的欄位"HP Model"，需填上LTF中相對應的HP model (如下所示)，接下來會使用這欄去串連其他資料
A27: 5 | B27: 當月出貨的所有品項都必須填上, 即使rebate=0的項目, 定義為FCS之後, EOL前的platform 當月出貨都需要寫上(也就是不含service part)
A28: 6 | B28: 每個月10日固定上傳此份rebate and spending report，請注意目前的Share point已經與財務共用，因此有任何要更新的地方都請通知Jenny並且上傳V2/V3…版本，且舊檔案勿刪除
A29: 7 | B29: 在上傳此份檔案前針對數字的部分需再三確認，因為這些數字會直接當作日後開發票的金額
A30: 8 | B30: excel欄位有相乘的部分 (rebate amount), 請不要直接在公式以外做數字上的調整, 沒有邏輯性的數字, 程式會偵測異常
A31: 9 | B31: Summary_1不能有任何註記, 需要呈現最真實的數字, Summary_2貴司可有一些註記符號, 或是rebate抵扣等地紀錄是能夠被容許的

Sheet FY24 Summary_1
B3: Acrox | C3: 2023 11 | D3: 2023 12 | E3: 2024 01 | F3: Total Q1
B4: Rebate amount | C4: ='FY24'!AP1 -> 36153.6 | D4: ='FY24'!AR1 -> 24589.2 | E4: ='FY24'!AT1 -> 45935.6 | F4: =SUM(C4:E4) -> 106678.4
B5: E&O reduction | F5: =SUM(C5:E5) -> 0
B6: Complexity reduction | F6: =SUM(C6:E6) -> 0 | H6: 1. 新增Summary_1, 原先的Summary重新命名為Summary_2
B7: Total amount | C7: =SUM(C4:C6) -> 36153.6 | D7: =SUM(D4:D6) -> 24589.2 | E7: =SUM(E4:E6) -> 45935.6 | F7: =SUM(F4:F6) -> 106678.4
H8: 2.黃色部位為貴司名稱, 請整份報告都跟檔名貴司名稱撰寫方式一致
B10: Acrox | C10: 2024 02 | D10: 2024 03 | E10: 2024 04 | F10: Total Q2 | H10: 3. 這些欄位一定要固定, B3-B28, C3-C28, D3-D28, E3-E28, F3-F28都有賦予定義
B11: Rebate amount | C11: ='FY24'!AV1 -> 12514.2 | D11: ='FY24'!AX1 -> 37755 | E11: ='FY24'!AZ1 -> 54170 | F11: =SUM(C11:E11) -> 104439.2
B12: E&O reduction | F12: =SUM(C12:E12) -> 0 | H12: 4. Rebate amount 指得是summary_2的page金額 (就是我們一直以來收集的金額)
B13: Complexity reduction | F13: =SUM(C13:E13) -> 0
B14: Total amount | C14: =SUM(C11:C13) -> 12514.2 | D14: =SUM(D11:D13) -> 37755 | E14: =SUM(E11:E13) -> 54170 | F14: =SUM(F11:F13) -> 104439.2 | H14: 5. 新增 E&O reduction 及complexity reduction品項, 先留足空間
H15: 若目前還未有此款項存在都先填0
B17: Acrox | C17: 2024 05 | D17: 2024 06 | E17: 2024 07 | F17: Total Q3 | H17: 6. 金額都放未經調整後的真實數字, 分析才具意義
B18: Rebate amount | C18: ='FY24'!BB1 -> 58734.6 | D18: ='FY24'!BD1 -> 46686 | E18: ='FY24'!BF1 -> 40968.2 | F18: =SUM(C18:E18) -> 146388.8
B19: E&O reduction | F19: =SUM(C19:E19) -> 0
B20: Complexity reduction | F20: =SUM(C20:E20) -> 0
B21: Total amount | C21: =SUM(C18:C20) -> 58734.6 | D21: =SUM(D18:D20) -> 46686 | E21: =SUM(E18:E20) -> 40968.2 | F21: =SUM(F18:F20) -> 146388.8
B24: Acrox | C24: 2024 08 | D24: 2024 09 | E24: 2024 10 | F24: Total Q4
B25: Rebate amount | C25: ='FY24'!BH1 -> 43588.6 | D25: ='FY24'!BJ1 -> 70368.16 | E25: ='FY24'!BL1 -> 59608.44 | F25: =SUM(C25:E25) -> 173565.2
B26: E&O reduction
B27: Complexity reduction
B28: Total amount | C28: =SUM(C25:C27) -> 43588.6 | D28: =SUM(D25:D27) -> 70368.16 | E28: =SUM(E25:E27) -> 59608.44 | F28: =SUM(F25:F27) -> 173565.2

Sheet FY23 Summary_1
B3: Supplier's name | C3: 2022 11 | D3: 2022 12 | E3: 2023 01 | F3: Total Q1
B4: Rebate amount | C4: ='FY23'!AO1 -> 13543.84 | D4: ='FY23'!AQ1 -> 4205.76 | E4: ='FY23'!AS1 -> 18630.44 | F4: =SUM(C4:E4) -> 36380.04
B5: E&O reduction | F5: =SUM(C5:E5) -> 0
B6: Complexity reduction | F6: =SUM(C6:E6) -> 0 | H6: 1. 新增Summary_1, 原先的Summary重新命名為Summary_2
B7: Total amount | C7: =SUM(C4:C6) -> 13543.84 | D7: =SUM(D4:D6) -> 4205.76 | E7: =SUM(E4:E6) -> 18630.44 | F7: =SUM(F4:F6) -> 36380.04
H8: 2.黃色部位為貴司名稱, 請整份報告都跟檔名貴司名稱撰寫方式一致
B10: Supplier's name | C10: 2023 02 | D10: 2023 03 | E10: 2023 04 | F10: Total Q2 | H10: 3. 這些欄位一定要固定, B3-B28, C3-C28, D3-D28, E3-E28, F3-F28都有賦予定義
B11: Rebate amount | C11: ='FY23'!AU1 -> 11427.6 | D11: ='FY23'!AW1 -> 16572.6 | E11: ='FY23'!AY1 -> 10147 | F11: =SUM(C11:E11) -> 38147.2
B12: E&O reduction | F12: =SUM(C12:E12) -> 0 | H12: 4. Rebate amount 指得是summary_2的page金額 (就是我們一直以來收集的金額)
B13: Complexity reduction | F13: =SUM(C13:E13) -> 0
B14: Total amount | C14: =SUM(C11:C13) -> 11427.6 | D14: =SUM(D11:D13) -> 16572.6 | E14: =SUM(E11:E13) -> 10147 | F14: =SUM(F11:F13) -> 38147.2 | H14: 5. 新增 E&O reduction 及complexity reduction品項, 先留足空間
H15: 若目前還未有此款項存在都先填0
B17: Supplier's name | C17: 2023 05 | D17: 2023 06 | E17: 2023 07 | F17: Total Q3 | H17: 6. 金額都放未經調整後的真實數字, 分析才具意義
B18: Rebate amount | C18: ='FY23'!BA1 -> 15430.8 | D18: ='FY23'!BC1 -> 9727.4 | E18: ='FY23'!BE1 -> 18492.2 | F18: =SUM(C18:E18) -> 43650.4
B19: E&O reduction | F19: =SUM(C19:E19) -> 0
B20: Complexity reduction | F20: =SUM(C20:E20) -> 0
B21: Total amount | C21: =SUM(C18:C20) -> 15430.8 | D21: =SUM(D18:D20) -> 9727.4 | E21: =SUM(E18:E20) -> 18492.2 | F21: =SUM(F18:F20) -> 43650.4
B24: Supplier's name | C24: 2023 08 | D24: 2023 09 | E24: 2023 10 | F24: Total Q4
B25: Rebate amount | C25: ='FY23'!BG1 -> 15672.2 | D25: ='FY23'!BI1 -> 8242 | E25: ='FY23'!BK1 -> 6241.2 | F25: =SUM(C25:E25) -> 30155.4
B26: E&O reduction | F26: =SUM(C26:E26) -> 0
B27: Complexity reduction | F27: =SUM(C27:E27) -> 0
B28: Total amount | C28: =SUM(C25:C27) -> 15672.2 | D28: =SUM(D25:D27) -> 8242 | E28: =SUM(E25:E27) -> 6241.2 | F28: =SUM(F25:F27) -> 30155.4

Sheet FY23 Summary_2
B3: Q1 Actual by Segment
C4: Segment | D4: 44866 | E4: 44896 | F4: 44927 | G4: Total Rebate in Q1 2023 (US$)
B5: CMIT Input Devices | C5: 200 series (6U)
C6: 400 series (S)
C7: 600 series (B)
C8: 800 series (P)
C9: 1000 series (M
C10: MWS (Workstation)
C11: Soft Keyboard
C12: Chrome Book
C13: Clickpad
C14: Education
C15: Peripherals/AMO
C16: Desktop
B17: Consumer Input Devices | C17: OPP
C18: Chrome Book
C19: Pavillion
C20: Spectre
C21: Envy
C22: Stream
C23: Omen
C24: Peripherals/AMO
C25: Desktop
B28: Q1 Actual by Segment
C29: Supplier | D29: 44866 | E29: 44896 | F29: 44927 | G29: Total Rebate in Q1 2023 (US$)
B30: Input Devices | C30: Acrox | D30: 13543.84 | E30: 4205.76 | F30: 18630.44 | G30: 36380.04
C31: Chicony
C32: Darfon
C33: Liteon
C34: Primax
C35: Sunrex
F36: Total Rebate Amount
B39: Q2 Actual by Segment
C40: Segment | D40: 44958 | E40: 44986 | F40: 45017 | G40: Total Rebate in Q2 2023 (US$)
B41: CMIT Input Devices | C41: 200 series (6U)
C42: 400 series (S)
C43: 600 series (B)
C44: 800 series (P)
C45: 1000 series (M
C46: MWS (Workstation)
...

Sheet FY23
D1: Consumer/Commercial/ Peripheral | E1: NB/DT/Peripheral | G1: 2020/2021/2022 | H1: Remove Size/Color, define Platform naming Hagrid/Hedwig/Granger/Ashmore/Ramla (follow naming rule of product list) | I1: NBL KB/BL KB/Mouse /Combo/Clickpad/Others | J1: NA/ | K1: NA/ | L1: (E China/W China/S China/NMC) | M1: COMPAL/ QUANTA /INVENTEC /WISTRON/ FOXCONN/ OTHERS | AO1: =SUM(AO3:AO1028) -> 13543.84 | AQ1: =SUM(AQ3:AQ1028) -> 4205.76 | AS1: =SUM(AS3:AS1028) -> 18630.44 | AU1: =SUM(AU3:AU1028) -> 11427.6 | AW1: =SUM(AW3:AW1028) -> 16572.6 | AY1: =SUM(AY3:AY1028) -> 10147 | BA1: =SUM(BA3:BA1028) -> 15430.8 | BC1: =SUM(BC3:BC1028) -> 9727.4 | BE1: =SUM(BE3:BE1028) -> 18492.2 | BG1: =SUM(BG3:BG1028) -> 15672.2 | BI1: =SUM(BI3:BI1028) -> 8242 | BK1: =SUM(BK3:BK1028) -> 6241.2
A2: FY23 | B2: SPM (Project Owner) | C2: GTK Suppliers | D2: Category | E2: Segment | F2: Series | G2: Production Year | H2: Platforms | I2: Product | J2: Size | K2: Color | L2: Location | M2: ODM | N2: The lowest unit table price (ODM cost) | O2: Table Price Nov | P2: Table Price Dec | Q2: Table Price Jan | R2: Table Price Feb | S2: Table Price Mar | T2: Table Price Apr | U2: Table Price May | V2: Table Price Jun | W2: Table Price Jul | X2: Table Price Aug | Y2: Table Price Sep | Z2: Table Price Oct | AA2: The lowest unit rebate cost | AB2: Unit Rebate Nov | AC2: Unit Rebate Dec | AD2: Unit Rebate Jan | AE2: Unit Rebate Feb | AF2: Unit Rebate Mar | AG2: Unit Rebate Apr | AH2: Unit Rebate May | AI2: Unit Rebate Jun | AJ2: Unit Rebate Jul | AK2: Unit Rebate Aug | AL2: Unit Rebate Sep | AM2: Unit Rebate Oct | AN2: Nov Q'ty | AO2: Nov Rebate Amount | AP2: Dec Q'ty | AQ2: Dec Rebate Amount | AR2: Jan Q'ty | AS2: Jan Rebate Amount | AT2: Feb Q'ty | AU2: Feb Rebate Amount | AV2: Mar Q'ty | AW2: Mar Rebate Amount | AX2: Apr Q'ty | AY2: Apr Rebate Amount | AZ2: May Q'ty | BA2: May Rebate Amount | BB2: Jun Q'ty | BC2: Jun Rebate Amount | BD2: Jul Q'ty | BE2: Jul Rebate Amount | BF2: Aug Q'ty | BG2: Aug Rebate Amount | BH2: Sep Q'ty | BI2: Sep Rebate Amount | BJ2: Oct Q'ty | BK2: Oct Rebate Amount | BL2: Supplier Part# | BM2: Comment | BN2: REMARK1
A3: FY23 | B3: Allen Chen | C3: Acrox | D3: Peripheral | E3: Peripheral | F3: Peripherals | G3: 2018 | H3: BOGOTA | I3: Mouse | J3: NA | K3: Black | L3: S China | M3: OTHERS | N3: 1.86 | O3: 1.86 | P3: 1.86 | Q3: 1.86 | R3: 1.86 | S3: 1.86 | T3: 1.86 | U3: 1.86 | V3: 1.86 | W3: 1.86 | X3: 1.86 | Y3: 1.86 | Z3: 1.86 | AA3: 0 | AB3: 0 | AC3: 0 | AD3: 0 | AE3: 0 | AF3: 0 | AG3: 0 | AH3: 0 | AI3: 0 | AJ3: 0 | AK3: 0 | AL3: 0 | AM3: 0 | AN3: 5760 | AO3: =AB3*AN3 -> 0 | AP3: 0 | AQ3: =AC3*AP3 -> 0 | AR3: 0 | AS3: =AD3*AR3 -> 0 | AT3: 0 | AU3: =AE3*AT3 -> 0 | AV3: 5760 | AW3: =AF3*AV3 -> 0 | AX3: 2880 | AY3: =AG3*AX3 -> 0 | AZ3: 2880 | BA3: =AH3*AZ3 -> 0 | BB3: 11520 | BC3: =AI3*BB3 -> 0 | BD3: 0 | BE3: =AJ3*BD3 -> 0 | BF3: 5760 | BG3: =AK3*BF3 -> 0 | BH3: 0 | BI3: =AL3*BH3 -> 0 | BJ3: 0 | BK3: =AM3*BJ3 -> 0 | BM3: 4QM14AA#ACJ/CPS/2880/EM
A4: FY23 | B4: Allen Chen | G4: 2018 | H4: BOGOTA | I4: Mouse | J4: NA | K4: Black | L4: S China | M4: OTHERS | N4: 2 | O4: 2 | P4: 2 | Q4: 2 | R4: 2 | S4: 2 | T4: 2 | U4: 2 | V4: 2 | W4: 2 | X4: 2 | Y4: 2 | Z4: 2 | AA4: 0 | AB4: 0 | AC4: 0 | AD4: 0 | AE4: 0 | AF4: 0 | AG4: 0 | AH4: 0 | AI4: 0 | AJ4: 0 | AK4: 0 | AL4: 0 | AM4: 0 | AN4: 2880 | AO4: =AB4*AN4 -> 0 | AP4: 0 | AQ4: =AC4*AP4 -> 0 | AR4: 5760 | AS4: =AD4*AR4 -> 0 | AT4: 2880 | AU4: =AE4*AT4 -> 0 | AV4: 14400 | AW4: =AF4*AV4 -> 0 | AX4: 0 | AY4: =AG4*AX4 -> 0 | AZ4: 8640 | BA4: =AH4*AZ4 -> 0 | BB4: 0 | BC4: =AI4*BB4 -> 0 | BD4: 2880 | BE4: =AJ4*BD4 -> 0 | BF4: 0 | BG4: =AK4*BF4 -> 0 | BH4: 0 | BI4: =AL4*BH4 -> 0 | BJ4: 2880 | BK4: =AM4*BJ4 -> 0 | BM4: 4QM14AA#UUF/CPS/2880/EM
A5: FY23 | B5: Simon Yang | G5: 2020 | H5: BRAC | I5: Combo | J5: NA | K5: Black | L5: S China | M5: OTHERS | N5: 8.85 | O5: 8.85 | P5: 8.85 | Q5: 8.85 | R5: 8.85 | S5: 8.85 | T5: 8.85 | U5: 8.85 | V5: 8.85 | W5: 8.85 | X5: 8.85 | Y5: 8.85 | Z5: 8.85 | AA5: 0 | AB5: 0 | AC5: 0 | AD5: 0 | AE5: 0 | AF5: 0 | AG5: 0 | AH5: 0 | AI5: 0 | AJ5: 0 | AK5: 0 | AL5: 0 | AM5: 0 | AN5: 8960 | AO5: =AB5*AN5 -> 0 | AP5: 0 | AQ5: =AC5*AP5 -> 0 | AR5: 0 | AS5: =AD5*AR5 -> 0 | AT5: 2560 | AU5: =AE5*AT5 -> 0 | AV5: 1280 | AW5: =AF5*AV5 -> 0 | AX5: 0 | AY5: =AG5*AX5 -> 0 | AZ5: 1280 | BA5: =AH5*AZ5 -> 0 | BB5: 2560 | BC5: =AI5*BB5 -> 0 | BD5: 32000 | BE5: =AJ5*BD5 -> 0 | BF5: 0 | BG5: =AK5*BF5 -> 0 | BH5: 0 | BI5: =AL5*BH5 -> 0 | BJ5: 1280 | BK5: =AM5*BJ5 -> 0 | BM5: 18H24AA#UUF/CPS/1280/GBU
A6: FY23 | B6: Simon Yang | G6: 2020 | H6: BRAC | I6: Combo | J6: NA | K6: Black | L6: S China | M6: OTHERS | N6: 9 | O6: 9 | P6: 9 | Q6: 9 | R6: 9 | S6: 9 | T6: 9 | U6: 9 | V6: 9 | W6: 9 | X6: 9 | Y6: 9 | Z6: 9 | AA6: 0 | AB6: 0 | AC6: 0 | AD6: 0 | AE6: 0 | AF6: 0 | AG6: 0 | AH6: 0 | AI6: 0 | AJ6: 0 | AK6: 0 | AL6: 0 | AM6: 0 | AN6: 20480 | AO6: =AB6*AN6 -> 0 | AP6: 33280 | AQ6: =AC6*AP6 -> 0 | AR6: 28160 | AS6: =AD6*AR6 -> 0 | AT6: 24320 | AU6: =AE6*AT6 -> 0 | AV6: 8960 | AW6: =AF6*AV6 -> 0 | AX6: 0 | AY6: =AG6*AX6 -> 0 | AZ6: 0 | BA6: =AH6*AZ6 -> 0 | BB6: 0 | BC6: =AI6*BB6 -> 0 | BD6: 2560 | BE6: =AJ6*BD6 -> 0 | BF6: 7680 | BG6: =AK6*BF6 -> 0 | BH6: 10240 | BI6: =AL6*BH6 -> 0 | BJ6: 1280 | BK6: =AM6*BJ6 -> 0 | BM6: 1Y4D0AA#UUF/BPS/1280/GBU
A7: FY23 | B7: Simon Yang | G7: 2020 | H7: BRAC | I7: Combo | J7: NA | K7: Black | L7: S China | M7: OTHERS | N7: 9.72 | O7: 9.72 | P7: 9.72 | Q7: 9.72 | R7: 9.72 | S7: 9.72 | T7: 9.72 | U7: 9.72 | V7: 9.72 | W7: 9.72 | X7: 9.72 | Y7: 9.72 | Z7: 9.72 | AA7: 0 | AB7: 0 | AC7: 0 | AD7: 0 | AE7: 0 | AF7: 0 | AG7: 0 | AH7: 0 | AI7: 0 | AJ7: 0 | AK7: 0 | AL7: 0 | AM7: 0 | AN7: 1360 | AO7: =AB7*AN7 -> 0 | AP7: 10190 | AQ7: =AC7*AP7 -> 0 | AR7: 6480 | AS7: =AD7*AR7 -> 0 | AT7: 1080 | AU7: =AE7*AT7 -> 0 | AV7: 2160 | AW7: =AF7*AV7 -> 0 | AX7: 1080 | AY7: =AG7*AX7 -> 0 | AZ7: 4320 | BA7: =AH7*AZ7 -> 0 | BB7: 8640 | BC7: =AI7*BB7 -> 0 | BD7: 3240 | BE7: =AJ7*BD7 -> 0 | BF7: 3240 | BG7: =AK7*BF7 -> 0 | BH7: 4320 | BI7: =AL7*BH7 -> 0 | BJ7: 2160 | BK7: =AM7*BJ7 -> 0 | BM7: M40045-161/DIB/1080/Brown box
A8: FY23 | B8: Simon Yang | G8: 2020 | H8: BRAC | I8: Combo | J8: NA | K8: Black | L8: S China | M8: OTHERS | N8: 9.16 | O8: 9.16 | P8: 9.16 | Q8: 9.16 | R8: 9.16 | S8: 9.16 | T8: 9.16 | U8: 9.16 | V8: 9.16 | W8: 9.16 | X8: 9.16 | Y8: 9.16 | Z8: 9.16 | AA8: 0 | AB8: 0 | AC8: 0 | AD8: 0 | AE8: 0 | AF8: 0 | AG8: 0 | AH8: 0 | AI8: 0 | AJ8: 0 | AK8: 0 | AL8: 0 | AM8: 0 | AN8: 9300 | AO8: =AB8*AN8 -> 0 | AP8: 19000 | AQ8: =AC8*AP8 -> 0 | AR8: 28000 | AS8: =AD8*AR8 -> 0 | AT8: 0 | AU8: =AE8*AT8 -> 0 | AV8: 22000 | AW8: =AF8*AV8 -> 0 | AX8: 11500 | AY8: =AG8*AX8 -> 0 | AZ8: 32000 | BA8: =AH8*AZ8 -> 0 | BB8: 25000 | BC8: =AI8*BB8 -> 0 | BD8: 12060 | BE8: =AJ8*BD8 -> 0 | BF8: 19000 | BG8: =AK8*BF8 -> 0 | BH8: 23000 | BI8: =AL8*BH8 -> 0 | BJ8: 27800 | BK8: =AM8*BJ8 -> 0 | BM8: 1Y4D0AA#AC3/BPS/1280/GBU
A9: FY23 | B9: Simon Yang | G9: 2020 | H9: BRAC | I9: Combo | J9: NA | K9: Black | L9: S China | M9: OTHERS | N9: 8.87 | O9: 8.87 | P9: 8.87 | Q9: 8.87 | R9: 8.87 | S9: 8.87 | T9: 8.87 | U9: 8.87 | V9: 8.87 | W9: 8.87 | X9: 8.87 | Y9: 8.87 | Z9: 8.87 | AA9: 0 | AB9: 0 | AC9: 0 | AD9: 0 | AE9: 0 | AF9: 0 | AG9: 0 | AH9: 0 | AI9: 0 | AJ9: 0 | AK9: 0 | AL9: 0 | AM9: 0 | AN9: 2560 | AO9: =AB9*AN9 -> 0 | AP9: 2560 | AQ9: =AC9*AP9 -> 0 | AR9: 2560 | AS9: =AD9*AR9 -> 0 | AT9: 1280 | AU9: =AE9*AT9 -> 0 | AV9: 3840 | AW9: =AF9*AV9 -> 0 | AX9: 2560 | AY9: =AG9*AX9 -> 0 | AZ9: 7680 | BA9: =AH9*AZ9 -> 0 | BB9: 3840 | BC9: =AI9*BB9 -> 0 | BD9: 0 | BE9: =AJ9*BD9 -> 0 | BF9: 6400 | BG9: =AK9*BF9 -> 0 | BH9: 1280 | BI9: =AL9*BH9 -> 0 | BJ9: 0 | BK9: =AM9*BJ9 -> 0 | BM9: 18H24AA#ABM/CPS/1280/GBU
A10: FY23 | B10: Simon Yang | G10: 2020 | H10: BRAC | I10: Combo | J10: NA | K10: Black | L10: S China | M10: OTHERS | N10: 9.02 | O10: 9.02 | P10: 9.02 | Q10: 9.02 | R10: 9.02 | S10: 9.02 | T10: 9.02 | U10: 9.02 | V10: 9.02 | W10: 9.02 | X10: 9.02 | Y10: 9.02 | Z10: 9.02 | AA10: 0 | AB10: 0 | AC10: 0 | AD10: 0 | AE10: 0 | AF10: 0 | AG10: 0 | AH10: 0 | AI10: 0 | AJ10: 0 | AK10: 0 | AL10: 0 | AM10: 0 | AN10: 0 | AO10: =AB10*AN10 -> 0 | AP10: 3840 | AQ10: =AC10*AP10 -> 0 | AR10: 2560 | AS10: =AD10*AR10 -> 0 | AT10: 8960 | AU10: =AE10*AT10 -> 0 | AV10: 3840 | AW10: =AF10*AV10 -> 0 | AX10: 3840 | AY10: =AG10*AX10 -> 0 | AZ10: 2560 | BA10: =AH10*AZ10 -> 0 | BB10: 0 | BC10: =AI10*BB10 -> 0 | BD10: 0 | BE10: =AJ10*BD10 -> 0 | BF10: 0 | BG10: =AK10*BF10 -> 0 | BH10: 2560 | BI10: =AL10*BH10 -> 0 | BJ10: 1280 | BK10: =AM10*BJ10 -> 0 | BM10: 1Y4D0AA#ABM/BPS/1280/GBU
A11: FY23 | B11: Simon Yang | G11: 2021 | H11: BRAC WHITE | I11: Combo | J11: NA | K11: White | L11: S China | M11: OTHERS | N11: 11.28 | O11: 11.28 | P11: 11.28 | Q11: 11.28 | R11: 11.28 | S11: 11.28 | T11: 11.28 | U11: 11.28 | V11: 11.28 | W11: 11.28 | X11: 11.28 | Y11: 11.28 | Z11: 11.28 | AA11: 0 | AB11: 0 | AC11: 0 | AD11: 0 | AE11: 0 | AF11: 0 | AG11: 0 | AH11: 0 | AI11: 0 | AJ11: 0 | AK11: 0 | AL11: 0 | AM11: 0 | AN11: 0 | AO11: =AB11*AN11 -> 0 | AP11: 2520 | AQ11: =AC11*AP11 -> 0 | AR11: 5040 | AS11: =AD11*AR11 -> 0 | AT11: 2520 | AU11: =AE11*AT11 -> 0 | AV11: 2520 | AW11: =AF11*AV11 -> 0 | AX11: 2520 | AY11: =AG11*AX11 -> 0 | AZ11: 7560 | BA11: =AH11*AZ11 -> 0 | BB11: 0 | BC11: =AI11*BB11 -> 0 | BD11: 0 | BE11: =AJ11*BD11 -> 0 | BF11: 2520 | BG11: =AK11*BF11 -> 0 | BH11: 2520 | BI11: =AL11*BH11 -> 0 | BJ11: 10080 | BK11: =AM11*BJ11 -> 0 | BM11: M40043-161/DIB/2520/Brown box
A12: FY23 | B12: Simon Yang | G12: 2021 | H12: BRAC WLKB | I12: NBL KB | J12: NA | K12: Black | L12: S China | M12: OTHERS | N12: 7.58 | O12: 7.58 | P12: 7.58 | Q12: 7.58 | R12: 7.58 | S12: 7.58 | T12: 7.58 | U12: 7.58 | V12: 7.58 | W12: 7.58 | X12: 7.58 | Y12: 7.58 | Z12: 7.58 | AA12: 0 | AB12: 0 | AC12: 0 | AD12: 0 | AE12: 0 | AF12: 0 | AG12: 0 | AH12: 0 | AI12: 0 | AJ12: 0 | AK12: 0 | AL12: 0 | AM12: 0 | AN12: 3500 | AO12: =AB12*AN12 -> 0 | AP12: 0 | AQ12: =AC12*AP12 -> 0 | AR12: 3680 | AS12: =AD12*AR12 -> 0 | AT12: 0 | AU12: =AE12*AT12 -> 0 | AV12: 11800 | AW12: =AF12*AV12 -> 0 | AX12: 0 | AY12: =AG12*AX12 -> 0 | AZ12: 1280 | BA12: =AH12*AZ12 -> 0 | BB12: 1280 | BC12: =AI12*BB12 -> 0 | BD12: 4000 | BE12: =AJ12*BD12 -> 0 | BF12: 0 | BG12: =AK12*BF12 -> 0 | BH12: 2560 | BI12: =AL12*BH12 -> 0 | BJ12: 6060 | BK12: =AM12*BJ12 -> 0 | BM12: 3L1E7AA#AC3/CPS/1200/GBU
A13: FY23 | B13: Simon Yang | G13: 2021 | H13: BRAC WLKB | I13: NBL KB | J13: NA | K13: Black | L13: S China | M13: OTHERS | N13: 7.46 | O13: 7.46 | P13: 7.46 | Q13: 7.46 | R13: 7.46 | S13: 7.46 | T13: 7.46 | U13: 7.46 | V13: 7.46 | W13: 7.46 | X13: 7.46 | Y13: 7.46 | Z13: 7.46 | AA13: 0 | AB13: 0 | AC13: 0 | AD13: 0 | AE13: 0 | AF13: 0 | AG13: 0 | AH13: 0 | AI13: 0 | AJ13: 0 | AK13: 0 | AL13: 0 | AM13: 0 | AN13: 0 | AO13: =AB13*AN13 -> 0 | AP13: 2400 | AQ13: =AC13*AP13 -> 0 | AR13: 1200 | AS13: =AD13*AR13 -> 0 | AT13: 1200 | AU13: =AE13*AT13 -> 0 | AV13: 1200 | AW13: =AF13*AV13 -> 0 | AX13: 1200 | AY13: =AG13*AX13 -> 0 | AZ13: 4800 | BA13: =AH13*AZ13 -> 0 | BB13: 0 | BC13: =AI13*BB13 -> 0 | BD13: 0 | BE13: =AJ13*BD13 -> 0 | BF13: 0 | BG13: =AK13*BF13 -> 0 | BH13: 0 | BI13: =AL13*BH13 -> 0 | BJ13: 1200 | BK13: =AM13*BJ13 -> 0 | BM13: 3L1E7AA#ABM/CPS/1200/GBU
A14: FY23 | B14: Allen Chen | G14: 2020 | H14: BRAIN | I14: Mouse | J14: NA | K14: Nightfull black | L14: S China | M14: OTHERS | N14: 30.42 | O14: 30.42 | P14: 30.42 | Q14: 30.42 | R14: 30.42 | S14: 30.42 | T14: 30.42 | U14: 30.42 | V14: 30.42 | W14: 30.42 | X14: 30.42 | Y14: 30.42 | Z14: 30.42 | AA14: 0 | AB14: 0 | AC14: 0 | AD14: 0 | AE14: 0 | AF14: 0 | AG14: 0 | AH14: 0 | AI14: 0 | AJ14: 0 | AK14: 0 | AL14: 0 | AM14: 0 | AN14: 1008 | AO14: =AB14*AN14 -> 0 | AP14: 0 | AQ14: =AC14*AP14 -> 0 | AR14: 0 | AS14: =AD14*AR14 -> 0 | AT14: 0 | AU14: =AE14*AT14 -> 0 | AV14: 1008 | AW14: =AF14*AV14 -> 0 | AX14: 0 | AY14: =AG14*AX14 -> 0 | AZ14: 0 | BA14: =AH14*AZ14 -> 0 | BB14: 0 | BC14: =AI14*BB14 -> 0 | BD14: 0 | BE14: =AJ14*BD14 -> 0 | BF14: 0 | BG14: =AK14*BF14 -> 0 | BH14: 0 | BI14: =AL14*BH14 -> 0 | BJ14: 0 | BK14: =AM14*BJ14 -> 0 | BM14: 1D0K8AA#ABA/BPS/1008/BOX
A15: FY23 | B15: Allen Chen | G15: 2020 | H15: BRAIN | I15: Mouse | J15: NA | K15: Natural Silver | L15: S China | M15: OTHERS | N15: 30.52 | O15: 30.52 | P15: 30.52 | Q15: 30.52 | R15: 30.52 | S15: 30.52 | T15: 30.52 | U15: 30.52 | V15: 30.52 | W15: 30.52 | X15: 30.52 | Y15: 30.52 | Z15: 30.52 | AA15: 0 | AB15: 0 | AC15: 0 | AD15: 0 | AE15: 0 | AF15: 0 | AG15: 0 | AH15: 0 | AI15: 0 | AJ15: 0 | AK15: 0 | AL15: 0 | AM15: 0 | AN15: 0 | AO15: =AB15*AN15 -> 0 | AP15: 1008 | AQ15: =AC15*AP15 -> 0 | AR15: 1008 | AS15: =AD15*AR15 -> 0 | AT15: 0 | AU15: =AE15*AT15 -> 0 | AV15: 0 | AW15: =AF15*AV15 -> 0 | AX15: 0 | AY15: =AG15*AX15 -> 0 | AZ15: 0 | BA15: =AH15*AZ15 -> 0 | BB15: 1008 | BC15: =AI15*BB15 -> 0 | BD15: 0 | BE15: =AJ15*BD15 -> 0 | BF15: 0 | BG15: =AK15*BF15 -> 0 | BH15: 0 | BI15: =AL15*BH15 -> 0 | BJ15: 0 | BK15: =AM15*BJ15 -> 0 | BM15: 1D0K9AA#ABB/CPS/1008/BOX
... A22: FY23 | B22: Simon Yang | G22: 2022 | H22: ELEPHANTA KB | I22: NBL KB | J22: NA | K22: Black | L22: S China | M22: OTHERS | N22: 3.75 | O22: 3.75 | P22: 3.75 | Q22: 3.75 | R22: 3.75 | S22: 3.75 | T22: 3.75 | U22: 3.75 | V22: 3.75 | W22: 3.75 | X22: 3.75 | Y22: 3.75 | Z22: 3.75 | AA22: 0.21 | AB22: 0.21 | AC22: 0.21 | AD22: 0.21 | AE22: 0.21 | AF22: 0.21 | AG22: 0.21 | AH22: 0.21 | AI22: 0.21 | AJ22: 0.21 | AK22: 0.21 | AL22: 0.21 | AM22: 0.21 | AN22: 15000 | AO22: =AB22*AN22 -> 3150 | AP22: 0 | AQ22: =AC22*AP22 -> 0 | AR22: 10000 | AS22: =AD22*AR22 -> 2100 | AT22: 0 | AU22: =AE22*AT22 -> 0 | AV22: 0 | AW22: =AF22*AV22 -> 0 | AX22: 0 | AY22: =AG22*AX22 -> 0 | AZ22: 0 | BA22: =AH22*AZ22 -> 0 | BB22: 0 | BC22: =AI22*BB22 -> 0 | BD22: 16800 | BE22: =AJ22*BD22 -> 3528 | BF22: 5600 | BG22: =AK22*BF22 -> 1176 | BH22: 0 | BI22: =AL22*BH22 -> 0 | BJ22: 0 | BK22: =AM22*BJ22 -> 0 | BM22: 664R5AA#UUF/CPS/5600/GBU
A23: FY23 | B23: Allen Chen | G23: 2016 | H23: GADGET | I23: Mouse | J23: NA | K23: Black | L23: S China | M23: OTHERS | N23: 5.95 | O23: 5.95 | P23: 5.95 | Q23: 5.95 | R23: 5.95 | S23: 5.95 | T23: 5.95 | U23: 5.95 | V23: 5.95 | W23: 5.95 | X23: 5.95 | Y23: 5.95 | Z23: 5.95 | AA23: 0 | AB23: 0.05 | AC23: 0.05 | AD23: 0.05 | AE23: 0.05 | AF23: 0.05 | AG23: 0.05 | AH23: 0.05 | AI23: 0.05 | AJ23: 0.05 | AK23: 0.05 | AL23: 0.05 | AM23: 0.05 | AN23: 864 | AO23: =AB23*AN23 -> 43.2 | AP23: 0 | AQ23: =AC23*AP23 -> 0 | AR23: 0 | AS23: =AD23*AR23 -> 0 | AT23: 0 | AU23: =AE23*AT23 -> 0 | AV23: 0 | AW23: =AF23*AV23 -> 0 | AX23: 0 | AY23: =AG23*AX23 -> 0 | AZ23: 0 | BA23: =AH23*AZ23 -> 0 | BB23: 0 | BC23: =AI23*BB23 -> 0 | BD23: 0 | BE23: =AJ23*BD23 -> 0 | BF23: 0 | BG23: =AK23*BF23 -> 0 | BH23: 0 | BI23: =AL23*BH23 -> 0 | BJ23: 0 | BK23: =AM23*BJ23 -> 0 | BM23: V0L79AA#UUF/CPS/1560/GBU | BN23: (上海)
A24: FY23 | B24: Allen Chen | G24: 2016 | H24: GADGET | I24: Mouse | J24: NA | K24: White | L24: S China | M24: OTHERS | N24: 6.05 | O24: 6.05 | P24: 6.05 | Q24: 6.05 | R24: 6.05 | S24: 6.05 | T24: 6.05 | U24: 6.05 | V24: 6.05 | W24: 6.05 | X24: 6.05 | Y24: 6.05 | Z24: 6.05 | AA24: 0 | AB24: 0.05 | AC24: 0.05 | AD24: 0.05 | AE24: 0.05 | AF24: 0.05 | AG24: 0.05 | AH24: 0.05 | AI24: 0.05 | AJ24: 0.05 | AK24: 0.05 | AL24: 0.05 | AM24: 0.05 | AN24: 864 | AO24: =AB24*AN24 -> 43.2 | AP24: 0 | AQ24: =AC24*AP24 -> 0 | AR24: 0 | AS24: =AD24*AR24 -> 0 | AT24: 0 | AU24: =AE24*AT24 -> 0 | AV24: 0 | AW24: =AF24*AV24 -> 0 | AX24: 0 | AY24: =AG24*AX24 -> 0 | AZ24: 1728 | BA24: =AH24*AZ24 -> 86.4 | BB24: 0 | BC24: =AI24*BB24 -> 0 | BD24: 0 | BE24: =AJ24*BD24 -> 0 | BF24: 0 | BG24: =AK24*BF24 -> 0 | BH24: 0 | BI24: =AL24*BH24 -> 0 | BJ24: 0 | BK24: =AM24*BJ24 -> 0 | BM24: V0L80AA#UUF/CPS/1560/GBU/Shanghai
A25: FY23 | B25: Allen Chen | G25: 2016 | H25: GADGET | I25: Mouse | J25: NA | K25: Rose Gold | L25: S China | M25: OTHERS | N25: 5.34 | O25: 5.34 | P25: 5.34 | Q25: 5.34 | R25: 5.34 | S25: 5.34 | T25: 5.34 | U25: 5.34 | V25: 5.34 | W25: 5.34 | X25: 5.34 | Y25: 5.34 | Z25: 5.34 | AA25: 0 | AB25: 0.05 | AC25: 0.05 | AD25: 0.05 | AE25: 0.05 | AF25: 0.05 | AG25: 0.05 | AH25: 0.05 | AI25: 0.05 | AJ25: 0.05 | AK25: 0.05 | AL25: 0.05 | AM25: 0.05 | AN25: 1000 | AO25: =AB25*AN25 -> 50 | AP25: 0 | AQ25: =AC25*AP25 -> 0 | AR25: 0 | AS25: =AD25*AR25 -> 0 | AT25: 800 | AU25: =AE25*AT25 -> 40 | AV25: 0 | AW25: =AF25*AV25 -> 0 | AX25: 0 | AY25: =AG25*AX25 -> 0 | AZ25: 0 | BA25: =AH25*AZ25 -> 0 | BB25: 0 | BC25: =AI25*BB25 -> 0 | BD25: 0 | BE25: =AJ25*BD25 -> 0 | BF25: 0 | BG25: =AK25*BF25 -> 0 | BH25: 0 | BI25: =AL25*BH25 -> 0 | BJ25: 0 | BK25: =AM25*BJ25 -> 0 | BM25: L77931-001/DIB/1000/bulk pack
A26: FY23 | B26: Allen Chen | G26: 2016 | H26: GADGET | I26: Mouse | J26: NA | K26: Ceramic White | L26: S China | M26: OTHERS | N26: 6.17 | O26: 6.17 | P26: 6.17 | Q26: 6.17 | R26: 6.17 | S26: 6.17 | T26: 6.17 | U26: 6.17 | V26: 6.17 | W26: 6.17 | X26: 6.17 | Y26: 6.17 | Z26: 6.17 | AA26: 0 | AB26: 0.05 | AC26: 0.05 | AD26: 0.05 | AE26: 0.05 | AF26: 0.05 | AG26: 0.05 | AH26: 0.05 | AI26: 0.05 | AJ26: 0.05 | AK26: 0.05 | AL26: 0.05 | AM26: 0.05 | AN26: 1560 | AO26: =AB26*AN26 -> 78 | AP26: 0 | AQ26: =AC26*AP26 -> 0 | AR26: 0 | AS26: =AD26*AR26 -> 0 | AT26: 1560 | AU26: =AE26*AT26 -> 78 | AV26: 1560 | AW26: =AF26*AV26 -> 78 | AX26: 0 | AY26: =AG26*AX26 -> 0 | AZ26: 3120 | BA26: =AH26*AZ26 -> 156 | BB26: 0 | BC26: =AI26*BB26 -> 0 | BD26: 0 | BE26: =AJ26*BD26 -> 0 | BF26: 0 | BG26: =AK26*BF26 -> 0 | BH26: 0 | BI26: =AL26*BH26 -> 0 | BJ26: 0 | BK26: =AM26*BJ26 -> 0 | BM26: 171D8AA#ABB/CPS/1560/GBU
A27: FY23 | B27: Allen Chen | G27: 2016 | H27: GADGET | I27: Mouse | J27: NA | K27: Tranquil Pink(painting) | L27: S China | M27: OTHERS | N27: 5.95 | O27: 5.95 | P27: 5.95 | Q27: 5.95 | R27: 5.95 | S27: 5.95 | T27: 5.95 | U27: 5.95 | V27: 5.95 | W27: 5.95 | X27: 5.95 | Y27: 5.95 | Z27: 5.95 | AA27: 0 | AB27: 0.05 | AC27: 0.05 | AD27: 0.05 | AE27: 0.05 | AF27: 0.05 | AG27: 0.05 | AH27: 0.05 | AI27: 0.05 | AJ27: 0.05 | AK27: 0.05 | AL27: 0.05 | AM27: 0.05 | AN27: 1560 | AO27: =AB27*AN27 -> 78 | AP27: 0 | AQ27: =AC27*AP27 -> 0 | AR27: 1560 | AS27: =AD27*AR27 -> 78 | AT27: 1560 | AU27: =AE27*AT27 -> 78 | AV27: 0 | AW27: =AF27*AV27 -> 0 | AX27: 1560 | AY27: =AG27*AX27 -> 78 | AZ27: 0 | BA27: =AH27*AZ27 -> 0 | BB27: 4320 | BC27: =AI27*BB27 -> 216 | BD27: 0 | BE27: =AJ27*BD27 -> 0 | BF27: 0 | BG27: =AK27*BF27 -> 0 | BH27: 0 | BI27: =AL27*BH27 -> 0 | BJ27: 0 | BK27: =AM27*BJ27 -> 0 | BM27: 4VY82AA#ABB/CPS/1560/GBU
A28: FY23 | B28: Allen Chen | G28: 2016 | H28: GADGET | I28: Mouse | J28: NA | K28: Black | L28: S China | M28: OTHERS | N28: 5.15 | O28: 5.15 | P28: 5.15 | Q28: 5.15 | R28: 5.15 | S28: 5.15 | T28: 5.15 | U28: 5.15 | V28: 5.15 | W28: 5.15 | X28: 5.15 | Y28: 5.15 | Z28: 5.15 | AA28: 0 | AB28: 0.05 | AC28: 0.05 | AD28: 0.05 | AE28: 0.05 | AF28: 0.05 | AG28: 0.05 | AH28: 0.05 | AI28: 0.05 | AJ28: 0.05 | AK28: 0.05 | AL28: 0.05 | AM28: 0.05 | AN28: 7800 | AO28: =AB28*AN28 -> 390 | AP28: 1560 | AQ28: =AC28*AP28 -> 78 | AR28: 7800 | AS28: =AD28*AR28 -> 390 | AT28: 0 | AU28: =AE28*AT28 -> 0 | AV28: 3120 | AW28: =AF28*AV28 -> 156 | AX28: 6240 | AY28: =AG28*AX28 -> 312 | AZ28: 7800 | BA28: =AH28*AZ28 -> 390 | BB28: 0 | BC28: =AI28*BB28 -> 0 | BD28: 0 | BE28: =AJ28*BD28 -> 0 | BF28: 0 | BG28: =AK28*BF28 -> 0 | BH28: 0 | BI28: =AL28*BH28 -> 0 | BJ28: 0 | BK28: =AM28*BJ28 -> 0 | BM28: V0L79AA#ABB/CPS/1560/GBU
A29: FY23 | B29: Allen Chen | G29: 2016 | H29: GADGET | I29: Mouse | J29: NA | K29: White | L29: S China | M29: OTHERS | N29: 5.23 | O29: 5.23 | P29: 5.23 | Q29: 5.23 | R29: 5.23 | S29: 5.23 | T29: 5.23 | U29: 5.23 | V29: 5.23 | W29: 5.23 | X29: 5.23 | Y29: 5.23 | Z29: 5.23 | AA29: 0 | AB29: 0.05 | AC29: 0.05 | AD29: 0.05 | AE29: 0.05 | AF29: 0.05 | AG29: 0.05 | AH29: 0.05 | AI29: 0.05 | AJ29: 0.05 | AK29: 0.05 | AL29: 0.05 | AM29: 0.05 | AN29: 6240 | AO29: =AB29*AN29 -> 312 | AP29: 1560 | AQ29: =AC29*AP29 -> 78 | AR29: 1560 | AS29: =AD29*AR29 -> 78 | AT29: 0 | AU29: =AE29*AT29 -> 0 | AV29: 0 | AW29: =AF29*AV29 -> 0 | AX29: 0 | AY29: =AG29*AX29 -> 0 | AZ29: 0 | BA29: =AH29*AZ29 -> 0 | BB29: 0 | BC29: =AI29*BB29 -> 0 | BD29: 0 | BE29: =AJ29*BD29 -> 0 | BF29: 0 | BG29: =AK29*BF29 -> 0 | BH29: 0 | BI29: =AL29*BH29 -> 0 | BJ29: 0 | BK29: =AM29*BJ29 -> 0 | BM29: V0L80AA#ABB/CPS/1560/GBU
A30: FY23 | B30: Allen Chen | G30: 2016 | H30: GADGET | I30: Mouse | J30: NA | K30: Blue | L30: S China | M30: OTHERS | N30: 5.23 | O30: 5.23 | P30: 5.23 | Q30: 5.23 | R30: 5.23 | S30: 5.23 | T30: 5.23 | U30: 5.23 | V30: 5.23 | W30: 5.23 | X30: 5.23 | Y30: 5.23 | Z30: 5.23 | AA30: 0 | AB30: 0.05 | AC30: 0.05 | AD30: 0.05 | AE30: 0.05 | AF30: 0.05 | AG30: 0.05 | AH30: 0.05 | AI30: 0.05 | AJ30: 0.05 | AK30: 0.05 | AL30: 0.05 | AM30: 0.05 | AN30: 1560 | AO30: =AB30*AN30 -> 78 | AP30: 0 | AQ30: =AC30*AP30 -> 0 | AR30: 0 | AS30: =AD30*AR30 -> 0 | AT30: 0 | AU30: =AE30*AT30 -> 0 | AV30: 0 | AW30: =AF30*AV30 -> 0 | AX30: 0 | AY30: =AG30*AX30 -> 0 | AZ30: 1560 | BA30: =AH30*AZ30 -> 78 | BB30: 0 | BC30: =AI30*BB30 -> 0 | BD30: 0 | BE30: =AJ30*BD30 -> 0 | BF30: 0 | BG30: =AK30*BF30 -> 0 | BH30: 0 | BI30: =AL30*BH30 -> 0 | BJ30: 0 | BK30: =AM30*BJ30 -> 0 | BM30: V0L81AA#ABB/CPS/1560/GBU
A31: FY23 | B31: Allen Chen | G31: 2016 | H31: GADGET | I31: Mouse | J31: NA | K31: Gold(painting) | L31: S China | M31: OTHERS | N31: 5.53 | O31: 5.53 | P31: 5.53 | Q31: 5.53 | R31: 5.53 | S31: 5.53 | T31: 5.53 | U31: 5.53 | V31: 5.53 | W31: 5.53 | X31: 5.53 | Y31: 5.53 | Z31: 5.53 | AA31: 0 | AB31: 0.05 | AC31: 0.05 | AD31: 0.05 | AE31: 0.05 | AF31: 0.05 | AG31: 0.05 | AH31: 0.05 | AI31: 0.05 | AJ31: 0.05 | AK31: 0.05 | AL31: 0.05 | AM31: 0.05 | AN31: 1560 | AO31: =AB31*AN31 -> 78 | AP31: 0 | AQ31: =AC31*AP31 -> 0 | AR31: 0 | AS31: =AD31*AR31 -> 0 | AT31: 0 | AU31: =AE31*AT31 -> 0 | AV31: 0 | AW31: =AF31*AV31 -> 0 | AX31: 0 | AY31: =AG31*AX31 -> 0 | AZ31: 3120 | BA31: =AH31*AZ31 -> 156 | BB31: 0 | BC31: =AI31*BB31 -> 0 | BD31: 0 | BE31: =AJ31*BD31 -> 0 | BF31: 0 | BG31: =AK31*BF31 -> 0 | BH31: 0 | BI31: =AL31*BH31 -> 0 | BJ31: 0 | BK31: =AM31*BJ31 -> 0 | BM31: X7Q43AA#ABB/CPS/1560/GBU
A32: FY23 | B32: Allen Chen | G32: 2016 | H32: GADGET | I32: Mouse | J32: NA | K32: NSilver(painting) | L32: S China | M32: OTHERS | N32: 5.34 | O32: 5.34 | P32: 5.34 | Q32: 5.34 | R32: 5.34 | S32: 5.34 | T32: 5.34 | U32: 5.34 | V32: 5.34 | W32: 5.34 | X32: 5.34 | Y32: 5.34 | Z32: 5.34 | AA32: 0 | AB32: 0.05 | AC32: 0.05 | AD32: 0.05 | AE32: 0.05 | AF32: 0.05 | AG32: 0.05 | AH32: 0.05 | AI32: 0.05 | AJ32: 0.05 | AK32: 0.05 | AL32: 0.05 | AM32: 0.05 | AN32: 0 | AO32: =AB32*AN32 -> 0 | AP32: 1000 | AQ32: =AC32*AP32 -> 50 | AR32: 1000 | AS32: =AD32*AR32 -> 50 | AT32: 5000 | AU32: =AE32*AT32 -> 250 | AV32: 6000 | AW32: =AF32*AV32 -> 300 | AX32: 3000 | AY32: =AG32*AX32 -> 150 | AZ32: 0 | BA32: =AH32*AZ32 -> 0 | BB32: 0 | BC32: =AI32*BB32 -> 0 | BD32: 0 | BE32: =AJ32*BD32 -> 0 | BF32: 0 | BG32: =AK32*BF32 -> 0 | BH32: 0 | BI32: =AL32*BH32 -> 0 | BJ32: 0 | BK32: =AM32*BJ32 -> 0 | BM32: L73781-201/DIB/1000/bulk pack
A33: FY23 | B33: Allen Chen | G33: 2016 | H33: GADGET | I33: Mouse | J33: NA | K33: Silver(painting) | L33: S China | M33: OTHERS | N33: 6.4062308 | O33: 6.4062308 | P33: 6.4062308 | Q33: 6.4062308 | R33: 6.4062308 | S33: 6.4062308 | T33: 6.4062308 | U33: 6.4062308 | V33: 6.4062308 | W33: 6.4062308 | X33: 6.4062308 | Y33: 6.4062308 | Z33: 6.4062308 | AA33: 0 | AB33: 0.05 | AC33: 0.05 | AD33: 0.05 | AE33: 0.05 | AF33: 0.05 | AG33: 0.05 | AH33: 0.05 | AI33: 0.05 | AJ33: 0.05 | AK33: 0.05 | AL33: 0.05 | AM33: 0.05 | AN33: 0 | AO33: =AB33*AN33 -> 0 | AP33: 864 | AQ33: =AC33*AP33 -> 43.2 | AR33: 0 | AS33: =AD33*AR33 -> 0 | AT33: 0 | AU33: =AE33*AT33 -> 0 | AV33: 0 | AW33: =AF33*AV33 -> 0 | AX33: 0 | AY33: =AG33*AX33 -> 0 | AZ33: 0 | BA33: =AH33*AZ33 -> 0 | BB33: 0 | BC33: =AI33*BB33 -> 0 | BD33: 0 | BE33: =AJ33*BD33 -> 0 | BF33: 0 | BG33: =AK33*BF33 -> 0 | BH33: 0 | BI33: =AL33*BH33 -> 0 | BJ33: 0 | BK33: =AM33*BJ33 -> 0 | BM33: X7Q44AA#UUF/CPS/1560/GBUShanghai
A34: FY23 | B34: Allen Chen | G34: 2019 | H34: GALAPAGOS | I34: Mouse | J34: NA | K34: Black | L34: S China | M34: OTHERS | N34: 1.72 | O34: 1.72 | P34: 1.72 | Q34: 1.72 | R34: 1.72 | S34: 1.72 | T34: 1.72 | U34: 1.72 | V34: 1.72 | W34: 1.72 | X34: 1.72 | Y34: 1.72 | Z34: 1.72 | AA34: 0 | AB34: 0 | AC34: 0 | AD34: 0 | AE34: 0 | AF34: 0 | AG34: 0 | AH34: 0 | AI34: 0 | AJ34: 0 | AK34: 0 | AL34: 0 | AM34: 0 | AN34: 10000 | AO34: =AB34*AN34 -> 0 | AP34: 0 | AQ34: =AC34*AP34 -> 0 | AR34: 0 | AS34: =AD34*AR34 -> 0 | AT34: 0 | AU34: =AE34*AT34 -> 0 | AV34: 10000 | AW34: =AF34*AV34 -> 0 | AX34: 10000 | AY34: =AG34*AX34 -> 0 | AZ34: 10000 | BA34: =AH34*AZ34 -> 0 | BB34: 10000 | BC34: =AI34*BB34 -> 0 | BD34: 0 | BE34: =AJ34*BD34 -> 0 | BF34: 0 | BG34: =AK34*BF34 -> 0 | BH34: 0 | BI34: =AL34*BH34 -> 0 | BJ34: 0 | BK34: =AM34*BJ34 -> 0 | BM34: 6VY96AA#ACJ/CPS/6720/EM
A35: FY23 | B35: Allen Chen | G35: 2019 | H35: GALAPAGOS | I35: Mouse | J35: NA | K35: Black | L35: S China | M35: OTHERS | N35: 1.89 | O35: 1.89 | P35: 1.89 | Q35: 1.89 | R35: 1.89 | S35: 1.89 | T35: 1.89 | U35: 1.89 | V35: 1.89 | W35: 1.89 | X35: 1.89 | Y35: 1.89 | Z35: 1.89 | AA35: 0 | AB35: 0 | AC35: 0 | AD35: 0 | AE35: 0 | AF35: 0 | AG35: 0 | AH35: 0 | AI35: 0 | AJ35: 0 | AK35: 0 | AL35: 0 | AM35: 0 | AN35: 2880 | AO35: =AB35*AN35 -> 0 | AP35: 0 | AQ35: =AC35*AP35 -> 0 | AR35: 0 | AS35: =AD35*AR35 -> 0 | AT35: 2880 | AU35: =AE35*AT35 -> 0 | AV35: 0 | AW35: =AF35*AV35 -> 0 | AX35: 2880 | AY35: =AG35*AX35 -> 0 | AZ35: 0 | BA35: =AH35*AZ35 -> 0 | BB35: 8640 | BC35: =AI35*BB35 -> 0 | BD35: 5760 | BE35: =AJ35*BD35 -> 0 | BF35: 2880 | BG35: =AK35*BF35 -> 0 | BH35: 2880 | BI35: =AL35*BH35 -> 0 | BJ35: 2880 | BK35: =AM35*BJ35 -> 0 | BM35: 6VY96AA#UUF/CPS/2880/EM
... A39: FY23 | B39: Simon Yang | G39: 2020 | H39: HAVELOCK | I39: Combo | J39: NA | K39: Black | L39: S China | M39: OTHERS | N39: 7.8 | O39: 7.8 | P39: 7.8 | Q39: 7.8 | R39: 7.8 | S39: 7.8 | T39: 7.8 | U39: 7.8 | V39: 7.8 | W39: 7.8 | X39: 7.8 | Y39: 7.8 | Z39: 7.8 | AA39: 0 | AB39: 0 | AC39: 0 | AD39: 0 | AE39: 0 | AF39: 0 | AG39: 0 | AH39: 0 | AI39: 0 | AJ39: 0 | AK39: 0 | AL39: 0 | AM39: 0 | AN39: 10000 | AO39: =AB39*AN39 -> 0 | AP39: 10000 | AQ39: =AC39*AP39 -> 0 | AR39: 0 | AS39: =AD39*AR39 -> 0 | AT39: 0 | AU39: =AE39*AT39 -> 0 | AV39: 10000 | AW39: =AF39*AV39 -> 0 | AX39: 0 | AY39: =AG39*AX39 -> 0 | AZ39: 10000 | BA39: =AH39*AZ39 -> 0 | BB39: 10000 | BC39: =AI39*BB39 -> 0 | BD39: 0 | BE39: =AJ39*BD39 -> 0 | BF39: 10560 | BG39: =AK39*BF39 -> 0 | BH39: 0 | BI39: =AL39*BH39 -> 0 | BJ39: 5280 | BK39: =AM39*BJ39 -> 0 | BM39: 2V9E6AA#ACJ/CPS/5280/GBU
A40: FY23 | G40: 2021 | H40: IVY DONGLE | I40: Others | J40: NA | K40: Black | L40: S China | M40: OTHERS | N40: 3.26 | O40: 3.26 | P40: 3.26 | Q40: 3.26 | R40: 3.26 | S40: 3.26 | T40: 3.26 | U40: 3.26 | V40: 3.26 | W40: 3.26 | X40: 3.26 | Y40: 3.26 | Z40: 3.26 | AA40: 0 | AB40: 0 | AC40: 0 | AD40: 0 | AE40: 0 | AF40: 0 | AG40: 0 | AH40: 0 | AI40: 0 | AJ40: 0 | AK40: 0 | AL40: 0 | AM40: 0 | AN40: 5000 | AO40: =AB40*AN40 -> 0 | AP40: 0 | AQ40: =AC40*AP40 -> 0 | AR40: 0 | AS40: =AD40*AR40 -> 0 | AT40: 1000 | AU40: =AE40*AT40 -> 0 | AV40: 2000 | AW40: =AF40*AV40 -> 0 | AX40: 0 | AY40: =AG40*AX40 -> 0 | AZ40: 1000 | BA40: =AH40*AZ40 -> 0 | BB40: 0 | BC40: =AI40*BB40 -> 0 | BD40: 3000 | BE40: =AJ40*BD40 -> 0 | BF40: 1000 | BG40: =AK40*BF40 -> 0 | BH40: 0 | BI40: =AL40*BH40 -> 0 | BJ40: 0 | BK40: =AM40*BJ40 -> 0 | BM40: 6E+P8C01.001/1000/Tray
A41: FY23 | B41: Allen Chen | G41: 2020 | H41: JERRY | I41: Mouse | J41: NA | K41: Nightfull black | L41: S China | M41: OTHERS | N41: 22.78 | O41: 22.78 | P41: 22.78 | Q41: 22.78 | R41: 22.78 | S41: 22.78 | T41: 22.78 | U41: 22.78 | V41: 22.78 | W41: 22.78 | X41: 22.78 | Y41: 22.78 | Z41: 22.78 | AA41: 0 | AB41: 0 | AC41: 0 | AD41: 0 | AE41: 0 | AF41: 0 | AG41: 0 | AH41: 0 | AI41: 0 | AJ41: 0 | AK41: 0 | AL41: 0 | AM41: 0 | AN41: 0 | AO41: =AB41*AN41 -> 0 | AP41: 1008 | AQ41: =AC41*AP41 -> 0 | AR41: 0 | AS41: =AD41*AR41 -> 0 | AT41: 0 | AU41: =AE41*AT41 -> 0 | AV41: 0 | AW41: =AF41*AV41 -> 0 | AX41: 1008 | AY41: =AG41*AX41 -> 0 | AZ41: 0 | BA41: =AH41*AZ41 -> 0 | BB41: 1008 | BC41: =AI41*BB41 -> 0 | BD41: 0 | BE41: =AJ41*BD41 -> 0 | BF41: 1008 | BG41: =AK41*BF41 -> 0 | BH41: 0 | BI41: =AL41*BH41 -> 0 | BJ41: 0 | BK41: =AM41*BJ41 -> 0 | BM41: 1D0K2AA#AC3/BPS/1008/BOX
A42: FY23 | B42: Allen Chen | G42: 2021 | H42: KENTING PLUS | I42: Mouse | J42: NA | K42: Black | L42: S China | M42: OTHERS | N42: 5.11 | O42: 5.11 | P42: 5.11 | Q42: 5.11 | R42: 5.11 | S42: 5.11 | T42: 5.11 | U42: 5.11 | V42: 5.11 | W42: 5.11 | X42: 5.11 | Y42: 5.11 | Z42: 5.11 | AA42: 0 | AB42: 0 | AC42: 0 | AD42: 0 | AE42: 0 | AF42: 0 | AG42: 0 | AH42: 0 | AI42: 0 | AJ42: 0 | AK42: 0 | AL42: 0 | AM42: 0 | AN42: 2880 | AO42: =AB42*AN42 -> 0 | AP42: 2880 | AQ42: =AC42*AP42 -> 0 | AR42: 0 | AS42: =AD42*AR42 -> 0 | AT42: 0 | AU42: =AE42*AT42 -> 0 | AV42: 0 | AW42: =AF42*AV42 -> 0 | AX42: 0 | AY42: =AG42*AX42 -> 0 | AZ42: 0 | BA42: =AH42*AZ42 -> 0 | BB42: 0 | BC42: =AI42*BB42 -> 0 | BD42: 0 | BE42: =AJ42*BD42 -> 0 | BF42: 0 | BG42: =AK42*BF42 -> 0 | BH42: 0 | BI42: =AL42*BH42 -> 0 | BJ42: 0 | BK42: =AM42*BJ42 -> 0 | BM42: 4E407AA#AB2/BPS/2880/EM | BN42: (上海)
A43: FY23 | B43: Allen Chen | G43: 2021 | H43: KENTING PLUS | I43: Mouse | J43: NA | K43: Black | L43: S China | M43: OTHERS | N43: 4.43 | O43: 4.43 | P43: 4.43 | Q43: 4.43 | R43: 4.43 | S43: 4.43 | T43: 4.43 | U43: 4.43 | V43: 4.43 | W43: 4.43 | X43: 4.43 | Y43: 4.43 | Z43: 4.43 | AA43: 0 | AB43: 0 | AC43: 0 | AD43: 0 | AE43: 0 | AF43: 0 | AG43: 0 | AH43: 0 | AI43: 0 | AJ43: 0 | AK43: 0 | AL43: 0 | AM43: 0 | AN43: 2880 | AO43: =AB43*AN43 -> 0 | AP43: 0 | AQ43: =AC43*AP43 -> 0 | AR43: 2880 | AS43: =AD43*AR43 -> 0 | AT43: 0 | AU43: =AE43*AT43 -> 0 | AV43: 0 | AW43: =AF43*AV43 -> 0 | AX43: 0 | AY43: =AG43*AX43 -> 0 | AZ43: 0 | BA43: =AH43*AZ43 -> 0 | BB43: 0 | BC43: =AI43*BB43 -> 0 | BD43: 0 | BE43: =AJ43*BD43 -> 0 | BF43: 2880 | BG43: =AK43*BF43 -> 0 | BH43: 0 | BI43: =AL43*BH43 -> 0 | BJ43: 0 | BK43: =AM43*BJ43 -> 0 | BM43: 4E407AA#ACJ/BPS/2880/EM
A44: FY23 | B44: Allen Chen | G44: 2021 | H44: KENTING PLUS | I44: Mouse | J44: NA | K44: Black | L44: S China | M44: OTHERS | N44: 4.39 | O44: 4.39 | P44: 4.39 | Q44: 4.39 | R44: 4.39 | S44: 4.39 | T44: 4.39 | U44: 4.39 | V44: 4.39 | W44: 4.39 | X44: 4.39 | Y44: 4.39 | Z44: 4.39 | AA44: 0 | AB44: 0 | AC44: 0 | AD44: 0 | AE44: 0 | AF44: 0 | AG44: 0 | AH44: 0 | AI44: 0 | AJ44: 0 | AK44: 0 | AL44: 0 | AM44: 0 | AN44: 2880 | AO44: =AB44*AN44 -> 0 | AP44: 0 | AQ44: =AC44*AP44 -> 0 | AR44: 0 | AS44: =AD44*AR44 -> 0 | AT44: 0 | AU44: =AE44*AT44 -> 0 | AV44: 0 | AW44: =AF44*AV44 -> 0 | AX44: 0 | AY44: =AG44*AX44 -> 0 | AZ44: 0 | BA44: =AH44*AZ44 -> 0 | BB44: 0 | BC44: =AI44*BB44 -> 0 | BD44: 0 | BE44: =AJ44*BD44 -> 0 | BF44: 0 | BG44: =AK44*BF44 -> 0 | BH44: 0 | BI44: =AL44*BH44 -> 0 | BJ44: 0 | BK44: =AM44*BJ44 -> 0 | BM44: 4E407AA#ABL/BPS/2880/Brown box
A45: FY23 | B45: Simon Yang | G45: 2019 | H45: KINGKONG | I45: Combo | J45: NA | K45: Black | L45: S China | M45: OTHERS | N45: 10.23 | O45: 10.23 | P45: 10.23 | Q45: 10.23 | R45: 10.23 | S45: 10.23 | T45: 10.23 | U45: 10.23 | V45: 10.23 | W45: 10.23 | X45: 10.23 | Y45: 10.23 | Z45: 10.23 | AA45: 0 | AB45: 0 | AC45: 0 | AD45: 0 | AE45: 0 | AF45: 0 | AG45: 0 | AH45: 0 | AI45: 0 | AJ45: 0 | AK45: 0 | AL45: 0 | AM45: 0 | AN45: 0 | AO45: =AB45*AN45 -> 0 | AP45: 5120 | AQ45: =AC45*AP45 -> 0 | AR45: 0 | AS45: =AD45*AR45 -> 0 | AT45: 0 | AU45: =AE45*AT45 -> 0 | AV45: 0 | AW45: =AF45*AV45 -> 0 | AX45: 5120 | AY45: =AG45*AX45 -> 0 | AZ45: 7680 | BA45: =AH45*AZ45 -> 0 | BB45: 0 | BC45: =AI45*BB45 -> 0 | BD45: 14080 | BE45: =AJ45*BD45 -> 0 | BF45: 16640 | BG45: =AK45*BF45 -> 0 | BH45: 0 | BI45: =AL45*BH45 -> 0 | BJ45: 0 | BK45: =AM45*BJ45 -> 0 | BM45: 3ML04AA#UUF/CPS/1280/GBU
A46: FY23 | B46: Allen Chen | G46: 2020 | H46: KITKAT | I46: Mouse | J46: NA | K46: Black | L46: S China | M46: OTHERS | N46: 3.33 | O46: 3.33 | P46: 3.33 | Q46: 3.33 | R46: 3.33 | S46: 3.33 | T46: 3.33 | U46: 3.33 | V46: 3.33 | W46: 3.33 | X46: 3.33 | Y46: 3.33 | Z46: 3.33 | AA46: 0 | AB46: 0 | AC46: 0 | AD46: 0 | AE46: 0 | AF46: 0 | AG46: 0 | AH46: 0 | AI46: 0 | AJ46: 0 | AK46: 0 | AL46: 0 | AM46: 0 | AN46: 10000 | AO46: =AB46*AN46 -> 0 | AP46: 10000 | AQ46: =AC46*AP46 -> 0 | AR46: 0 | AS46: =AD46*AR46 -> 0 | AT46: 0 | AU46: =AE46*AT46 -> 0 | AV46: 10000 | AW46: =AF46*AV46 -> 0 | AX46: 0 | AY46: =AG46*AX46 -> 0 | AZ46: 20000 | BA46: =AH46*AZ46 -> 0 | BB46: 10000 | BC46: =AI46*BB46 -> 0 | BD46: 0 | BE46: =AJ46*BD46 -> 0 | BF46: 16720 | BG46: =AK46*BF46 -> 0 | BH46: 0 | BI46: =AL46*BH46 -> 0 | BJ46: 6720 | BK46: =AM46*BJ46 -> 0 | BM46: 2S9L1AA#ABM/CPS/6720/EM
A47: FY23 | B47: Allen Chen | G47: 2020 | H47: KITKAT | I47: Mouse | J47: NA | K47: Black | L47: S China | M47: OTHERS | N47: 3.28 | O47: 3.28 | P47: 3.28 | Q47: 3.28 | R47: 3.28 | S47: 3.28 | T47: 3.28 | U47: 3.28 | V47: 3.28 | W47: 3.28 | X47: 3.28 | Y47: 3.28 | Z47: 3.28 | AA47: 0 | AB47: 0 | AC47: 0 | AD47: 0 | AE47: 0 | AF47: 0 | AG47: 0 | AH47: 0 | AI47: 0 | AJ47: 0 | AK47: 0 | AL47: 0 | AM47: 0 | AN47: 30000 | AO47: =AB47*AN47 -> 0 | AP47: 10000 | AQ47: =AC47*AP47 -> 0 | AR47: 10000 | AS47: =AD47*AR47 -> 0 | AT47: 0 | AU47: =AE47*AT47 -> 0 | AV47: 0 | AW47: =AF47*AV47 -> 0 | AX47: 0 | AY47: =AG47*AX47 -> 0 | AZ47: 0 | BA47: =AH47*AZ47 -> 0 | BB47: 10000 | BC47: =AI47*BB47 -> 0 | BD47: 13440 | BE47: =AJ47*BD47 -> 0 | BF47: 6720 | BG47: =AK47*BF47 -> 0 | BH47: 20160 | BI47: =AL47*BH47 -> 0 | BJ47: 13440 | BK47: =AM47*BJ47 -> 0 | BM47: 2S9L1AA#ABB/CPS/6720/EM
A48: FY23 | B48: Allen Chen | G48: 2020 | H48: KITKAT | I48: Mouse | J48: NA | K48: Black | L48: S China | M48: OTHERS | N48: 3.29 | O48: 3.29 | P48: 3.29 | Q48: 3.29 | R48: 3.29 | S48: 3.29 | T48: 3.29 | U48: 3.29 | V48: 3.29 | W48: 3.29 | X48: 3.29 | Y48: 3.29 | Z48: 3.29 | AA48: 0 | AB48: 0 | AC48: 0 | AD48: 0 | AE48: 0 | AF48: 0 | AG48: 0 | AH48: 0 | AI48: 0 | AJ48: 0 | AK48: 0 | AL48: 0 | AM48: 0 | AN48: 10000 | AO48: =AB48*AN48 -> 0 | AP48: 20000 | AQ48: =AC48*AP48 -> 0 | AR48: 10000 | AS48: =AD48*AR48 -> 0 | AT48: 0 | AU48: =AE48*AT48 -> 0 | AV48: 10000 | AW48: =AF48*AV48 -> 0 | AX48: 0 | AY48: =AG48*AX48 -> 0 | AZ48: 0 | BA48: =AH48*AZ48 -> 0 | BB48: 10000 | BC48: =AI48*BB48 -> 0 | BD48: 0 | BE48: =AJ48*BD48 -> 0 | BF48: 10000 | BG48: =AK48*BF48 -> 0 | BH48: 6720 | BI48: =AL48*BH48 -> 0 | BJ48: 6720 | BK48: =AM48*BJ48 -> 0 | BM48: 2S9L1AA#UUF/CPS/6720/EM
A49: FY23 | B49: Allen Chen | G49: 2020 | H49: KITKAT | I49: Mouse | J49: NA | K49: Black | L49: S China | M49: OTHERS | N49: 3.28 | O49: 3.28 | P49: 3.28 | Q49: 3.28 | R49: 3.28 | S49: 3.28 | T49: 3.28 | U49: 3.28 | V49: 3.28 | W49: 3.28 | X49: 3.28 | Y49: 3.28 | Z49: 3.28 | AA49: 0 | AB49: 0 | AC49: 0 | AD49: 0 | AE49: 0 | AF49: 0 | AG49: 0 | AH49: 0 | AI49: 0 | AJ49: 0 | AK49: 0 | AL49: 0 | AM49: 0 | AN49: 0 | AO49: =AB49*AN49 -> 0 | AP49: 10000 | AQ49: =AC49*AP49 -> 0 | AR49: 0 | AS49: =AD49*AR49 -> 0 | AT49: 10000 | AU49: =AE49*AT49 -> 0 | AV49: 16720 | AW49: =AF49*AV49 -> 0 | AX49: 3280 | AY49: =AG49*AX49 -> 0 | AZ49: 10000 | BA49: =AH49*AZ49 -> 0 | BB49: 10000 | BC49: =AI49*BB49 -> 0 | BD49: 10000 | BE49: =AJ49*BD49 -> 0 | BF49: 0 | BG49: =AK49*BF49 -> 0 | BH49: 0 | BI49: =AL49*BH49 -> 0 | BJ49: 6720 | BK49: =AM49*BJ49 -> 0 | BM49: 2S9L1AA#ACJ/CPS/6720/EM
...

Sheet FY24 Summary_2
B3: Q1 Actual by Segment
C4: Segment | D4: 45231 | E4: 45261 | F4: 45292 | G4: Total Rebate in Q1 2024 (US$)
B5: CMIT Input Devices | C5: 200 series (6U)
C6: 400 series (S)
C7: 600 series (B)
C8: 800 series (P)
C9: 1000 series (M
C10: MWS (Workstation)
C11: Soft Keyboard
C12: Chrome Book
C13: Clickpad
C14: Education
C15: Peripherals/AMO
C16: Desktop
B17: Consumer Input Devices | C17: OPP
C18: Chrome Book
C19: Pavillion
C20: Spectre
C21: Envy
C22: Stream
C23: Omen
C24: Peripherals/AMO
C25: Desktop
B28: Q1 Actual by Segment
C29: Supplier | D29: 45231 | E29: 45261 | F29: 45292 | G29: Total Rebate in Q1 2024 (US$)
B30: Input Devices | C30: Acrox | D30: ='FY24 Summary_1'!C4 -> 36153.6 | E30: ='FY24 Summary_1'!D4 -> 24589.2 | F30: ='FY24 Summary_1'!E4 -> 45935.6 | G30: =SUM(D30:F30) -> 106678.4
C31: Chicony
C32: Darfon
C33: Liteon
C34: Primax
C35: Sunrex
F36: Total Rebate Amount
B39: Q2 Actual by Segment
C40: Segment | D40: 45323 | E40: 45352 | F40: 45383 | G40: Total Rebate in Q2 2024 (US$)
B41: CMIT Input Devices | C41: 200 series (6U)
C42: 400 series (S)
C43: 600 series (B)
C44: 800 series (P)
C45: 1000 series (M
C46: MWS (Workstation)
...

Sheet 工作表1
D4: Compal | E4: 3000
D5: Flextronics CZ | E5: 63980
D6: FOX CQ | E6: 10800
D7: Foxconn CZ | E7: 58476
D8: Foxconn Indy | E8: 28378
D9: Foxconn LH | E9: 210900
D10: HP India | E10: 16560
D11: Inventec | E11: 3000
D12: QUANTA | E12: 23640
D13: Ryder Indy | E13: 43200
D14: Shanghai | E14: 1890
D15: 總計 | E15: 463824

Sheet 工作表3
A3: 加總 - Jul Q'ty
A4: 3214709.9 | C4: =_xlfn.XLOOKUP(A4,[1]工作表3!$A:$A,[1]工作表3!$B:$B,"0") -> 0 | E4: 0 | F4: 0 | G4: =E4-F4 -> 0
C5: =_xlfn.XLOOKUP(A5,[1]工作表3!$A:$A,[1]工作表3!$B:$B,"0") -> 0 | E5: 0 | F5: 0 | G5: =E5-F5 -> 0
C6: =_xlfn.XLOOKUP(A6,[1]工作表3!$A:$A,[1]工作表3!$B:$B,"0") -> 0 | E6: 11520 | F6: 11520 | G6: =E6-F6 -> 0
C7: =_xlfn.XLOOKUP(A7,[1]工作表3!$A:$A,[1]工作表3!$B:$B,"0") -> 0 | E7: 0 | F7: 0 | G7: =E7-F7 -> 0
C8: =_xlfn.XLOOKUP(A8,[1]工作表3!$A:$A,[1]工作表3!$B:$B,"0") -> 0 | E8: 25280 | F8: 25280 | G8: =E8-F8 -> 0
C9: =_xlfn.XLOOKUP(A9,[1]工作表3!$A:$A,[1]工作表3!$B:$B,"0") -> 0 | E9: 3840 | F9: 1280 | G9: =E9-F9 -> 2560
C10: =_xlfn.XLOOKUP(A10,[1]工作表3!$A:$A,[1]工作表3!$B:$B,"0") -> 0 | E10: 6400 | F10: 6400 | G10: =E10-F10 -> 0
C11: =_xlfn.XLOOKUP(A11,[1]工作表3!$A:$A,[1]工作表3!$B:$B,"0") -> 0 | E11: 1008 | F11: 1008 | G11: =E11-F11 -> 0
C12: =_xlfn.XLOOKUP(A12,[1]工作表3!$A:$A,[1]工作表3!$B:$B,"0") -> 0 | E12: 1008 | F12: 1008 | G12: =E12-F12 -> 0
C13: =_xlfn.XLOOKUP(A13,[1]工作表3!$A:$A,[1]工作表3!$B:$B,"0") -> 0 | E13: 0 | F13: 0 | G13: =E13-F13 -> 0
C14: =_xlfn.XLOOKUP(A14,[1]工作表3!$A:$A,[1]工作表3!$B:$B,"0") -> 0 | E14: 0 | F14: 0 | G14: =E14-F14 -> 0
C15: =_xlfn.XLOOKUP(A15,[1]工作表3!$A:$A,[1]工作表3!$B:$B,"0") -> 0 | E15: 1008 | F15: 1008 | G15: =E15-F15 -> 0
C16: =_xlfn.XLOOKUP(A16,[1]工作表3!$A:$A,[1]工作表3!$B:$B,"0") -> 0 | E16: 0 | F16: 0 | G16: =E16-F16 -> 0
... C97: =_xlfn.XLOOKUP(A97,[1]工作表3!$A:$A,[1]工作表3!$B:$B,"0") -> 0 | E97: 0 | F97: 0 | G97: =E97-F97 -> 0
C98: =_xlfn.XLOOKUP(A98,[1]工作表3!$A:$A,[1]工作表3!$B:$B,"0") -> 0 | E98: 0 | F98: 0 | G98: =E98-F98 -> 0
C99: =_xlfn.XLOOKUP(A99,[1]工作表3!$A:$A,[1]工作表3!$B:$B,"0") -> 0 | E99: 2880 | F99: 2880 | G99: =E99-F99 -> 0
C100: =_xlfn.XLOOKUP(A100,[1]工作表3!$A:$A,[1]工作表3!$B:$B,"0") -> 0 | E100: 5760 | F100: 5760 | G100: =E100-F100 -> 0
C101: =_xlfn.XLOOKUP(A101,[1]工作表3!$A:$A,[1]工作表3!$B:$B,"0") -> 0 | E101: 8640 | F101: 5760 | G101: =E101-F101 -> 2880
C102: =_xlfn.XLOOKUP(A102,[1]工作表3!$A:$A,[1]工作表3!$B:$B,"0") -> 0 | E102: 6720 | F102: 6720 | G102: =E102-F102 -> 0
C103: =_xlfn.XLOOKUP(A103,[1]工作表3!$A:$A,[1]工作表3!$B:$B,"0") -> 0 | E103: 2880 | F103: 2880 | G103: =E103-F103 -> 0
C104: =_xlfn.XLOOKUP(A104,[1]工作表3!$A:$A,[1]工作表3!$B:$B,"0") -> 0 | E104: 0 | F104: 0 | G104: =E104-F104 -> 0
C105: =_xlfn.XLOOKUP(A105,[1]工作表3!$A:$A,[1]工作表3!$B:$B,"0") -> 0 | E105: 4320 | F105: 4320 | G105: =E105-F105 -> 0
C106: =_xlfn.XLOOKUP(A106,[1]工作表3!$A:$A,[1]工作表3!$B:$B,"0") -> 0 | E106: 0 | F106: 0 | G106: =E106-F106 -> 0
C107: =_xlfn.XLOOKUP(A107,[1]工作表3!$A:$A,[1]工作表3!$B:$B,"0") -> 0 | E107: 0 | F107: 0 | G107: =E107-F107 -> 0
C108: =_xlfn.XLOOKUP(A108,[1]工作表3!$A:$A,[1]工作表3!$B:$B,"0") -> 0 | E108: 0 | F108: 0 | G108: =E108-F108 -> 0
C109: =_xlfn.XLOOKUP(A109,[1]工作表3!$A:$A,[1]工作表3!$B:$B,"0") -> 0 | E109: 0 | F109: 0 | G109: =E109-F109 -> 0
C110: =_xlfn.XLOOKUP(A110,[1]工作表3!$A:$A,[1]工作表3!$B:$B,"0") -> 0 | E110: 2800 | F110: 2800 | G110: =E110-F110 -> 0
... C166: =_xlfn.XLOOKUP(A166,[1]工作表3!$A:$A,[1]工作表3!$B:$B,"0") -> 0 | E166: 0 | F166: 0 | G166: =E166-F166 -> 0
C167: =_xlfn.XLOOKUP(A167,[1]工作表3!$A:$A,[1]工作表3!$B:$B,"0") -> 0 | E167: 0 | F167: 0 | G167: =E167-F167 -> 0
C168: =_xlfn.XLOOKUP(A168,[1]工作表3!$A:$A,[1]工作表3!$B:$B,"0") -> 0 | E168: 2880 | F168: 2880 | G168: =E168-F168 -> 0
C169: =_xlfn.XLOOKUP(A169,[1]工作表3!$A:$A,[1]工作表3!$B:$B,"0") -> 0 | E169: 0 | F169: 0 | G169: =E169-F169 -> 0
C170: =_xlfn.XLOOKUP(A170,[1]工作表3!$A:$A,[1]工作表3!$B:$B,"0") -> 0 | E170: 0 | F170: 0 | G170: =E170-F170 -> 0
C171: =_xlfn.XLOOKUP(A171,[1]工作表3!$A:$A,[1]工作表3!$B:$B,"0") -> 0 | E171: 0 | F171: 0 | G171: =E171-F171 -> 0
C172: =_xlfn.XLOOKUP(A172,[1]工作表3!$A:$A,[1]工作表3!$B:$B,"0") -> 0 | E172: 0 | F172: 0 | G172: =E172-F172 -> 0
C173: =_xlfn.XLOOKUP(A173,[1]工作表3!$A:$A,[1]工作表3!$B:$B,"0") -> 0 | E173: 0 | F173: 0 | G173: =E173-F173 -> 0
C174: =_xlfn.XLOOKUP(A174,[1]工作表3!$A:$A,[1]工作表3!$B:$B,"0") -> 0 | E174: 0 | F174: 0 | G174: =E174-F174 -> 0
C175: =_xlfn.XLOOKUP(A175,[1]工作表3!$A:$A,[1]工作表3!$B:$B,"0") -> 0 | E175: 0 | F175: 0 | G175: =E175-F175 -> 0
C176: =_xlfn.XLOOKUP(A176,[1]工作表3!$A:$A,[1]工作表3!$B:$B,"0") -> 0 | E176: 2880 | F176: 2880 | G176: =E176-F176 -> 0
C177: =_xlfn.XLOOKUP(A177,[1]工作表3!$A:$A,[1]工作表3!$B:$B,"0") -> 0 | E177: 1440 | F177: 1440 | G177: =E177-F177 -> 0
...

Sheet 工作表4
A3: 加總 - Aug Q'ty
A4: 3610759.1 | C4: =_xlfn.XLOOKUP(A4,[2]工作表1!$A:$A,[2]工作表1!$B:$B,"0") -> 0 | E4: 0 | F4: 0 | G4: =E4-F4 -> 0
C5: =_xlfn.XLOOKUP(A5,[2]工作表1!$A:$A,[2]工作表1!$B:$B,"0") -> 0 | E5: 0 | F5: 0 | G5: =E5-F5 -> 0
C6: =_xlfn.XLOOKUP(A6,[2]工作表1!$A:$A,[2]工作表1!$B:$B,"0") -> 0 | E6: 23040 | F6: 23040 | G6: =E6-F6 -> 0
C7: =_xlfn.XLOOKUP(A7,[2]工作表1!$A:$A,[2]工作表1!$B:$B,"0") -> 0 | E7: 3840 | F7: 3840 | G7: =E7-F7 -> 0
C8: =_xlfn.XLOOKUP(A8,[2]工作表1!$A:$A,[2]工作表1!$B:$B,"0") -> 0 | E8: 21280 | F8: 21280 | G8: =E8-F8 -> 0
C9: =_xlfn.XLOOKUP(A9,[2]工作表1!$A:$A,[2]工作表1!$B:$B,"0") -> 0 | E9: 8960 | F9: 8960 | G9: =E9-F9 -> 0
C10: =_xlfn.XLOOKUP(A10,[2]工作表1!$A:$A,[2]工作表1!$B:$B,"0") -> 0 | E10: 7680 | F10: 7680 | G10: =E10-F10 -> 0
C11: =_xlfn.XLOOKUP(A11,[2]工作表1!$A:$A,[2]工作表1!$B:$B,"0") -> 0 | E11: 0 | F11: 0 | G11: =E11-F11 -> 0
C12: =_xlfn.XLOOKUP(A12,[2]工作表1!$A:$A,[2]工作表1!$B:$B,"0") -> 0 | E12: 0 | F12: 0 | G12: =E12-F12 -> 0
C13: =_xlfn.XLOOKUP(A13,[2]工作表1!$A:$A,[2]工作表1!$B:$B,"0") -> 0 | E13: 0 | F13: 0 | G13: =E13-F13 -> 0
C14: =_xlfn.XLOOKUP(A14,[2]工作表1!$A:$A,[2]工作表1!$B:$B,"0") -> 0 | E14: 0 | F14: 0 | G14: =E14-F14 -> 0
C15: =_xlfn.XLOOKUP(A15,[2]工作表1!$A:$A,[2]工作表1!$B:$B,"0") -> 0 | E15: 0 | F15: 0 | G15: =E15-F15 -> 0
C16: =_xlfn.XLOOKUP(A16,[2]工作表1!$A:$A,[2]工作表1!$B:$B,"0") -> 0 | E16: 0 | F16: 0 | G16: =E16-F16 -> 0
... C38: =_xlfn.XLOOKUP(A38,[2]工作表1!$A:$A,[2]工作表1!$B:$B,"0") -> 0 | E38: 4800 | F38: 4800 | G38: =E38-F38 -> 0
C39: =_xlfn.XLOOKUP(A39,[2]工作表1!$A:$A,[2]工作表1!$B:$B,"0") -> 0 | E39: 0 | F39: 0 | G39: =E39-F39 -> 0
C40: =_xlfn.XLOOKUP(A40,[2]工作表1!$A:$A,[2]工作表1!$B:$B,"0") -> 0 | E40: 2600 | F40: 2600 | G40: =E40-F40 -> 0
C41: =_xlfn.XLOOKUP(A41,[2]工作表1!$A:$A,[2]工作表1!$B:$B,"0") -> 0 | E41: 10400 | F41: 0 | G41: =E41-F41 -> 10400
C42: =_xlfn.XLOOKUP(A42,[2]工作表1!$A:$A,[2]工作表1!$B:$B,"0") -> 0 | E42: 0 | F42: 0 | G42: =E42-F42 -> 0
C43: =_xlfn.XLOOKUP(A43,[2]工作表1!$A:$A,[2]工作表1!$B:$B,"0") -> 0 | E43: 5200 | F43: 5200 | G43: =E43-F43 -> 0
C44: =_xlfn.XLOOKUP(A44,[2]工作表1!$A:$A,[2]工作表1!$B:$B,"0") -> 0 | E44: 0 | F44: 0 | G44: =E44-F44 -> 0
C45: =_xlfn.XLOOKUP(A45,[2]工作表1!$A:$A,[2]工作表1!$B:$B,"0") -> 0 | E45: 2880 | F45: 2880 | G45: =E45-F45 -> 0
C46: =_xlfn.XLOOKUP(A46,[2]工作表1!$A:$A,[2]工作表1!$B:$B,"0") -> 0 | E46: 0 | F46: 0 | G46: =E46-F46 -> 0
C47: =_xlfn.XLOOKUP(A47,[2]工作表1!$A:$A,[2]工作表1!$B:$B,"0") -> 0 | E47: 0 | F47: 0 | G47: =E47-F47 -> 0
C48: =_xlfn.XLOOKUP(A48,[2]工作表1!$A:$A,[2]工作表1!$B:$B,"0") -> 0 | E48: 2880 | F48: 2880 | G48: =E48-F48 -> 0
C49: =_xlfn.XLOOKUP(A49,[2]工作表1!$A:$A,[2]工作表1!$B:$B,"0") -> 0 | E49: 0 | F49: 0 | G49: =E49-F49 -> 0
C50: =_xlfn.XLOOKUP(A50,[2]工作表1!$A:$A,[2]工作表1!$B:$B,"0") -> 0 | E50: 11520 | F50: 11520 | G50: =E50-F50 -> 0
C51: =_xlfn.XLOOKUP(A51,[2]工作表1!$A:$A,[2]工作表1!$B:$B,"0") -> 0 | E51: 0 | F51: 0 | G51: =E51-F51 -> 0
C52: =_xlfn.XLOOKUP(A52,[2]工作表1!$A:$A,[2]工作表1!$B:$B,"0") -> 0 | E52: 5760 | F52: 5760 | G52: =E52-F52 -> 0
C53: =_xlfn.XLOOKUP(A53,[2]工作表1!$A:$A,[2]工作表1!$B:$B,"0") -> 0 | E53: 0 | F53: 0 | G53: =E53-F53 -> 0
C54: =_xlfn.XLOOKUP(A54,[2]工作表1!$A:$A,[2]工作表1!$B:$B,"0") -> 0 | E54: 25920 | F54: 25920 | G54: =E54-F54 -> 0
... C58: =_xlfn.XLOOKUP(A58,[2]工作表1!$A:$A,[2]工作表1!$B:$B,"0") -> 0 | E58: 0 | F58: 0 | G58: =E58-F58 -> 0
C59: =_xlfn.XLOOKUP(A59,[2]工作表1!$A:$A,[2]工作表1!$B:$B,"0") -> 0 | E59: 1890 | F59: 0 | G59: =E59-F59 -> 1890
C60: =_xlfn.XLOOKUP(A60,[2]工作表1!$A:$A,[2]工作表1!$B:$B,"0") -> 0 | E60: 0 | F60: 0 | G60: =E60-F60 -> 0
C61: =_xlfn.XLOOKUP(A61,[2]工作表1!$A:$A,[2]工作表1!$B:$B,"0") -> 0 | E61: 5280 | F61: 0 | G61: =E61-F61 -> 5280
C62: =_xlfn.XLOOKUP(A62,[2]工作表1!$A:$A,[2]工作表1!$B:$B,"0") -> 0 | E62: 11500 | F62: 11500 | G62: =E62-F62 -> 0
C63: =_xlfn.XLOOKUP(A63,[2]工作表1!$A:$A,[2]工作表1!$B:$B,"0") -> 0 | E63: 5280 | F63: 0 | G63: =E63-F63 -> 5280
C64: =_xlfn.XLOOKUP(A64,[2]工作表1!$A:$A,[2]工作表1!$B:$B,"0") -> 0 | E64: 2640 | F64: 0 | G64: =E64-F64 -> 2640
C65: =_xlfn.XLOOKUP(A65,[2]工作表1!$A:$A,[2]工作表1!$B:$B,"0") -> 0 | E65: 5280 | F65: 0 | G65: =E65-F65 -> 5280
C66: =_xlfn.XLOOKUP(A66,[2]工作表1!$A:$A,[2]工作表1!$B:$B,"0") -> 0 | E66: 8640 | F66: 8640 | G66: =E66-F66 -> 0
...

Sheet 工作表2
A3: 列標籤 | B3: 加總 - Sep Rebate Amount
A4: Bogota | B4: 0 | C4: =_xlfn.XLOOKUP(A4,#REF!,#REF!) -> #REF!
A5: Brac | B5: 30621.6 | C5: =_xlfn.XLOOKUP(A5,#REF!,#REF!) -> #REF!
A6: Brain | B6: 70.56 | C6: =_xlfn.XLOOKUP(A6,#REF!,#REF!) -> #REF!
A7: Brazilia | B7: 0 | C7: =_xlfn.XLOOKUP(A7,#REF!,#REF!) -> #REF!
A8: Buble 2 | B8: 1296 | C8: =_xlfn.XLOOKUP(A8,#REF!,#REF!) -> #REF!
A9: Capri | B9: 0 | C9: =_xlfn.XLOOKUP(A9,#REF!,#REF!) -> #REF!
A10: Elephanta | B10: 0 | C10: =_xlfn.XLOOKUP(A10,#REF!,#REF!) -> #REF!
A11: Gadget | B11: 4335.6 | C11: =_xlfn.XLOOKUP(A11,#REF!,#REF!) -> #REF!
A12: Gadget dual | B12: 2466 | C12: =_xlfn.XLOOKUP(A12,#REF!,#REF!) -> #REF!
A13: Galapagos | B13: 0 | C13: =_xlfn.XLOOKUP(A13,#REF!,#REF!) -> #REF!
A14: Havelock | B14: 1267.2 | C14: =_xlfn.XLOOKUP(A14,#REF!,#REF!) -> #REF!
A15: Havelock KB | B15: 324 | C15: =_xlfn.XLOOKUP(A15,#REF!,#REF!) -> #REF!
... A38: 總計 | B38: 70368.16 | C38: =_xlfn.XLOOKUP(A38,#REF!,#REF!) -> #REF!

Sheet 工作表5
A1: Platforms | B1: Brac
A3: 列標籤 | B3: 加總 - Sep Rebate Amount
A4: 18H24AA#AB1 | B4: 0
A5: 18H24AA#ABA | B5: 6220.8
A6: 18H24AA#ABM | B6: 460.8
A7: 18H24AA#AC3 | B7: 8460
A8: 18H24AA#AC4 | B8: 0
A9: 18H24AA#UUF | B9: 2304
A10: 1Y4D0AA#AB1 | B10: 0
A11: 1Y4D0AA#ABA | B11: 0
A12: 1Y4D0AA#ABC | B12: 0
A13: 1Y4D0AA#ABM | B13: 0
A14: 1Y4D0AA#AC3 | B14: 0
A15: 1Y4D0AA#AC4 | B15: 0
... A25: 總計 | B25: 30621.6

Sheet 工作表7
A3: 加總 - Nov Q'ty
A4: 3033552.6

Sheet 工作表6
A3: 列標籤
A4: Bogota | C4: =_xlfn.XLOOKUP(A4,'[3]工作表1 (2)'!$A:$A,'[3]工作表1 (2)'!$B:$B) -> #N/A | D4: =B4-C4 -> #N/A
A5: Brac | C5: =_xlfn.XLOOKUP(A5,'[3]工作表1 (2)'!$A:$A,'[3]工作表1 (2)'!$B:$B) -> Flextronics CZ | D5: =B5-C5 -> #VALUE!
A6: Brain | C6: =_xlfn.XLOOKUP(A6,'[3]工作表1 (2)'!$A:$A,'[3]工作表1 (2)'!$B:$B) -> #N/A | D6: =B6-C6 -> #N/A
A7: Brazilia | C7: =_xlfn.XLOOKUP(A7,'[3]工作表1 (2)'!$A:$A,'[3]工作表1 (2)'!$B:$B) -> #N/A | D7: =B7-C7 -> #N/A
A8: Buble 2 | C8: =_xlfn.XLOOKUP(A8,'[3]工作表1 (2)'!$A:$A,'[3]工作表1 (2)'!$B:$B) -> #N/A | D8: =B8-C8 -> #N/A
A9: Capri | C9: =_xlfn.XLOOKUP(A9,'[3]工作表1 (2)'!$A:$A,'[3]工作表1 (2)'!$B:$B) -> #N/A | D9: =B9-C9 -> #N/A
A10: Elephanta | C10: =_xlfn.XLOOKUP(A10,'[3]工作表1 (2)'!$A:$A,'[3]工作表1 (2)'!$B:$B) -> #N/A | D10: =B10-C10 -> #N/A
A11: Gadget | C11: =_xlfn.XLOOKUP(A11,'[3]工作表1 (2)'!$A:$A,'[3]工作表1 (2)'!$B:$B) -> #N/A | D11: =B11-C11 -> #N/A
A12: Gadget dual | C12: =_xlfn.XLOOKUP(A12,'[3]工作表1 (2)'!$A:$A,'[3]工作表1 (2)'!$B:$B) -> #N/A | D12: =B12-C12 -> #N/A
A13: Galapagos | C13: =_xlfn.XLOOKUP(A13,'[3]工作表1 (2)'!$A:$A,'[3]工作表1 (2)'!$B:$B) -> #N/A | D13: =B13-C13 -> #N/A
A14: Havelock | C14: =_xlfn.XLOOKUP(A14,'[3]工作表1 (2)'!$A:$A,'[3]工作表1 (2)'!$B:$B) -> #N/A | D14: =B14-C14 -> #N/A
A15: Havelock KB | C15: =_xlfn.XLOOKUP(A15,'[3]工作表1 (2)'!$A:$A,'[3]工作表1 (2)'!$B:$B) -> #N/A | D15: =B15-C15 -> #N/A
... A38: 總計 | C38: =_xlfn.XLOOKUP(A38,'[3]工作表1 (2)'!$A:$A,'[3]工作表1 (2)'!$B:$B) -> 0 | D38: =B38-C38 -> 0

Sheet FY25 Summary_1
B3: Acrox | C3: 2024 11 | D3: 2024 12 | E3: 2025 01 | F3: Total Q1
B4: Rebate amount | C4: ='FY25'!AM1 -> 74615.32 | D4: ='FY25'!AO1 -> 63833.84 | E4: ='FY25'!AQ1 -> 64307.24 | F4: =SUM(C4:E4) -> 202756.4
B5: E&O reduction | F5: =SUM(C5:E5) -> 0
B6: Complexity reduction | F6: =SUM(C6:E6) -> 0 | H6: 1. 新增Summary_1, 原先的Summary重新命名為Summary_2
B7: Total amount | C7: =SUM(C4:C6) -> 74615.32 | D7: =SUM(D4:D6) -> 63833.84 | E7: =SUM(E4:E6) -> 64307.24 | F7: =SUM(F4:F6) -> 202756.4
H8: 2.黃色部位為貴司名稱, 請整份報告都跟檔名貴司名稱撰寫方式一致
B10: Acrox | C10: 2025 02 | D10: 2025 03 | E10: 2025 04 | F10: Total Q2 | H10: 3. 這些欄位一定要固定, B3-B28, C3-C28, D3-D28, E3-E28, F3-F28都有賦予定義
B11: Rebate amount | C11: ='FY25'!AS1 -> 39786 | D11: ='FY25'!AU1 -> 56274.5 | E11: ='FY25'!AW1 -> 71609.2 | F11: =SUM(C11:E11) -> 167669.7
B12: E&O reduction | F12: =SUM(C12:E12) -> 0 | H12: 4. Rebate amount 指得是summary_2的page金額 (就是我們一直以來收集的金額)
B13: Complexity reduction | F13: =SUM(C13:E13) -> 0
B14: Total amount | C14: =SUM(C11:C13) -> 39786 | D14: =SUM(D11:D13) -> 56274.5 | E14: =SUM(E11:E13) -> 71609.2 | F14: =SUM(F11:F13) -> 167669.7 | H14: 5. 新增 E&O reduction 及complexity reduction品項, 先留足空間
H15: 若目前還未有此款項存在都先填0
B17: Acrox | C17: 2025 05 | D17: 2025 06 | E17: 2025 07 | F17: Total Q3 | H17: 6. 金額都放未經調整後的真實數字, 分析才具意義
B18: Rebate amount | C18: ='FY25'!AY1 -> 37898.04 | D18: ='FY25'!BA1 -> 81459.4 | E18: ='FY25'!BC1 -> 90405.6 | F18: =SUM(C18:E18) -> 209763.04
B19: E&O reduction | F19: =SUM(C19:E19) -> 0
B20: Complexity reduction | F20: =SUM(C20:E20) -> 0
B21: Total amount | C21: =SUM(C18:C20) -> 37898.04 | D21: =SUM(D18:D20) -> 81459.4 | E21: =SUM(E18:E20) -> 90405.6 | F21: =SUM(F18:F20) -> 209763.04
B24: Acrox | C24: 2025 08 | D24: 2025 09 | E24: 2025 10 | F24: Total Q4
B25: Rebate amount | C25: ='FY25'!BE1 -> 75666.9 | D25: ='FY25'!BG1 -> 105555.92 | E25: ='FY25'!BI1 -> 60563.08 | F25: =SUM(C25:E25) -> 241785.9
B26: E&O reduction
B27: Complexity reduction
B28: Total amount | C28: =SUM(C25:C27) -> 75666.9 | D28: =SUM(D25:D27) -> 105555.92 | E28: =SUM(E25:E27) -> 60563.08 | F28: =SUM(F25:F27) -> 241785.9

Sheet FY25 Summary_2
B3: Q1 Actual by Segment
C4: Segment | D4: 45597 | E4: 45627 | F4: 45658 | G4: Total Rebate in Q1 2025 (US$)
B5: CMIT Input Devices | C5: 200 series (6U)
C6: 400 series (S)
C7: 600 series (B)
C8: 800 series (P)
C9: 1000 series (M
C10: MWS (Workstation)
C11: Soft Keyboard
C12: Chrome Book
C13: Clickpad
C14: Education
C15: Peripherals/AMO
C16: Desktop
B17: Consumer Input Devices | C17: OPP
C18: Chrome Book
C19: Pavillion
C20: Spectre
C21: Envy
C22: Stream
C23: Omen
C24: Peripherals/AMO
C25: Desktop
B28: Q1 Actual by Segment
C29: Supplier | D29: 45597 | E29: 45627 | F29: 45658 | G29: Total Rebate in Q1 2025 (US$)
B30: Input Devices | C30: Acrox | D30: ='FY25 Summary_1'!C4 -> 74615.32 | E30: ='FY25 Summary_1'!D4 -> 63833.84 | F30: ='FY25 Summary_1'!E4 -> 64307.24 | G30: =SUM(D30:F30) -> 202756.4
C31: Chicony
C32: Darfon
C33: Liteon
C34: Primax
C35: Sunrex
F36: Total Rebate Amount
B39: Q2 Actual by Segment
C40: Segment | D40: 45689 | E40: 45717 | F40: 45748 | G40: Total Rebate in Q2 2025 (US$)
B41: CMIT Input Devices | C41: 200 series (6U)
C42: 400 series (S)
C43: 600 series (B)
C44: 800 series (P)
C45: 1000 series (M
C46: MWS (Workstation)
...

Sheet FY26 Summary_1
