Workbook
Name Region: #REF!

Sheet 說明頁_更新版
A1: ID | B1: Action | C1: Remark
A2: 1 | B2: A-M欄及BM-BP欄照理來說不會更動只會新增
A3: 2 | B3: 檔名的部分請像這樣 "Rebate and Spending report Supplier’s name_2025 01"，勿加上其他說明，若有V2版本請寫 "Rebate and Spending report Supplier’s name_2025 01_V2"
A4: 3 | B4: 請全年度都放在同一個tab，Summary也是Q1-Q4都放在一起，若有更新的年度請一樣要加上對應的Summary
A5: 4 | B5: Title相關規範請看右方所示, 請按照此欄位進行填寫, 勿更改資料次序 *上面也附上Example, 參考的顏色表以及Mason的PDF instruction | C5: A欄位:打上年度，新年度記得要更新
C6: B欄位: SPM, 請填全名, ex Benson Chen, 而不是Benson，若SPM有異動也請更新
C7: C 欄位: 一律填自己公司名稱
C8: D欄位: 請照上方指示, 勿自創提詞, 須注意只有NB和DT才會有Consumer/Commercial之分, F欄位是Peripheral則D和E都是填Peripheral
C9: E欄位 : 請照上方指示, 勿自創提詞
C10: F欄位 : Peripheral只需填寫Peripheral
C11: G欄位 : 已更新到2025
C12: H欄位 : -請一定不能空白此欄位，不然後面的數字都會讀不到 -如果多個platforms共用同keyboard, 請用 '/' 去 group這些platforms，大小寫沒關係。 -請Platform name請跟LTF一模一樣，像是有些後面會加上尺寸也請加上( BAYMAX14/LUISA14/BAYMAXW14/BAYMAX13/BAYMAX13X) -請用"/"來 Grouping 不同 Platform (e.g. ANDAZ/ABU) ，勿用其他符號，錯誤範例如:ANDAZ&ABU
C13: I欄位 : 請照上方指示, 勿自創提詞
C14: J欄位 : 如果沒有Size，則填寫"NA/"，請注意不要只寫"NA"
C15: K欄 : -要注意勿將 Color grouping 在一起，像是Jet Black/Soft Grey，若有n個顏色需分成n筆資料去填 -如果沒有Color，則填寫"NA/"，請注意不要只寫"NA" -Color 需確保填寫正確，如 SEAFOAM TEAL PEARL 需完整打出來，避免填成 SEAFOAM TEAL -請確保在顏色中間加上空格，大小寫沒關係。 -關於灰色，請使用“Grey” 而非“Gray” -Color 欄位需保持正常format，像是 PERFORMANCE BLUE OPAQUE 請避免填成 PERFORMANCE BLUE OPAQUE-RGB -針對CNB Gaming，關於Numpad及RGB方面請遵照以下方式及右方的說明 : RGB Per Key W Numpad_Soft Grey RGB Per Key W/O Numpad_Soft Grey 1 Zone W Numpad_Soft Grey, 1 Zone Red W Numpad_Soft Grey 4 Zone RGB W Numpad_Soft Grey 1 Zone W/O Numpad_Soft Grey, 1 Zone Red W/O Numpad_Soft Grey 4 Zone RGB W/O Numpad_Soft Grey 1 Zone RGB W Numpad_Soft Grey 1 Zone RGB W/O Numpad_Soft Grey
C16: L欄 : 請照上方指示，勿自創提詞，注意NMC更新為Thailand/Vietnam
C17: M欄 : 請照上方指示填寫對應ODM，勿自創提詞或簡寫。若發生ODM不存在於上方的情況，請勿寫上OTHERS，需參照在contract中寫的ODM或Regional site名稱
... C22: BP欄 : 如果有HP Part#就填上，如果沒有的話就填上ODM Part# (語言別的部分可以屏蔽並用星號代替，除非有語言別會造成價格不同的情況才需列出語言別的部分)
A23: 5 | B23: 當月出貨的所有品項都必須填上, 即使rebate=0的項目, 定義為FCS之後, EOL前的platform 當月出貨都需要寫上(也就是不含service part)
A24: 6 | B24: 每個月10日固定上傳此份rebate and spending report，請注意目前的Share point已經與財務共用，因此有任何要更新的地方都請通知Jenny並且上傳V2/V3…版本，且舊檔案勿刪除
A25: 7 | B25: 在上傳此份檔案前針對數字的部分需再三確認，因為這些數字會直接當作日後開發票的金額
A26: 8 | B26: excel欄位有相乘的部分 (rebate amount), 請不要直接在公式以外做數字上的調整, 沒有邏輯性的數字, 程式會偵測異常
A27: 9 | B27: Summary_1不能有任何註記, 需要呈現最真實的數字, Summary_2貴司可有一些註記符號, 或是rebate抵扣等地紀錄是能夠被容許的

Sheet FY26 Summary_1
B3: Chicony | C3: 2025 11 | D3: 2025 12 | E3: 2026 01 | F3: Total Q1
B4: Rebate amount | C4: ='FY26'!AM1 -> 382332.68 | D4: ='FY26'!AO1 -> 353760.81 | E4: ='FY26'!AQ1 -> 247777.1 | F4: =SUM(C4:E4) -> 983870.59
B5: E&O reduction | C5: 0 | D5: 0 | E5: 0 | F5: =SUM(C5:E5) -> 0
B6: Complexity reduction | C6: 0 | D6: 0 | E6: 0 | F6: =SUM(C6:E6) -> 0 | H6: 1. 新增Summary_1, 原先的Summary重新命名為Summary_2
B7: Total amount | C7: =SUM(C4:C6) -> 382332.68 | D7: =SUM(D4:D6) -> 353760.81 | E7: =SUM(E4:E6) -> 247777.1 | F7: =SUM(F4:F6) -> 983870.59
H8: 2.黃色部位為貴司名稱, 請整份報告都跟檔名貴司名稱撰寫方式一致
B10: Chicony | C10: 2026 02 | D10: 2026 03 | E10: 2026 04 | F10: Total Q2 | H10: 3. 這些欄位一定要固定, B3-B28, C3-C28, D3-D28, E3-E28, F3-F28都有賦予定義
B11: Rebate amount | C11: ='FY26'!AS1 -> 35221.64 | D11: ='FY26'!AU1 -> 552986.01 | E11: ='FY26'!AW1 -> 354896.54 | F11: =SUM(C11:E11) -> 943104.19
B12: E&O reduction | C12: 0 | D12: 0 | E12: 0 | F12: =SUM(C12:E12) -> 0 | H12: 4. Rebate amount 指得是summary_2的page金額 (就是我們一直以來收集的金額)
B13: Complexity reduction | C13: 0 | D13: 0 | E13: 0 | F13: =SUM(C13:E13) -> 0
B14: Total amount | C14: =SUM(C11:C13) -> 35221.64 | D14: =SUM(D11:D13) -> 552986.01 | E14: =SUM(E11:E13) -> 354896.54 | F14: =SUM(F11:F13) -> 943104.19 | H14: 5. 新增 E&O reduction 及complexity reduction品項, 先留足空間
H15: 若目前還未有此款項存在都先填0
B17: Chicony | C17: 2026 05 | D17: 2026 06 | E17: 2026 07 | F17: Total Q3 | H17: 6. 金額都放未經調整後的真實數字, 分析才具意義
B18: Rebate amount | C18: ='FY26'!AY1 -> 358883.55 | D18: ='FY26'!BA1 -> 357298.55 | E18: ='FY26'!BC1 -> 312037.98 | F18: =SUM(C18:E18) -> 1028220.1
B19: E&O reduction | C19: 0 | D19: 0 | E19: 0 | F19: =SUM(C19:E19) -> 0
B20: Complexity reduction | C20: 0 | D20: 0 | E20: 0 | F20: =SUM(C20:E20) -> 0
B21: Total amount | C21: =SUM(C18:C20) -> 358883.55 | D21: =SUM(D18:D20) -> 357298.55 | E21: =SUM(E18:E20) -> 312037.98 | F21: =SUM(F18:F20) -> 1028220.1
B24: Chicony | C24: 2026 08 | D24: 2026 09 | E24: 2026 10 | F24: Total Q4
B25: Rebate amount | C25: ='FY26'!BE1 -> 324327.34 | D25: ='FY26'!BG1 -> 382597.22 | E25: ='FY26'!BI1 -> 316037.34 | F25: =SUM(C25:E25) -> 1022961.9
B26: E&O reduction | C26: 0 | D26: 0 | E26: 0 | F26: =SUM(C26:E26) -> 0
B27: Complexity reduction | C27: 0 | D27: 0 | E27: 0 | F27: =SUM(C27:E27) -> 0
B28: Total amount | C28: =SUM(C25:C27) -> 324327.34 | D28: =SUM(D25:D27) -> 382597.22 | E28: =SUM(E25:E27) -> 316037.34 | F28: =SUM(F25:F27) -> 1022961.9

Sheet FY26 Summary_2
A1: Q1 Actual by Supplier
B2: Segment | C2: 45962 | D2: 45992 | E2: 46023 | F2: Total Rebate in Q1 2026 (US$) | G2: Remark
A3: Commercial Input Devices | B3: 200 series | C3: =SUM('FY26'!AM$144:AM$215)*0.25 -> 21029.508 | D3: =SUM('FY26'!AO$144:AO$215)*0.25 -> 10280.33 | E3: =SUM('FY26'!AQ$144:AQ$215)*0.25 -> 11219.5 | F3: =SUM(C3:E3) -> 42529.338
B4: 400/600 series | C4: =SUM('FY26'!AM$3:AM$11) -> 19319.6 | D4: =SUM('FY26'!AO$3:AO$11) -> 13987.69 | E4: =SUM('FY26'!AQ$3:AQ$11) -> 11666.59 | F4: =SUM(C4:E4) -> 44973.88
B5: 800 series | C5: =SUM('FY26'!AM$12:AM$33) -> 46425.58 | D5: =SUM('FY26'!AO$12:AO$33) -> 50429.13 | E5: =SUM('FY26'!AQ$12:AQ$33) -> 22443.34 | F5: =SUM(C5:E5) -> 119298.05
B6: 1000 series | C6: =SUM('FY26'!AM$34:AM$41) -> 36870.56 | D6: =SUM('FY26'!AO$34:AO$41) -> 52270.58 | E6: =SUM('FY26'!AQ$34:AQ$41) -> 28786.78 | F6: =SUM(C6:E6) -> 117927.92
B7: Probook | C7: =SUM('FY26'!AM$42:AM$47) -> 3998.4 | D7: =SUM('FY26'!AO$42:AO$47) -> 5569.2 | E7: =SUM('FY26'!AQ$42:AQ$47) -> 3931.2 | F7: =SUM(C7:E7) -> 13498.8
B8: MWS | C8: =SUM('FY26'!AM48:AM50) -> 7003.62 | D8: =SUM('FY26'!AO48:AO50) -> 6739.05 | E8: =SUM('FY26'!AQ48:AQ50) -> 7364.88 | F8: =SUM(C8:E8) -> 21107.55
B9: Soft keyboard | C9: 0 | D9: 0 | E9: 0 | F9: =SUM(C9:E9) -> 0
B10: ChromeBook | C10: =SUM('FY26'!AM$51:AM$61)*0.7+SUM('FY26'!AM$216:AM$223)*0.7 -> 10221.911 | D10: =SUM('FY26'!AO$51:AO$61)*0.7+SUM('FY26'!AO$216:AO$223)*0.7 -> 3977.974 | E10: =SUM('FY26'!AQ$51:AQ$61)*0.7+SUM('FY26'!AQ$216:AQ$223)*0.7 -> 6407.492 | F10: =SUM(C10:E10) -> 20607.377
B11: Desktop | C11: =SUM('FY26'!AM$62:AM$143) -> 60088.16 | D11: =SUM('FY26'!AO$62:AO$143) -> 90466.94 | E11: =SUM('FY26'!AQ$62:AQ$143) -> 67378.46 | F11: =SUM(C11:E11) -> 217933.56
A12: Consumer Input Devices | B12: OPP | C12: =SUM('FY26'!AM$144:AM$215)*0.75 -> 63088.523 | D12: =SUM('FY26'!AO$144:AO$215)*0.75 -> 30840.99 | E12: =SUM('FY26'!AQ$144:AQ$215)*0.75 -> 33658.5 | F12: =SUM(C12:E12) -> 127588.01
B13: ChromeBook | C13: =SUM('FY26'!AM$51:AM$61)*0.3+SUM('FY26'!AM$216:AM$223)*0.3 -> 4380.819 | D13: =SUM('FY26'!AO$51:AO$61)*0.3+SUM('FY26'!AO$216:AO$223)*0.3 -> 1704.846 | E13: =SUM('FY26'!AQ$51:AQ$61)*0.3+SUM('FY26'!AQ$216:AQ$223)*0.3 -> 2746.068 | F13: =SUM(C13:E13) -> 8831.733
B14: Pavilion | C14: =SUM('FY26'!AM$224:AM$239) -> 61156.7 | D14: =SUM('FY26'!AO$224:AO$239) -> 46346.34 | E14: =SUM('FY26'!AQ$224:AQ$239) -> 15556.05 | F14: =SUM(C14:E14) -> 123059.09
B15: Spectre | C15: =SUM('FY26'!AM$240:AM$248) -> 10564.58 | D15: =SUM('FY26'!AO$240:AO$248) -> 14850.34 | E15: =SUM('FY26'!AQ$240:AQ$248) -> 19672.8 | F15: =SUM(C15:E15) -> 45087.72
B16: Envy | C16: =SUM('FY26'!AM$249:AM$262) -> 38184.72 | D16: =SUM('FY26'!AO$249:AO$262) -> 26297.4 | E16: =SUM('FY26'!AQ$249:AQ$262) -> 16945.44 | F16: =SUM(C16:E16) -> 81427.56
B17: Stream | C17: 0 | D17: 0 | E17: 0 | F17: =SUM(C17:E17) -> 0
B18: OMEN | C18: 0 | D18: 0 | E18: 0 | F18: =SUM(C18:E18) -> 0
B19: Desktop | C19: 0 | D19: 0 | E19: 0 | F19: =SUM(C19:E19) -> 0
A20: Peripherals | B20: Peripherals/AMO | C20: 0 | D20: 0 | E20: 0 | F20: =SUM(C20:E20) -> 0
F21: =SUM(F3:F20) -> 983870.59
A23: Q1 Actual by Supplier
B24: Segment | C24: 45962 | D24: 45992 | E24: 46023 | F24: Total Rebate in Q1 2026 (US$) | G24: Remark
A25: Input Devices | B25: Chicony | C25: =SUM(C3:C22) -> 382332.68 | D25: =SUM(D3:D22) -> 353760.81 | E25: =SUM(E3:E22) -> 247777.1 | F25: =SUM(C25:E25) -> 983870.59
B26: Darfon | F26: =SUM(C26:E26) -> 0
B27: Liteon | F27: =SUM(C27:E27) -> 0
B28: Primax | F28: =SUM(C28:E28) -> 0
B29: Sunrex | F29: =SUM(C29:E29) -> 0
E30: Total Rebate ASount | F30: =SUM(F25:F29) -> 983870.59
A32: Q2 Projection by Supplier
B33: Segment | C33: 46054 | D33: 46082 | E33: 46113 | F33: Total Rebate in Q2 2026 (US$) | G33: Remark
A34: CMIT Input Devices | B34: 200 series | C34: =SUM('FY26'!AS$144:AS$215)*0.25 -> 0 | D34: =SUM('FY26'!AU$144:AU$215)*0.25 -> 27410.57 | E34: =SUM('FY26'!AW$144:AW$215)*0.25 -> 20556.865 | F34: =SUM(C34:E34) -> 47967.435
B35: 400/600 series | C35: =SUM('FY26'!AS$3:AS$11) -> 0 | D35: =SUM('FY26'!AU$3:AU$11) -> 22975.92 | E35: =SUM('FY26'!AW$3:AW$11) -> 16431.89 | F35: =SUM(C35:E35) -> 39407.81
B36: 800 series | C36: =SUM('FY26'!AS$12:AS$33) -> 0 | D36: =SUM('FY26'!AU$12:AU$33) -> 41495.66 | E36: =SUM('FY26'!AW$12:AW$33) -> 19142.13 | F36: =SUM(C36:E36) -> 60637.79
B37: 1000 series | C37: =SUM('FY26'!AS$34:AS$41) -> 0 | D37: =SUM('FY26'!AU$34:AU$41) -> 49630.42 | E37: =SUM('FY26'!AW$34:AW$41) -> 43495.4 | F37: =SUM(C37:E37) -> 93125.82
B38: Probook | C38: =SUM('FY26'!AS$42:AS$47) -> 0 | D38: =SUM('FY26'!AU$42:AU$47) -> 16329.6 | E38: =SUM('FY26'!AW$42:AW$47) -> 7744.38 | F38: =SUM(C38:E38) -> 24073.98
B39: MWS | C39: =SUM('FY26'!AS48:AS50) -> 0 | D39: =SUM('FY26'!AU48:AU50) -> 4506.92 | E39: =SUM('FY26'!AW48:AW50) -> 1845.01 | F39: =SUM(C39:E39) -> 6351.93
B40: Soft keyboard | C40: 0 | D40: 0 | E40: 0 | F40: =SUM(C40:E40) -> 0
B41: ChromeBook | C41: =SUM('FY26'!AS$51:AS$61)*0.7+SUM('FY26'!AS$216:AS$223)*0.7 -> 0 | D41: =SUM('FY26'!AU$51:AU$61)*0.7+SUM('FY26'!AU$216:AU$223)*0.7 -> 28021.98 | E41: =SUM('FY26'!AW$51:AW$61)*0.7+SUM('FY26'!AW$216:AW$223)*0.7 -> 19642.91 | F41: =SUM(C41:E41) -> 47664.89
B42: Desktop | C42: =SUM('FY26'!AS$62:AS$143) -> 35221.64 | D42: =SUM('FY26'!AU$62:AU$143) -> 135161.32 | E42: =SUM('FY26'!AW$62:AW$143) -> 53568.32 | F42: =SUM(C42:E42) -> 223951.28
...

Sheet FY26
D1: Consumer/Commercial/ Peripheral | E1: NB/DT/Peripheral | G1: 2009/2010/….2023/2024/2025 | H1: Platform name please strictly follow the LTF | I1: NBL KB/BL KB/Mouse /Combo/Clickpad/Dongle | J1: If no Size, fill in "NA/" | K1: If no Color, fill in "NA/" | L1: E China/W China/S China/Thailand/Vietnam | M1: COMPAL/QUANTA/INVENTEC/WISTRON/FOXCONN *If the ODM is not listed above, do not write 'OTHERS'. Please refer to the ODM or Regional site name as stated in the contract. | AM1: =SUM(AM3:AM262) -> 382332.68 | AO1: =SUM(AO3:AO262) -> 353760.81 | AQ1: =SUM(AQ3:AQ262) -> 247777.1 | AS1: =SUM(AS3:AS262) -> 35221.64 | AU1: =SUM(AU3:AU262) -> 552986.01 | AW1: =SUM(AW3:AW262) -> 354896.54 | AY1: =SUM(AY3:AY262) -> 358883.55 | BA1: =SUM(BA3:BA262) -> 357298.55 | BC1: =SUM(BC3:BC262) -> 312037.98 | BE1: =SUM(BE3:BE262) -> 324327.34 | BG1: =SUM(BG3:BG262) -> 382597.22 | BI1: =SUM(BI3:BI262) -> 316037.34 | BJ1: Please fill in your supplier part# | BK1: Do not fill in ODM or Supplier part# at this column | BL1: APJ/EMEA/NA/ODM | BM1: If you don't have hp part#, pls fill in ODM part# without localization
A2: FY26 | B2: SPM (Project Owner) | C2: GTK Suppliers | D2: Category | E2: Segment | F2: Series | G2: Production Year | H2: Platforms | I2: Product | J2: Size | K2: Color | L2: Location | M2: ODM | N2: Table Price Nov | O2: Table Price Dec | P2: Table Price Jan | Q2: Table Price Feb | R2: Table Price Mar | S2: Table Price Apr | T2: Table Price May | U2: Table Price Jun | V2: Table Price Jul | W2: Table Price Aug | X2: Table Price Sep | Y2: Table Price Oct | Z2: Unit Rebate Nov | AA2: Unit Rebate Dec | AB2: Unit Rebate Jan | AC2: Unit Rebate Feb | AD2: Unit Rebate Mar | AE2: Unit Rebate Apr | AF2: Unit Rebate May | AG2: Unit Rebate Jun | AH2: Unit Rebate Jul | AI2: Unit Rebate Aug | AJ2: Unit Rebate Sep | AK2: Unit Rebate Oct | AL2: Nov Q'ty | AM2: Nov Rebate Amount | AN2: Dec Q'ty | AO2: Dec Rebate Amount | AP2: Jan Q'ty | AQ2: Jan Rebate Amount | AR2: Feb Q'ty | AS2: Feb Rebate Amount | AT2: Mar Q'ty | AU2: Mar Rebate Amount | AV2: Apr Q'ty | AW2: Apr Rebate Amount | AX2: May Q'ty | AY2: May Rebate Amount | AZ2: Jun Q'ty | BA2: Jun Rebate Amount | BB2: Jul Q'ty | BC2: Jul Rebate Amount | BD2: Aug Q'ty | BE2: Aug Rebate Amount | BF2: Sep Q'ty | BG2: Sep Rebate Amount | BH2: Oct Q'ty | BI2: Oct Rebate Amount | BJ2: Supplier Part# | BK2: Comment | BL2: Region | BM2: HP/ODM Part#
A3: FY26 | B3: Benson Chen | C3: Chicony | D3: Commercial | E3: NB | F3: 400/600 | G3: 2024 | H3: ROZ 14/REX 13/14/ OAKEN 14/OLAF 14/REDHEADTC | I3: BL KB | J3: 14 | K3: Soft Grey | L3: Thailand | M3: QUANTA_TH | N3: 7.33 | O3: 7.33 | P3: 7.33 | Q3: 7.33 | R3: 8 | S3: 8 | T3: 8 | U3: 8 | V3: 8 | W3: 8 | X3: 8 | Y3: 8 | Z3: 0.12 | AA3: 0.12 | AB3: 0.12 | AC3: 0 | AD3: 0.38 | AE3: 0.38 | AF3: 0.38 | AG3: 0.38 | AH3: 0.38 | AI3: 0.38 | AJ3: 0.38 | AK3: 0.38 | AL3: 3982 | AM3: =Z3*AL3 -> 477.84 | AN3: 7016 | AO3: =AA3*AN3 -> 841.92 | AP3: 10060 | AQ3: =AB3*AP3 -> 1207.2 | AR3: 9640 | AS3: =AC3*AR3 -> 0 | AT3: 18800 | AU3: =AD3*AT3 -> 7144 | AV3: 11833 | AW3: =AE3*AV3 -> 4496.54 | AX3: 14181 | AY3: =AF3*AX3 -> 5388.78 | AZ3: 20157 | BA3: =AG3*AZ3 -> 7659.66 | BB3: 0 | BC3: =AH3*BB3 -> 0 | BD3: 0 | BE3: =AI3*BD3 -> 0 | BF3: 0 | BG3: =AJ3*BF3 -> 0 | BH3: 0 | BI3: =AK3*BH3 -> 0 | BJ3: HPM23G3*J920*T | BL3: ODM | BM3: AEX8U**0210
A4: FY26 | B4: Benson Chen | C4: Chicony | G4: 2024 | H4: ROZ 14/REX 13/14/ OAKEN 14/OLAF 14/REDHEADTC | I4: BL KB | J4: 14 | K4: Soft Grey | L4: W China | M4: QUANTA_CQ | N4: 7.33 | O4: 7.33 | P4: 7.33 | Q4: 7.33 | R4: 8 | S4: 8 | T4: 8 | U4: 8 | V4: 8 | W4: 8 | X4: 8 | Y4: 8 | Z4: 0.12 | AA4: 0.12 | AB4: 0.12 | AC4: 0 | AD4: 0.38 | AE4: 0.38 | AF4: 0.38 | AG4: 0.38 | AH4: 0.38 | AI4: 0.38 | AJ4: 0.38 | AK4: 0.38 | AL4: 9548 | AM4: =Z4*AL4 -> 1145.76 | AN4: 11767 | AO4: =AA4*AN4 -> 1412.04 | AP4: 3400 | AQ4: =AB4*AP4 -> 408 | AR4: 5360 | AS4: =AC4*AR4 -> 0 | AT4: 3840 | AU4: =AD4*AT4 -> 1459.2 | AV4: 3370 | AW4: =AE4*AV4 -> 1280.6 | AX4: 276 | AY4: =AF4*AX4 -> 104.88 | AZ4: 118 | BA4: =AG4*AZ4 -> 44.84 | BB4: 482.53466 | BC4: =AH4*BB4 -> 183.36317 | BD4: 329.56132 | BE4: =AI4*BD4 -> 125.2333 | BF4: 267.46958 | BG4: =AJ4*BF4 -> 101.63844 | BH4: 193.79148 | BI4: =AK4*BH4 -> 73.640761 | BJ4: HPM23G3*J920 | BL4: ODM | BM4: AEX8U**0210
A5: FY26 | B5: Benson Chen | C5: Chicony | G5: 2024 | H5: ROZ 14/REX 13/14/ OAKEN 14/OLAF 14/REDHEADTC | I5: NBL KB | J5: 14 | K5: Soft Grey | L5: Thailand | M5: QUANTA_TH | N5: 3.38 | O5: 3.38 | P5: 3.38 | Q5: 3.38 | R5: 4.05 | S5: 4.05 | T5: 4.05 | U5: 4.05 | V5: 4.05 | W5: 4.05 | X5: 4.05 | Y5: 4.05 | Z5: 0.03 | AA5: 0.03 | AB5: 0.03 | AC5: 0 | AD5: 0.29 | AE5: 0.29 | AF5: 0.29 | AG5: 0.29 | AH5: 0.29 | AI5: 0.29 | AJ5: 0.29 | AK5: 0.29 | AL5: 1400 | AM5: =Z5*AL5 -> 42 | AN5: 7720 | AO5: =AA5*AN5 -> 231.6 | AP5: 1640 | AQ5: =AB5*AP5 -> 49.2 | AR5: 3880 | AS5: =AC5*AR5 -> 0 | AT5: 7040 | AU5: =AD5*AT5 -> 2041.6 | AV5: 3070 | AW5: =AE5*AV5 -> 890.3 | AX5: 3363 | AY5: =AF5*AX5 -> 975.27 | AZ5: 4280 | BA5: =AG5*AZ5 -> 1241.2 | BB5: 0 | BC5: =AH5*BB5 -> 0 | BD5: 0 | BE5: =AI5*BD5 -> 0 | BF5: 0 | BG5: =AJ5*BF5 -> 0 | BH5: 0 | BI5: =AK5*BH5 -> 0 | BJ5: HPM23G5*-920*T | BL5: ODM | BM5: AEX8U**1210
A6: FY26 | B6: Benson Chen | C6: Chicony | G6: 2024 | H6: ROZ 14/REX 13/14/ OAKEN 14/OLAF 14/REDHEADTC | I6: NBL KB | J6: 14 | K6: Soft Grey | L6: W China | M6: QUANTA_CQ | N6: 3.38 | O6: 3.38 | P6: 3.38 | Q6: 3.38 | R6: 4.05 | S6: 4.05 | T6: 4.05 | U6: 4.05 | V6: 4.05 | W6: 4.05 | X6: 4.05 | Y6: 4.05 | Z6: 0.03 | AA6: 0.03 | AB6: 0.03 | AC6: 0 | AD6: 0.29 | AE6: 0.29 | AF6: 0.29 | AG6: 0.29 | AH6: 0.29 | AI6: 0.29 | AJ6: 0.29 | AK6: 0.29 | AL6: 5389 | AM6: =Z6*AL6 -> 161.67 | AN6: 2040 | AO6: =AA6*AN6 -> 61.2 | AP6: 6200 | AQ6: =AB6*AP6 -> 186 | AR6: 1080 | AS6: =AC6*AR6 -> 0 | AT6: 4590 | AU6: =AD6*AT6 -> 1331.1 | AV6: 1089 | AW6: =AE6*AV6 -> 315.81 | AX6: 107 | AY6: =AF6*AX6 -> 31.03 | AZ6: 27 | BA6: =AG6*AZ6 -> 7.83 | BB6: 197.36998 | BC6: =AH6*BB6 -> 57.237295 | BD6: 155.08332 | BE6: =AI6*BD6 -> 44.974163 | BF6: 118.11099 | BG6: =AJ6*BF6 -> 34.252186 | BH6: 80.112078 | BI6: =AK6*BH6 -> 23.232503 | BJ6: HPM23G5*-920 | BL6: ODM | BM6: AEX8U**1210
A7: FY26 | B7: Benson Chen | C7: Chicony | G7: 2025 | H7: WAFER13/WAFER14/WAFFLE14/WAFFLE14N/PUDDING14/RAINBOWCAKE14/RUMCAKE14/WAFER14R/DALGONA/DIVINITY | I7: BL KB | J7: 14 | K7: Soft Grey | L7: W China | M7: QUANTA_CQ | N7: 7.24 | O7: 7.24 | P7: 7.12 | Q7: 7.12 | R7: 7.8 | S7: 7.8 | T7: 7.8 | U7: 7.8 | V7: 7.8 | W7: 7.8 | X7: 7.8 | Y7: 7.8 | Z7: 0.16 | AA7: 0.16 | AB7: 0.11 | AC7: 0 | AD7: 0.38 | AE7: 0.38 | AF7: 0.38 | AG7: 0.38 | AH7: 0.38 | AI7: 0.38 | AJ7: 0.38 | AK7: 0.38 | AL7: 725 | AM7: =Z7*AL7 -> 116 | AN7: 1912 | AO7: =AA7*AN7 -> 305.92 | AP7: 200 | AQ7: =AB7*AP7 -> 22 | AR7: 80 | AS7: =AC7*AR7 -> 0 | AT7: 0 | AU7: =AD7*AT7 -> 0 | AV7: 396 | AW7: =AE7*AV7 -> 150.48 | AX7: 388 | AY7: =AF7*AX7 -> 147.44 | AZ7: 434 | BA7: =AG7*AZ7 -> 164.92 | BB7: 463.70958 | BC7: =AH7*BB7 -> 176.20964 | BD7: 344.01743 | BE7: =AI7*BD7 -> 130.72662 | BF7: 167.2862 | BG7: =AJ7*BF7 -> 63.568756 | BH7: 25.552068 | BI7: =AK7*BH7 -> 9.7097859 | BJ7: HPM23G3*J9205* | BL7: ODM | BM7: AEX8U**5210
A8: FY26 | B8: Benson Chen | C8: Chicony | G8: 2025 | H8: WAFER13/WAFER14/WAFFLE14/WAFFLE14N/PUDDING14/RAINBOWCAKE14/RUMCAKE14/WAFER14R/DALGONA/DIVINITY | I8: BL KB | J8: 14 | K8: Soft Grey | L8: W China | M8: QUANTA_CQ | N8: 7.24 | O8: 7.24 | P8: 7.12 | Q8: 7.12 | R8: 7.8 | S8: 7.8 | T8: 7.8 | U8: 7.8 | V8: 7.8 | W8: 7.8 | X8: 7.8 | Y8: 7.8 | Z8: 0.16 | AA8: 0.16 | AB8: 0.11 | AC8: 0 | AD8: 0.38 | AE8: 0.38 | AF8: 0.38 | AG8: 0.38 | AH8: 0.38 | AI8: 0.38 | AJ8: 0.38 | AK8: 0.38 | AL8: 27280 | AM8: =Z8*AL8 -> 4364.8 | AN8: 16442 | AO8: =AA8*AN8 -> 2630.72 | AP8: 18473 | AQ8: =AB8*AP8 -> 2032.03 | AR8: 7855 | AS8: =AC8*AR8 -> 0 | AT8: 14769 | AU8: =AD8*AT8 -> 5612.22 | AV8: 16438 | AW8: =AE8*AV8 -> 6246.44 | AX8: 17399 | AY8: =AF8*AX8 -> 6611.62 | AZ8: 20861 | BA8: =AG8*AZ8 -> 7927.18 | BB8: 18562.201 | BC8: =AH8*BB8 -> 7053.6362 | BD8: 12907.126 | BE8: =AI8*BD8 -> 4904.7078 | BF8: 7062.585 | BG8: =AJ8*BF8 -> 2683.7823 | BH8: 1176.3378 | BI8: =AK8*BH8 -> 447.00837 | BJ8: HPM23G3*J9204* | BL8: ODM | BM8: AEX8U**3210
A9: FY26 | B9: Benson Chen | C9: Chicony | G9: 2025 | H9: WAFER13/WAFER14/WAFFLE14/WAFFLE14N/PUDDING14/RAINBOWCAKE14/RUMCAKE14/WAFER14R/DALGONA/DIVINITY | I9: NBL KB | J9: 14 | K9: Soft Grey | L9: W China | M9: QUANTA_CQ | N9: 3.3 | O9: 3.3 | P9: 3.26 | Q9: 3.26 | R9: 3.95 | S9: 3.95 | T9: 3.95 | U9: 3.95 | V9: 3.95 | W9: 3.95 | X9: 3.95 | Y9: 3.95 | Z9: 0.07 | AA9: 0.07 | AB9: 0.03 | AC9: 0 | AD9: 0.31 | AE9: 0.31 | AF9: 0.31 | AG9: 0.31 | AH9: 0.31 | AI9: 0.31 | AJ9: 0.31 | AK9: 0.31 | AL9: 11411 | AM9: =Z9*AL9 -> 798.77 | AN9: 13915 | AO9: =AA9*AN9 -> 974.05 | AP9: 15924 | AQ9: =AB9*AP9 -> 477.72 | AR9: 15279 | AS9: =AC9*AR9 -> 0 | AT9: 17380 | AU9: =AD9*AT9 -> 5387.8 | AV9: 6040 | AW9: =AE9*AV9 -> 1872.4 | AX9: 5177 | AY9: =AF9*AX9 -> 1604.87 | AZ9: 5691 | BA9: =AG9*AZ9 -> 1764.21 | BB9: 0 | BC9: =AH9*BB9 -> 0 | BD9: 0 | BE9: =AI9*BD9 -> 0 | BF9: 0 | BG9: =AJ9*BF9 -> 0 | BH9: 0 | BI9: =AK9*BH9 -> 0 | BJ9: HPM23G5*-9202* | BL9: ODM | BM9: AEX8U**4210
A10: FY26 | B10: Benson Chen | C10: Chicony | G10: 2021 | H10: RABON/IONIAN14/DIANSHAN14/PETROF/DONGQIAN14/PRIMA14/DARKSTAR/THANOS14/THUNDRA14/RONIN14/DOOP14/REDSTART/TURACO/KNUCKER14/PAN14/KRAKEN14/ROC14 | I10: NBL KB | J10: 14 | K10: Flint Opaque | L10: W China | M10: QUANTA_CQ | N10: 4.07 | O10: 4.07 | P10: 4.07 | Q10: 4.07 | R10: 4.07 | S10: 4.07 | T10: 4.07 | U10: 4.07 | V10: 4.07 | W10: 4.07 | X10: 4.07 | Y10: 4.07 | Z10: 0.87 | AA10: 0.87 | AB10: 0.87 | AC10: 0 | AD10: 0.87 | AE10: 0.87 | AF10: 0.87 | AG10: 0.87 | AH10: 0.87 | AI10: 0.87 | AJ10: 0.87 | AK10: 0.87 | AL10: 360 | AM10: =Z10*AL10 -> 313.2 | AN10: 0 | AO10: =AA10*AN10 -> 0 | AP10: 680 | AQ10: =AB10*AP10 -> 591.6 | AR10: 0 | AS10: =AC10*AR10 -> 0 | AT10: 0 | AU10: =AD10*AT10 -> 0 | AV10: 220 | AW10: =AE10*AV10 -> 191.4 | AX10: 231 | AY10: =AF10*AX10 -> 200.97 | AZ10: 465 | BA10: =AG10*AZ10 -> 404.55 | BB10: 0 | BC10: =AH10*BB10 -> 0 | BD10: 0 | BE10: =AI10*BD10 -> 0 | BF10: 0 | BG10: =AJ10*BF10 -> 0 | BH10: 0 | BI10: =AK10*BH10 -> 0 | BJ10: HPM20A3*-920* | BL10: ODM | BM10: AEX8Q**1010
A11: FY26 | B11: Benson Chen | C11: Chicony | G11: 2021 | H11: RABON/IONIAN14/DIANSHAN14/PETROF/DONGQIAN14/PRIMA14/DARKSTAR/THANOS14/THUNDRA14/RONIN14/DOOP14/REDSTART/TURACO/KNUCKER14/PAN14/KRAKEN14/ROC14 | I11: BL KB | J11: 14 | K11: Flint Opaque | L11: W China | M11: QUANTA_CQ | N11: 9.12 | O11: 9.12 | P11: 9.12 | Q11: 9.12 | R11: 9.12 | S11: 9.12 | T11: 9.12 | U11: 9.12 | V11: 9.12 | W11: 9.12 | X11: 9.12 | Y11: 9.12 | Z11: 2.12 | AA11: 2.12 | AB11: 2.12 | AC11: 0 | AD11: 2.12 | AE11: 2.12 | AF11: 2.12 | AG11: 2.12 | AH11: 2.12 | AI11: 2.12 | AJ11: 2.12 | AK11: 2.12 | AL11: 5613 | AM11: =Z11*AL11 -> 11899.56 | AN11: 3552 | AO11: =AA11*AN11 -> 7530.24 | AP11: 3157 | AQ11: =AB11*AP11 -> 6692.84 | AR11: 0 | AS11: =AC11*AR11 -> 0 | AT11: 0 | AU11: =AD11*AT11 -> 0 | AV11: 466 | AW11: =AE11*AV11 -> 987.92 | AX11: 795 | AY11: =AF11*AX11 -> 1685.4 | AZ11: 72 | BA11: =AG11*AZ11 -> 152.64 | BB11: 0 | BC11: =AH11*BB11 -> 0 | BD11: 0 | BE11: =AI11*BD11 -> 0 | BF11: 0 | BG11: =AJ11*BF11 -> 0 | BH11: 0 | BI11: =AK11*BH11 -> 0 | BJ11: HPM20A2*J920* | BL11: ODM | BM11: AEX8Q**0010
A12: FY26 | B12: Benson Chen | C12: Chicony | D12: Commercial | E12: NB | F12: 800 | G12: 2023 | H12: BAYMAX 14/LUISA 14/BAYMAXW14/BAYMAX13/BAYMAX13X | I12: BL KB | J12: 14 | K12: Flint Opaque | L12: W China | M12: INVENTEC_CQ | N12: 9.75 | O12: 9.75 | P12: 9.75 | Q12: 9.75 | R12: 9.75 | S12: 9.75 | T12: 9.75 | U12: 9.75 | V12: 9.75 | W12: 9.75 | X12: 9.75 | Y12: 9.75 | Z12: 2.25 | AA12: 2.25 | AB12: 2.25 | AC12: 0 | AD12: 2.25 | AE12: 2.25 | AF12: 2.25 | AG12: 2.25 | AH12: 2.25 | AI12: 2.25 | AJ12: 2.25 | AK12: 2.25 | AL12: 2529 | AM12: =Z12*AL12 -> 5690.25 | AN12: 3000 | AO12: =AA12*AN12 -> 6750 | AP12: 2016 | AQ12: =AB12*AP12 -> 4536 | AR12: 261 | AS12: =AC12*AR12 -> 0 | AT12: 0 | AU12: =AD12*AT12 -> 0 | AV12: 2331 | AW12: =AE12*AV12 -> 5244.75 | AX12: 0 | AY12: =AF12*AX12 -> 0 | AZ12: 0 | BA12: =AG12*AZ12 -> 0 | BB12: 0 | BC12: =AH12*BB12 -> 0 | BD12: 0 | BE12: =AI12*BD12 -> 0 | BF12: 0 | BG12: =AJ12*BF12 -> 0 | BH12: 0 | BI12: =AK12*BH12 -> 0 | BJ12: HPM21B6*J930D/E | BK12: G11 | BL12: ODM | BM12: 6037B02786**
A13: FY26 | B13: Benson Chen | C13: Chicony | G13: 2024 | H13: BAYMAX 14/LUISA 14/BAYMAXW14/BAYMAX13/BAYMAX13X | I13: BL KB | J13: 14 | K13: Flint Opaque | L13: W China | M13: INVENTEC_MX | N13: 9.77 | O13: 9.77 | P13: 9.77 | Q13: 9.77 | R13: 9.77 | S13: 9.77 | T13: 9.77 | U13: 9.77 | V13: 9.77 | W13: 9.77 | X13: 9.77 | Y13: 9.77 | Z13: 2.25 | AA13: 2.25 | AB13: 2.25 | AC13: 0 | AD13: 2.25 | AE13: 2.25 | AF13: 2.25 | AG13: 2.25 | AH13: 2.25 | AI13: 2.25 | AJ13: 2.25 | AK13: 2.25 | AL13: 480 | AM13: =Z13*AL13 -> 1080 | AN13: 200 | AO13: =AA13*AN13 -> 450 | AP13: 160 | AQ13: =AB13*AP13 -> 360 | AR13: 0 | AS13: =AC13*AR13 -> 0 | AT13: 0 | AU13: =AD13*AT13 -> 0 | AV13: 0 | AW13: =AE13*AV13 -> 0 | AX13: 0 | AY13: =AF13*AX13 -> 0 | AZ13: 0 | BA13: =AG13*AZ13 -> 0 | BB13: 0 | BC13: =AH13*BB13 -> 0 | BD13: 0 | BE13: =AI13*BD13 -> 0 | BF13: 0 | BG13: =AJ13*BF13 -> 0 | BH13: 0 | BI13: =AK13*BH13 -> 0 | BJ13: HPM21B6*J930F/G | BK13: G11, Mexico | BL13: ODM | BM13: 6037B02786**
A14: FY26 | B14: Benson Chen | C14: Chicony | G14: 2023 | H14: BAYMAX 14/LUISA 14/BAYMAXW14/BAYMAX13/BAYMAX13X | I14: NBL KB | J14: 14 | K14: Flint Opaque | L14: W China | M14: INVENTEC_CQ | N14: 5.97 | O14: 5.97 | P14: 5.97 | Q14: 5.97 | R14: 5.97 | S14: 5.97 | T14: 5.97 | U14: 5.97 | V14: 5.97 | W14: 5.97 | X14: 5.97 | Y14: 5.97 | Z14: 1.17 | AA14: 1.17 | AB14: 1.17 | AC14: 0 | AD14: 1.17 | AE14: 1.17 | AF14: 1.17 | AG14: 1.17 | AH14: 1.17 | AI14: 1.17 | AJ14: 1.17 | AK14: 1.17 | AL14: 1208 | AM14: =Z14*AL14 -> 1413.36 | AN14: 80 | AO14: =AA14*AN14 -> 93.6 | AP14: 2276 | AQ14: =AB14*AP14 -> 2662.92 | AR14: 0 | AS14: =AC14*AR14 -> 0 | AT14: 0 | AU14: =AD14*AT14 -> 0 | AV14: 90 | AW14: =AE14*AV14 -> 105.3 | AX14: 0 | AY14: =AF14*AX14 -> 0 | AZ14: 0 | BA14: =AG14*AZ14 -> 0 | BB14: 0 | BC14: =AH14*BB14 -> 0 | BD14: 0 | BE14: =AI14*BD14 -> 0 | BF14: 0 | BG14: =AJ14*BF14 -> 0 | BH14: 0 | BI14: =AK14*BH14 -> 0 | BJ14: HPM21B7*6930B | BK14: G11 | BL14: ODM | BM14: 6037B02785**
A15: FY26 | B15: Benson Chen | C15: Chicony | G15: 2024 | H15: BAYMAX 14/LUISA 14/BAYMAXW14/BAYMAX13/BAYMAX13X | I15: NBL KB | J15: 14 | K15: Flint Opaque | L15: W China | M15: INVENTEC_MX | N15: 5.99 | O15: 5.99 | P15: 5.99 | Q15: 5.99 | R15: 5.99 | S15: 5.99 | T15: 5.99 | U15: 5.99 | V15: 5.99 | W15: 5.99 | X15: 5.99 | Y15: 5.99 | Z15: 1.17 | AA15: 1.17 | AB15: 1.17 | AC15: 0 | AD15: 1.17 | AE15: 1.17 | AF15: 1.17 | AG15: 1.17 | AH15: 1.17 | AI15: 1.17 | AJ15: 1.17 | AK15: 1.17 | AL15: 320 | AM15: =Z15*AL15 -> 374.4 | AN15: 0 | AO15: =AA15*AN15 -> 0 | AP15: 0 | AQ15: =AB15*AP15 -> 0 | AR15: 0 | AS15: =AC15*AR15 -> 0 | AT15: 0 | AU15: =AD15*AT15 -> 0 | AV15: 0 | AW15: =AE15*AV15 -> 0 | AX15: 0 | AY15: =AF15*AX15 -> 0 | AZ15: 0 | BA15: =AG15*AZ15 -> 0 | BB15: 0 | BC15: =AH15*BB15 -> 0 | BD15: 0 | BE15: =AI15*BD15 -> 0 | BF15: 0 | BG15: =AJ15*BF15 -> 0 | BH15: 0 | BI15: =AK15*BH15 -> 0 | BJ15: HPM21B7*6930C | BK15: G11, Mexico | BL15: ODM | BM15: 6037B02785**
A16: FY26 | B16: Benson Chen | C16: Chicony | G16: 2024 | H16: LOX16/BAYMAX 16/LUISA 16 | I16: BL KB | J16: 16 | K16: Flint Opaque | L16: W China | M16: INVENTEC_MX | N16: 10.23 | O16: 10.23 | P16: 10.23 | Q16: 10.23 | R16: 10.23 | S16: 10.23 | T16: 10.23 | U16: 10.23 | V16: 10.23 | W16: 10.23 | X16: 10.23 | Y16: 10.23 | Z16: 2.33 | AA16: 2.33 | AB16: 2.33 | AC16: 0 | AD16: 2.33 | AE16: 2.33 | AF16: 2.33 | AG16: 2.33 | AH16: 2.33 | AI16: 2.33 | AJ16: 2.33 | AK16: 2.33 | AL16: 40 | AM16: =Z16*AL16 -> 93.2 | AN16: 0 | AO16: =AA16*AN16 -> 0 | AP16: 0 | AQ16: =AB16*AP16 -> 0 | AR16: 0 | AS16: =AC16*AR16 -> 0 | AT16: 0 | AU16: =AD16*AT16 -> 0 | AV16: 0 | AW16: =AE16*AV16 -> 0 | AX16: 0 | AY16: =AF16*AX16 -> 0 | AZ16: 0 | BA16: =AG16*AZ16 -> 0 | BB16: 0 | BC16: =AH16*BB16 -> 0 | BD16: 0 | BE16: =AI16*BD16 -> 0 | BF16: 0 | BG16: =AJ16*BF16 -> 0 | BH16: 0 | BI16: =AK16*BH16 -> 0 | BJ16: HPM21B8*J930C/D | BK16: G11, Mexico | BL16: ODM | BM16: 6037B02788**
A17: FY26 | B17: Benson Chen | C17: Chicony | G17: 2023 | H17: LOX16/BAYMAX 16/LUISA 16 | I17: BL KB | J17: 16 | K17: Flint Opaque | L17: W China | M17: INVENTEC_CQ | N17: 10.23 | O17: 10.23 | P17: 10.23 | Q17: 10.23 | R17: 10.23 | S17: 10.23 | T17: 10.23 | U17: 10.23 | V17: 10.23 | W17: 10.23 | X17: 10.23 | Y17: 10.23 | Z17: 2.33 | AA17: 2.33 | AB17: 2.33 | AC17: 0 | AD17: 2.33 | AE17: 2.33 | AF17: 2.33 | AG17: 2.33 | AH17: 2.33 | AI17: 2.33 | AJ17: 2.33 | AK17: 2.33 | AL17: 980 | AM17: =Z17*AL17 -> 2283.4 | AN17: 0 | AO17: =AA17*AN17 -> 0 | AP17: 0 | AQ17: =AB17*AP17 -> 0 | AR17: 230 | AS17: =AC17*AR17 -> 0 | AT17: 0 | AU17: =AD17*AT17 -> 0 | AV17: 0 | AW17: =AE17*AV17 -> 0 | AX17: 0 | AY17: =AF17*AX17 -> 0 | AZ17: 0 | BA17: =AG17*AZ17 -> 0 | BB17: 0 | BC17: =AH17*BB17 -> 0 | BD17: 0 | BE17: =AI17*BD17 -> 0 | BF17: 0 | BG17: =AJ17*BF17 -> 0 | BH17: 0 | BI17: =AK17*BH17 -> 0 | BJ17: HPM21B8*J930A/B | BK17: G11 | BL17: ODM | BM17: 6037B02788**
A18: FY26 | B18: Benson Chen | C18: Chicony | G18: 2023 | H18: LOX16/BAYMAX 16/LUISA 16 | I18: NBL KB | J18: 16 | K18: Flint Opaque | L18: W China | M18: INVENTEC_CQ | N18: 6.06 | O18: 6.06 | P18: 6.06 | Q18: 6.06 | R18: 6.06 | S18: 6.06 | T18: 6.06 | U18: 6.06 | V18: 6.06 | W18: 6.06 | X18: 6.06 | Y18: 6.06 | Z18: 1.06 | AA18: 1.06 | AB18: 1.06 | AC18: 0 | AD18: 1.06 | AE18: 1.06 | AF18: 1.06 | AG18: 1.06 | AH18: 1.06 | AI18: 1.06 | AJ18: 1.06 | AK18: 1.06 | AL18: 0 | AM18: =Z18*AL18 -> 0 | AN18: 0 | AO18: =AA18*AN18 -> 0 | AP18: 0 | AQ18: =AB18*AP18 -> 0 | AR18: 0 | AS18: =AC18*AR18 -> 0 | AT18: 0 | AU18: =AD18*AT18 -> 0 | AV18: 0 | AW18: =AE18*AV18 -> 0 | AX18: 0 | AY18: =AF18*AX18 -> 0 | AZ18: 0 | BA18: =AG18*AZ18 -> 0 | BB18: 0 | BC18: =AH18*BB18 -> 0 | BD18: 0 | BE18: =AI18*BD18 -> 0 | BF18: 0 | BG18: =AJ18*BF18 -> 0 | BH18: 0 | BI18: =AK18*BH18 -> 0 | BJ18: HPM21B9*6930A | BK18: G11 | BL18: ODM | BM18: 6037B02789**
A19: FY26 | B19: Benson Chen | C19: Chicony | G19: 2024 | H19: LOX16/BAYMAX 16/LUISA 16 | I19: NBL KB | J19: 16 | K19: Flint Opaque | L19: W China | M19: INVENTEC_MX | N19: 6.06 | O19: 6.06 | P19: 6.06 | Q19: 6.06 | R19: 6.06 | S19: 6.06 | T19: 6.06 | U19: 6.06 | V19: 6.06 | W19: 6.06 | X19: 6.06 | Y19: 6.06 | Z19: 1.06 | AA19: 1.06 | AB19: 1.06 | AC19: 0 | AD19: 1.06 | AE19: 1.06 | AF19: 1.06 | AG19: 1.06 | AH19: 1.06 | AI19: 1.06 | AJ19: 1.06 | AK19: 1.06 | AL19: 40 | AM19: =Z19*AL19 -> 42.4 | AN19: 0 | AO19: =AA19*AN19 -> 0 | AP19: 0 | AQ19: =AB19*AP19 -> 0 | AR19: 0 | AS19: =AC19*AR19 -> 0 | AT19: 0 | AU19: =AD19*AT19 -> 0 | AV19: 0 | AW19: =AE19*AV19 -> 0 | AX19: 0 | AY19: =AF19*AX19 -> 0 | AZ19: 0 | BA19: =AG19*AZ19 -> 0 | BB19: 0 | BC19: =AH19*BB19 -> 0 | BD19: 0 | BE19: =AI19*BD19 -> 0 | BF19: 0 | BG19: =AJ19*BF19 -> 0 | BH19: 0 | BI19: =AK19*BH19 -> 0 | BJ19: HPM21B9*6930B | BK19: G11, Mexico | BL19: ODM | BM19: 6037B02789**
A20: FY26 | B20: Benson Chen | C20: Chicony | G20: 2025 | H20: MACHU14/MACHU14N/MACHUW14/MACHU13/MACHU13X/LAPAZW14/LAPAZW14N/COLOSSEUMW14N/LAPAZ13N/LAPAZ14/LAPAZ14N/LAPAZ13 | I20: BL KB | J20: 14 | K20: Soft Grey | L20: W China | M20: INVENTEC_CQ | N20: 7.9 | O20: 7.9 | P20: 7.74 | Q20: 7.74 | R20: 8.25 | S20: 8.25 | T20: 8.25 | U20: 8.25 | V20: 8.25 | W20: 8.25 | X20: 8.25 | Y20: 8.25 | Z20: 0.39 | AA20: 0.39 | AB20: 0.31 | AC20: 0 | AD20: 0.41 | AE20: 0.41 | AF20: 0.41 | AG20: 0.41 | AH20: 0.41 | AI20: 0.41 | AJ20: 0.41 | AK20: 0.41 | AL20: 54001 | AM20: =Z20*AL20 -> 21060.39 | AN20: 78182 | AO20: =AA20*AN20 -> 30490.98 | AP20: 23938 | AQ20: =AB20*AP20 -> 7420.78 | AR20: 41402 | AS20: =AC20*AR20 -> 0 | AT20: 57050 | AU20: =AD20*AT20 -> 23390.5 | AV20: 19671 | AW20: =AE20*AV20 -> 8065.11 | AX20: 15210 | AY20: =AF20*AX20 -> 6236.1 | AZ20: 19253 | BA20: =AG20*AZ20 -> 7893.73 | BB20: 31899.858 | BC20: =AH20*BB20 -> 13078.942 | BD20: 24562.127 | BE20: =AI20*BD20 -> 10070.472 | BF20: 21312.544 | BG20: =AJ20*BF20 -> 8738.1432 | BH20: 7780.1798 | BI20: =AK20*BH20 -> 3189.8737 | BJ20: HPM24F5*J930/1 | BL20: ODM | BM20: 6037B02853**
A21: FY26 | B21: Benson Chen | C21: Chicony | G21: 2025 | H21: MACHU14/MACHU14N/MACHUW14/MACHU13/MACHU13X/LAPAZW14/LAPAZW14N/COLOSSEUMW14N/LAPAZ13N/LAPAZ14/LAPAZ14N/LAPAZ13 | I21: NBL KB | J21: 14 | K21: Soft Grey | L21: W China | M21: INVENTEC_CQ | N21: 4.82 | O21: 4.82 | P21: 4.75 | Q21: 4.75 | R21: 5.25 | S21: 5.25 | T21: 5.25 | U21: 5.25 | V21: 5.25 | W21: 5.25 | X21: 5.25 | Y21: 5.25 | Z21: 0.39 | AA21: 0.39 | AB21: 0.32 | AC21: 0 | AD21: 0.41 | AE21: 0.41 | AF21: 0.41 | AG21: 0.41 | AH21: 0.41 | AI21: 0.41 | AJ21: 0.41 | AK21: 0.41 | AL21: 4648 | AM21: =Z21*AL21 -> 1812.72 | AN21: 2783 | AO21: =AA21*AN21 -> 1085.37 | AP21: 3440 | AQ21: =AB21*AP21 -> 1100.8 | AR21: 1176 | AS21: =AC21*AR21 -> 0 | AT21: 3894 | AU21: =AD21*AT21 -> 1596.54 | AV21: 1506 | AW21: =AE21*AV21 -> 617.46 | AX21: 1938 | AY21: =AF21*AX21 -> 794.58 | AZ21: 1974 | BA21: =AG21*AZ21 -> 809.34 | BB21: 2782.2676 | BC21: =AH21*BB21 -> 1140.7297 | BD21: 2172.6403 | BE21: =AI21*BD21 -> 890.78251 | BF21: 1508.8436 | BG21: =AJ21*BF21 -> 618.62589 | BH21: 996.48975 | BI21: =AK21*BH21 -> 408.5608 | BJ21: HPM24F6*6930* | BL21: ODM | BM21: 6037B02852**
A22: FY26 | B22: Benson Chen | C22: Chicony | G22: 2025 | H22: MACHU16/MACHUW16/MACHU16N/LAPAZ16/LAPAZ16N/GEMTREE16/GEMTREE18 | I22: BL KB | J22: 16 | K22: Soft Grey | L22: W China | M22: INVENTEC_CQ | N22: 8.23 | O22: 8.23 | P22: 8.14 | Q22: 8.14 | R22: 8.89 | S22: 8.89 | T22: 8.89 | U22: 8.89 | V22: 8.89 | W22: 8.89 | X22: 8.89 | Y22: 8.89 | Z22: 0.3 | AA22: 0.3 | AB22: 0.29 | AC22: 0 | AD22: 0.54 | AE22: 0.54 | AF22: 0.54 | AG22: 0.54 | AH22: 0.54 | AI22: 0.54 | AJ22: 0.54 | AK22: 0.54 | AL22: 23152 | AM22: =Z22*AL22 -> 6945.6 | AN22: 27167 | AO22: =AA22*AN22 -> 8150.1 | AP22: 6233 | AQ22: =AB22*AP22 -> 1807.57 | AR22: 13068 | AS22: =AC22*AR22 -> 0 | AT22: 20878 | AU22: =AD22*AT22 -> 11274.12 | AV22: 0 | AW22: =AE22*AV22 -> 0 | AX22: 0 | AY22: =AF22*AX22 -> 0 | AZ22: 0 | BA22: =AG22*AZ22 -> 0 | BB22: 10521.521 | BC22: =AH22*BB22 -> 5681.6213 | BD22: 8343.4864 | BE22: =AI22*BD22 -> 4505.4827 | BF22: 8842.7864 | BG22: =AJ22*BF22 -> 4775.1047 | BH22: 6187.8827 | BI22: =AK22*BH22 -> 3341.4567 | BJ22: HPM24F7*J930/1 | BL22: ODM | BM22: 6037B02851**
A23: FY26 | B23: Benson Chen | C23: Chicony | G23: 2025 | H23: MACHU16/MACHUW16/MACHU16N/LAPAZ16/LAPAZ16N/GEMTREE16/GEMTREE18 | I23: BL KB | J23: 16 | K23: Soft Grey | L23: W China | M23: INVENTEC_MX | N23: 8.25 | O23: 8.25 | P23: 8.16 | Q23: 8.16 | R23: 8.95 | S23: 8.95 | T23: 8.95 | U23: 8.95 | V23: 8.95 | W23: 8.95 | X23: 8.95 | Y23: 8.95 | Z23: 0.3 | AA23: 0.3 | AB23: 0.29 | AC23: 0 | AD23: 0.58 | AE23: 0.58 | AF23: 0.58 | AG23: 0.58 | AH23: 0.58 | AI23: 0.58 | AJ23: 0.58 | AK23: 0.58 | AL23: 2840 | AM23: =Z23*AL23 -> 852 | AN23: 1040 | AO23: =AA23*AN23 -> 312 | AP23: 3323 | AQ23: =AB23*AP23 -> 963.67 | AR23: 2920 | AS23: =AC23*AR23 -> 0 | AT23: 3038 | AU23: =AD23*AT23 -> 1762.04 | AV23: 0 | AW23: =AE23*AV23 -> 0 | AX23: 0 | AY23: =AF23*AX23 -> 0 | AZ23: 0 | BA23: =AG23*AZ23 -> 0 | BB23: 0 | BC23: =AH23*BB23 -> 0 | BD23: 0 | BE23: =AI23*BD23 -> 0 | BF23: 0 | BG23: =AJ23*BF23 -> 0 | BH23: 0 | BI23: =AK23*BH23 -> 0 | BJ23: HPM24F7*J9302/3 | BK23: Mexico | BL23: ODM | BM23: 6037B02851**
A24: FY26 | B24: Benson Chen | C24: Chicony | G24: 2025 | H24: MACHU16/MACHUW16/MACHU16N/LAPAZ16/LAPAZ16N/GEMTREE16/GEMTREE18 | I24: NBL KB | J24: 16 | K24: Soft Grey | L24: W China | M24: INVENTEC_CQ | N24: 5.2 | O24: 5.2 | P24: 5.08 | Q24: 5.08 | R24: 5.83 | S24: 5.83 | T24: 5.83 | U24: 5.83 | V24: 5.83 | W24: 5.83 | X24: 5.83 | Y24: 5.83 | Z24: 0.42 | AA24: 0.42 | AB24: 0.3 | AC24: 0 | AD24: 0.55 | AE24: 0.55 | AF24: 0.55 | AG24: 0.55 | AH24: 0.55 | AI24: 0.55 | AJ24: 0.55 | AK24: 0.55 | AL24: 2329 | AM24: =Z24*AL24 -> 978.18 | AN24: 1914 | AO24: =AA24*AN24 -> 803.88 | AP24: 440 | AQ24: =AB24*AP24 -> 132 | AR24: 1960 | AS24: =AC24*AR24 -> 0 | AT24: 1445 | AU24: =AD24*AT24 -> 794.75 | AV24: 597 | AW24: =AE24*AV24 -> 328.35 | AX24: 578 | AY24: =AF24*AX24 -> 317.9 | AZ24: 612 | BA24: =AG24*AZ24 -> 336.6 | BB24: 464.54105 | BC24: =AH24*BB24 -> 255.49758 | BD24: 416.79573 | BE24: =AI24*BD24 -> 229.23765 | BF24: 380.65297 | BG24: =AJ24*BF24 -> 209.35913 | BH24: 426.88753 | BI24: =AK24*BH24 -> 234.78814 | BJ24: HPM24F8*6930* | BL24: ODM | BM24: 6037B02862**
A25: FY26 | B25: Benson Chen | C25: Chicony | G25: 2025 | H25: MACHU14/MACHU14N/MACHUW14/MACHU13/MACHU13X/LAPAZW14/LAPAZW14N/COLOSSEUMW14N/LAPAZ13N/LAPAZ14/LAPAZ14N/LAPAZ13 | I25: BL KB | J25: 14 | K25: Soft Grey | L25: Thailand | M25: INVENTEC_TH | N25: 7.9 | O25: 7.9 | P25: 7.74 | Q25: 7.74 | R25: 8.25 | S25: 8.25 | T25: 8.25 | U25: 8.25 | V25: 8.25 | W25: 8.25 | X25: 8.25 | Y25: 8.25 | Z25: 0.39 | AA25: 0.39 | AB25: 0.31 | AC25: 0 | AD25: 0.41 | AE25: 0.41 | AF25: 0.41 | AG25: 0.41 | AH25: 0.41 | AI25: 0.41 | AJ25: 0.41 | AK25: 0.41 | AL25: 4000 | AM25: =Z25*AL25 -> 1560 | AN25: 0 | AO25: =AA25*AN25 -> 0 | AP25: 0 | AQ25: =AB25*AP25 -> 0 | AR25: 40 | AS25: =AC25*AR25 -> 0 | AT25: 3680 | AU25: =AD25*AT25 -> 1508.8 | AV25: 0 | AW25: =AE25*AV25 -> 0 | AX25: 0 | AY25: =AF25*AX25 -> 0 | AZ25: 0 | BA25: =AG25*AZ25 -> 0 | BB25: 0 | BC25: =AH25*BB25 -> 0 | BD25: 0 | BE25: =AI25*BD25 -> 0 | BF25: 0 | BG25: =AJ25*BF25 -> 0 | BH25: 0 | BI25: =AK25*BH25 -> 0 | BJ25: HPM24F5*J930T/1T | BL25: ODM | BM25: 6037B02853**
A26: FY26 | B26: Benson Chen | C26: Chicony | G26: 2025 | H26: MACHU14/MACHU14N/MACHUW14/MACHU13/MACHU13X/LAPAZW14/LAPAZW14N/COLOSSEUMW14N/LAPAZ13N/LAPAZ14/LAPAZ14N/LAPAZ13 | I26: BL KB | J26: 14 | K26: Soft Grey | L26: W China | M26: INVENTEC_MX | N26: 7.92 | O26: 7.92 | P26: 7.76 | Q26: 7.76 | R26: 8.27 | S26: 8.27 | T26: 8.27 | U26: 8.27 | V26: 8.27 | W26: 8.27 | X26: 8.27 | Y26: 8.27 | Z26: 0.39 | AA26: 0.39 | AB26: 0.31 | AC26: 0 | AD26: 0.41 | AE26: 0.41 | AF26: 0.41 | AG26: 0.41 | AH26: 0.41 | AI26: 0.41 | AJ26: 0.41 | AK26: 0.41 | AL26: 5712 | AM26: =Z26*AL26 -> 2227.68 | AN26: 5880 | AO26: =AA26*AN26 -> 2293.2 | AP26: 11160 | AQ26: =AB26*AP26 -> 3459.6 | AR26: 9000 | AS26: =AC26*AR26 -> 0 | AT26: 2851 | AU26: =AD26*AT26 -> 1168.91 | AV26: 1162 | AW26: =AE26*AV26 -> 476.42 | AX26: 5732 | AY26: =AF26*AX26 -> 2350.12 | AZ26: 3049 | BA26: =AG26*AZ26 -> 1250.09 | BB26: 0 | BC26: =AH26*BB26 -> 0 | BD26: 0 | BE26: =AI26*BD26 -> 0 | BF26: 0 | BG26: =AJ26*BF26 -> 0 | BH26: 0 | BI26: =AK26*BH26 -> 0 | BJ26: HPM24F5*J9304/5 | BK26: Mexico | BL26: ODM | BM26: 6037B02853**
A27: FY26 | B27: Benson Chen | C27: Chicony | G27: 2025 | H27: MACHU14/MACHU14N/MACHUW14/MACHU13/MACHU13X/LAPAZW14/LAPAZW14N/COLOSSEUMW14N/LAPAZ13N/LAPAZ14/LAPAZ14N/LAPAZ13 | I27: NBL KB | J27: 14 | K27: Soft Grey | L27: Thailand | M27: INVENTEC_TH | N27: 4.82 | O27: 4.82 | P27: 4.75 | Q27: 4.75 | R27: 5.25 | S27: 5.25 | T27: 5.25 | U27: 5.25 | V27: 5.25 | W27: 5.25 | X27: 5.25 | Y27: 5.25 | Z27: 0.39 | AA27: 0.39 | AB27: 0.32 | AC27: 0 | AD27: 0.41 | AE27: 0.41 | AF27: 0.41 | AG27: 0.41 | AH27: 0.41 | AI27: 0.41 | AJ27: 0.41 | AK27: 0.41 | AL27: 0 | AM27: =Z27*AL27 -> 0 | AN27: 0 | AO27: =AA27*AN27 -> 0 | AP27: 0 | AQ27: =AB27*AP27 -> 0 | AR27: 0 | AS27: =AC27*AR27 -> 0 | AT27: 0 | AU27: =AD27*AT27 -> 0 | AV27: 0 | AW27: =AE27*AV27 -> 0 | AX27: 0 | AY27: =AF27*AX27 -> 0 | AZ27: 0 | BA27: =AG27*AZ27 -> 0 | BB27: 0 | BC27: =AH27*BB27 -> 0 | BD27: 0 | BE27: =AI27*BD27 -> 0 | BF27: 0 | BG27: =AJ27*BF27 -> 0 | BH27: 0 | BI27: =AK27*BH27 -> 0 | BJ27: HPM24F6*6930*T | BL27: ODM | BM27: 6037B02852**
A28: FY26 | B28: Benson Chen | C28: Chicony | G28: 2025 | H28: MACHU16/MACHUW16/MACHU16N/LAPAZ16/LAPAZ16N/GEMTREE16/GEMTREE18 | I28: BL KB | J28: 16 | K28: Soft Grey | L28: Thailand | M28: INVENTEC_TH | N28: 8.23 | O28: 8.23 | P28: 8.14 | Q28: 8.14 | R28: 8.89 | S28: 8.89 | T28: 8.89 | U28: 8.89 | V28: 8.89 | W28: 8.89 | X28: 8.89 | Y28: 8.89 | Z28: 0.3 | AA28: 0.3 | AB28: 0.29 | AC28: 0 | AD28: 0.54 | AE28: 0.54 | AF28: 0.54 | AG28: 0.54 | AH28: 0.54 | AI28: 0.54 | AJ28: 0.54 | AK28: 0.54 | AL28: 40 | AM28: =Z28*AL28 -> 12 | AN28: 0 | AO28: =AA28*AN28 -> 0 | AP28: 0 | AQ28: =AB28*AP28 -> 0 | AR28: 520 | AS28: =AC28*AR28 -> 0 | AT28: 0 | AU28: =AD28*AT28 -> 0 | AV28: 0 | AW28: =AE28*AV28 -> 0 | AX28: 2 | AY28: =AF28*AX28 -> 1.08 | AZ28: 2 | BA28: =AG28*AZ28 -> 1.08 | BB28: 0 | BC28: =AH28*BB28 -> 0 | BD28: 0 | BE28: =AI28*BD28 -> 0 | BF28: 0 | BG28: =AJ28*BF28 -> 0 | BH28: 0 | BI28: =AK28*BH28 -> 0 | BJ28: HPM24F7*J930*T | BL28: ODM | BM28: 6037B02851**
A29: FY26 | B29: Benson Chen | C29: Chicony | G29: 2026 | H29: LAMPAS14/LAMPASW14/MERINO13/MERINO13X/MERINO14/MERINOW14 | I29: BL KB | J29: 14 | K29: Soft Grey | L29: W China | M29: INVENTEC_CQ | N29: 7.2 | O29: 7.2 | P29: 7.2 | Q29: 7.2 | R29: 7.75 | S29: 7.75 | T29: 7.75 | U29: 7.75 | V29: 7.75 | W29: 7.75 | X29: 7.75 | Y29: 7.75 | Z29: 0 | AA29: 0 | AB29: 0.26 | AC29: 0 | AD29: 0.4 | AE29: 0.4 | AF29: 0.4 | AG29: 0.4 | AH29: 0.4 | AI29: 0.4 | AJ29: 0.4 | AK29: 0.4 | AL29: 0 | AM29: =Z29*AL29 -> 0 | AN29: 0 | AO29: =AA29*AN29 -> 0 | AP29: 0 | AQ29: =AB29*AP29 -> 0 | AR29: 0 | AS29: =AC29*AR29 -> 0 | AT29: 0 | AU29: =AD29*AT29 -> 0 | AV29: 10276 | AW29: =AE29*AV29 -> 4110.4 | AX29: 17171 | AY29: =AF29*AX29 -> 6868.4 | AZ29: 16391 | BA29: =AG29*AZ29 -> 6556.4 | BB29: 0 | BC29: =AH29*BB29 -> 0 | BD29: 0 | BE29: =AI29*BD29 -> 0 | BF29: 0 | BG29: =AJ29*BF29 -> 0 | BH29: 0 | BI29: =AK29*BH29 -> 0 | BJ29: HPM24F5*J9306 | BL29: ODM | BM29: 6037B03218**
A30: FY26 | B30: Benson Chen | C30: Chicony | G30: 2026 | H30: LAMPAS14/LAMPASW14/MERINO13/MERINO13X/MERINO14/MERINOW14 | I30: BL KB | J30: 14 | K30: Soft Grey | L30: W China | M30: INVENTEC_CQ | N30: 7.2 | O30: 7.2 | P30: 7.2 | Q30: 7.2 | R30: 7.75 | S30: 7.75 | T30: 7.75 | U30: 7.75 | V30: 7.75 | W30: 7.75 | X30: 7.75 | Y30: 7.75 | Z30: 0 | AA30: 0 | AB30: 0.26 | AC30: 0 | AD30: 0.4 | AE30: 0.4 | AF30: 0.4 | AG30: 0.4 | AH30: 0.4 | AI30: 0.4 | AJ30: 0.4 | AK30: 0.4 | AL30: 0 | AM30: =Z30*AL30 -> 0 | AN30: 0 | AO30: =AA30*AN30 -> 0 | AP30: 0 | AQ30: =AB30*AP30 -> 0 | AR30: 0 | AS30: =AC30*AR30 -> 0 | AT30: 0 | AU30: =AD30*AT30 -> 0 | AV30: 0 | AW30: =AE30*AV30 -> 0 | AX30: 0 | AY30: =AF30*AX30 -> 0 | AZ30: 0 | BA30: =AG30*AZ30 -> 0 | BB30: 0 | BC30: =AH30*BB30 -> 0 | BD30: 0 | BE30: =AI30*BD30 -> 0 | BF30: 0 | BG30: =AJ30*BF30 -> 0 | BH30: 0 | BI30: =AK30*BH30 -> 0 | BJ30: HPM24F5*J9307 | BL30: ODM | BM30: 6037B03218**
A31: FY26 | B31: Benson Chen | C31: Chicony | G31: 2026 | H31: LAMPAS14/LAMPASW14/MERINO13/MERINO13X/MERINO14/MERINOW14 | I31: BL KB | J31: 14 | K31: Soft Grey | L31: W China | M31: INVENTEC_MX | N31: 7.22 | O31: 7.22 | P31: 7.22 | Q31: 7.22 | R31: 7.77 | S31: 7.77 | T31: 7.77 | U31: 7.77 | V31: 7.77 | W31: 7.77 | X31: 7.77 | Y31: 7.77 | Z31: 0 | AA31: 0 | AB31: 0.26 | AC31: 0 | AD31: 0.4 | AE31: 0.4 | AF31: 0.4 | AG31: 0.4 | AH31: 0.4 | AI31: 0.4 | AJ31: 0.4 | AK31: 0.4 | AL31: 0 | AM31: =Z31*AL31 -> 0 | AN31: 0 | AO31: =AA31*AN31 -> 0 | AP31: 0 | AQ31: =AB31*AP31 -> 0 | AR31: 0 | AS31: =AC31*AR31 -> 0 | AT31: 0 | AU31: =AD31*AT31 -> 0 | AV31: 0 | AW31: =AE31*AV31 -> 0 | AX31: 0 | AY31: =AF31*AX31 -> 0 | AZ31: 0 | BA31: =AG31*AZ31 -> 0 | BB31: 0 | BC31: =AH31*BB31 -> 0 | BD31: 0 | BE31: =AI31*BD31 -> 0 | BF31: 0 | BG31: =AJ31*BF31 -> 0 | BH31: 0 | BI31: =AK31*BH31 -> 0 | BJ31: HPM24F5*J9308 | BL31: ODM | BM31: 6037B03218**
A32: FY26 | B32: Benson Chen | C32: Chicony | G32: 2026 | H32: LAMPAS14/LAMPASW14/MERINO13/MERINO13X/MERINO14/MERINOW14 | I32: BL KB | J32: 14 | K32: Soft Grey | L32: W China | M32: INVENTEC_MX | N32: 7.22 | O32: 7.22 | P32: 7.22 | Q32: 7.22 | R32: 7.77 | S32: 7.77 | T32: 7.77 | U32: 7.77 | V32: 7.77 | W32: 7.77 | X32: 7.77 | Y32: 7.77 | Z32: 0 | AA32: 0 | AB32: 0.26 | AC32: 0 | AD32: 0.4 | AE32: 0.4 | AF32: 0.4 | AG32: 0.4 | AH32: 0.4 | AI32: 0.4 | AJ32: 0.4 | AK32: 0.4 | AL32: 0 | AM32: =Z32*AL32 -> 0 | AN32: 0 | AO32: =AA32*AN32 -> 0 | AP32: 0 | AQ32: =AB32*AP32 -> 0 | AR32: 0 | AS32: =AC32*AR32 -> 0 | AT32: 0 | AU32: =AD32*AT32 -> 0 | AV32: 0 | AW32: =AE32*AV32 -> 0 | AX32: 0 | AY32: =AF32*AX32 -> 0 | AZ32: 0 | BA32: =AG32*AZ32 -> 0 | BB32: 0 | BC32: =AH32*BB32 -> 0 | BD32: 0 | BE32: =AI32*BD32 -> 0 | BF32: 0 | BG32: =AJ32*BF32 -> 0 | BH32: 0 | BI32: =AK32*BH32 -> 0 | BJ32: HPM24F5*J9309 | BL32: ODM | BM32: 6037B03218**
A33: FY26 | B33: Benson Chen | C33: Chicony | G33: 2026 | H33: LAMPAS16/LAMPASW16/MERINO16/MERINOW16 | I33: NBL KB | J33: 14 | K33: Soft Grey | L33: W China | M33: INVENTEC_CQ | N33: 4.82 | O33: 4.82 | P33: 4.75 | Q33: 4.75 | R33: 5.25 | S33: 5.25 | T33: 5.25 | U33: 5.25 | V33: 5.25 | W33: 5.25 | X33: 5.25 | Y33: 5.25 | Z33: 0 | AA33: 0 | AB33: 0.32 | AC33: 0 | AD33: 0.41 | AE33: 0.41 | AF33: 0.41 | AG33: 0.41 | AH33: 0.41 | AI33: 0.41 | AJ33: 0.41 | AK33: 0.41 | AL33: 0 | AM33: =Z33*AL33 -> 0 | AN33: 0 | AO33: =AA33*AN33 -> 0 | AP33: 0 | AQ33: =AB33*AP33 -> 0 | AR33: 0 | AS33: =AC33*AR33 -> 0 | AT33: 0 | AU33: =AD33*AT33 -> 0 | AV33: 474 | AW33: =AE33*AV33 -> 194.34 | AX33: 955 | AY33: =AF33*AX33 -> 391.55 | AZ33: 862 | BA33: =AG33*AZ33 -> 353.42 | BB33: 0 | BC33: =AH33*BB33 -> 0 | BD33: 0 | BE33: =AI33*BD33 -> 0 | BF33: 0 | BG33: =AJ33*BF33 -> 0 | BH33: 0 | BI33: =AK33*BH33 -> 0 | BJ33: HPM24F6*69302 | BL33: ODM | BM33: 6037B03250**
A34: FY26 | B34: Benson Chen | C34: Chicony | D34: Commercial | E34: NB | F34: 1000 | G34: 2024 | H34: ERNESTO/ERNESTOX/MASADAN/MASADANX | I34: BL KB | J34: 14 | K34: Soft Grey | L34: W China | M34: INVENTEC_CQ | N34: 9.61 | O34: 9.61 | P34: 9.44 | Q34: 9.44 | R34: 9.44 | S34: 9.44 | T34: 9.44 | U34: 9.44 | V34: 9.44 | W34: 9.44 | X34: 9.44 | Y34: 9.44 | Z34: 0.94 | AA34: 0.94 | AB34: 0.86 | AC34: 0 | AD34: 0.86 | AE34: 0.86 | AF34: 0.86 | AG34: 0.86 | AH34: 0.86 | AI34: 0.86 | AJ34: 0.86 | AK34: 0.86 | AL34: 13510 | AM34: =Z34*AL34 -> 12699.4 | AN34: 16727 | AO34: =AA34*AN34 -> 15723.38 | AP34: 13175 | AQ34: =AB34*AP34 -> 11330.5 | AR34: 20144 | AS34: =AC34*AR34 -> 0 | AT34: 22059 | AU34: =AD34*AT34 -> 18970.74 | AV34: 5507 | AW34: =AE34*AV34 -> 4736.02 | AX34: 2940 | AY34: =AF34*AX34 -> 2528.4 | AZ34: 4159 | BA34: =AG34*AZ34 -> 3576.74 | BB34: 2183.6874 | BC34: =AH34*BB34 -> 1877.9711 | BD34: 0 | BE34: =AI34*BD34 -> 0 | BF34: 0 | BG34: =AJ34*BF34 -> 0 | BH34: 0 | BI34: =AK34*BH34 -> 0 | BJ34: HPM23C7*J930/1 | BL34: ODM | BM34: 6037B02726**
A35: FY26 | B35: Benson Chen | C35: Chicony | G35: 2024 | H35: ERNESTO/ERNESTOX/MASADAN/MASADANX | I35: BL KB | J35: 14 | K35: Soft Grey | L35: Thailand | M35: INVENTEC_TH | N35: 9.61 | O35: 9.61 | P35: 9.44 | Q35: 9.44 | R35: 9.44 | S35: 9.44 | T35: 9.44 | U35: 9.44 | V35: 9.44 | W35: 9.44 | X35: 9.44 | Y35: 9.44 | Z35: 0.94 | AA35: 0.94 | AB35: 0.86 | AC35: 0 | AD35: 0.86 | AE35: 0.86 | AF35: 0.86 | AG35: 0.86 | AH35: 0.86 | AI35: 0.86 | AJ35: 0.86 | AK35: 0.86 | AL35: 8000 | AM35: =Z35*AL35 -> 7520 | AN35: 9880 | AO35: =AA35*AN35 -> 9287.2 | AP35: 2960 | AQ35: =AB35*AP35 -> 2545.6 | AR35: 7960 | AS35: =AC35*AR35 -> 0 | AT35: 5780 | AU35: =AD35*AT35 -> 4970.8 | AV35: 4150 | AW35: =AE35*AV35 -> 3569 | AX35: 3801 | AY35: =AF35*AX35 -> 3268.86 | AZ35: 3629 | BA35: =AG35*AZ35 -> 3120.94 | BB35: 0 | BC35: =AH35*BB35 -> 0 | BD35: 0 | BE35: =AI35*BD35 -> 0 | BF35: 0 | BG35: =AJ35*BF35 -> 0 | BH35: 0 | BI35: =AK35*BH35 -> 0 | BJ35: HPM23C7*J930T/1T | BL35: ODM | BM35: 6037B02726**
A36: FY26 | B36: Benson Chen | C36: Chicony | G36: 2024 | H36: MASADAN/MASADANX | I36: BL KB | J36: 14 | K36: Atmospheric Blue | L36: W China | M36: INVENTEC_CQ | N36: 9.61 | O36: 9.61 | P36: 9.44 | Q36: 9.44 | R36: 9.44 | S36: 9.44 | T36: 9.44 | U36: 9.44 | V36: 9.44 | W36: 9.44 | X36: 9.44 | Y36: 9.44 | Z36: 0.94 | AA36: 0.94 | AB36: 0.86 | AC36: 0 | AD36: 0.86 | AE36: 0.86 | AF36: 0.86 | AG36: 0.86 | AH36: 0.86 | AI36: 0.86 | AJ36: 0.86 | AK36: 0.86 | AL36: 12634 | AM36: =Z36*AL36 -> 11875.96 | AN36: 18920 | AO36: =AA36*AN36 -> 17784.8 | AP36: 12618 | AQ36: =AB36*AP36 -> 10851.48 | AR36: 17539 | AS36: =AC36*AR36 -> 0 | AT36: 14492 | AU36: =AD36*AT36 -> 12463.12 | AV36: 20445 | AW36: =AE36*AV36 -> 17582.7 | AX36: 8701 | AY36: =AF36*AX36 -> 7482.86 | AZ36: 13238 | BA36: =AG36*AZ36 -> 11384.68 | BB36: 2168.5521 | BC36: =AH36*BB36 -> 1864.9548 | BD36: 0 | BE36: =AI36*BD36 -> 0 | BF36: 0 | BG36: =AJ36*BF36 -> 0 | BH36: 0 | BI36: =AK36*BH36 -> 0 | BJ36: HPM23C7*J9302/3 | BL36: ODM | BM36: 6037B02880**
A37: FY26 | B37: Benson Chen | C37: Chicony | G37: 2024 | H37: MASADAN/MASADANX | I37: BL KB | J37: 14 | K37: Atmospheric Blue | L37: Thailand | M37: INVENTEC_TH | N37: 9.61 | O37: 9.61 | P37: 9.44 | Q37: 9.44 | R37: 9.44 | S37: 9.44 | T37: 9.44 | U37: 9.44 | V37: 9.44 | W37: 9.44 | X37: 9.44 | Y37: 9.44 | Z37: 0.94 | AA37: 0.94 | AB37: 0.86 | AC37: 0 | AD37: 0.86 | AE37: 0.86 | AF37: 0.86 | AG37: 0.86 | AH37: 0.86 | AI37: 0.86 | AJ37: 0.86 | AK37: 0.86 | AL37: 5080 | AM37: =Z37*AL37 -> 4775.2 | AN37: 10080 | AO37: =AA37*AN37 -> 9475.2 | AP37: 4720 | AQ37: =AB37*AP37 -> 4059.2 | AR37: 4000 | AS37: =AC37*AR37 -> 0 | AT37: 12920 | AU37: =AD37*AT37 -> 11111.2 | AV37: 4352 | AW37: =AE37*AV37 -> 3742.72 | AX37: 4667 | AY37: =AF37*AX37 -> 4013.62 | AZ37: 4370 | BA37: =AG37*AZ37 -> 3758.2 | BB37: 0 | BC37: =AH37*BB37 -> 0 | BD37: 0 | BE37: =AI37*BD37 -> 0 | BF37: 0 | BG37: =AJ37*BF37 -> 0 | BH37: 0 | BI37: =AK37*BH37 -> 0 | BJ37: HPM23C7*J9302T/3T | BL37: ODM | BM37: 6037B02880**
A38: FY26 | B38: Benson Chen | C38: Chicony | G38: 2026 | H38: CASHMERE | I38: BL KB | J38: 14 | K38: Atmospheric Blue | L38: W China | M38: INVENTEC_CQ | N38: 9.82 | O38: 9.82 | P38: 9.82 | Q38: 9.82 | R38: 10.25 | S38: 10.25 | T38: 10.25 | U38: 10.25 | V38: 10.25 | W38: 10.25 | X38: 10.25 | Y38: 10.25 | Z38: 1.26 | AA38: 1.26 | AB38: 1.26 | AC38: 0 | AD38: 1.28 | AE38: 1.28 | AF38: 1.28 | AG38: 1.28 | AH38: 1.28 | AI38: 1.28 | AJ38: 1.28 | AK38: 1.28 | AL38: 0 | AM38: =Z38*AL38 -> 0 | AN38: 0 | AO38: =AA38*AN38 -> 0 | AP38: 0 | AQ38: =AB38*AP38 -> 0 | AR38: 1888 | AS38: =AC38*AR38 -> 0 | AT38: 1240 | AU38: =AD38*AT38 -> 1587.2 | AV38: 3456 | AW38: =AE38*AV38 -> 4423.68 | AX38: 2252 | AY38: =AF38*AX38 -> 2882.56 | AZ38: 6924 | BA38: =AG38*AZ38 -> 8862.72 | BB38: 2477.856 | BC38: =AH38*BB38 -> 3171.6557 | BD38: 2825.536 | BE38: =AI38*BD38 -> 3616.6861 | BF38: 3194.84 | BG38: =AJ38*BF38 -> 4089.3952 | BH38: 3158.8 | BI38: =AK38*BH38 -> 4043.264 | BJ38: HPM25A8*J9302/3 | BL38: ODM | BM38: 6037B03076**
A39: FY26 | B39: Benson Chen | C39: Chicony | G39: 2026 | H39: CASHMERE | I39: BL KB | J39: 14 | K39: SOFT GREY | L39: W China | M39: INVENTEC_CQ | N39: 9.82 | O39: 9.82 | P39: 9.82 | Q39: 9.82 | R39: 10.25 | S39: 10.25 | T39: 10.25 | U39: 10.25 | V39: 10.25 | W39: 10.25 | X39: 10.25 | Y39: 10.25 | Z39: 1.26 | AA39: 1.26 | AB39: 1.26 | AC39: 0 | AD39: 1.28 | AE39: 1.28 | AF39: 1.28 | AG39: 1.28 | AH39: 1.28 | AI39: 1.28 | AJ39: 1.28 | AK39: 1.28 | AL39: 0 | AM39: =Z39*AL39 -> 0 | AN39: 0 | AO39: =AA39*AN39 -> 0 | AP39: 0 | AQ39: =AB39*AP39 -> 0 | AR39: 992 | AS39: =AC39*AR39 -> 0 | AT39: 292 | AU39: =AD39*AT39 -> 373.76 | AV39: 3132 | AW39: =AE39*AV39 -> 4008.96 | AX39: 1732 | AY39: =AF39*AX39 -> 2216.96 | AZ39: 6084 | BA39: =AG39*AZ39 -> 7787.52 | BB39: 2197.344 | BC39: =AH39*BB39 -> 2812.6003 | BD39: 2505.664 | BE39: =AI39*BD39 -> 3207.2499 | BF39: 2833.16 | BG39: =AJ39*BF39 -> 3626.4448 | BH39: 2801.2 | BI39: =AK39*BH39 -> 3585.536 | BJ39: HPM25A8*J930/1 | BL39: ODM | BM39: 6037B03068**
A40: FY26 | B40: Benson Chen | C40: Chicony | G40: 2026 | H40: CASHMERE | I40: BL KB | J40: 14 | K40: Atmospheric Blue | L40: Thailand | M40: INVENTEC_TH | N40: 9.82 | O40: 9.82 | P40: 9.82 | Q40: 9.82 | R40: 10.25 | S40: 10.25 | T40: 10.25 | U40: 10.25 | V40: 10.25 | W40: 10.25 | X40: 10.25 | Y40: 10.25 | Z40: 1.26 | AA40: 1.26 | AB40: 1.26 | AC40: 0 | AD40: 1.28 | AE40: 1.28 | AF40: 1.28 | AG40: 1.28 | AH40: 1.28 | AI40: 1.28 | AJ40: 1.28 | AK40: 1.28 | AL40: 0 | AM40: =Z40*AL40 -> 0 | AN40: 0 | AO40: =AA40*AN40 -> 0 | AP40: 0 | AQ40: =AB40*AP40 -> 0 | AR40: 80 | AS40: =AC40*AR40 -> 0 | AT40: 120 | AU40: =AD40*AT40 -> 153.6 | AV40: 2103 | AW40: =AE40*AV40 -> 2691.84 | AX40: 2968 | AY40: =AF40*AX40 -> 3799.04 | AZ40: 3470 | BA40: =AG40*AZ40 -> 4441.6 | BB40: 0 | BC40: =AH40*BB40 -> 0 | BD40: 0 | BE40: =AI40*BD40 -> 0 | BF40: 0 | BG40: =AJ40*BF40 -> 0 | BH40: 0 | BI40: =AK40*BH40 -> 0 | BJ40: HPM25A8*J9302T | BL40: ODM | BM40: 6037B03076**
...
