Workbook
Name Region: #REF!
Name Region: #REF!
Name Region: #REF!
Name Region: #REF!

Sheet 說明頁_更新版
A1: ID | B1: Action | C1: Remark
A2: 1 | B2: A-M欄及BM-BP欄照理來說不會更動只會新增
A3: 2 | B3: 檔名的部分請像這樣 "Rebate and Spending report Supplier’s name_2025 01"，勿加上其他說明，若有V2版本請寫 "Rebate and Spending report Supplier’s name_2025 01_V2"
A4: 3 | B4: 請全年度都放在同一個tab，Summary也是Q1-Q4都放在一起，若有更新的年度請一樣要加上對應的Summary
A5: 4 | B5: Title相關規範請看右方所示, 請按照此欄位進行填寫, 勿更改資料次序 *上面也附上Example, 參考的顏色表以及Mason的PDF instruction | C5: A欄位:打上年度，新年度記得要更新
C6: B欄位: SPM, 請填全名, ex Benson Chen, 而不是Benson，若SPM有異動也請更新
C7: C 欄位: 一律填自己公司名稱
C8: D欄位: 請照上方指示, 勿自創提詞, 須注意只有NB和DT才會有Consumer/Commercial之分, F欄位是Peripheral則D和E都是填Peripheral
C9: E欄位 : 請照上方指示, 勿自創提詞
C10: F欄位 : Peripheral只需填寫Peripheral
C11: G欄位 : 已更新到2025
C12: H欄位 : -請一定不能空白此欄位，不然後面的數字都會讀不到 -如果多個platforms共用同keyboard, 請用 '/' 去 group這些platforms，大小寫沒關係。 -請Platform name請跟LTF一模一樣，像是有些後面會加上尺寸也請加上( BAYMAX14/LUISA14/BAYMAXW14/BAYMAX13/BAYMAX13X) -請用"/"來 Grouping 不同 Platform (e.g. ANDAZ/ABU) ，勿用其他符號，錯誤範例如:ANDAZ&ABU
C13: I欄位 : 請照上方指示, 勿自創提詞
C14: J欄位 : 如果沒有Size，則填寫"NA/"，不要只寫"NA"
C15: K欄 : -要注意勿將 Color grouping 在一起，像是Jet Black/Soft Grey，若有n個顏色需分成n筆資料去填 -如果沒有Color，則填寫"NA/"，請注意不要只寫"NA" -Color 需確保填寫正確，如 SEAFOAM TEAL PEARL 需完整打出來，避免填成 SEAFOAM TEAL -請確保在顏色中間加上空格，大小寫沒關係。 -關於灰色，請使用“Grey” 而非“Gray” -Color 欄位需保持正常format，像是 PERFORMANCE BLUE OPAQUE 請避免填成 PERFORMANCE BLUE OPAQUE-RGB -針對CNB Gaming，關於Numpad及RGB方面請遵照以下方式及右方的說明 : RGB Per Key W Numpad_Soft Grey RGB Per Key W/O Numpad_Soft Grey 1 Zone W Numpad_Soft Grey, 1 Zone Red W Numpad_Soft Grey 4 Zone RGB W Numpad_Soft Grey 1 Zone W/O Numpad_Soft Grey, 1 Zone Red W/O Numpad_Soft Grey 4 Zone RGB W/O Numpad_Soft Grey 1 Zone RGB W Numpad_Soft Grey 1 Zone RGB W/O Numpad_Soft Grey
C16: L欄 : 請照上方指示，勿自創提詞，注意NMC更新為Thailand/Vietnam
C17: M欄 : 請照上方指示，勿自創提詞或簡寫，後面多加 Site 等
... C22: BP欄 : 新增的欄位"HP Model"，這欄只有針對NB KB，需填上LTF中相對應的HP model (如下所示)，接下來會使用這欄去串連其他資料
A27: 5 | B27: 當月出貨的所有品項都必須填上, 即使rebate=0的項目, 定義為FCS之後, EOL前的platform 當月出貨都需要寫上(也就是不含service part)
A28: 6 | B28: 每個月10日固定上傳此份rebate and spending report，請注意目前的Share point已經與財務共用，因此有任何要更新的地方都請通知Jenny並且上傳V2/V3…版本，且舊檔案勿刪除
A29: 7 | B29: 在上傳此份檔案前針對數字的部分需再三確認，因為這些數字會直接當作日後開發票的金額
A30: 8 | B30: excel欄位有相乘的部分 (rebate amount), 請不要直接在公式以外做數字上的調整, 沒有邏輯性的數字, 程式會偵測異常
A31: 9 | B31: Summary_1不能有任何註記, 需要呈現最真實的數字, Summary_2貴司可有一些註記符號, 或是rebate抵扣等地紀錄是能夠被容許的

Sheet FY23 Summary_1
B3: Primax | C3: 2022 11 | D3: 2022 12 | E3: 2023 01 | F3: Total Q1
B4: Rebate amount | C4: ='FY23'!AO1 -> 1643474.5 | D4: ='FY23'!AQ1 -> 1869696.1 | E4: ='FY23'!AS1 -> 1785552.1 | F4: =SUM(C4:E4) -> 5298722.7
B5: E&O reduction | F5: =SUM(C5:E5) -> 0
B6: Complexity reduction | F6: =SUM(C6:E6) -> 0 | H6: 1. 新增Summary_1, 原先的Summary重新命名為Summary_2
B7: Total amount | C7: =SUM(C4:C6) -> 1643474.5 | D7: =SUM(D4:D6) -> 1869696.1 | E7: =SUM(E4:E6) -> 1785552.1 | F7: =SUM(F4:F6) -> 5298722.7
H8: 2.黃色部位為貴司名稱, 請整份報告都跟檔名貴司名稱撰寫方式一致
B10: Primax | C10: 2023 02 | D10: 2023 03 | E10: 2023 04 | F10: Total Q2 | H10: 3. 這些欄位一定要固定, B3-B28, C3-C28, D3-D28, E3-E28, F3-F28都有賦予定義
B11: Rebate amount | C11: ='FY23'!AU1 -> 1519345.7 | D11: ='FY23'!AW1 -> 2017904.8 | E11: ='FY23'!AY1 -> 1577362.8 | F11: =SUM(C11:E11) -> 5114613.3
B12: E&O reduction | E12: 18724.49 | F12: =SUM(C12:E12) -> 18724.49 | H12: 4. Rebate amount 指得是summary_2的page金額 (就是我們一直以來收集的金額)
B13: Complexity reduction | F13: =SUM(C13:E13) -> 0
B14: Total amount | C14: =SUM(C11:C13) -> 1519345.7 | D14: =SUM(D11:D13) -> 2017904.8 | E14: =SUM(E11:E13) -> 1596087.3 | F14: =SUM(F11:F13) -> 5133337.8 | H14: 5. 新增 E&O reduction 及complexity reduction品項, 先留足空間
H15: 若目前還未有此款項存在都先填0
B17: Primax | C17: 2023 05 | D17: 2023 06 | E17: 2023 07 | F17: Total Q3 | H17: 6. 金額都放未經調整後的真實數字, 分析才具意義
B18: Rebate amount | C18: ='FY23'!BA1 -> 1861807 | D18: ='FY23'!BC1 -> 2056001.3 | E18: ='FY23'!BE1 -> 1553369.1 | F18: =SUM(C18:E18) -> 5471177.4
B19: E&O reduction | F19: =SUM(C19:E19) -> 0
B20: Complexity reduction | F20: =SUM(C20:E20) -> 0
B21: Total amount | C21: =SUM(C18:C20) -> 1861807 | D21: =SUM(D18:D20) -> 2056001.3 | E21: =SUM(E18:E20) -> 1553369.1 | F21: =SUM(F18:F20) -> 5471177.4
B24: Primax | C24: 2023 08 | D24: 2023 09 | E24: 2023 10 | F24: Total Q4
B25: Rebate amount | C25: ='FY23'!BG1 -> 1932655.5 | D25: ='FY23'!BI1 -> 1962274.7 | E25: ='FY23'!BK1 -> 1580598.7 | F25: =SUM(C25:E25) -> 5475528.9
B26: E&O reduction | E26: =(55883.05+35510.55 )*15% -> 13709.04 | F26: =SUM(C26:E26) -> 13709.04
B27: Complexity reduction | F27: =SUM(C27:E27) -> 0
B28: Total amount | C28: =SUM(C25:C27) -> 1932655.5 | D28: =SUM(D25:D27) -> 1962274.7 | E28: =SUM(E25:E27) -> 1594307.7 | F28: =SUM(F25:F27) -> 5489238

Sheet FY23 Summary_2
B3: Q1 Actual by Segment
C4: Segment | D4: 44866 | E4: 44896 | F4: 44927 | G4: Total Rebate in Q1 2023 (US$)
B5: CMIT Input Devices | C5: 200 series (6U) | D5: ='[1]FY23 '!Q4 -> 99973.28 | E5: ='[1]FY23 '!U4 -> 117551.68 | F5: ='[1]FY23 '!Y4 -> 75927.68 | G5: =SUM(D5:F5) -> 293452.64
C6: 400 series (S) | D6: 0 | E6: 0 | F6: 0 | G6: =SUM(D6:F6) -> 0
C7: 600 series (B) | D7: 0 | E7: 0 | F7: 0 | G7: =SUM(D7:F7) -> 0
C8: 800 series (P) | D8: =SUM('[1]FY23 '!Q21:Q30) -> 544597.3 | E8: =SUM('[1]FY23 '!U21:U30) -> 575037.47 | F8: =SUM('[1]FY23 '!Y21:Y30) -> 693475.2 | G8: =SUM(D8:F8) -> 1813110
C9: 1000 series (M | D9: =SUM('[1]FY23 '!Q32:Q33) -> 5900 | E9: =SUM('[1]FY23 '!U32:U33) -> 20836 | F9: =SUM('[1]FY23 '!Y32:Y33) -> 12836 | G9: =SUM(D9:F9) -> 39572
C10: MWS (Workstation) | D10: ='[1]FY23 '!Q40 -> 10240 | E10: ='[1]FY23 '!U40 -> 10240 | F10: ='[1]FY23 '!Y40 -> 10240 | G10: =SUM(D10:F10) -> 30720
C11: Soft Keyboard | D11: ='[1]FY23 '!Q42 -> 0 | E11: ='[1]FY23 '!U42 -> 0 | F11: ='[1]FY23 '!Y42 -> 0 | G11: =SUM(D11:F11) -> 0
C12: Chrome Book | D12: 0 | E12: 0 | F12: 0 | G12: =SUM(D12:F12) -> 0
C13: Clickpad | D13: 0 | E13: 0 | F13: 0 | G13: =SUM(D13:F13) -> 0
C14: Education | D14: ='[1]FY23 '!Q38 -> 1166 | E14: ='[1]FY23 '!U38 -> 480 | F14: ='[1]FY23 '!Y38 -> 1200 | G14: =SUM(D14:F14) -> 2846
C15: Peripherals/AMO | D15: =SUM('[1]FY23 '!Q217:Q229) -> 19715.2 | E15: =SUM('[1]FY23 '!U217:U229) -> 22863 | F15: =SUM('[1]FY23 '!Y217:Y229) -> 15914.28 | G15: =SUM(D15:F15) -> 58492.48
C16: Desktop | D16: =SUM('[1]FY23 '!Q49:Q59) -> 75568.26 | E16: =SUM('[1]FY23 '!U49:U59) -> 110301.46 | F16: =SUM('[1]FY23 '!Y49:Y59) -> 119271.71 | G16: =SUM(D16:F16) -> 305141.43
B17: Consumer Input Devices | C17: OPP | D17: =SUM('[1]FY23 '!Q61:Q81) -> 299921.2 | E17: =SUM('[1]FY23 '!U61:U81) -> 352662.88 | F17: =SUM('[1]FY23 '!Y61:Y81) -> 249572.15 | G17: =SUM(D17:F17) -> 902156.23
C18: Chrome Book | D18: =SUM('[1]FY23 '!Q94:Q98) -> 10134.6 | E18: =SUM('[1]FY23 '!U94:U98) -> 2568.8 | F18: =SUM('[1]FY23 '!Y94:Y98) -> 5915.2 | G18: =SUM(D18:F18) -> 18618.6
C19: Pavillion | D19: =SUM('[1]FY23 '!Q103:Q122) -> 397688.05 | E19: =SUM('[1]FY23 '!U103:U122) -> 489403 | F19: =SUM('[1]FY23 '!Y103:Y122) -> 398095.53 | G19: =SUM(D19:F19) -> 1285186.6
C20: Spectre | D20: 0 | E20: 0 | F20: 0 | G20: =SUM(D20:F20) -> 0
C21: Envy | D21: =SUM('[1]FY23 '!Q149:Q151) -> 64504.32 | E21: =SUM('[1]FY23 '!U149:U151) -> 35733.12 | F21: =SUM('[1]FY23 '!Y149:Y151) -> 71844.5 | G21: =SUM(D21:F21) -> 172081.94
C22: Stream | D22: 0 | E22: 0 | F22: 0 | G22: =SUM(D22:F22) -> 0
C23: Omen | D23: =SUM('[1]FY23 '!Q159:Q176) -> 27393 | E23: =SUM('[1]FY23 '!U159:U176) -> 26968.98 | F23: =SUM('[1]FY23 '!Y159:Y176) -> 41360.06 | G23: =SUM(D23:F23) -> 95722.04
C24: Peripherals/AMO | D24: =SUM('[1]FY23 '!Q204:Q216) -> 4887.04 | E24: =SUM('[1]FY23 '!U204:U216) -> 3018.84 | F24: =SUM('[1]FY23 '!Y204:Y216) -> 5466.8 | G24: =SUM(D24:F24) -> 13372.68
C25: Desktop | D25: =SUM('[1]FY23 '!Q185:Q203) -> 81786.28 | E25: =SUM('[1]FY23 '!U185:U203) -> 102030.87 | F25: =SUM('[1]FY23 '!Y185:Y203) -> 84432.96 | G25: =SUM(D25:F25) -> 268250.11
G26: =SUM(G4:G25) -> 5298722.7
B28: Q1 Actual by Segment
C29: Supplier | D29: 44866 | E29: 44896 | F29: 44927 | G29: Total Rebate in Q1 2023 (US$)
B30: Input Devices | C30: Acrox
C31: Chicony
C32: Darfon
C33: Liteon
C34: Primax | D34: =SUM(D5:D25) -> 1643474.5 | E34: =SUM(E5:E25) -> 1869696.1 | F34: =SUM(F5:F25) -> 1785552.1 | G34: =SUM(D34:F34) -> 5298722.7
C35: Sunrex
F36: Total Rebate Amount
B39: Q2 Actual by Segment
C40: Segment | D40: 44958 | E40: 44986 | F40: 45017 | G40: Total Rebate in Q2 2023 (US$)
B41: CMIT Input Devices | C41: 200 series (6U) | D41: =SUM('[1]FY23 '!AE4) -> 67224.48 | E41: ='[1]FY23 '!AI4 -> 117551.68 | F41: ='[1]FY23 '!AM4 -> 34503.2 | G41: =SUM(D41:F41) -> 219279.36
C42: 400 series (S) | D42: 0 | E42: 0 | F42: 0 | G42: =SUM(D42:F42) -> 0
C43: 600 series (B) | D43: 0 | E43: 0 | F43: 0 | G43: =SUM(D43:F43) -> 0
C44: 800 series (P) | D44: =SUM('[1]FY23 '!AE21:AE30) -> 682946.42 | E44: =SUM('[1]FY23 '!AI21:AI30) -> 675201.54 | F44: =SUM('[1]FY23 '!AM21:AM31) -> 537191.51 | G44: =SUM(D44:F44) -> 1895339.5
C45: 1000 series (M | D45: ='[1]FY23 '!AE32+'[1]FY23 '!AE33 -> 5040 | E45: =SUM('[1]FY23 '!AI32:AI33) -> 12780 | F45: =SUM('[1]FY23 '!AM32:AM33) -> 6480 | G45: =SUM(D45:F45) -> 24300
...

Sheet FY23
AO1: =SUM(AO3:AO235) -> 1643474.5 | AQ1: =SUM(AQ3:AQ235) -> 1869696.1 | AS1: =SUM(AS3:AS235) -> 1785552.1 | AU1: =SUM(AU3:AU235) -> 1519345.7 | AW1: =SUM(AW3:AW235) -> 2017904.8 | AY1: =SUM(AY3:AY235) -> 1577362.8 | BA1: =SUM(BA3:BA235) -> 1861807 | BC1: =SUM(BC3:BC235) -> 2056001.3 | BE1: =SUM(BE3:BE235) -> 1553369.1 | BG1: =SUM(BG3:BG235) -> 1932655.5 | BI1: =SUM(BI3:BI235) -> 1962274.7 | BK1: =SUM(BK3:BK235) -> 1580598.7
A2: FY23 | B2: SPM (Project Owner) | C2: GTK Suppliers | D2: Category | E2: Segment | F2: Series | G2: Production Year | H2: Platforms | I2: Product | J2: Size | K2: Color | L2: Location | M2: ODM | N2: The lowest unit table price (ODM cost) | O2: Table Price Nov | P2: Table Price Dec | Q2: Table Price Jan | R2: Table Price Feb | S2: Table Price Mar | T2: Table Price Apr | U2: Table Price May | V2: Table Price Jun | W2: Table Price Jul | X2: Table Price Aug | Y2: Table Price Sep | Z2: Table Price Oct | AA2: The lowest unit rebate cost | AB2: Unit Rebate Nov | AC2: Unit Rebate Dec | AD2: Unit Rebate Jan | AE2: Unit Rebate Feb | AF2: Unit Rebate Mar | AG2: Unit Rebate Apr | AH2: Unit Rebate May | AI2: Unit Rebate Jun | AJ2: Unit Rebate Jul | AK2: Unit Rebate Aug | AL2: Unit Rebate Sep | AM2: Unit Rebate Oct | AN2: Nov Q'ty | AO2: Nov Rebate Amount | AP2: Dec Q'ty | AQ2: Dec Rebate Amount | AR2: Jan Q'ty | AS2: Jan Rebate Amount | AT2: Feb Q'ty | AU2: Feb Rebate Amount | AV2: Mar Q'ty | AW2: Mar Rebate Amount | AX2: Apr Q'ty | AY2: Apr Rebate Amount | AZ2: May Q'ty | BA2: May Rebate Amount | BB2: Jun Q'ty | BC2: Jun Rebate Amount | BD2: Jul Q'ty | BE2: Jul Rebate Amount | BF2: Aug Q'ty | BG2: Aug Rebate Amount | BH2: Sep Q'ty | BI2: Sep Rebate Amount | BJ2: Oct Q'ty | BK2: Oct Rebate Amount | BL2: Supplier Part# | BM2: Comment
A3: FY23 | B3: Benson Chen | C3: Primax | D3: Commercial | E3: NB | F3: 200 | G3: 2019 | H3: LANGKAWI/REBAK | I3: BL KB | J3: 15 | K3: Pike Silver | L3: W China | M3: QUANTA | N3: 13.2 | O3: 13.2 | P3: 13.2 | Q3: 13.2 | R3: 13.2 | S3: 13.2 | T3: 13.2 | U3: 13.2 | V3: 13.2 | W3: 13.2 | X3: 13.2 | Y3: 13.2 | Z3: 13.2 | AA3: 3.44 | AB3: =AA3 -> 3.44 | AC3: =AB3 -> 3.44 | AD3: =AC3 -> 3.44 | AE3: =AD3 -> 3.44 | AF3: =AE3 -> 3.44 | AG3: =AF3 -> 3.44 | AH3: =AG3 -> 3.44 | AI3: =AH3 -> 3.44 | ... AM3: =AL3 -> 3.44 | AN3: 29062 | AO3: =AB3*AN3 -> 99973.28 | AP3: 34172 | AQ3: =AC3*AP3 -> 117551.68 | AR3: 22072 | AS3: =AD3*AR3 -> 75927.68 | AT3: 19542 | AU3: =AE3*AT3 -> 67224.48 | AV3: 34172 | AW3: =AF3*AV3 -> 117551.68 | AX3: 10030 | AY3: =AG3*AX3 -> 34503.2 | AZ3: 28967 | BA3: =AH3*AZ3 -> 99646.48 | BB3: 40850 | BC3: =AI3*BB3 -> 140524 | BD3: 20373 | BE3: =AJ3*BD3 -> 70083.12 | BF3: 30000 | BG3: =AK3*BF3 -> 103200 | BH3: 20000 | BI3: =AL3*BH3 -> 68800 | BJ3: 12800 | BK3: =AM3*BJ3 -> 44032
A4: FY23 | AO4: =AB4*AN4 -> 0 | AQ4: =AC4*AP4 -> 0 | AS4: =AD4*AR4 -> 0 | AU4: =AE4*AT4 -> 0 | AW4: =AF4*AV4 -> 0 | AY4: =AG4*AX4 -> 0 | BA4: =AH4*AZ4 -> 0 | BC4: =AI4*BB4 -> 0 | BE4: =AJ4*BD4 -> 0 | BG4: =AK4*BF4 -> 0 | BI4: =AL4*BH4 -> 0 | BK4: =AM4*BJ4 -> 0
A5: FY23 | AO5: =AB5*AN5 -> 0 | AQ5: =AC5*AP5 -> 0 | AS5: =AD5*AR5 -> 0 | AU5: =AE5*AT5 -> 0 | AW5: =AF5*AV5 -> 0 | AY5: =AG5*AX5 -> 0 | BA5: =AH5*AZ5 -> 0 | BC5: =AI5*BB5 -> 0 | BE5: =AJ5*BD5 -> 0 | BG5: =AK5*BF5 -> 0 | BI5: =AL5*BH5 -> 0 | BK5: =AM5*BJ5 -> 0
A6: FY23 | F6: 400 | AO6: =AB6*AN6 -> 0 | AQ6: =AC6*AP6 -> 0 | AS6: =AD6*AR6 -> 0 | AU6: =AE6*AT6 -> 0 | AW6: =AF6*AV6 -> 0 | AY6: =AG6*AX6 -> 0 | BA6: =AH6*AZ6 -> 0 | BC6: =AI6*BB6 -> 0 | BE6: =AJ6*BD6 -> 0 | BG6: =AK6*BF6 -> 0 | BI6: =AL6*BH6 -> 0 | BK6: =AM6*BJ6 -> 0
A7: FY23 | AO7: =AB7*AN7 -> 0 | AQ7: =AC7*AP7 -> 0 | AS7: =AD7*AR7 -> 0 | AU7: =AE7*AT7 -> 0 | AW7: =AF7*AV7 -> 0 | AY7: =AG7*AX7 -> 0 | BA7: =AH7*AZ7 -> 0 | BC7: =AI7*BB7 -> 0 | BE7: =AJ7*BD7 -> 0 | BG7: =AK7*BF7 -> 0 | BI7: =AL7*BH7 -> 0 | BK7: =AM7*BJ7 -> 0
A8: FY23 | AO8: =AB8*AN8 -> 0 | AQ8: =AC8*AP8 -> 0 | AS8: =AD8*AR8 -> 0 | AU8: =AE8*AT8 -> 0 | AW8: =AF8*AV8 -> 0 | AY8: =AG8*AX8 -> 0 | BA8: =AH8*AZ8 -> 0 | BC8: =AI8*BB8 -> 0 | BE8: =AJ8*BD8 -> 0 | BG8: =AK8*BF8 -> 0 | BI8: =AL8*BH8 -> 0 | BK8: =AM8*BJ8 -> 0
A9: FY23 | AO9: =AB9*AN9 -> 0 | AQ9: =AC9*AP9 -> 0 | AS9: =AD9*AR9 -> 0 | AU9: =AE9*AT9 -> 0 | AW9: =AF9*AV9 -> 0 | AY9: =AG9*AX9 -> 0 | BA9: =AH9*AZ9 -> 0 | BC9: =AI9*BB9 -> 0 | BE9: =AJ9*BD9 -> 0 | BG9: =AK9*BF9 -> 0 | BI9: =AL9*BH9 -> 0 | BK9: =AM9*BJ9 -> 0
A10: FY23 | AO10: =AB10*AN10 -> 0 | AQ10: =AC10*AP10 -> 0 | AS10: =AD10*AR10 -> 0 | AU10: =AE10*AT10 -> 0 | AW10: =AF10*AV10 -> 0 | AY10: =AG10*AX10 -> 0 | BA10: =AH10*AZ10 -> 0 | BC10: =AI10*BB10 -> 0 | BE10: =AJ10*BD10 -> 0 | BG10: =AK10*BF10 -> 0 | BI10: =AL10*BH10 -> 0 | BK10: =AM10*BJ10 -> 0
A11: FY23 | AO11: =AB11*AN11 -> 0 | AQ11: =AC11*AP11 -> 0 | AS11: =AD11*AR11 -> 0 | AU11: =AE11*AT11 -> 0 | AW11: =AF11*AV11 -> 0 | AY11: =AG11*AX11 -> 0 | BA11: =AH11*AZ11 -> 0 | BC11: =AI11*BB11 -> 0 | BE11: =AJ11*BD11 -> 0 | BG11: =AK11*BF11 -> 0 | BI11: =AL11*BH11 -> 0 | BK11: =AM11*BJ11 -> 0
A12: FY23 | AO12: =AB12*AN12 -> 0 | AQ12: =AC12*AP12 -> 0 | AS12: =AD12*AR12 -> 0 | AU12: =AE12*AT12 -> 0 | AW12: =AF12*AV12 -> 0 | AY12: =AG12*AX12 -> 0 | BA12: =AH12*AZ12 -> 0 | BC12: =AI12*BB12 -> 0 | BE12: =AJ12*BD12 -> 0 | BG12: =AK12*BF12 -> 0 | BI12: =AL12*BH12 -> 0 | BK12: =AM12*BJ12 -> 0
A13: FY23 | AO13: =AB13*AN13 -> 0 | AQ13: =AC13*AP13 -> 0 | AS13: =AD13*AR13 -> 0 | AU13: =AE13*AT13 -> 0 | AW13: =AF13*AV13 -> 0 | AY13: =AG13*AX13 -> 0 | BA13: =AH13*AZ13 -> 0 | BC13: =AI13*BB13 -> 0 | BE13: =AJ13*BD13 -> 0 | BG13: =AK13*BF13 -> 0 | BI13: =AL13*BH13 -> 0 | BK13: =AM13*BJ13 -> 0
A14: FY23 | F14: 600 | AO14: =AB14*AN14 -> 0 | AQ14: =AC14*AP14 -> 0 | AS14: =AD14*AR14 -> 0 | AU14: =AE14*AT14 -> 0 | AW14: =AF14*AV14 -> 0 | AY14: =AG14*AX14 -> 0 | BA14: =AH14*AZ14 -> 0 | BC14: =AI14*BB14 -> 0 | BE14: =AJ14*BD14 -> 0 | BG14: =AK14*BF14 -> 0 | BI14: =AL14*BH14 -> 0 | BK14: =AM14*BJ14 -> 0
A15: FY23 | AO15: =AB15*AN15 -> 0 | AQ15: =AC15*AP15 -> 0 | AS15: =AD15*AR15 -> 0 | AU15: =AE15*AT15 -> 0 | AW15: =AF15*AV15 -> 0 | AY15: =AG15*AX15 -> 0 | BA15: =AH15*AZ15 -> 0 | BC15: =AI15*BB15 -> 0 | BE15: =AJ15*BD15 -> 0 | BG15: =AK15*BF15 -> 0 | BI15: =AL15*BH15 -> 0 | BK15: =AM15*BJ15 -> 0
A16: FY23 | AO16: =AB16*AN16 -> 0 | AQ16: =AC16*AP16 -> 0 | AS16: =AD16*AR16 -> 0 | AU16: =AE16*AT16 -> 0 | AW16: =AF16*AV16 -> 0 | AY16: =AG16*AX16 -> 0 | BA16: =AH16*AZ16 -> 0 | BC16: =AI16*BB16 -> 0 | BE16: =AJ16*BD16 -> 0 | BG16: =AK16*BF16 -> 0 | BI16: =AL16*BH16 -> 0 | BK16: =AM16*BJ16 -> 0
A17: FY23 | AO17: =AB17*AN17 -> 0 | AQ17: =AC17*AP17 -> 0 | AS17: =AD17*AR17 -> 0 | AU17: =AE17*AT17 -> 0 | AW17: =AF17*AV17 -> 0 | AY17: =AG17*AX17 -> 0 | BA17: =AH17*AZ17 -> 0 | BC17: =AI17*BB17 -> 0 | BE17: =AJ17*BD17 -> 0 | BG17: =AK17*BF17 -> 0 | BI17: =AL17*BH17 -> 0 | BK17: =AM17*BJ17 -> 0
A18: FY23 | AO18: =AB18*AN18 -> 0 | AQ18: =AC18*AP18 -> 0 | AS18: =AD18*AR18 -> 0 | AU18: =AE18*AT18 -> 0 | AW18: =AF18*AV18 -> 0 | AY18: =AG18*AX18 -> 0 | BA18: =AH18*AZ18 -> 0 | BC18: =AI18*BB18 -> 0 | BE18: =AJ18*BD18 -> 0 | BG18: =AK18*BF18 -> 0 | BI18: =AL18*BH18 -> 0 | BK18: =AM18*BJ18 -> 0
A19: FY23 | AO19: =AB19*AN19 -> 0 | AQ19: =AC19*AP19 -> 0 | AS19: =AD19*AR19 -> 0 | AU19: =AE19*AT19 -> 0 | AW19: =AF19*AV19 -> 0 | AY19: =AG19*AX19 -> 0 | BA19: =AH19*AZ19 -> 0 | BC19: =AI19*BB19 -> 0 | BE19: =AJ19*BD19 -> 0 | BG19: =AK19*BF19 -> 0 | BI19: =AL19*BH19 -> 0 | BK19: =AM19*BJ19 -> 0
A20: FY23 | B20: Iris Huang | C20: Primax | D20: Commercial | E20: NB | F20: 800 | G20: 2020 | H20: Camellia | I20: BL KB | J20: 15 | K20: Flint Opaque | L20: W China | M20: INVENTEC | N20: 22.15 | O20: 22.15 | P20: 22.15 | Q20: 22.15 | R20: 22.15 | S20: 22.15 | T20: 22.15 | U20: 22.15 | V20: 22.15 | W20: 22.15 | X20: 22.15 | Y20: 22.15 | Z20: 22.15 | AA20: 6.5 | AB20: 7 | AC20: =AB20 -> 7 | AD20: =AC20 -> 7 | AE20: 8.21 | AF20: =AE20 -> 8.21 | AG20: =AF20 -> 8.21 | AH20: =AG20 -> 8.21 | AI20: =AH20 -> 8.21 | AJ20: =AI20 -> 8.21 | AK20: =AJ20 -> 8.21 | AL20: =AK20 -> 8.21 | AM20: =AL20 -> 8.21 | AN20: 16576 | AO20: =AB20*AN20 -> 116032 | AP20: 27267 | AQ20: =AC20*AP20 -> 190869 | AR20: 31380 | AS20: =AD20*AR20 -> 219660 | AT20: 17026 | AU20: =AE20*AT20 -> 139783.46 | AV20: 15760 | AW20: =AF20*AV20 -> 129389.6 | AX20: 14730 | AY20: =AG20*AX20 -> 120933.3 | AZ20: 10114 | BA20: =AH20*AZ20 -> 83035.94 | BB20: 8011 | BC20: =AI20*BB20 -> 65770.31 | BD20: 5790 | BE20: =AJ20*BD20 -> 47535.9 | BF20: 13370 | BG20: =AK20*BF20 -> 109767.7 | BH20: 7110 | BI20: =AL20*BH20 -> 58373.1 | BJ20: 2320 | BK20: =AM20*BJ20 -> 19047.2
A21: FY23 | B21: Iris Huang | C21: Primax | D21: Commercial | E21: NB | G21: 2020 | H21: Camellia | I21: NBL KB | J21: 15 | K21: Flint Opaque | L21: W China | M21: INVENTEC | N21: 11.09 | O21: 11.09 | P21: 11.09 | Q21: 11.09 | R21: 11.09 | S21: 11.09 | T21: 11.09 | U21: 11.09 | V21: 11.09 | W21: 11.09 | X21: 11.09 | Y21: 11.09 | Z21: 11.09 | AA21: 1 | AB21: =AA21 -> 1 | AC21: =AB21 -> 1 | AD21: =AC21 -> 1 | AE21: 1.5 | AF21: =AE21 -> 1.5 | AG21: =AF21 -> 1.5 | AH21: =AG21 -> 1.5 | AI21: =AH21 -> 1.5 | AJ21: =AI21 -> 1.5 | AK21: =AJ21 -> 1.5 | AL21: =AK21 -> 1.5 | AM21: =AL21 -> 1.5 | AN21: 3800 | AO21: =AB21*AN21 -> 3800 | AP21: 2950 | AQ21: =AC21*AP21 -> 2950 | AR21: 5320 | AS21: =AD21*AR21 -> 5320 | AT21: 2674 | AU21: =AE21*AT21 -> 4011 | AV21: 4080 | AW21: =AF21*AV21 -> 6120 | AX21: 3120 | AY21: =AG21*AX21 -> 4680 | AZ21: 3156 | BA21: =AH21*AZ21 -> 4734 | BB21: 1599 | BC21: =AI21*BB21 -> 2398.5 | BD21: 2800 | BE21: =AJ21*BD21 -> 4200 | BF21: 1800 | BG21: =AK21*BF21 -> 2700 | BH21: 480 | BI21: =AL21*BH21 -> 720 | BJ21: 320 | BK21: =AM21*BJ21 -> 480
A22: FY23 | B22: Iris Huang | C22: Primax | D22: Commercial | E22: NB | G22: 2020 | H22: Camellia/Linden | I22: BL KB | J22: 14 | K22: Flint Opaque | L22: W China | M22: INVENTEC | N22: 20.41 | O22: 20.41 | P22: 20.41 | Q22: 20.41 | R22: 20.41 | S22: 20.41 | T22: 20.41 | U22: 20.41 | V22: 20.41 | W22: 20.41 | X22: 20.41 | Y22: 20.41 | Z22: 20.41 | AA22: 4.5 | AB22: 6 | AC22: =AB22 -> 6 | AD22: =AC22 -> 6 | AE22: 6.91 | AF22: =AE22 -> 6.91 | AG22: =AF22 -> 6.91 | AH22: =AG22 -> 6.91 | AI22: =AH22 -> 6.91 | AJ22: =AI22 -> 6.91 | AK22: =AJ22 -> 6.91 | AL22: =AK22 -> 6.91 | AM22: =AL22 -> 6.91 | AN22: 2200 | AO22: =AB22*AN22 -> 13200 | AP22: 8440 | AQ22: =AC22*AP22 -> 50640 | AR22: 278 | AS22: =AD22*AR22 -> 1668 | AT22: 296 | AU22: =AE22*AT22 -> 2045.36 | AV22: 3280 | AW22: =AF22*AV22 -> 22664.8 | AX22: 3385 | AY22: =AG22*AX22 -> 23390.35 | AZ22: 3239 | BA22: =AH22*AZ22 -> 22381.49 | BB22: 2215 | BC22: =AI22*BB22 -> 15305.65 | BD22: 1114 | BE22: =AJ22*BD22 -> 7697.74 | BF22: 1320 | BG22: =AK22*BF22 -> 9121.2 | BH22: 0 | BI22: =AL22*BH22 -> 0 | BJ22: 0 | BK22: =AM22*BJ22 -> 0
A23: FY23 | B23: Iris Huang | C23: Primax | D23: Commercial | E23: NB | G23: 2020 | H23: Camellia/Linden | I23: NBL KB | J23: 14 | K23: Flint Opaque | L23: W China | M23: INVENTEC | N23: 11.02 | O23: 11.02 | P23: 11.02 | Q23: 11.02 | R23: 11.02 | S23: 11.02 | T23: 11.02 | U23: 11.02 | V23: 11.02 | W23: 11.02 | X23: 11.02 | Y23: 11.02 | Z23: 11.02 | AA23: 1 | AB23: 1.11 | AC23: =AB23 -> 1.11 | AD23: =AC23 -> 1.11 | AE23: 1.73 | AF23: =AE23 -> 1.73 | AG23: =AF23 -> 1.73 | AH23: =AG23 -> 1.73 | AI23: =AH23 -> 1.73 | AJ23: =AI23 -> 1.73 | AK23: =AJ23 -> 1.73 | AL23: =AK23 -> 1.73 | AM23: =AL23 -> 1.73 | AN23: 160 | AO23: =AB23*AN23 -> 177.6 | AP23: 2280 | AQ23: =AC23*AP23 -> 2530.8 | AR23: 80 | AS23: =AD23*AR23 -> 88.8 | AT23: 320 | AU23: =AE23*AT23 -> 553.6 | AV23: 240 | AW23: =AF23*AV23 -> 415.2 | AX23: 200 | AY23: =AG23*AX23 -> 346 | AZ23: 0 | BA23: =AH23*AZ23 -> 0 | BB23: 0 | BC23: =AI23*BB23 -> 0 | BD23: 0 | BE23: =AJ23*BD23 -> 0 | BF23: 760 | BG23: =AK23*BF23 -> 1314.8 | BH23: 0 | BI23: =AL23*BH23 -> 0 | BJ23: 0 | BK23: =AM23*BJ23 -> 0
A24: FY23 | B24: Iris Huang | C24: Primax | D24: Commercial | E24: NB | G24: 2020 | H24: Camellia/Linden | I24: BL KB | J24: 13 | K24: Flint Opaque | L24: W China | M24: INVENTEC | N24: 16.17 | O24: 16.17 | P24: 16.17 | Q24: 16.17 | R24: 16.17 | S24: 16.17 | T24: 16.17 | U24: 16.17 | V24: 16.17 | W24: 16.17 | X24: 16.17 | Y24: 16.17 | Z24: 16.17 | AA24: 4.5 | AB24: 6.5 | AC24: =AB24 -> 6.5 | AD24: =AC24 -> 6.5 | AE24: 6.97 | AF24: =AE24 -> 6.97 | AG24: =AF24 -> 6.97 | AH24: =AG24 -> 6.97 | AI24: =AH24 -> 6.97 | AJ24: =AI24 -> 6.97 | AK24: =AJ24 -> 6.97 | AL24: =AK24 -> 6.97 | AM24: =AL24 -> 6.97 | AN24: 38020 | AO24: =AB24*AN24 -> 247130 | AP24: 26816 | AQ24: =AC24*AP24 -> 174304 | AR24: 37580 | AS24: =AD24*AR24 -> 244270 | AT24: 41530 | AU24: =AE24*AT24 -> 289464.1 | AV24: 21950 | AW24: =AF24*AV24 -> 152991.5 | AX24: 17320 | AY24: =AG24*AX24 -> 120720.4 | AZ24: 14170 | BA24: =AH24*AZ24 -> 98764.9 | BB24: 19040 | BC24: =AI24*BB24 -> 132708.8 | BD24: 12580 | BE24: =AJ24*BD24 -> 87682.6 | BF24: 12490 | BG24: =AK24*BF24 -> 87055.3 | BH24: 8120 | BI24: =AL24*BH24 -> 56596.4 | BJ24: 5080 | BK24: =AM24*BJ24 -> 35407.6
A25: FY23 | B25: Iris Huang | C25: Primax | D25: Commercial | E25: NB | G25: 2020 | H25: Camellia/Linden | I25: NBL KB | J25: 13 | K25: Flint Opaque | L25: W China | M25: INVENTEC | N25: 6.78 | O25: 6.78 | P25: 6.78 | Q25: 6.78 | R25: 6.78 | S25: 6.78 | T25: 6.78 | U25: 6.78 | V25: 6.78 | W25: 6.78 | X25: 6.78 | Y25: 6.78 | Z25: 6.78 | AA25: 1 | AB25: 1.53 | AC25: =AB25 -> 1.53 | AD25: =AC25 -> 1.53 | AE25: 1.71 | AF25: =AE25 -> 1.71 | AG25: =AF25 -> 1.71 | AH25: =AG25 -> 1.71 | AI25: =AH25 -> 1.71 | AJ25: =AI25 -> 1.71 | AK25: =AJ25 -> 1.71 | AL25: =AK25 -> 1.71 | AM25: =AL25 -> 1.71 | AN25: 10350 | AO25: =AB25*AN25 -> 15835.5 | AP25: 8132 | AQ25: =AC25*AP25 -> 12441.96 | AR25: 18820 | AS25: =AD25*AR25 -> 28794.6 | AT25: 19110 | AU25: =AE25*AT25 -> 32678.1 | AV25: 22390 | AW25: =AF25*AV25 -> 38286.9 | AX25: 8200 | AY25: =AG25*AX25 -> 14022 | AZ25: 6196 | BA25: =AH25*AZ25 -> 10595.16 | BB25: 11220 | BC25: =AI25*BB25 -> 19186.2 | BD25: 5480 | BE25: =AJ25*BD25 -> 9370.8 | BF25: 10180 | BG25: =AK25*BF25 -> 17407.8 | BH25: 6510 | BI25: =AL25*BH25 -> 11132.1 | BJ25: 1080 | BK25: =AM25*BJ25 -> 1846.8
A26: FY23 | B26: Iris Huang | C26: Primax | D26: Commercial | E26: NB | G26: 2022 | H26: G9 Warpath/Warpath W/Lockheed/Firefly | I26: BL KB | J26: 16 | K26: Flint Opaque | L26: W China | M26: INVENTEC | N26: =17.3-1 -> 16.3 | O26: =17.3-1 -> 16.3 | P26: =17.3-1 -> 16.3 | Q26: =17.3-1 -> 16.3 | R26: =17.3-1 -> 16.3 | S26: =17.3-1 -> 16.3 | T26: =17.3-1 -> 16.3 | U26: =17.3-1 -> 16.3 | ... Z26: =17.3-1 -> 16.3 | AA26: 3.5 | AB26: =AA26 -> 3.5 | AC26: =AB26 -> 3.5 | AD26: =AC26 -> 3.5 | AE26: 4 | AF26: =AE26 -> 4 | AG26: =AF26 -> 4 | AH26: =AG26 -> 4 | AI26: =AH26 -> 4 | AJ26: =AI26 -> 4 | AK26: =AJ26 -> 4 | AL26: 5 | AM26: 5 | AN26: 8520 | AO26: =AB26*AN26 -> 29820 | AP26: 11481 | AQ26: =AC26*AP26 -> 40183.5 | AR26: 17120 | AS26: =AD26*AR26 -> 59920 | AT26: 12520 | AU26: =AE26*AT26 -> 50080 | AV26: 19818 | AW26: =AF26*AV26 -> 79272 | AX26: 14130 | AY26: =AG26*AX26 -> 56520 | AZ26: 19709 | BA26: =AH26*AZ26 -> 78836 | BB26: 13717 | BC26: =AI26*BB26 -> 54868 | BD26: 17237 | BE26: =AJ26*BD26 -> 68948 | BF26: 8169 | BG26: =AK26*BF26 -> 32676 | BH26: 4800 | BI26: =AL26*BH26 -> 24000 | BJ26: 4560 | BK26: =AM26*BJ26 -> 22800
A27: FY23 | B27: Iris Huang | C27: Primax | D27: Commercial | E27: NB | G27: 2022 | H27: G9 Warpath/Warpath W/Lockheed/Firefly | I27: NBL KB | J27: 16 | K27: Flint Opaque | L27: W China | M27: INVENTEC | N27: =6.95-0.7 -> 6.25 | O27: =6.95-0.7 -> 6.25 | P27: =6.95-0.7 -> 6.25 | Q27: =6.95-0.7 -> 6.25 | R27: =6.95-0.7 -> 6.25 | S27: =6.95-0.7 -> 6.25 | T27: =6.95-0.7 -> 6.25 | U27: =6.95-0.7 -> 6.25 | ... Z27: =6.95-0.7 -> 6.25 | AA27: 0.6 | AB27: =AA27 -> 0.6 | AC27: =AB27 -> 0.6 | AD27: =AC27 -> 0.6 | AE27: =AD27 -> 0.6 | AF27: =AE27 -> 0.6 | AG27: =AF27 -> 0.6 | AH27: =AG27 -> 0.6 | AI27: =AH27 -> 0.6 | ... AM27: =AL27 -> 0.6 | AN27: 960 | AO27: =AB27*AN27 -> 576 | AP27: 839 | AQ27: =AC27*AP27 -> 503.4 | AR27: 1080 | AS27: =AD27*AR27 -> 648 | AT27: 1080 | AU27: =AE27*AT27 -> 648 | AV27: 1719 | AW27: =AF27*AV27 -> 1031.4 | AX27: 760 | AY27: =AG27*AX27 -> 456 | AZ27: 1440 | BA27: =AH27*AZ27 -> 864 | BB27: 1559 | BC27: =AI27*BB27 -> 935.4 | BD27: 674 | BE27: =AJ27*BD27 -> 404.4 | BF27: 1320 | BG27: =AK27*BF27 -> 792 | BH27: 598 | BI27: =AL27*BH27 -> 358.8 | BJ27: 520 | BK27: =AM27*BJ27 -> 312
A28: FY23 | B28: Iris Huang | C28: Primax | D28: Commercial | E28: NB | G28: 2022 | H28: G9 Warpath/Warpath W/Lockheed/ Firefly | I28: BL KB | J28: 14 | K28: Flint Opaque | L28: W China | M28: INVENTEC | N28: =15.6-1 -> 14.6 | O28: =15.6-1 -> 14.6 | P28: =15.6-1 -> 14.6 | Q28: =15.6-1 -> 14.6 | R28: =15.6-1 -> 14.6 | S28: =15.6-1 -> 14.6 | T28: =15.6-1 -> 14.6 | U28: =15.6-1 -> 14.6 | ... Z28: =15.6-1 -> 14.6 | AA28: 3 | AB28: 3.47 | AC28: =AB28 -> 3.47 | AD28: =AC28 -> 3.47 | AE28: 4.42 | AF28: =AE28 -> 4.42 | AG28: =AF28 -> 4.42 | AH28: =AG28 -> 4.42 | AI28: =AH28 -> 4.42 | AJ28: =AI28 -> 4.42 | AK28: =AJ28 -> 4.42 | AL28: =AK28 -> 4.42 | AM28: =AL28 -> 4.42 | AN28: 33460 | AO28: =AB28*AN28 -> 116106.2 | AP28: 28683 | AQ28: =AC28*AP28 -> 99530.01 | AR28: 37660 | AS28: =AD28*AR28 -> 130680.2 | AT28: 36380 | AU28: =AE28*AT28 -> 160799.6 | AV28: 54487 | AW28: =AF28*AV28 -> 240832.54 | AX28: 43873 | AY28: =AG28*AX28 -> 193918.66 | AZ28: 42034 | BA28: =AH28*AZ28 -> 185790.28 | BB28: 40545 | BC28: =AI28*BB28 -> 179208.9 | BD28: 26615 | BE28: =AJ28*BD28 -> 117638.3 | BF28: 24500 | BG28: =AK28*BF28 -> 108290 | BH28: 25870 | BI28: =AL28*BH28 -> 114345.4 | BJ28: 19720 | BK28: =AM28*BJ28 -> 87162.4
A29: FY23 | B29: Iris Huang | C29: Primax | D29: Commercial | E29: NB | G29: 2022 | H29: G9 Warpath/Warpath W/Lockheed/ Firefly | I29: NBL KB | J29: 14 | K29: Flint Opaque | L29: W China | M29: INVENTEC | N29: =6.85-0.7 -> 6.15 | O29: =6.85-0.7 -> 6.15 | P29: =6.85-0.7 -> 6.15 | Q29: =6.85-0.7 -> 6.15 | R29: =6.85-0.7 -> 6.15 | S29: =6.85-0.7 -> 6.15 | T29: =6.85-0.7 -> 6.15 | U29: =6.85-0.7 -> 6.15 | ... Z29: =6.85-0.7 -> 6.15 | AA29: 0.8 | AB29: =AA29 -> 0.8 | AC29: =AB29 -> 0.8 | AD29: =AC29 -> 0.8 | AE29: 1.06 | AF29: =AE29 -> 1.06 | AG29: =AF29 -> 1.06 | AH29: =AG29 -> 1.06 | AI29: =AH29 -> 1.06 | AJ29: =AI29 -> 1.06 | AK29: =AJ29 -> 1.06 | AL29: =AK29 -> 1.06 | AM29: =AL29 -> 1.06 | AN29: 2400 | AO29: =AB29*AN29 -> 1920 | AP29: 1356 | AQ29: =AC29*AP29 -> 1084.8 | AR29: 3032 | AS29: =AD29*AR29 -> 2425.6 | AT29: 2720 | AU29: =AE29*AT29 -> 2883.2 | AV29: 3960 | AW29: =AF29*AV29 -> 4197.6 | AX29: 2080 | AY29: =AG29*AX29 -> 2204.8 | AZ29: 3800 | BA29: =AH29*AZ29 -> 4028 | BB29: 4920 | BC29: =AI29*BB29 -> 5215.2 | BD29: 3376 | BE29: =AJ29*BD29 -> 3578.56 | BF29: 3500 | BG29: =AK29*BF29 -> 3710 | BH29: 4800 | BI29: =AL29*BH29 -> 5088 | BJ29: 4012 | BK29: =AM29*BJ29 -> 4252.72
A30: FY23 | B30: Iris Huang | C30: Primax | D30: Commercial | E30: NB | G30: 2023 | H30: G10 Warg/Warg W/ Lox | I30: BL KB | J30: 16 | K30: Flint Opaque | L30: W China | M30: INVENTEC | N30: =N26+0.26 -> 16.56 | O30: =O26+0.26 -> 16.56 | P30: =P26+0.26 -> 16.56 | Q30: =Q26+0.26 -> 16.56 | R30: =R26+0.26 -> 16.56 | S30: =S26+0.26 -> 16.56 | T30: =T26+0.26 -> 16.56 | U30: =U26+0.26 -> 16.56 | ... Z30: =Z26+0.26 -> 16.56 | AA30: 0 | AB30: 0 | AC30: 0 | AD30: 0 | AE30: 0 | AF30: 0 | AG30: 0 | AH30: 4 | AI30: 4 | AJ30: 4 | AK30: 4 | AL30: 5 | AM30: 5 | AZ30: 6160 | BA30: =AH30*AZ30 -> 24640 | BB30: 14546 | BC30: =AI30*BB30 -> 58184 | BD30: 13183 | BE30: =AJ30*BD30 -> 52732 | BF30: 14848 | BG30: =AK30*BF30 -> 59392 | BH30: 23120 | BI30: =AL30*BH30 -> 115600 | BJ30: 18960 | BK30: =AM30*BJ30 -> 94800
A31: FY23 | B31: Iris Huang | C31: Primax | D31: Commercial | E31: NB | G31: 2023 | H31: G10 Warg/Warg W/ Lox | I31: NBL KB | J31: 16 | K31: Flint Opaque | L31: W China | M31: INVENTEC | N31: =N27+0.17 -> 6.42 | O31: =O27+0.17 -> 6.42 | P31: =P27+0.17 -> 6.42 | Q31: =Q27+0.17 -> 6.42 | R31: =R27+0.17 -> 6.42 | S31: =S27+0.17 -> 6.42 | T31: =T27+0.17 -> 6.42 | U31: =U27+0.17 -> 6.42 | ... Z31: =Z27+0.17 -> 6.42 | AA31: 0 | AB31: 0 | AC31: 0 | AD31: 0 | AE31: 0 | AF31: 0 | AG31: 0 | AH31: 0.6 | AI31: 0.6 | AJ31: 0.6 | AK31: 0.6 | AL31: =AK31 -> 0.6 | AM31: =AL31 -> 0.6 | AZ31: 280 | BA31: =AH31*AZ31 -> 168 | BB31: 1120 | BC31: =AI31*BB31 -> 672 | BD31: 2606 | BE31: =AJ31*BD31 -> 1563.6 | BF31: 2000 | BG31: =AK31*BF31 -> 1200 | BH31: 1592 | BI31: =AL31*BH31 -> 955.2 | BJ31: 1480 | BK31: =AM31*BJ31 -> 888
A32: FY23 | B32: Iris Huang | C32: Primax | D32: Commercial | E32: NB | G32: 2023 | H32: G10 Warg/Warg W/ Lox | I32: BL KB | J32: 14 | K32: Flint Opaque | L32: W China | M32: INVENTEC | N32: =N28+0.26 -> 14.86 | O32: =O28+0.26 -> 14.86 | P32: =P28+0.26 -> 14.86 | Q32: =Q28+0.26 -> 14.86 | R32: =R28+0.26 -> 14.86 | S32: =S28+0.26 -> 14.86 | T32: =T28+0.26 -> 14.86 | U32: =U28+0.26 -> 14.86 | ... Z32: =Z28+0.26 -> 14.86 | AA32: 0 | AB32: 0 | AC32: 0 | AD32: 0 | AE32: 0 | AF32: 0 | AG32: 0 | AH32: 4.42 | AI32: 4.42 | AJ32: 4.42 | AK32: 4.42 | AL32: =AK32 -> 4.42 | AM32: =AL32 -> 4.42 | AZ32: 7040 | BA32: =AH32*AZ32 -> 31116.8 | BB32: 23150 | BC32: =AI32*BB32 -> 102323 | BD32: 24315 | BE32: =AJ32*BD32 -> 107472.3 | BF32: 37598 | BG32: =AK32*BF32 -> 166183.16 | BH32: 48426 | BI32: =AL32*BH32 -> 214042.92 | BJ32: 62654 | BK32: =AM32*BJ32 -> 276930.68
A33: FY23 | B33: Iris Huang | C33: Primax | D33: Commercial | E33: NB | G33: 2023 | H33: G10 Warg/Warg W/ Lox | I33: NBL KB | J33: 14 | K33: Flint Opaque | L33: W China | M33: INVENTEC | N33: =N29+0.17 -> 6.32 | O33: =O29+0.17 -> 6.32 | P33: =P29+0.17 -> 6.32 | Q33: =Q29+0.17 -> 6.32 | R33: =R29+0.17 -> 6.32 | S33: =S29+0.17 -> 6.32 | T33: =T29+0.17 -> 6.32 | U33: =U29+0.17 -> 6.32 | ... Z33: =Z29+0.17 -> 6.32 | AA33: 0 | AB33: 0 | AC33: 0 | AD33: 0 | AE33: 0 | AF33: 0 | AG33: 0 | AH33: 1.06 | AI33: 1.06 | AJ33: 1.06 | AK33: 1.06 | AL33: =AK33 -> 1.06 | AM33: =AL33 -> 1.06 | AZ33: 240 | BA33: =AH33*AZ33 -> 254.4 | BB33: 1040 | BC33: =AI33*BB33 -> 1102.4 | BD33: 904 | BE33: =AJ33*BD33 -> 958.24 | BF33: 1958 | BG33: =AK33*BF33 -> 2075.48 | BH33: 2039 | BI33: =AL33*BH33 -> 2161.34 | BJ33: 2318 | BK33: =AM33*BJ33 -> 2457.08
A34: FY23 | AC34: =AB34 -> 0 | AF34: =AE34 -> 0 | AG34: =AF34 -> 0 | AH34: =AG34 -> 0 | AI34: =AH34 -> 0 | AJ34: =AI34 -> 0 | AK34: =AJ34 -> 0 | AL34: =AK34 -> 0 | AM34: =AL34 -> 0 | AO34: =AB34*AN34 -> 0 | AQ34: =AC34*AP34 -> 0 | AS34: =AD34*AR34 -> 0 | AU34: =AE34*AT34 -> 0 | AW34: =AF34*AV34 -> 0 | AY34: =AG34*AX34 -> 0 | BA34: =AH34*AZ34 -> 0 | BC34: =AI34*BB34 -> 0 | BE34: =AJ34*BD34 -> 0 | BG34: =AK34*BF34 -> 0 | BI34: =AL34*BH34 -> 0 | BK34: =AM34*BJ34 -> 0
A35: FY23 | B35: Iris Huang | C35: Primax | D35: Commercial | E35: NB | F35: 1000 | G35: 2022 | H35: G3 Starfox | I35: BL KB | J35: 13 | K35: Sentry Black | L35: W China | M35: INVENTEC | N35: 17.3 | O35: 17.3 | P35: 17.3 | Q35: 17.3 | R35: 17.3 | S35: 17.3 | T35: 17.3 | U35: 17.3 | V35: 17.3 | W35: 17.3 | X35: 17.3 | Y35: 17.3 | Z35: 17.3 | AA35: 4 | AB35: =AA35 -> 4 | AC35: =AB35 -> 4 | AD35: =AC35 -> 4 | AE35: 4.5 | AF35: =AE35 -> 4.5 | AG35: =AF35 -> 4.5 | AH35: =AG35 -> 4.5 | AI35: =AH35 -> 4.5 | AJ35: =AI35 -> 4.5 | AK35: =AJ35 -> 4.5 | AL35: 5 | AM35: 5 | AN35: 475 | AO35: =AB35*AN35 -> 1900 | AP35: 2170 | AQ35: =AC35*AP35 -> 8680 | AR35: 1170 | AS35: =AD35*AR35 -> 4680 | AT35: 440 | AU35: =AE35*AT35 -> 1980 | AV35: 240 | AW35: =AF35*AV35 -> 1080 | AX35: 160 | AY35: =AG35*AX35 -> 720 | AZ35: 120 | BA35: =AH35*AZ35 -> 540 | BB35: 160 | BC35: =AI35*BB35 -> 720 | BD35: 80 | BE35: =AJ35*BD35 -> 360 | BF35: 320 | BG35: =AK35*BF35 -> 1440 | BH35: 240 | BI35: =AL35*BH35 -> 1200 | BJ35: 320 | BK35: =AM35*BJ35 -> 1600
A36: FY23 | B36: Iris Huang | C36: Primax | D36: Commercial | E36: NB | G36: 2022 | H36: G3 Starfox | I36: BL KB | J36: 13 | K36: Slate Blue | L36: W China | M36: INVENTEC | N36: 18.65 | O36: 18.65 | P36: 18.65 | Q36: 18.65 | R36: 18.65 | S36: 18.65 | T36: 18.65 | U36: 18.65 | V36: 18.65 | W36: 18.65 | X36: 18.65 | Y36: 18.65 | Z36: 18.65 | AA36: 4 | AB36: =AA36 -> 4 | AC36: =AB36 -> 4 | AD36: =AC36 -> 4 | AE36: 4.5 | AF36: =AE36 -> 4.5 | AG36: =AF36 -> 4.5 | AH36: =AG36 -> 4.5 | AI36: =AH36 -> 4.5 | AJ36: =AI36 -> 4.5 | AK36: =AJ36 -> 4.5 | AL36: 5.2 | AM36: 5.2 | AN36: 1000 | AO36: =AB36*AN36 -> 4000 | AP36: 3039 | AQ36: =AC36*AP36 -> 12156 | AR36: 2039 | AS36: =AD36*AR36 -> 8156 | AT36: 680 | AU36: =AE36*AT36 -> 3060 | AV36: 2600 | AW36: =AF36*AV36 -> 11700 | AX36: 1280 | AY36: =AG36*AX36 -> 5760 | AZ36: 1400 | BA36: =AH36*AZ36 -> 6300 | BB36: 2595 | BC36: =AI36*BB36 -> 11677.5 | BD36: 1320 | BE36: =AJ36*BD36 -> 5940 | BF36: 2400 | BG36: =AK36*BF36 -> 10800 | BH36: 6400 | BI36: =AL36*BH36 -> 33280 | BJ36: 5800 | BK36: =AM36*BJ36 -> 30160
A37: FY23 | AC37: =AB37 -> 0 | AF37: =AE37 -> 0 | AG37: =AF37 -> 0 | AH37: =AG37 -> 0 | AI37: =AH37 -> 0 | AJ37: =AI37 -> 0 | AK37: =AJ37 -> 0 | AL37: =AK37 -> 0 | AM37: =AL37 -> 0 | AO37: =AB37*AN37 -> 0 | AQ37: =AC37*AP37 -> 0 | AS37: =AD37*AR37 -> 0 | AU37: =AE37*AT37 -> 0 | AW37: =AF37*AV37 -> 0 | AY37: =AG37*AX37 -> 0 | BA37: =AH37*AZ37 -> 0 | BC37: =AI37*BB37 -> 0 | BE37: =AJ37*BD37 -> 0 | BG37: =AK37*BF37 -> 0 | BI37: =AL37*BH37 -> 0 | BK37: =AM37*BJ37 -> 0
A38: FY23 | AC38: =AB38 -> 0 | AF38: =AE38 -> 0 | AG38: =AF38 -> 0 | AH38: =AG38 -> 0 | AI38: =AH38 -> 0 | AJ38: =AI38 -> 0 | AK38: =AJ38 -> 0 | AL38: =AK38 -> 0 | AM38: =AL38 -> 0 | AO38: =AB38*AN38 -> 0 | AQ38: =AC38*AP38 -> 0 | AS38: =AD38*AR38 -> 0 | AU38: =AE38*AT38 -> 0 | AW38: =AF38*AV38 -> 0 | AY38: =AG38*AX38 -> 0 | BA38: =AH38*AZ38 -> 0 | BC38: =AI38*BB38 -> 0 | BE38: =AJ38*BD38 -> 0 | BG38: =AK38*BF38 -> 0 | BI38: =AL38*BH38 -> 0 | BK38: =AM38*BJ38 -> 0
A39: FY23 | F39: Probook | AC39: =AB39 -> 0 | AF39: =AE39 -> 0 | AG39: =AF39 -> 0 | AH39: =AG39 -> 0 | AI39: =AH39 -> 0 | AJ39: =AI39 -> 0 | AK39: =AJ39 -> 0 | AL39: =AK39 -> 0 | AM39: =AL39 -> 0 | AO39: =AB39*AN39 -> 0 | AQ39: =AC39*AP39 -> 0 | AS39: =AD39*AR39 -> 0 | AU39: =AE39*AT39 -> 0 | AW39: =AF39*AV39 -> 0 | AY39: =AG39*AX39 -> 0 | BA39: =AH39*AZ39 -> 0 | BC39: =AI39*BB39 -> 0 | BE39: =AJ39*BD39 -> 0 | BG39: =AK39*BF39 -> 0 | BI39: =AL39*BH39 -> 0 | BK39: =AM39*BJ39 -> 0
A40: FY23 | AC40: =AB40 -> 0 | AF40: =AE40 -> 0 | AG40: =AF40 -> 0 | AH40: =AG40 -> 0 | AI40: =AH40 -> 0 | AJ40: =AI40 -> 0 | AK40: =AJ40 -> 0 | AL40: =AK40 -> 0 | AM40: =AL40 -> 0 | AO40: =AB40*AN40 -> 0 | AQ40: =AC40*AP40 -> 0 | AS40: =AD40*AR40 -> 0 | AU40: =AE40*AT40 -> 0 | AW40: =AF40*AV40 -> 0 | AY40: =AG40*AX40 -> 0 | BA40: =AH40*AZ40 -> 0 | BC40: =AI40*BB40 -> 0 | BE40: =AJ40*BD40 -> 0 | BG40: =AK40*BF40 -> 0 | BI40: =AL40*BH40 -> 0 | BK40: =AM40*BJ40 -> 0
...

Sheet FY24 Summary_1
B3: Primax | C3: 2023 11 | D3: 2023 12 | E3: 2024 01 | F3: Total Q1
B4: Rebate amount | C4: ='FY24'!AP1 -> 1455240.2 | D4: ='FY24'!AR1 -> 1297732.2 | E4: ='FY24'!AT1 -> 1009232.9 | F4: =SUM(C4:E4) -> 3762205.4
B5: E&O reduction | C5: 0 | D5: 0 | E5: =47291.37*20% -> 9458.274 | F5: =SUM(C5:E5) -> 9458.274
B6: Complexity reduction | C6: 0 | D6: 0 | E6: 0 | F6: =SUM(C6:E6) -> 0 | H6: 1. 新增Summary_1, 原先的Summary重新命名為Summary_2
B7: Total amount | C7: =SUM(C4:C6) -> 1455240.2 | D7: =SUM(D4:D6) -> 1297732.2 | E7: =SUM(E4:E6) -> 1018691.2 | F7: =SUM(F4:F6) -> 3771663.6
H8: 2.黃色部位為貴司名稱, 請整份報告都跟檔名貴司名稱撰寫方式一致
B10: Primax | C10: 2024 02 | D10: 2024 03 | E10: 2024 04 | F10: Total Q2 | H10: 3. 這些欄位一定要固定, B3-B28, C3-C28, D3-D28, E3-E28, F3-F28都有賦予定義
B11: Rebate amount | C11: ='FY24'!AV1 -> 913750.01 | D11: ='FY24'!AX1 -> 1273934.4 | E11: ='FY24'!AZ1 -> 1187669.8 | F11: =SUM(C11:E11) -> 3375354.2
B12: E&O reduction | C12: 0 | D12: 0 | E12: 0 | F12: =SUM(C12:E12) -> 0 | H12: 4. Rebate amount 指得是summary_2的page金額 (就是我們一直以來收集的金額)
B13: Complexity reduction | C13: 0 | D13: 0 | E13: 0 | F13: =SUM(C13:E13) -> 0
B14: Total amount | C14: =SUM(C11:C13) -> 913750.01 | D14: =SUM(D11:D13) -> 1273934.4 | E14: =SUM(E11:E13) -> 1187669.8 | F14: =SUM(F11:F13) -> 3375354.2 | H14: 5. 新增 E&O reduction 及complexity reduction品項, 先留足空間
H15: 若目前還未有此款項存在都先填0
B17: Primax | C17: 2024 05 | D17: 2024 06 | E17: 2024 07 | F17: Total Q3 | H17: 6. 金額都放未經調整後的真實數字, 分析才具意義
B18: Rebate amount | C18: ='FY24'!BB1 -> 1527709.2 | D18: ='FY24'!BD1 -> 1759003.9 | E18: ='FY24'!BF1 -> 1510030.6 | F18: =SUM(C18:E18) -> 4796743.7
B19: E&O reduction | C19: 141204.37 | D19: 50128.95 | E19: 0 | F19: =SUM(C19:E19) -> 191333.32
B20: Complexity reduction | C20: 0 | D20: 0 | E20: 0 | F20: =SUM(C20:E20) -> 0
B21: Total amount | C21: =SUM(C18:C20) -> 1668913.6 | D21: =SUM(D18:D20) -> 1809132.8 | E21: =SUM(E18:E20) -> 1510030.6 | F21: =SUM(F18:F20) -> 4988077
B24: Primax | C24: 2024 08 | D24: 2024 09 | E24: 2024 10 | F24: Total Q4
B25: Rebate amount | C25: ='FY24'!BH1 -> 1349175.5 | D25: ='FY24'!BJ1 -> 1696123 | E25: ='FY24'!BL1 -> 1426855.9 | F25: =SUM(C25:E25) -> 4472154.4
B26: E&O reduction | C26: 17098.64 | D26: 0 | E26: 41617.84 | F26: =SUM(C26:E26) -> 58716.48
B27: Complexity reduction | C27: 0 | D27: 0 | E27: 0 | F27: =SUM(C27:E27) -> 0
B28: Total amount | C28: =SUM(C25:C27) -> 1366274.1 | D28: =SUM(D25:D27) -> 1696123 | E28: =SUM(E25:E27) -> 1468473.7 | F28: =SUM(F25:F27) -> 4530870.9

Sheet FY24 Summary_2
B3: Q1 Actual by Segment
C4: Segment | D4: 45231 | E4: 45261 | F4: 45292 | G4: Total Rebate in Q1 2024 (US$)
B5: CMIT Input Devices | C5: 200 series (6U) | D5: =SUM('FY24'!AP3:AP5)+SUM('FY24'!AP115:AP149)*0.25 -> 60832.265 | E5: =SUM('FY24'!AR3:AR5)+SUM('FY24'!AR115:AR149)*0.25 -> 63143.69 | F5: =SUM('FY24'!AT3:AT5)+SUM('FY24'!AT115:AT149)*0.25 -> 46957.1 | G5: =SUM(D5:F5) -> 170933.05
C6: 400 series (S) | D6: 0 | E6: 0 | F6: 0 | G6: =SUM(D6:F6) -> 0
C7: 600 series (B) | D7: 0 | E7: 0 | F7: 0 | G7: =SUM(D7:F7) -> 0
C8: 800 series (P) | D8: =SUM('FY24'!AP20:AP40) -> 364313.86 | E8: =SUM('FY24'!AR20:AR40) -> 249507.55 | F8: =SUM('FY24'!AT20:AT40) -> 239916.46 | G8: =SUM(D8:F8) -> 853737.87
C9: 1000 series (M | D9: =SUM('FY24'!AP41:AP44) -> 39166 | E9: =SUM('FY24'!AR41:AR44) -> 37733.6 | F9: =SUM('FY24'!AT41:AT44) -> 25016 | G9: =SUM(D9:F9) -> 101915.6
C10: MWS (Workstation) | D10: =SUM('FY24'!AP49:AP50) -> 58800 | E10: =SUM('FY24'!AR49:AR50) -> 58200 | F10: =SUM('FY24'!AT49:AT50) -> 30400 | G10: =SUM(D10:F10) -> 147400
C11: Soft Keyboard | D11: 0 | E11: 0 | F11: 0 | G11: =SUM(D11:F11) -> 0
C12: Chrome Book | D12: =SUM('FY24'!AP55:AP61) -> 4040 | E12: =SUM('FY24'!AR55:AR61) -> 5497.5 | F12: =SUM('FY24'!AT55:AT61) -> 2920 | G12: =SUM(D12:F12) -> 12457.5
C13: Clickpad | D13: 0 | E13: 0 | F13: 0 | G13: =SUM(D13:F13) -> 0
C14: Education | D14: =SUM('FY24'!AP47:AP48) -> 420 | E14: =SUM('FY24'!AR47:AR48) -> 630 | F14: =SUM('FY24'!AT47:AT48) -> 501.9 | G14: =SUM(D14:F14) -> 1551.9
C15: Peripherals/AMO | D15: =SUM('FY24'!AP304:AP327) -> 19869.6 | E15: =SUM('FY24'!AR304:AR327) -> 63934.44 | F15: =SUM('FY24'!AT304:AT327) -> 67631.44 | G15: =SUM(D15:F15) -> 151435.48
C16: Desktop | D16: =SUM('FY24'!AP62:AP84) -> 60842.46 | E16: =SUM('FY24'!AR62:AR84) -> 130721.04 | F16: =SUM('FY24'!AT62:AT84) -> 160802.56 | G16: =SUM(D16:F16) -> 352366.06
B17: Consumer Input Devices | C17: OPP | D17: =SUM('FY24'!AP85:AP114)+SUM('FY24'!AP115:AP149)*0.75 -> 238173.33 | E17: =SUM('FY24'!AR85:AR114)+SUM('FY24'!AR115:AR149)*0.75 -> 334061.67 | F17: =SUM('FY24'!AT85:AT114)+SUM('FY24'!AT115:AT149)*0.75 -> 176720.06 | G17: =SUM(D17:F17) -> 748955.06
C18: Chrome Book | D18: =SUM('FY24'!AP150:AP169) -> 27475.29 | E18: =SUM('FY24'!AR150:AR169) -> 1730.4 | F18: =SUM('FY24'!AT150:AT169) -> 6341.2 | G18: =SUM(D18:F18) -> 35546.89
C19: Pavillion | D19: =SUM('FY24'!AP170:AP205) -> 419935.3 | E19: =SUM('FY24'!AR170:AR205) -> 209434.8 | F19: =SUM('FY24'!AT170:AT205) -> 104351.85 | G19: =SUM(D19:F19) -> 733721.95
C20: Spectre | D20: 0 | E20: 0 | F20: 0 | G20: =SUM(D20:F20) -> 0
C21: Envy | D21: =SUM('FY24'!AP216:AP225) -> 40173 | E21: =SUM('FY24'!AR216:AR225) -> 57639 | F21: =SUM('FY24'!AT216:AT225) -> 51018 | G21: =SUM(D21:F21) -> 148830
C22: Stream | D22: 0 | E22: 0 | F22: 0 | G22: =SUM(D22:F22) -> 0
C23: Omen | D23: =SUM('FY24'!AP228:AP254) -> 28686.4 | E23: =SUM('FY24'!AR228:AR254) -> 15183.1 | F23: =SUM('FY24'!AT228:AT254) -> 25003.14 | G23: =SUM(D23:F23) -> 68872.64
C24: Peripherals/AMO | D24: =SUM('FY24'!AP288:AP303) -> 9537.16 | E24: =SUM('FY24'!AR288:AR303) -> 22906.4 | F24: =SUM('FY24'!AT288:AT303) -> 33744.2 | G24: =SUM(D24:F24) -> 66187.76
C25: Desktop | D25: =SUM('FY24'!AP255:AP287) -> 82975.5 | E25: =SUM('FY24'!AR255:AR287) -> 47409.06 | F25: =SUM('FY24'!AT255:AT287) -> 37909.03 | G25: =SUM(D25:F25) -> 168293.59
G26: =SUM(G5:G25) -> 3762205.4
B28: Q1 Actual by Segment
C29: Supplier | D29: 45231 | E29: 45261 | F29: 45292 | G29: Total Rebate in Q1 2024 (US$)
B30: Input Devices | C30: Acrox
C31: Chicony
C32: Darfon
C33: Liteon
C34: Primax | D34: =SUM(D5:D25) -> 1455240.2 | E34: =SUM(E5:E25) -> 1297732.2 | F34: =SUM(F5:F25) -> 1009232.9 | G34: =SUM(D34:F34) -> 3762205.4
C35: Sunrex
F36: Total Rebate Amount
B39: Q2 Actual by Segment
C40: Segment | D40: 45323 | E40: 45352 | F40: 45383 | G40: Total Rebate in Q2 2024 (US$)
B41: CMIT Input Devices | C41: 200 series (6U) | D41: =SUM('FY24'!AV115:AV149)*0.25 -> 28099.5 | E41: =SUM('FY24'!AX115:AX149)*0.25 -> 42767.6 | F41: =SUM('FY24'!AZ115:AZ149)*0.25 -> 21702 | G41: =SUM(D41:F41) -> 92569.1
C42: 400 series (S) | D42: 0 | E42: =SUM('FY24'!AX6:AX9) -> 0 | F42: =SUM('FY24'!AZ6:AZ9) -> 0 | G42: =SUM(D42:F42) -> 0
C43: 600 series (B) | D43: 0 | E43: 0 | F43: 0 | G43: =SUM(D43:F43) -> 0
C44: 800 series (P) | D44: =SUM('FY24'!AV20:AV40) -> 264543.92 | E44: =SUM('FY24'!AX20:AX40) -> 386081.68 | F44: =SUM('FY24'!AZ20:AZ40) -> 424280.28 | G44: =SUM(D44:F44) -> 1074905.9
C45: 1000 series (M | D45: =SUM('FY24'!AV41:AV44) -> 23320 | E45: =SUM('FY24'!AX41:AX44) -> 26620 | F45: =SUM('FY24'!AZ41:AZ44) -> 10956 | G45: =SUM(D45:F45) -> 60896
...

Sheet FY24
D1: Consumer/Commercial/ Peripheral | E1: NB/DT/Peripheral | G1: 2020/2021/2022 | H1: Remove Size/Color, define Platform naming Hagrid/Hedwig/Granger/Ashmore/Ramla (follow naming rule of product list) | I1: NBL KB/BL KB/Mouse /Combo/Clickpad/Others | J1: NA/ | K1: NA/ | L1: (E China/W China/S China/NMC) | M1: COMPAL/ QUANTA /INVENTEC /WISTRON/ FOXCONN/ OTHERS | AP1: =SUM(AP3:AP327) -> 1455240.2 | AR1: =SUM(AR3:AR327) -> 1297732.2 | AT1: =SUM(AT3:AT327) -> 1009232.9 | AV1: =SUM(AV3:AV327) -> 913750.01 | AX1: =SUM(AX3:AX327) -> 1273934.4 | AZ1: =SUM(AZ3:AZ327) -> 1187669.8 | BB1: =SUM(BB3:BB327) -> 1527709.2 | BD1: =SUM(BD3:BD327) -> 1759003.9 | BF1: =SUM(BF3:BF327) -> 1510030.6 | BH1: =SUM(BH3:BH327) -> 1349175.5 | BJ1: =SUM(BJ3:BJ327) -> 1696123 | BL1: =SUM(BL3:BL327) -> 1426855.9 | BN1: =SUM(AP1:BL1) -> 16406458 | BO1: NA/EMEA/APJ
A2: FY24 | B2: SPM (Project Owner) | C2: GTK Suppliers | D2: Category | E2: Segment | F2: Series | G2: Production Year | H2: Platforms | I2: Product | J2: Size | K2: Color | L2: Location | M2: ODM | N2: RFQ Final Cost | O2: The lowest unit table price (ODM cost) | P2: Table Price Nov | Q2: Table Price Dec | R2: Table Price Jan | S2: Table Price Feb | T2: Table Price Mar | U2: Table Price Apr | V2: Table Price May | W2: Table Price Jun | X2: Table Price Jul | Y2: Table Price Aug | Z2: Table Price Sep | AA2: Table Price Oct | AB2: The lowest unit rebate cost | AC2: Unit Rebate Nov | AD2: Unit Rebate Dec | AE2: Unit Rebate Jan | AF2: Unit Rebate Feb | AG2: Unit Rebate Mar | AH2: Unit Rebate Apr | AI2: Unit Rebate May | AJ2: Unit Rebate Jun | AK2: Unit Rebate Jul | AL2: Unit Rebate Aug | AM2: Unit Rebate Sep | AN2: Unit Rebate Oct | AO2: Nov Q'ty | AP2: Nov Rebate Amount | AQ2: Dec Q'ty | AR2: Dec Rebate Amount | AS2: Jan Q'ty | AT2: Jan Rebate Amount | AU2: Feb Q'ty | AV2: Feb Rebate Amount | AW2: Mar Q'ty | AX2: Mar Rebate Amount | AY2: Apr Q'ty | AZ2: Apr Rebate Amount | BA2: May Q'ty | BB2: May Rebate Amount | BC2: Jun Q'ty | BD2: Jun Rebate Amount | BE2: Jul Q'ty | BF2: Jul Rebate Amount | BG2: Aug Q'ty | BH2: Aug Rebate Amount | BI2: Sep Q'ty | BJ2: Sep Rebate Amount | BK2: Oct Q'ty | BL2: Oct Rebate Amount | BM2: Supplier Part# | BN2: Comment | BO2: Region
A3: FY24 | F3: 200 | AO3: 0 | AP3: =AC3*AO3 -> 0 | AQ3: 0 | AR3: =AD3*AQ3 -> 0 | AS3: 0 | AT3: =AE3*AS3 -> 0 | AU3: 0 | AV3: =AF3*AU3 -> 0 | AW3: 0 | AX3: =AG3*AW3 -> 0 | AY3: 0 | AZ3: =AH3*AY3 -> 0 | BA3: 0 | BB3: =AI3*BA3 -> 0 | BC3: 0 | BD3: =AJ3*BC3 -> 0 | BE3: 0 | BF3: =AK3*BE3 -> 0 | BG3: 0 | BH3: =AL3*BG3 -> 0 | BI3: 520 | BJ3: =AM3*BI3 -> 0 | BK3: 1283 | BL3: =AN3*BK3 -> 0
A4: FY24 | AP4: =AC4*AO4 -> 0 | AR4: =AD4*AQ4 -> 0 | AT4: =AE4*AS4 -> 0 | AV4: =AF4*AU4 -> 0 | AX4: =AG4*AW4 -> 0 | AZ4: =AH4*AY4 -> 0 | BB4: =AI4*BA4 -> 0 | BD4: =AJ4*BC4 -> 0 | BE4: 0 | BF4: =AK4*BE4 -> 0 | BG4: 0 | BH4: =AL4*BG4 -> 0 | BI4: 120 | BJ4: =AM4*BI4 -> 0 | BL4: =AN4*BK4 -> 0
A5: FY24 | AO5: 0 | AP5: =AC5*AO5 -> 0 | AQ5: 0 | AR5: =AD5*AQ5 -> 0 | AS5: 0 | AT5: =AE5*AS5 -> 0 | AU5: 0 | AV5: =AF5*AU5 -> 0 | AW5: 0 | AX5: =AG5*AW5 -> 0 | AY5: 0 | AZ5: =AH5*AY5 -> 0 | BA5: 0 | BB5: =AI5*BA5 -> 0 | BC5: 0 | BD5: =AJ5*BC5 -> 0 | BE5: 0 | BF5: =AK5*BE5 -> 0 | BG5: 0 | BH5: =AL5*BG5 -> 0 | BI5: 758 | BJ5: =AM5*BI5 -> 0 | BK5: 43 | BL5: =AN5*BK5 -> 0
A6: FY24 | B6: Sandy Lu | C6: Primax | D6: Commercial | E6: NB | F6: 400/600 | G6: 2024 | H6: ROZ 14/REX 13/14/ OAKEN 14/OLAF 14 | I6: BL KB | J6: 14 | K6: Soft Grey | L6: W China | M6: QUANTA | N6: 7.35 | O6: 12.39 | S6: 14.16 | T6: 14.16 | U6: 14.16 | V6: 12.39 | W6: 12.39 | X6: 12.39 | Y6: 12.39 | Z6: 12.39 | AA6: 12.39 | AB6: 0 | AI6: 5.04 | AJ6: 5.04 | AK6: 5.04 | AL6: 5.04 | AM6: 5.04 | AN6: 5.04 | AP6: =AC6*AO6 -> 0 | AR6: =AD6*AQ6 -> 0 | AT6: =AE6*AS6 -> 0 | AV6: =AF6*AU6 -> 0 | AX6: =AG6*AW6 -> 0 | AZ6: =AH6*AY6 -> 0 | BB6: =AI6*BA6 -> 0 | BD6: =AJ6*BC6 -> 0 | BF6: =AK6*BE6 -> 0 | BG6: 21640 | BH6: =AL6*BG6 -> 109065.6 | BI6: 48325 | BJ6: =AM6*BI6 -> 243558 | BK6: 76734 | BL6: =AN6*BK6 -> 386739.36 | BM6: 2H-BERUSQ19511
A7: FY24 | B7: Sandy Lu | C7: Primax | D7: Commercial | E7: NB | G7: 2024 | H7: ROZ 14/REX 13/14/ OAKEN 14/OLAF 14 | I7: NBL KB | J7: 14 | K7: Soft Grey | L7: W China | M7: QUANTA | N7: 3.65 | O7: 4.16 | S7: 4.24 | T7: 4.24 | U7: 4.24 | V7: 4.16 | W7: 4.16 | X7: 4.16 | Y7: 4.16 | Z7: 4.16 | AA7: 4.16 | AB7: 0 | AI7: 0.51 | AJ7: 0.51 | AK7: 0.51 | AL7: 0.51 | AM7: 0.51 | AN7: 0.51 | AP7: =AC7*AO7 -> 0 | AR7: =AD7*AQ7 -> 0 | AT7: =AE7*AS7 -> 0 | AV7: =AF7*AU7 -> 0 | AX7: =AG7*AW7 -> 0 | AZ7: =AH7*AY7 -> 0 | BB7: =AI7*BA7 -> 0 | BD7: =AJ7*BC7 -> 0 | BF7: =AK7*BE7 -> 0 | BG7: 6440 | BH7: =AL7*BG7 -> 3284.4 | BI7: 7240 | BJ7: =AM7*BI7 -> 3692.4 | BK7: 9689 | BL7: =AN7*BK7 -> 4941.39 | BM7: 2H-AERUSQ19511
A8: FY24 | B8: Sandy Lu | C8: Primax | D8: Commercial | E8: NB | G8: 2024 | H8: ROZ 16/REX 16/ OAKEN 16/OLAF 16 | I8: BL KB | J8: 16 | K8: Soft Grey | L8: W China | M8: QUANTA | N8: 7.88 | O8: 13.63 | S8: 15.58 | T8: 15.58 | U8: 15.58 | V8: 13.63 | W8: 13.63 | X8: 13.63 | Y8: 13.63 | Z8: 13.63 | AA8: 13.63 | AB8: 0 | AI8: 5.75 | AJ8: 5.75 | AK8: 5.75 | AL8: 5.75 | AM8: 5.75 | AN8: 5.75 | AP8: =AC8*AO8 -> 0 | AR8: =AD8*AQ8 -> 0 | AT8: =AE8*AS8 -> 0 | AV8: =AF8*AU8 -> 0 | AX8: =AG8*AW8 -> 0 | AZ8: =AH8*AY8 -> 0 | BB8: =AI8*BA8 -> 0 | BD8: =AJ8*BC8 -> 0 | BF8: =AK8*BE8 -> 0 | BG8: 4080 | BH8: =AL8*BG8 -> 23460 | BI8: 9344 | BJ8: =AM8*BI8 -> 53728 | BK8: 17330 | BL8: =AN8*BK8 -> 99647.5 | BM8: 2H-BESUSQ19511
A9: FY24 | B9: Sandy Lu | C9: Primax | D9: Commercial | E9: NB | G9: 2024 | H9: ROZ 16/REX 16/ OAKEN 16/OLAF 16 | I9: NBL KB | J9: 16 | K9: Soft Grey | L9: W China | M9: QUANTA | N9: 4 | O9: 4.43 | S9: 4.52 | T9: 4.52 | U9: 4.52 | V9: 4.43 | W9: 4.43 | X9: 4.43 | Y9: 4.43 | Z9: 4.43 | AA9: 4.43 | AB9: 0 | AI9: 0.43 | AJ9: 0.43 | AK9: 0.43 | AL9: 0.43 | AM9: 0.43 | AN9: 0.43 | AP9: =AC9*AO9 -> 0 | AR9: =AD9*AQ9 -> 0 | AT9: =AE9*AS9 -> 0 | AV9: =AF9*AU9 -> 0 | AX9: =AG9*AW9 -> 0 | AZ9: =AH9*AY9 -> 0 | BB9: =AI9*BA9 -> 0 | BD9: =AJ9*BC9 -> 0 | BF9: =AK9*BE9 -> 0 | BG9: 4720 | BH9: =AL9*BG9 -> 2029.6 | BI9: 1520 | BJ9: =AM9*BI9 -> 653.6 | BK9: 10610 | BL9: =AN9*BK9 -> 4562.3 | BM9: 2H-AESUSQ19511
A10: FY24 | B10: Sandy Lu | C10: Primax | D10: Commercial | E10: NB | G10: 2024 | H10: ROZ 14/REX 13/14/ OAKEN 14/OLAF 14 | I10: BL KB | J10: 14 | K10: Soft Grey | L10: W China | M10: QUANTA | N10: 7.35 | O10: 12.39 | S10: 14.16 | T10: 14.16 | U10: 14.16 | V10: 12.39 | W10: 12.39 | X10: 12.39 | Y10: 12.39 | Z10: 12.39 | AA10: 12.39 | AB10: 0 | AI10: 5.04 | AJ10: 5.04 | AK10: 5.04 | AL10: 5.04 | AM10: 5.04 | AN10: 5.04 | AP10: =AC10*AO10 -> 0 | AR10: =AD10*AQ10 -> 0 | AT10: =AE10*AS10 -> 0 | AV10: =AF10*AU10 -> 0 | AX10: =AG10*AW10 -> 0 | AZ10: =AH10*AY10 -> 0 | BB10: =AI10*BA10 -> 0 | BD10: =AJ10*BC10 -> 0 | BF10: =AK10*BE10 -> 0 | BG10: 0 | BH10: =AL10*BG10 -> 0 | BI10: 280 | BJ10: =AM10*BI10 -> 1411.2 | BK10: 1080 | BL10: =AN10*BK10 -> 5443.2 | BM10: 2H-BERUSQ19532
A11: FY24 | B11: Sandy Lu | C11: Primax | D11: Commercial | E11: NB | G11: 2024 | H11: ROZ 14/REX 13/14/ OAKEN 14/OLAF 14 | I11: NBL KB | J11: 14 | K11: Soft Grey | L11: W China | M11: QUANTA | N11: 3.65 | O11: 4.16 | S11: 4.24 | T11: 4.24 | U11: 4.24 | V11: 4.16 | W11: 4.16 | X11: 4.16 | Y11: 4.16 | Z11: 4.16 | AA11: 4.16 | AB11: 0 | AI11: 0.51 | AJ11: 0.51 | AK11: 0.51 | AL11: 0.51 | AM11: 0.51 | AN11: 0.51 | AP11: =AC11*AO11 -> 0 | AR11: =AD11*AQ11 -> 0 | AT11: =AE11*AS11 -> 0 | AV11: =AF11*AU11 -> 0 | AX11: =AG11*AW11 -> 0 | AZ11: =AH11*AY11 -> 0 | BB11: =AI11*BA11 -> 0 | BD11: =AJ11*BC11 -> 0 | BF11: =AK11*BE11 -> 0 | BG11: 0 | BH11: =AL11*BG11 -> 0 | BI11: 120 | BJ11: =AM11*BI11 -> 61.2 | BK11: 760 | BL11: =AN11*BK11 -> 387.6 | BM11: 2H-AERUSQ19522
A12: FY24 | B12: Sandy Lu | C12: Primax | D12: Commercial | E12: NB | G12: 2024 | H12: ROZ 16/REX 16/ OAKEN 16/OLAF 16 | I12: BL KB | J12: 16 | K12: Soft Grey | L12: W China | M12: QUANTA | N12: 7.88 | O12: 13.63 | S12: 15.58 | T12: 15.58 | U12: 15.58 | V12: 13.63 | W12: 13.63 | X12: 13.63 | Y12: 13.63 | Z12: 13.63 | AA12: 13.63 | AB12: 0 | AI12: 5.75 | AJ12: 5.75 | AK12: 5.75 | AL12: 5.75 | AM12: 5.75 | AN12: 5.75 | AP12: =AC12*AO12 -> 0 | AR12: =AD12*AQ12 -> 0 | AT12: =AE12*AS12 -> 0 | AV12: =AF12*AU12 -> 0 | AX12: =AG12*AW12 -> 0 | AZ12: =AH12*AY12 -> 0 | BB12: =AI12*BA12 -> 0 | BD12: =AJ12*BC12 -> 0 | BF12: =AK12*BE12 -> 0 | BG12: 8120 | BH12: =AL12*BG12 -> 46690 | BI12: 12560 | BJ12: =AM12*BI12 -> 72220 | BK12: 10760 | BL12: =AN12*BK12 -> 61870 | BM12: 2H-BESUSQ19532
A13: FY24 | B13: Sandy Lu | C13: Primax | D13: Commercial | E13: NB | G13: 2024 | H13: ROZ 16/REX 16/ OAKEN 16/OLAF 16 | I13: NBL KB | J13: 16 | K13: Soft Grey | L13: W China | M13: QUANTA | N13: 4 | O13: 4.43 | S13: 4.52 | T13: 4.52 | U13: 4.52 | V13: 4.43 | W13: 4.43 | X13: 4.43 | Y13: 4.43 | Z13: 4.43 | AA13: 4.43 | AB13: 0 | AI13: 0.43 | AJ13: 0.43 | AK13: 0.43 | AL13: 0.43 | AM13: 0.43 | AN13: 0.43 | AP13: =AC13*AO13 -> 0 | AR13: =AD13*AQ13 -> 0 | AT13: =AE13*AS13 -> 0 | AV13: =AF13*AU13 -> 0 | AX13: =AG13*AW13 -> 0 | AZ13: =AH13*AY13 -> 0 | BB13: =AI13*BA13 -> 0 | BD13: =AJ13*BC13 -> 0 | BF13: =AK13*BE13 -> 0 | BG13: 3040 | BH13: =AL13*BG13 -> 1307.2 | BI13: 2800 | BJ13: =AM13*BI13 -> 1204 | BK13: 3160 | BL13: =AN13*BK13 -> 1358.8 | BM13: 2H-AESUSQ19522
A14: FY24 | B14: Mandy Yu | C14: Primax | D14: Commercial | E14: Clickpad | F14: 400/600 | G14: 2024 | H14: DIVINITY/OAKEN14/OLAF14/PUDDING14/RAINBOWCAKE14/REX13&14/ROZ14/WAFER13&14/WAFFLE14 | I14: Clickpad | J14: 14 | K14: NA/ | L14: W China | M14: QUANTA | N14: 4.66 | O14: 4.69 | P14: 4.86 | Q14: 4.86 | R14: 4.86 | S14: 4.86 | T14: 4.86 | U14: 4.86 | V14: 4.86 | W14: 4.86 | X14: 4.86 | Y14: 4.86 | Z14: 4.69 | AA14: 4.69 | AB14: =AN14 -> 0.11 | AI14: 0.1 | AJ14: 0.1 | AK14: 0.1 | AL14: 0.2 | AM14: 0.11 | AN14: 0.11 | AP14: =AC14*AO14 -> 0 | AR14: =AD14*AQ14 -> 0 | AT14: =AE14*AS14 -> 0 | AV14: =AF14*AU14 -> 0 | AW14: 220 | AX14: =AG14*AW14 -> 0 | AY14: 9872 | AZ14: =AH14*AY14 -> 0 | BA14: 39710 | BB14: =AI14*BA14 -> 3971 | BC14: 77330 | BD14: =AJ14*BC14 -> 7733 | BE14: 67760 | BF14: =AK14*BE14 -> 6776 | BG14: 101640 | BH14: =AL14*BG14 -> 20328 | BI14: 131450 | BJ14: =AM14*BI14 -> 14459.5 | BK14: 245630 | BL14: =AN14*BK14 -> 27019.3 | BM14: 2A-1A901H101 2A-1AJ01H101
A15: FY24 | B15: Mandy Yu | C15: Primax | D15: Commercial | E15: Clickpad | G15: 2024 | H15: DIVINITY/OAKEN14/OLAF14/PUDDING14/RAINBOWCAKE14/REX13&14/ROZ14/WAFER13&14/WAFFLE14 | I15: Clickpad | J15: 14 | K15: NA/ | L15: NMC | M15: QMB | N15: 4.66 | O15: 4.69 | P15: 4.86 | Q15: 4.86 | R15: 4.86 | S15: 4.86 | T15: 4.86 | U15: 4.86 | V15: 4.86 | W15: 4.86 | X15: 4.86 | Y15: 4.86 | Z15: 4.69 | AA15: 4.69 | AB15: =AN15 -> 0.11 | AI15: 0.1 | AJ15: 0.1 | AK15: 0.1 | AL15: 0.2 | AM15: 0.11 | AN15: 0.11 | AP15: =AC15*AO15 -> 0 | AR15: =AD15*AQ15 -> 0 | AT15: =AE15*AS15 -> 0 | AV15: =AF15*AU15 -> 0 | AX15: =AG15*AW15 -> 0 | AZ15: =AH15*AY15 -> 0 | BB15: =AI15*BA15 -> 0 | BD15: =AJ15*BC15 -> 0 | BF15: =AK15*BE15 -> 0 | BH15: =AL15*BG15 -> 0 | BI15: 1300 | BJ15: =AM15*BI15 -> 143 | BK15: 10000 | BL15: =AN15*BK15 -> 1100 | BM15: 2A-1A901H102
A16: FY24 | AP16: =AC16*AO16 -> 0 | AR16: =AD16*AQ16 -> 0 | AT16: =AE16*AS16 -> 0 | AV16: =AF16*AU16 -> 0 | AX16: =AG16*AW16 -> 0 | AZ16: =AH16*AY16 -> 0 | BB16: =AI16*BA16 -> 0 | BD16: =AJ16*BC16 -> 0 | BF16: =AK16*BE16 -> 0 | BH16: =AL16*BG16 -> 0 | BJ16: =AM16*BI16 -> 0 | BL16: =AN16*BK16 -> 0
A17: FY24 | AP17: =AC17*AO17 -> 0 | AR17: =AD17*AQ17 -> 0 | AT17: =AE17*AS17 -> 0 | AV17: =AF17*AU17 -> 0 | AX17: =AG17*AW17 -> 0 | AZ17: =AH17*AY17 -> 0 | BB17: =AI17*BA17 -> 0 | BD17: =AJ17*BC17 -> 0 | BF17: =AK17*BE17 -> 0 | BH17: =AL17*BG17 -> 0 | BJ17: =AM17*BI17 -> 0 | BL17: =AN17*BK17 -> 0
A18: FY24 | AP18: =AC18*AO18 -> 0 | AR18: =AD18*AQ18 -> 0 | AT18: =AE18*AS18 -> 0 | AV18: =AF18*AU18 -> 0 | AX18: =AG18*AW18 -> 0 | AZ18: =AH18*AY18 -> 0 | BB18: =AI18*BA18 -> 0 | BD18: =AJ18*BC18 -> 0 | BF18: =AK18*BE18 -> 0 | BH18: =AL18*BG18 -> 0 | BJ18: =AM18*BI18 -> 0 | BL18: =AN18*BK18 -> 0
A19: FY24 | AP19: =AC19*AO19 -> 0 | AR19: =AD19*AQ19 -> 0 | AT19: =AE19*AS19 -> 0 | AV19: =AF19*AU19 -> 0 | AX19: =AG19*AW19 -> 0 | AZ19: =AH19*AY19 -> 0 | BB19: =AI19*BA19 -> 0 | BD19: =AJ19*BC19 -> 0 | BF19: =AK19*BE19 -> 0 | BH19: =AL19*BG19 -> 0 | BJ19: =AM19*BI19 -> 0 | BL19: =AN19*BK19 -> 0
A20: FY24 | B20: Sandy Lu | C20: Primax | D20: Commercial | E20: NB | F20: 800 | G20: 2020 | H20: LANCIA/CADILLAC/LINDEN/CAMELLIA | I20: BL KB | J20: 15 | K20: Flint Opaque | L20: W China | M20: INVENTEC | N20: 13.94 | O20: 22.15 | P20: 22.15 | Q20: 22.15 | R20: 22.15 | S20: 22.15 | T20: 22.15 | U20: 22.15 | V20: 22.15 | W20: 22.15 | X20: 22.15 | Y20: 22.15 | Z20: 22.15 | AA20: 22.15 | AB20: 8.21 | AC20: 8.21 | AD20: 8.21 | AE20: 8.21 | AF20: 8.21 | AG20: 8.21 | AH20: 8.21 | AI20: 8.21 | AJ20: 8.21 | AK20: 8.21 | AL20: 8.21 | AM20: 8.21 | AN20: 8.21 | AO20: 2400 | AP20: =AC20*AO20 -> 19704 | AQ20: 3439 | AR20: =AD20*AQ20 -> 28234.19 | AS20: 3000 | AT20: =AE20*AS20 -> 24630 | AU20: 1680 | AV20: =AF20*AU20 -> 13792.8 | AW20: 2160 | AX20: =AG20*AW20 -> 17733.6 | AY20: 1080 | AZ20: =AH20*AY20 -> 8866.8 | BB20: =AI20*BA20 -> 0 | BD20: =AJ20*BC20 -> 0 | BF20: =AK20*BE20 -> 0 | BH20: =AL20*BG20 -> 0 | BJ20: =AM20*BI20 -> 0 | BL20: =AN20*BK20 -> 0 | BM20: 2H-BCFUSI64312
A21: FY24 | B21: Sandy Lu | C21: Primax | D21: Commercial | E21: NB | G21: 2020 | H21: LANCIA/CADILLAC/LINDEN/CAMELLIA | J21: 15 | K21: Flint Opaque | L21: W China | M21: INVENTEC | N21: 9.59 | O21: 11.09 | P21: 11.09 | Q21: 11.09 | R21: 11.09 | S21: 11.09 | T21: 11.09 | U21: 11.09 | V21: 11.09 | W21: 11.09 | X21: 11.09 | Y21: 11.09 | Z21: 11.09 | AA21: 11.09 | AB21: 1.5 | AC21: 1.5 | AD21: 1.5 | AE21: 1.5 | AF21: 1.5 | AG21: 1.5 | AH21: 1.5 | AI21: 1.5 | AJ21: 1.5 | AK21: 1.5 | AL21: 1.5 | AM21: 1.5 | AN21: 1.5 | AO21: 240 | AP21: =AC21*AO21 -> 360 | AQ21: 520 | AR21: =AD21*AQ21 -> 780 | AS21: 280 | AT21: =AE21*AS21 -> 420 | AU21: 240 | AV21: =AF21*AU21 -> 360 | AW21: 360 | AX21: =AG21*AW21 -> 540 | AY21: 280 | AZ21: =AH21*AY21 -> 420 | BB21: =AI21*BA21 -> 0 | BD21: =AJ21*BC21 -> 0 | BF21: =AK21*BE21 -> 0 | BH21: =AL21*BG21 -> 0 | BJ21: =AM21*BI21 -> 0 | BL21: =AN21*BK21 -> 0 | BM21: 2H-ACFUSI64312
A22: FY24 | B22: Sandy Lu | C22: Primax | D22: Commercial | E22: NB | G22: 2020 | H22: LANCIA/CORVETTE/CORVETTE/CAMELLIA/LINDEN/LOCHNESS | I22: BL KB | J22: 14 | K22: Flint Opaque | L22: W China | M22: INVENTEC | N22: 13.5 | O22: 20.41 | P22: 20.41 | Q22: 20.41 | R22: 20.41 | S22: 20.41 | T22: 20.41 | U22: 20.41 | V22: 20.41 | W22: 20.41 | X22: 20.41 | Y22: 20.41 | Z22: 20.41 | AA22: 20.41 | AB22: 6.91 | AC22: 6.91 | AD22: 6.91 | AE22: 6.91 | AF22: 6.91 | AG22: 6.91 | AH22: 6.91 | AI22: 6.91 | AJ22: 6.91 | AK22: 6.91 | AL22: 6.91 | AM22: 6.91 | AN22: 6.91 | AO22: 0 | AP22: =AC22*AO22 -> 0 | AQ22: 0 | AR22: =AD22*AQ22 -> 0 | AS22: 0 | AT22: =AE22*AS22 -> 0 | AU22: 0 | AV22: =AF22*AU22 -> 0 | AW22: 0 | AX22: =AG22*AW22 -> 0 | AY22: 0 | AZ22: =AH22*AY22 -> 0 | BB22: =AI22*BA22 -> 0 | BD22: =AJ22*BC22 -> 0 | BF22: =AK22*BE22 -> 0 | BH22: =AL22*BG22 -> 0 | BJ22: =AM22*BI22 -> 0 | BL22: =AN22*BK22 -> 0 | BM22: 2H-BCGUSI64312
A23: FY24 | B23: Sandy Lu | C23: Primax | D23: Commercial | E23: NB | G23: 2020 | H23: LANCIA/CORVETTE/CORVETTE/CAMELLIA/LINDEN/LOCHNESS | I23: NBL KB | J23: 14 | K23: Flint Opaque | L23: W China | M23: INVENTEC | N23: 9.29 | O23: 11.02 | P23: 11.02 | Q23: 11.02 | R23: 11.02 | S23: 11.02 | T23: 11.02 | U23: 11.02 | V23: 11.02 | W23: 11.02 | X23: 11.02 | Y23: 11.02 | Z23: 11.02 | AA23: 11.02 | AB23: 1.73 | AC23: 1.73 | AD23: 1.73 | AE23: 1.73 | AF23: 1.73 | AG23: 1.73 | AH23: 1.73 | AI23: 1.73 | AJ23: 1.73 | AK23: 1.73 | AL23: 1.73 | AM23: 1.73 | AN23: 1.73 | AO23: 0 | AP23: =AC23*AO23 -> 0 | AQ23: 0 | AR23: =AD23*AQ23 -> 0 | AS23: 0 | AT23: =AE23*AS23 -> 0 | AU23: 0 | AV23: =AF23*AU23 -> 0 | AW23: 0 | AX23: =AG23*AW23 -> 0 | AY23: 0 | AZ23: =AH23*AY23 -> 0 | BB23: =AI23*BA23 -> 0 | BD23: =AJ23*BC23 -> 0 | BF23: =AK23*BE23 -> 0 | BH23: =AL23*BG23 -> 0 | BJ23: =AM23*BI23 -> 0 | BL23: =AN23*BK23 -> 0 | BM23: 2H-ACGUSI64312
A24: FY24 | B24: Sandy Lu | C24: Primax | D24: Commercial | E24: NB | G24: 2020 | H24: GRIZZLY/GRIZZLY2/LANCIA/CORVETTE/CAMELLIA/HOKKAIDO/OPEL/LINDEN/OLEANDER | I24: BL KB | J24: 13 | K24: Flint Opaque | L24: W China | M24: INVENTEC | N24: 9.2 | O24: 16.17 | P24: 16.17 | Q24: 16.17 | R24: 16.17 | S24: 16.17 | T24: 16.17 | U24: 16.17 | V24: 16.17 | W24: 16.17 | X24: 16.17 | Y24: 16.17 | Z24: 16.17 | AA24: 16.17 | AB24: 6.97 | AC24: 6.97 | AD24: 6.97 | AE24: 6.97 | AF24: 6.97 | AG24: 6.97 | AH24: 6.97 | AI24: 6.97 | AJ24: 6.97 | AK24: 6.97 | AL24: 6.97 | AM24: 6.97 | AN24: 6.97 | AO24: 2800 | AP24: =AC24*AO24 -> 19516 | AQ24: 2200 | AR24: =AD24*AQ24 -> 15334 | AS24: 5392 | AT24: =AE24*AS24 -> 37582.24 | AU24: 2920 | AV24: =AF24*AU24 -> 20352.4 | AW24: 2620 | AX24: =AG24*AW24 -> 18261.4 | AY24: 1280 | AZ24: =AH24*AY24 -> 8921.6 | BB24: =AI24*BA24 -> 0 | BD24: =AJ24*BC24 -> 0 | BF24: =AK24*BE24 -> 0 | BH24: =AL24*BG24 -> 0 | BJ24: =AM24*BI24 -> 0 | BL24: =AN24*BK24 -> 0 | BM24: 2H-BCHUSI64311
