Workbook
Name Region: #REF!
Name Region: #REF!
Name Region: #REF!
Name Region: #REF!

Sheet 說明頁_更新版
A1: ID | B1: Action | C1: Remark
A2: 1 | B2: A-M欄及BM-BP欄照理來說不會更動只會新增
A3: 2 | B3: 檔名的部分請像這樣 "Rebate and Spending report Supplier’s name_2025 01"，勿加上其他說明，若有V2版本請寫 "Rebate and Spending report Supplier’s name_2025 01_V2"
A4: 3 | B4: 請全年度都放在同一個tab，Summary也是Q1-Q4都放在一起，若有更新的年度請一樣要加上對應的Summary
A5: 4 | B5: Title相關規範請看右方所示, 請按照此欄位進行填寫, 勿更改資料次序 *上面也附上Example, 參考的顏色表以及Mason的PDF instruction | C5: A欄位:打上年度，新年度記得要更新
C6: B欄位: SPM, 請填全名, ex Benson Chen, 而不是Benson，若SPM有異動也請更新
C7: C 欄位: 一律填自己公司名稱
C8: D欄位: 請照上方指示, 勿自創提詞, 須注意只有NB和DT才會有Consumer/Commercial之分, F欄位是Peripheral則D和E都是填Peripheral
C9: E欄位 : 請照上方指示, 勿自創提詞
C10: F欄位 : Peripheral只需填寫Peripheral
C11: G欄位 : 已更新到2025
C12: H欄位 : -請一定不能空白此欄位，不然後面的數字都會讀不到 -如果多個platforms共用同keyboard, 請用 '/' 去 group這些platforms，大小寫沒關係。 -請Platform name請跟LTF一模一樣，像是有些後面會加上尺寸也請加上( BAYMAX14/LUISA14/BAYMAXW14/BAYMAX13/BAYMAX13X) -請用"/"來 Grouping 不同 Platform (e.g. ANDAZ/ABU) ，勿用其他符號，錯誤範例如:ANDAZ&ABU
C13: I欄位 : 請照上方指示, 勿自創提詞
C14: J欄位 : 如果沒有Size，則填寫"NA/"，不要只寫"NA"
C15: K欄 : -要注意勿將 Color grouping 在一起，像是Jet Black/Soft Grey，若有n個顏色需分成n筆資料去填 -如果沒有Color，則填寫"NA/"，請注意不要只寫"NA" -Color 需確保填寫正確，如 SEAFOAM TEAL PEARL 需完整打出來，避免填成 SEAFOAM TEAL -請確保在顏色中間加上空格，大小寫沒關係。 -關於灰色，請使用“Grey” 而非“Gray” -Color 欄位需保持正常format，像是 PERFORMANCE BLUE OPAQUE 請避免填成 PERFORMANCE BLUE OPAQUE-RGB -針對CNB Gaming，關於Numpad及RGB方面請遵照以下方式及右方的說明 : RGB Per Key W Numpad_Soft Grey RGB Per Key W/O Numpad_Soft Grey 1 Zone W Numpad_Soft Grey, 1 Zone Red W Numpad_Soft Grey 4 Zone RGB W Numpad_Soft Grey 1 Zone W/O Numpad_Soft Grey, 1 Zone Red W/O Numpad_Soft Grey 4 Zone RGB W/O Numpad_Soft Grey 1 Zone RGB W Numpad_Soft Grey 1 Zone RGB W/O Numpad_Soft Grey
C16: L欄 : 請照上方指示，勿自創提詞，注意NMC更新為Thailand/Vietnam
C17: M欄 : 請照上方指示填寫對應ODM，勿自創提詞或簡寫。若發生ODM不存在於上方的情況，請勿寫上OTHERS，需參照在contract中寫的ODM或Regional site名稱
... C22: BP欄 : 如果有HP Part#就填上，如果沒有的話就填上ODM Part# (語言別的部分可以屏蔽並用星號代替，除非有語言別會造成價格不同的情況才需列出語言別的部分)
A23: 5 | B23: 當月出貨的所有品項都必須填上, 即使rebate=0的項目, 定義為FCS之後, EOL前的platform 當月出貨都需要寫上(也就是不含service part)
A24: 6 | B24: 每個月10日固定上傳此份rebate and spending report，請注意目前的Share point已經與財務共用，因此有任何要更新的地方都請通知Jenny並且上傳V2/V3…版本，且舊檔案勿刪除
A25: 7 | B25: 在上傳此份檔案前針對數字的部分需再三確認，因為這些數字會直接當作日後開發票的金額
A26: 8 | B26: excel欄位有相乘的部分 (rebate amount), 請不要直接在公式以外做數字上的調整, 沒有邏輯性的數字, 程式會偵測異常
A27: 9 | B27: Summary_1不能有任何註記, 需要呈現最真實的數字, Summary_2貴司可有一些註記符號, 或是rebate抵扣等地紀錄是能夠被容許的

Sheet FY23 Summary_1
B3: Sunrex | C3: 2022 11 | D3: 2022 12 | E3: 2023 01 | F3: Total Q1
B4: Rebate amount | C4: ='FY23'!AO1 -> 713857.41 | D4: ='FY23'!AQ1 -> 505702.96 | E4: ='FY23'!AS1 -> 450934.89 | F4: =SUM(C4:E4) -> 1670495.3
B5: E&O reduction | F5: =SUM(C5:E5) -> 0
B6: Complexity reduction | F6: =SUM(C6:E6) -> 0 | H6: 1. 新增Summary_1, 原先的Summary重新命名為Summary_2
B7: Total amount | C7: =SUM(C4:C6) -> 713857.41 | D7: =SUM(D4:D6) -> 505702.96 | E7: =SUM(E4:E6) -> 450934.89 | F7: =SUM(F4:F6) -> 1670495.3
H8: 2.黃色部位為貴司名稱, 請整份報告都跟檔名貴司名稱撰寫方式一致
B10: Sunrex | C10: 2023 02 | D10: 2023 03 | E10: 2023 04 | F10: Total Q2 | H10: 3. 這些欄位一定要固定, B3-B28, C3-C28, D3-D28, E3-E28, F3-F28都有賦予定義
B11: Rebate amount | C11: ='FY23'!AU1 -> 658718.2 | D11: ='FY23'!AW1 -> 951497.85 | E11: ='FY23'!AY1 -> 773763.87 | F11: =SUM(C11:E11) -> 2383979.9
B12: E&O reduction | F12: =SUM(C12:E12) -> 0 | H12: 4. Rebate amount 指得是summary_2的page金額 (就是我們一直以來收集的金額)
B13: Complexity reduction | F13: =SUM(C13:E13) -> 0
B14: Total amount | C14: =SUM(C11:C13) -> 658718.2 | D14: =SUM(D11:D13) -> 951497.85 | E14: =SUM(E11:E13) -> 773763.87 | F14: =SUM(F11:F13) -> 2383979.9 | H14: 5. 新增 E&O reduction 及complexity reduction品項, 先留足空間
H15: 若目前還未有此款項存在都先填0
B17: Sunrex | C17: 2023 05 | D17: 2023 06 | E17: 2023 07 | F17: Total Q3 | H17: 6. 金額都放未經調整後的真實數字, 分析才具意義
B18: Rebate amount | C18: ='FY23'!BA1 -> 964658.73 | D18: ='FY23'!BC1 -> 1151172.7 | E18: ='FY23'!BE1 -> 937017.67 | F18: =SUM(C18:E18) -> 3052849.1
B19: E&O reduction | F19: =SUM(C19:E19) -> 0
B20: Complexity reduction | F20: =SUM(C20:E20) -> 0
B21: Total amount | C21: =SUM(C18:C20) -> 964658.73 | D21: =SUM(D18:D20) -> 1151172.7 | E21: =SUM(E18:E20) -> 937017.67 | F21: =SUM(F18:F20) -> 3052849.1
B24: Sunrex | C24: 2023 08 | D24: 2023 09 | E24: 2023 10 | F24: Total Q4
B25: Rebate amount | C25: ='FY23'!BG1 -> 1034158.6 | D25: ='FY23'!BI1 -> 998920.3 | E25: ='FY23'!BK1 -> 980312.27 | F25: =SUM(C25:E25) -> 3013391.1
B26: E&O reduction | E26: 7185 | F26: =SUM(C26:E26) -> 7185
B27: Complexity reduction | F27: =SUM(C27:E27) -> 0
B28: Total amount | C28: =SUM(C25:C27) -> 1034158.6 | D28: =SUM(D25:D27) -> 998920.3 | E28: =SUM(E25:E27) -> 987497.27 | F28: =SUM(F25:F27) -> 3020576.1

Sheet FY23 Summary_2
B3: Q1 Actual by Segment
C4: Segment | D4: 44866 | E4: 44896 | F4: 44927 | G4: Total Rebate in Q1 2023 (US$)
B5: CMIT Input Devices | C5: 200 series (6U) | D5: 5144.225 | E5: 10523.725 | F5: 7217.425 | G5: =SUM(D5:F5) -> 22885.375
C6: 400 series (S) | D6: 263753.36 | E6: 270470.45 | F6: 255563.81 | G6: =SUM(D6:F6) -> 789787.62
C7: 600 series (B) | D7: 65938.34 | E7: 67617.612 | F7: 63890.952 | G7: =SUM(D7:F7) -> 197446.9
C8: 800 series (P) | G8: =SUM(D8:F8) -> 0
C9: 1000 series (M | G9: =SUM(D9:F9) -> 0
C10: MWS (Workstation) | G10: =SUM(D10:F10) -> 0
C11: Soft Keyboard | G11: =SUM(D11:F11) -> 0
C12: Chrome Book | D12: 51637.01 | E12: 24995 | F12: 12473.88 | G12: =SUM(D12:F12) -> 89105.89
C13: Clickpad | D13: 32551 | E13: 31883 | F13: 21837.55 | G13: =SUM(D13:F13) -> 86271.55
C14: Education | G14: =SUM(D14:F14) -> 0
C15: Peripherals/AMO | G15: =SUM(D15:F15) -> 0
C16: Desktop | G16: =SUM(D16:F16) -> 0
B17: Consumer Input Devices | C17: OPP | D17: 15432.675 | E17: 31571.175 | F17: 21652.275 | G17: =SUM(D17:F17) -> 68656.125
C18: Chrome Book | E18: 0 | F18: 0 | G18: =SUM(D18:F18) -> 0
C19: Pavilion | D19: 220661.7 | E19: 44739 | F19: 44339.5 | G19: =SUM(D19:F19) -> 309740.2
C20: Spectre | G20: =SUM(D20:F20) -> 0
C21: Envy | D21: 27264.6 | E21: 10483 | F21: 16387 | G21: =SUM(D21:F21) -> 54134.6
C22: Stream | G22: =SUM(D22:F22) -> 0
C23: Omen | D23: 31474.5 | E23: 13420 | F23: 7572.5 | G23: =SUM(D23:F23) -> 52467
C24: Peripherals/AMO | G24: =SUM(D24:F24) -> 0
C25: Desktop | G25: =SUM(D25:F25) -> 0
G26: =SUM(G5:G25) -> 1670495.3
B28: Q1 Actual by Segment
C29: Supplier | D29: 44866 | E29: 44896 | F29: 44927 | G29: Total Rebate in Q1 2023 (US$)
B30: Input Devices | C30: Chicony
C31: Darfon
C32: Liteon
C33: Primax
C34: Sunrex | D34: =SUM(D5:D25) -> 713857.41 | E34: =SUM(E5:E25) -> 505702.96 | F34: =SUM(F5:F25) -> 450934.89 | G34: =SUM(D34:F34) -> 1670495.3
B35: reserved | F35: 50000 | G35: 50000
C36: Total Q1 Rebate Amount Afer Adjustment | G36: =G34-G35 -> 1620495.3
B38: Q2 Actual by Segment
C39: Segment | D39: 44958 | E39: 44986 | F39: 45017 | G39: Total Rebate in Q2 2023 (US$)
B40: CMIT Input Devices | C40: 200 series (6U) | D40: 9153.55 | E40: 19520.875 | F40: 12753.225 | G40: =SUM(D40:F40) -> 41427.65
C41: 400 series (S) | D41: 335091.24 | E41: 390527.09 | F41: 366128.04 | G41: =SUM(D41:F41) -> 1091746.4
C42: 600 series (B) | D42: 83772.81 | E42: 97631.772 | F42: 91532.01 | G42: =SUM(D42:F42) -> 272936.59
C43: 800 series (P) | G43: =SUM(D43:F43) -> 0
C44: 1000 series (M | G44: =SUM(D44:F44) -> 0
...

Sheet FY23
D1: Consumer/Commercial/ Peripheral | E1: NB/DT/Peripheral | G1: 2020/2021/2022 | H1: Remove Size/Color, define Platform naming Hagrid/Hedwig/Granger/Ashmore/Ramla (follow naming rule of product list) | I1: NBL KB/BL KB/Mouse /Combo/Clickpad/Others | J1: NA/ | K1: NA/ | L1: (E China/W China/S China/NMC) | M1: COMPAL/ QUANTA /INVENTEC /WISTRON/ FOXCONN/ OTHERS | AB1: =SUM(AB3:AB115) -> 161.86 | AC1: =SUM(AC3:AC115) -> 161.86 | AD1: =SUM(AD3:AD115) -> 170.76 | AE1: =SUM(AE3:AE115) -> 207.19 | AF1: =SUM(AF3:AF115) -> 211 | AG1: =SUM(AG3:AG115) -> 221 | AH1: =SUM(AH3:AH115) -> 244.82 | AI1: =SUM(AI3:AI115) -> 244.82 | ... AM1: =SUM(AM3:AM115) -> 254.08 | AO1: =SUM(AO3:AO1004) -> 713857.41 | AQ1: =SUM(AQ3:AQ1004) -> 505702.96 | AS1: =SUM(AS3:AS1004) -> 450934.89 | AU1: =SUM(AU3:AU1004) -> 658718.2 | AW1: =SUM(AW3:AW1004) -> 951497.85 | AY1: =SUM(AY3:AY1004) -> 773763.87 | BA1: =SUM(BA3:BA1004) -> 964658.73 | BC1: =SUM(BC3:BC1004) -> 1151172.7 | BE1: =SUM(BE3:BE1004) -> 937017.67 | BG1: =SUM(BG3:BG1004) -> 1034158.6 | BI1: =SUM(BI3:BI1004) -> 998920.3 | BK1: =SUM(BK3:BK1004) -> 980312.27
A2: FY23 | B2: SPM (Project Owner) | C2: GTK Suppliers | D2: Category | E2: Segment | F2: Series | G2: Production Year | H2: Platforms | I2: Product | J2: Size | K2: Color | L2: Location | M2: ODM | N2: The lowest unit table price (ODM cost) | O2: Table Price Nov | P2: Table Price Dec | Q2: Table Price Jan | R2: Table Price Feb | S2: Table Price Mar | T2: Table Price Apr | U2: Table Price May | V2: Table Price Jun | W2: Table Price Jul | X2: Table Price Aug | Y2: Table Price Sep | Z2: Table Price Oct | AA2: The lowest unit rebate cost | AB2: Unit Rebate Nov | AC2: Unit Rebate Dec | AD2: Unit Rebate Jan | AE2: Unit Rebate Feb | AF2: Unit Rebate Mar | AG2: Unit Rebate Apr | AH2: Unit Rebate May | AI2: Unit Rebate Jun | AJ2: Unit Rebate Jul | AK2: Unit Rebate Aug | AL2: Unit Rebate Sep | AM2: Unit Rebate Oct | AN2: Nov Q'ty | AO2: Nov Rebate Amount | AP2: Dec Q'ty | AQ2: Dec Rebate Amount | AR2: Jan Q'ty | AS2: Jan Rebate Amount | AT2: Feb Q'ty | AU2: Feb Rebate Amount | AV2: Mar Q'ty | AW2: Mar Rebate Amount | AX2: Apr Q'ty | AY2: Apr Rebate Amount | AZ2: May Q'ty | BA2: May Rebate Amount | BB2: Jun Q'ty | BC2: Jun Rebate Amount | BD2: Jul Q'ty | BE2: Jul Rebate Amount | BF2: Aug Q'ty | BG2: Aug Rebate Amount | BH2: Sep Q'ty | BI2: Sep Rebate Amount | BJ2: Oct Q'ty | BK2: Oct Rebate Amount | BL2: Supplier Part# | BM2: Comment
A3: FY23 | C3: SUNREX | D3: Commercial | E3: NB | F3: 200 | AO3: =AB3*AN3 -> 0 | AQ3: =AC3*AP3 -> 0 | AS3: =AD3*AR3 -> 0 | AU3: =AE3*AT3 -> 0 | AW3: =AF3*AV3 -> 0 | AY3: =AG3*AX3 -> 0 | BA3: =AH3*AZ3 -> 0 | BC3: =AI3*BB3 -> 0 | BE3: =AJ3*BD3 -> 0 | BG3: =AK3*BF3 -> 0 | BI3: =AL3*BH3 -> 0 | BK3: =AM3*BJ3 -> 0
A4: FY23 | C4: SUNREX | E4: NB | AO4: =AB4*AN4 -> 0 | AQ4: =AC4*AP4 -> 0 | AS4: =AD4*AR4 -> 0 | AU4: =AE4*AT4 -> 0 | AW4: =AF4*AV4 -> 0 | AY4: =AG4*AX4 -> 0 | BA4: =AH4*AZ4 -> 0 | BC4: =AI4*BB4 -> 0 | BE4: =AJ4*BD4 -> 0 | BG4: =AK4*BF4 -> 0 | BI4: =AL4*BH4 -> 0 | BK4: =AM4*BJ4 -> 0
A5: FY23 | B5: Iris Huang | C5: SUNREX | E5: NB | F5: 400 | G5: 2021 | H5: PRIMROSE/PEPPER/PIXIE/PAX | I5: NBL KB | J5: 13 | K5: FLINT OPAQUE | L5: W China | M5: INVENTEC | N5: 4.4 | O5: 4.4 | P5: 4.4 | Q5: 4.4 | R5: 4.4 | S5: 4.4 | T5: 4.4 | U5: 4.4 | V5: 4.4 | W5: 4.4 | X5: 4.4 | Y5: 4.4 | Z5: 4.4 | AA5: 0.73 | AB5: 0.73 | AC5: 0.73 | AD5: 0.73 | AE5: 0.73 | AF5: 0.73 | AG5: 0.73 | AH5: 0.73 | AI5: 0.73 | AJ5: 0.73 | AK5: 0.73 | AL5: 0.73 | AM5: 0.73 | AN5: 400 | AO5: =AB5*AN5 -> 292 | AP5: 1352 | AQ5: =AC5*AP5 -> 986.96 | AR5: 1352 | AS5: =AD5*AR5 -> 986.96 | AT5: 1160 | AU5: =AE5*AT5 -> 846.8 | AV5: 3647 | AW5: =AF5*AV5 -> 2662.31 | AX5: 400 | AY5: =AG5*AX5 -> 292 | AZ5: 400 | BA5: =AH5*AZ5 -> 292 | BB5: 6959 | BC5: =AI5*BB5 -> 5080.07 | BD5: 1600 | BE5: =AJ5*BD5 -> 1168 | BF5: 5419 | BG5: =AK5*BF5 -> 3955.87 | BH5: 4560 | BI5: =AL5*BH5 -> 3328.8 | BJ5: 2840 | BK5: =AM5*BJ5 -> 2073.2
A6: FY23 | B6: Iris Huang | C6: SUNREX | E6: NB | G6: 2021 | H6: PRIMROSE/PEPPER/PIXIE/PAX | I6: BL KB | J6: 13 | K6: FLINT OPAQUE | L6: W China | M6: INVENTEC | N6: 14.9 | O6: 14.9 | P6: 14.9 | Q6: 14.9 | R6: 14.9 | S6: 14.9 | T6: 14.9 | U6: 14.9 | V6: 14.9 | W6: 14.9 | X6: 14.9 | Y6: 14.9 | Z6: 14.9 | AA6: 6.79 | AB6: 6.79 | AC6: 6.79 | AD6: 6.79 | AE6: 6.79 | AF6: 6.79 | AG6: 6.79 | AH6: 6.79 | AI6: 6.79 | AJ6: 6.79 | AK6: 6.79 | AL6: 6.79 | AM6: 6.79 | AN6: 1920 | AO6: =AB6*AN6 -> 13036.8 | AP6: 400 | AQ6: =AC6*AP6 -> 2716 | AR6: 400 | AS6: =AD6*AR6 -> 2716 | AT6: 1200 | AU6: =AE6*AT6 -> 8148 | AV6: 2840 | AW6: =AF6*AV6 -> 19283.6 | AX6: 1352 | AY6: =AG6*AX6 -> 9180.08 | AZ6: 1352 | BA6: =AH6*AZ6 -> 9180.08 | BB6: 3018 | BC6: =AI6*BB6 -> 20492.22 | BD6: 1120 | BE6: =AJ6*BD6 -> 7604.8 | BF6: 1320 | BG6: =AK6*BF6 -> 8962.8 | BH6: 2860 | BI6: =AL6*BH6 -> 19419.4 | BJ6: 2840 | BK6: =AM6*BJ6 -> 19283.6
A7: FY23 | B7: Iris Huang | C7: SUNREX | E7: NB | G7: 2020 | H7: DIANSHAN/REEDS/IONIAN/KRAKEN | I7: NBL KB | J7: 13 | K7: FLINT OPAQUE | L7: W China | M7: QUANTA | N7: 4.4 | O7: 4.4 | P7: 4.4 | Q7: 4.4 | R7: 4.4 | S7: 4.4 | T7: 4.4 | U7: 4.4 | V7: 4.4 | W7: 4.4 | X7: 4.4 | Y7: 4.4 | Z7: 4.4 | AA7: 0.2 | AB7: 0.2 | AC7: 0.2 | AD7: 0.2 | AE7: 0.25 | AF7: 0.25 | AG7: 0.25 | AH7: 0.25 | AI7: 0.25 | AJ7: 0.25 | AK7: 0.25 | AL7: 0.25 | AM7: 0.25 | AN7: 41999 | AO7: =AB7*AN7 -> 8399.8 | AP7: 12001 | AQ7: =AC7*AP7 -> 2400.2 | AR7: 6266 | AS7: =AD7*AR7 -> 1253.2 | AT7: 10388 | AU7: =AE7*AT7 -> 2597 | AV7: 7638 | AW7: =AF7*AV7 -> 1909.5 | AX7: 35382 | AY7: =AG7*AX7 -> 8845.5 | AZ7: 8111 | BA7: =AH7*AZ7 -> 2027.75 | BB7: 7079 | BC7: =AI7*BB7 -> 1769.75 | BD7: 14280 | BE7: =AJ7*BD7 -> 3570 | BF7: 10154 | BG7: =AK7*BF7 -> 2538.5 | BH7: 18676 | BI7: =AL7*BH7 -> 4669 | BJ7: 24229 | BK7: =AM7*BJ7 -> 6057.25
A8: FY23 | B8: Iris Huang | C8: SUNREX | E8: NB | G8: 2020 | H8: DIANSHAN/REEDS/IONIAN/KRAKEN | I8: BL KB | J8: 13 | K8: FLINT OPAQUE | L8: W China | M8: QUANTA | N8: 14.9 | O8: 14.9 | P8: 14.9 | Q8: 14.9 | R8: 14.9 | S8: 14.9 | T8: 14.9 | U8: 14.9 | V8: 14.9 | W8: 14.9 | X8: 14.9 | Y8: 14.9 | Z8: 14.9 | AA8: 4.5 | AB8: 4.5 | AC8: 4.5 | AD8: 4.5 | AE8: 4.86 | AF8: 4.86 | AG8: 4.86 | AH8: 4.86 | AI8: 4.86 | AJ8: 4.86 | AK8: 4.86 | AL8: 4.86 | AM8: 5.22 | AN8: 5705 | AO8: =AB8*AN8 -> 25672.5 | AP8: 7445 | AQ8: =AC8*AP8 -> 33502.5 | AR8: 4202 | AS8: =AD8*AR8 -> 18909 | AT8: 4999 | AU8: =AE8*AT8 -> 24295.14 | AV8: 5647 | AW8: =AF8*AV8 -> 27444.42 | AX8: 17385 | AY8: =AG8*AX8 -> 84491.1 | AZ8: 6286 | BA8: =AH8*AZ8 -> 30549.96 | BB8: 4439 | BC8: =AI8*BB8 -> 21573.54 | BD8: 3640 | BE8: =AJ8*BD8 -> 17690.4 | BF8: 1445 | BG8: =AK8*BF8 -> 7022.7 | BH8: 1953 | BI8: =AL8*BH8 -> 9491.58 | BJ8: 1728 | BK8: =AM8*BJ8 -> 9020.16
A9: FY23 | B9: Iris Huang | C9: SUNREX | E9: NB | G9: 2020 | H9: DONGQIAN/DIANSHAN/PETROF/RABON/IONIAN/IRONOAK/KRAKEN/ROC/XUANWU/KNUCKER/PAN | I9: NBL KB | J9: 14 | K9: FLINT OPAQUE | L9: W China | M9: QUANTA | N9: 4.4 | O9: 4.4 | P9: 4.4 | Q9: 4.4 | R9: 4.4 | S9: 4.4 | T9: 4.4 | U9: 4.4 | V9: 4.4 | W9: 4.4 | X9: 4.4 | Y9: 4.4 | Z9: 4.4 | AA9: 0.6 | AB9: 0.6 | AC9: 0.6 | AD9: 0.6 | AE9: 0.6 | AF9: 0.6 | AG9: 0.6 | AH9: 0.6 | AI9: 0.6 | AJ9: 0.6 | AK9: 0.6 | AL9: 0.6 | AM9: 0.6 | AN9: 118724 | AO9: =AB9*AN9 -> 71234.4 | AP9: 62690 | AQ9: =AC9*AP9 -> 37614 | AR9: 50367 | AS9: =AD9*AR9 -> 30220.2 | AT9: 38708 | AU9: =AE9*AT9 -> 23224.8 | AV9: 132419 | AW9: =AF9*AV9 -> 79451.4 | AX9: 127352 | AY9: =AG9*AX9 -> 76411.2 | AZ9: 116480 | BA9: =AH9*AZ9 -> 69888 | BB9: 133026 | BC9: =AI9*BB9 -> 79815.6 | BD9: 163850 | BE9: =AJ9*BD9 -> 98310 | BF9: 187965 | BG9: =AK9*BF9 -> 112779 | BH9: 133405 | BI9: =AL9*BH9 -> 80043 | BJ9: 148756 | BK9: =AM9*BJ9 -> 89253.6
A10: FY23 | B10: Iris Huang | C10: SUNREX | E10: NB | G10: 2020 | H10: DONGQIAN/DIANSHAN/PETROF/RABON/IONIAN/IRONOAK/KRAKEN/ROC/XUANWU/KNUCKER/PAN | I10: BL KB | J10: 14 | K10: FLINT OPAQUE | L10: W China | M10: QUANTA | N10: 14.9 | O10: 14.9 | P10: 14.9 | Q10: 14.9 | R10: 14.9 | S10: 14.9 | T10: 14.9 | U10: 14.9 | V10: 14.9 | W10: 14.9 | X10: 14.9 | Y10: 14.9 | Z10: 14.9 | AA10: 5 | AB10: 5 | AC10: 5 | AD10: 5 | AE10: 5.36 | AF10: 5.36 | AG10: 5.36 | AH10: 5.36 | AI10: 5.36 | AJ10: 5.36 | AK10: 5.36 | AL10: 5.36 | AM10: 6.17 | AN10: 34889 | AO10: =AB10*AN10 -> 174445 | AP10: 41656 | AQ10: =AC10*AP10 -> 208280 | AR10: 37451 | AS10: =AD10*AR10 -> 187255 | AT10: 57790 | AU10: =AE10*AT10 -> 309754.4 | AV10: 53728 | AW10: =AF10*AV10 -> 287982.08 | AX10: 42735 | AY10: =AG10*AX10 -> 229059.6 | AZ10: 55251 | BA10: =AH10*AZ10 -> 296145.36 | BB10: 63684 | BC10: =AI10*BB10 -> 341346.24 | BD10: 60669 | BE10: =AJ10*BD10 -> 325185.84 | BF10: 57771 | BG10: =AK10*BF10 -> 309652.56 | BH10: 56529 | BI10: =AL10*BH10 -> 302995.44 | BJ10: 50733 | BK10: =AM10*BJ10 -> 313022.61
A11: FY23 | B11: Iris Huang | C11: SUNREX | E11: NB | G11: 2020 | H11: DIANSHAN/PECONIC/RARITAN/IONIAN/IRONOAK/KRAKEN/ROC/XUANWU/KNUCKER/PAN | I11: NBL KB | J11: 15 | K11: FLINT OPAQUE | L11: W China | M11: QUANTA | N11: 4.5 | O11: 4.5 | P11: 4.5 | Q11: 4.5 | R11: 4.5 | S11: 4.5 | T11: 4.5 | U11: 4.5 | V11: 4.5 | W11: 4.5 | X11: 4.5 | Y11: 4.5 | Z11: 4.5 | AA11: 0.8 | AB11: 0.8 | AC11: 0.8 | AD11: 0.8 | AE11: 0.81 | AF11: 0.81 | AG11: 0.81 | AH11: 0.81 | AI11: 0.81 | AJ11: 0.81 | AK11: 0.81 | AL11: 0.81 | AM11: 0.81 | AN11: 20459 | AO11: =AB11*AN11 -> 16367.2 | AP11: 21253 | AQ11: =AC11*AP11 -> 17002.4 | AR11: 8018 | AS11: =AD11*AR11 -> 6414.4 | AT11: 17567 | AU11: =AE11*AT11 -> 14229.27 | AV11: 23995 | AW11: =AF11*AV11 -> 19435.95 | AX11: 12557 | AY11: =AG11*AX11 -> 10171.17 | AZ11: 30316 | BA11: =AH11*AZ11 -> 24555.96 | BB11: 33783 | BC11: =AI11*BB11 -> 27364.23 | BD11: 30469 | BE11: =AJ11*BD11 -> 24679.89 | BF11: 36347 | BG11: =AK11*BF11 -> 29441.07 | BH11: 41980 | BI11: =AL11*BH11 -> 34003.8 | BJ11: 92967 | BK11: =AM11*BJ11 -> 75303.27
A12: FY23 | B12: Iris Huang | C12: SUNREX | E12: NB | G12: 2020 | H12: DIANSHAN/PECONIC/RARITAN/IONIAN/IRONOAK/KRAKEN/ROC/XUANWU/KNUCKER/PAN | I12: BL KB | J12: 15 | K12: FLINT OPAQUE | L12: W China | M12: QUANTA | N12: 16.2 | O12: 16.2 | P12: 16.2 | Q12: 16.2 | R12: 16.2 | S12: 16.2 | T12: 16.2 | U12: 16.2 | V12: 16.2 | W12: 16.2 | X12: 16.2 | Y12: 16.2 | Z12: 16.2 | AA12: 6 | AB12: 6 | AC12: 6 | AD12: 6 | AE12: 6.36 | AF12: 6.36 | AG12: 6.36 | AH12: 6.36 | AI12: 6.36 | AJ12: 6.36 | AK12: 6.36 | AL12: 6.36 | AM12: 7.42 | AN12: 3374 | AO12: =AB12*AN12 -> 20244 | AP12: 5931 | AQ12: =AC12*AP12 -> 35586 | AR12: 11950 | AS12: =AD12*AR12 -> 71700 | AT12: 5624 | AU12: =AE12*AT12 -> 35768.64 | AV12: 7860 | AW12: =AF12*AV12 -> 49989.6 | AX12: 6165 | AY12: =AG12*AX12 -> 39209.4 | AZ12: 6434 | BA12: =AH12*AZ12 -> 40920.24 | BB12: 20179 | BC12: =AI12*BB12 -> 128338.44 | BD12: 12939 | BE12: =AJ12*BD12 -> 82292.04 | BF12: 11434 | BG12: =AK12*BF12 -> 72720.24 | BH12: 8505 | BI12: =AL12*BH12 -> 54091.8 | BJ12: 7520 | BK12: =AM12*BJ12 -> 55798.4
A13: FY23 | B13: Chris Chang | C13: SUNREX | E13: NB | G13: 2020 | H13: IONIAN/RABON/PRTROF/REEDS/DONGQIAN/DIANSHAN | I13: CLICKPAD | J13: 13/14 | K13: PIKE SILVER | L13: W China | M13: QUANTA | N13: 4.46 | O13: 4.46 | P13: 4.46 | Q13: 4.46 | R13: 4.46 | S13: 4.46 | T13: 4.46 | U13: 4.46 | V13: 4.46 | W13: 4.46 | X13: 4.46 | Y13: 4.46 | Z13: 4.46 | AA13: 0.05 | AB13: 0.05 | AC13: 0.05 | AD13: 0.05 | AE13: 0.05 | AF13: 0.05 | AG13: 0.05 | AH13: 0.05 | AI13: 0.05 | AJ13: 0.05 | AK13: 0.05 | AL13: 0.05 | AM13: 0.05 | AN13: 97560 | AO13: =AB13*AN13 -> 4878 | AP13: 45600 | AQ13: =AC13*AP13 -> 2280 | AR13: 38520 | AS13: =AD13*AR13 -> 1926 | AT13: 0 | AU13: =AE13*AT13 -> 0 | AV13: 8839 | AW13: =AF13*AV13 -> 441.95 | AX13: 1200 | AY13: =AG13*AX13 -> 60 | AZ13: 1880 | BA13: =AH13*AZ13 -> 94 | BB13: 3000 | BC13: =AI13*BB13 -> 150 | BD13: 720 | BE13: =AJ13*BD13 -> 36 | BF13: 2280 | BG13: =AK13*BF13 -> 114 | BH13: 0 | BI13: =AL13*BH13 -> 0 | BJ13: 960 | BK13: =AM13*BJ13 -> 48
A14: FY23 | B14: Chris Chang | C14: SUNREX | E14: NB | G14: 2020 | H14: IONIAN/RABON/PRTROF/REEDS | I14: CLICKPAD | J14: 13/14 | K14: PIKE SILVER | L14: W China | M14: QUANTA | N14: 4.5 | O14: 4.5 | P14: 4.5 | Q14: 4.5 | R14: 4.5 | S14: 4.5 | T14: 4.5 | U14: 4.5 | V14: 4.5 | W14: 4.5 | X14: 4.5 | Y14: 4.5 | Z14: 4.5 | AA14: 0.05 | AB14: 0.05 | AC14: 0.05 | AD14: 0.05 | AE14: 0.05 | AF14: 0.05 | AG14: 0.05 | AH14: 0.05 | AI14: 0.05 | AJ14: 0.05 | AK14: 0.05 | AL14: 0.05 | AM14: 0.05 | AN14: 2180 | AO14: =AB14*AN14 -> 109 | AP14: 460 | AQ14: =AC14*AP14 -> 23 | AR14: 3191 | AS14: =AD14*AR14 -> 159.55 | AT14: 5229 | AU14: =AE14*AT14 -> 261.45 | AV14: 0 | AW14: =AF14*AV14 -> 0 | AX14: 9120 | AY14: =AG14*AX14 -> 456 | AZ14: 5560 | BA14: =AH14*AZ14 -> 278 | BB14: 6436 | BC14: =AI14*BB14 -> 321.8 | BD14: 6360 | BE14: =AJ14*BD14 -> 318 | BF14: 14599 | BG14: =AK14*BF14 -> 729.95 | BH14: 13409 | BI14: =AL14*BH14 -> 670.45 | BJ14: 13359 | BK14: =AM14*BJ14 -> 667.95
A15: FY23 | B15: Chris Chang | C15: SUNREX | E15: NB | G15: 2022 | H15: THANS/THUNDRA/RONIN/PRIMA/DOOP/REDSTART/DARKSTAR | I15: CLICKPAD | J15: 13/14 | K15: PIKE SILVER | L15: W China | M15: QUANTA | N15: 4.46 | O15: 4.46 | P15: 4.46 | Q15: 4.46 | R15: 4.46 | S15: 4.46 | T15: 4.46 | U15: 4.46 | V15: 4.46 | W15: 4.46 | X15: 4.46 | Y15: 4.46 | Z15: 4.46 | AA15: 0.05 | AB15: 0.05 | AC15: 0.05 | AD15: 0.05 | AE15: 0.05 | AF15: 0.05 | AG15: 0.05 | AH15: 0.05 | AI15: 0.05 | AJ15: 0.05 | AK15: 0.05 | AL15: 0.05 | AM15: 0.05 | AN15: 386980 | AO15: =AB15*AN15 -> 19349 | AP15: 273120 | AQ15: =AC15*AP15 -> 13656 | AR15: 100080 | AS15: =AD15*AR15 -> 5004 | AT15: 250777 | AU15: =AE15*AT15 -> 12538.85 | AV15: 326040 | AW15: =AF15*AV15 -> 16302 | AX15: 336480 | AY15: =AG15*AX15 -> 16824 | AZ15: 266220 | BA15: =AH15*AZ15 -> 13311 | BB15: 288360 | BC15: =AI15*BB15 -> 14418 | BD15: 187560 | BE15: =AJ15*BD15 -> 9378 | BF15: 220968 | BG15: =AK15*BF15 -> 11048.4 | BH15: 161760 | BI15: =AL15*BH15 -> 8088 | BJ15: 143360 | BK15: =AM15*BJ15 -> 7168
A16: FY23 | B16: Chris Chang | C16: SUNREX | E16: NB | G16: 2023 | H16: KRAKEN/PAN/ROC/KNUCKER/KRAKEN/XUANWU | I16: CLICKPAD | J16: 13/14 | K16: PIKE SILVER | L16: W China | M16: QUANTA | N16: 4.46 | O16: 4.46 | P16: 4.46 | Q16: 4.46 | R16: 4.46 | S16: 4.46 | T16: 4.46 | U16: 4.46 | V16: 4.46 | W16: 4.46 | X16: 4.46 | Y16: 4.46 | Z16: 4.46 | AA16: 0 | AB16: 0 | AC16: 0 | AD16: 0 | AE16: 0 | AF16: 0.05 | AG16: 0.05 | AH16: 0.05 | AI16: 0.05 | AJ16: 0.05 | AK16: 0.05 | AL16: 0.05 | AM16: 0.05 | AN16: 0 | AO16: =AB16*AN16 -> 0 | AP16: 0 | AQ16: =AC16*AP16 -> 0 | AR16: 0 | AS16: =AD16*AR16 -> 0 | AT16: 0 | AU16: =AE16*AT16 -> 0 | AV16: 120 | AW16: =AF16*AV16 -> 6 | AX16: 23040 | AY16: =AG16*AX16 -> 1152 | AZ16: 73640 | BA16: =AH16*AZ16 -> 3682 | BB16: 144824 | BC16: =AI16*BB16 -> 7241.2 | BD16: 192360 | BE16: =AJ16*BD16 -> 9618 | BF16: 162600 | BG16: =AK16*BF16 -> 8130 | BH16: 237600 | BI16: =AL16*BH16 -> 11880 | BJ16: 291027 | BK16: =AM16*BJ16 -> 14551.35
A17: FY23 | C17: SUNREX | E17: NB | AO17: =AB17*AN17 -> 0 | AQ17: =AC17*AP17 -> 0 | AS17: =AD17*AR17 -> 0 | AU17: =AE17*AT17 -> 0 | AW17: =AF17*AV17 -> 0 | AY17: =AG17*AX17 -> 0 | BA17: =AH17*AZ17 -> 0 | BB17: 0 | BC17: =AI17*BB17 -> 0 | BE17: =AJ17*BD17 -> 0 | BF17: 0 | BG17: =AK17*BF17 -> 0 | BH17: 0 | BI17: =AL17*BH17 -> 0
A18: FY23 | C18: SUNREX | E18: NB | F18: 600 | AO18: =AB18*AN18 -> 0 | AQ18: =AC18*AP18 -> 0 | AS18: =AD18*AR18 -> 0 | AU18: =AE18*AT18 -> 0 | AW18: =AF18*AV18 -> 0 | AY18: =AG18*AX18 -> 0 | BA18: =AH18*AZ18 -> 0 | BC18: =AI18*BB18 -> 0 | BE18: =AJ18*BD18 -> 0 | BF18: 0 | BG18: =AK18*BF18 -> 0 | BH18: 0 | BI18: =AL18*BH18 -> 0 | BK18: =AM18*BJ18 -> 0
A19: FY23 | C19: SUNREX | E19: NB | AO19: =AB19*AN19 -> 0 | AQ19: =AC19*AP19 -> 0 | AS19: =AD19*AR19 -> 0 | AU19: =AE19*AT19 -> 0 | AW19: =AF19*AV19 -> 0 | AY19: =AG19*AX19 -> 0 | BA19: =AH19*AZ19 -> 0 | BC19: =AI19*BB19 -> 0 | BE19: =AJ19*BD19 -> 0 | BF19: 0 | BG19: =AK19*BF19 -> 0 | BH19: 0 | BI19: =AL19*BH19 -> 0 | BK19: =AM19*BJ19 -> 0
A20: FY23 | B20: Chris Chang | C20: SUNREX | E20: NB | F20: 800 | G20: 2021 | H20: WARPATH/LOCKHEED | I20: CLICKPAD | J20: 14 | K20: PIKE SILVER/NOUVELLE SILVER | L20: W China | M20: INVENTEC | N20: 8.12 | O20: 8.12 | P20: 8.12 | Q20: 8.12 | R20: 8.12 | S20: 8.12 | T20: 8.12 | U20: 8.12 | V20: 8.12 | W20: 8.12 | X20: 8.12 | Y20: 8.12 | Z20: 8.12 | AA20: 0 | AB20: 0.2 | AC20: 0.2 | AD20: 0.2 | AE20: 0.26 | AF20: 0.26 | AG20: 0.26 | AH20: 0.26 | AI20: 0.26 | AJ20: 0.26 | AK20: 0.26 | AL20: 0.26 | AM20: 0.26 | AN20: 21400 | AO20: =AB20*AN20 -> 4280 | AP20: 68700 | AQ20: =AC20*AP20 -> 13740 | AR20: 47920 | AS20: =AD20*AR20 -> 9584 | AT20: 92510 | AU20: =AE20*AT20 -> 24052.6 | AV20: 89506 | AW20: =AF20*AV20 -> 23271.56 | AX20: 70000 | AY20: =AG20*AX20 -> 18200 | AZ20: 95800 | BA20: =AH20*AZ20 -> 24908 | BB20: 70000 | BC20: =AI20*BB20 -> 18200 | BD20: 71304 | BE20: =AJ20*BD20 -> 18539.04 | BF20: 128477 | BG20: =AK20*BF20 -> 33404.02 | BH20: 41500 | BI20: =AL20*BH20 -> 10790 | BJ20: 102910 | BK20: =AM20*BJ20 -> 26756.6
A21: FY23 | B21: Chris Chang | C21: SUNREX | E21: NB | G21: 2023 | H21: LOX/WARG/LOXW | I21: CLICKPAD | J21: 14 | K21: PIKE SILVER/NOUVELLE SILVER | L21: W China | M21: INVENTEC | N21: 8.12 | O21: 8.12 | P21: 8.12 | Q21: 8.12 | R21: 8.12 | S21: 8.12 | T21: 8.12 | U21: 8.12 | V21: 8.12 | W21: 8.12 | X21: 8.12 | Y21: 8.12 | Z21: 8.12 | AA21: 0 | AB21: 0 | AC21: 0 | AD21: 0 | AE21: 0 | AF21: 0.26 | AG21: 0.26 | AH21: 0.26 | AI21: 0.26 | AJ21: 0.26 | AK21: 0.26 | AL21: 0.26 | AM21: 0.26 | AN21: 0 | AO21: =AB21*AN21 -> 0 | AP21: 0 | AQ21: =AC21*AP21 -> 0 | AR21: 0 | AS21: =AD21*AR21 -> 0 | AT21: 0 | AU21: =AE21*AT21 -> 0 | AV21: 3645 | AW21: =AF21*AV21 -> 947.7 | AX21: 3839 | AY21: =AG21*AX21 -> 998.14 | AZ21: 16200 | BA21: =AH21*AZ21 -> 4212 | BB21: 80301 | BC21: =AI21*BB21 -> 20878.26 | BD21: 29861 | BE21: =AJ21*BD21 -> 7763.86 | BF21: 83789 | BG21: =AK21*BF21 -> 21785.14 | BH21: 83899 | BI21: =AL21*BH21 -> 21813.74 | BJ21: 86040 | BK21: =AM21*BJ21 -> 22370.4
A22: FY23 | C22: SUNREX | E22: NB | AO22: =AB22*AN22 -> 0 | AQ22: =AC22*AP22 -> 0 | AS22: =AD22*AR22 -> 0 | AU22: =AE22*AT22 -> 0 | AW22: =AF22*AV22 -> 0 | AY22: =AG22*AX22 -> 0 | BA22: =AH22*AZ22 -> 0 | BB22: 0 | BC22: =AI22*BB22 -> 0 | BD22: 0 | BE22: =AJ22*BD22 -> 0 | BF22: 0 | BG22: =AK22*BF22 -> 0 | BH22: 0 | BI22: =AL22*BH22 -> 0 | BK22: =AM22*BJ22 -> 0
A23: FY23 | B23: Chris Chang | C23: SUNREX | E23: NB | F23: 1000 | G23: 2020 | H23: SPYKER | I23: CLICKPAD | J23: 14 | K23: PIKE SILVER | L23: E China | M23: COMPAL | N23: 6.94 | O23: 6.94 | P23: 6.94 | Q23: 6.94 | R23: 6.94 | S23: 6.94 | T23: 6.94 | U23: 6.94 | V23: 6.94 | W23: 6.94 | X23: 6.94 | Y23: 6.94 | Z23: 6.94 | AA23: 0.05 | AB23: 0.05 | AC23: 0.05 | AD23: 0.05 | AE23: 0.05 | AF23: 0.05 | AG23: 0.05 | AH23: 0.05 | AI23: 0.05 | AJ23: 0.05 | AK23: 0.05 | AL23: 0.05 | AM23: 0.05 | AN23: 9120 | AO23: =AB23*AN23 -> 456 | AP23: 1920 | AQ23: =AC23*AP23 -> 96 | AR23: 4200 | AS23: =AD23*AR23 -> 210 | AT23: 9600 | AU23: =AE23*AT23 -> 480 | AV23: 1920 | AW23: =AF23*AV23 -> 96 | AX23: 4440 | AY23: =AG23*AX23 -> 222 | AZ23: 0 | BA23: =AH23*AZ23 -> 0 | BB23: 3120 | BC23: =AI23*BB23 -> 156 | BD23: 720 | BE23: =AJ23*BD23 -> 36 | BF23: 0 | BG23: =AK23*BF23 -> 0 | BH23: 0 | BI23: =AL23*BH23 -> 0 | BJ23: 0 | BK23: =AM23*BJ23 -> 0
A24: FY23 | B24: Chris Chang | C24: SUNREX | E24: NB | G24: 2020 | H24: SPYKER | I24: CLICKPAD | J24: 13 | K24: PIKE SILVER | L24: E China | M24: COMPAL | N24: 6.69 | O24: 6.69 | P24: 6.69 | Q24: 6.69 | R24: 6.69 | S24: 6.69 | T24: 6.69 | U24: 6.69 | V24: 6.69 | W24: 6.69 | X24: 6.69 | Y24: 6.69 | Z24: 6.69 | AA24: 0.05 | AB24: 0.05 | AC24: 0.05 | AD24: 0.05 | AE24: 0.05 | AF24: 0.05 | AG24: 0.05 | AH24: 0.05 | AI24: 0.05 | AJ24: 0.05 | AK24: 0.05 | AL24: 0.05 | AM24: 0.05 | AN24: 11760 | AO24: =AB24*AN24 -> 588 | AP24: 0 | AQ24: =AC24*AP24 -> 0 | AR24: 10440 | AS24: =AD24*AR24 -> 522 | AT24: 0 | AU24: =AE24*AT24 -> 0 | AV24: 3600 | AW24: =AF24*AV24 -> 180 | AX24: 3000 | AY24: =AG24*AX24 -> 150 | AZ24: 0 | BA24: =AH24*AZ24 -> 0 | BB24: 0 | BC24: =AI24*BB24 -> 0 | BD24: 720 | BE24: =AJ24*BD24 -> 36 | BF24: 0 | BG24: =AK24*BF24 -> 0 | BH24: 0 | BI24: =AL24*BH24 -> 0 | BJ24: 0 | BK24: =AM24*BJ24 -> 0
A25: FY23 | B25: Chris Chang | C25: SUNREX | E25: NB | G25: 2019 | H25: SYLVA | I25: CLICKPAD | J25: 13 | K25: GALAXY BLUE | L25: W China | M25: INVENTEC | N25: 6.52 | O25: 6.52 | P25: 6.52 | Q25: 6.52 | R25: 6.52 | S25: 6.52 | T25: 6.52 | U25: 6.52 | V25: 6.52 | W25: 6.52 | X25: 6.52 | Y25: 6.52 | Z25: 6.52 | AA25: 0.1 | AB25: 0.1 | AC25: 0.1 | AD25: 0.1 | AE25: 0.1 | AF25: 0.1 | AG25: 0.1 | AH25: 0.1 | AI25: 0.1 | AJ25: 0.1 | AK25: 0.1 | AL25: 0.1 | AM25: 0.1 | AN25: 8040 | AO25: =AB25*AN25 -> 804 | AP25: 4800 | AQ25: =AC25*AP25 -> 480 | AR25: =960+60+8400 -> 9420 | AS25: =AD25*AR25 -> 942 | AT25: 5040 | AU25: =AE25*AT25 -> 504 | AV25: 0 | AW25: =AF25*AV25 -> 0 | AX25: 720 | AY25: =AG25*AX25 -> 72 | AZ25: 0 | BA25: =AH25*AZ25 -> 0 | BB25: 480 | BC25: =AI25*BB25 -> 48 | BD25: 240 | BE25: =AJ25*BD25 -> 24 | BF25: 0 | BG25: =AK25*BF25 -> 0 | BH25: 0 | BI25: =AL25*BH25 -> 0 | BJ25: 0 | BK25: =AM25*BJ25 -> 0
A26: FY23 | B26: Chris Chang | C26: SUNREX | E26: NB | G26: 2020 | H26: STARLIGHT | I26: CLICKPAD | J26: 13 | K26: SPARKING BLACK | L26: W China | M26: INVENTEC | N26: 6.53 | O26: 6.53 | P26: 6.53 | Q26: 6.53 | R26: 6.53 | S26: 6.53 | T26: 6.53 | U26: 6.53 | V26: 6.53 | W26: 6.53 | X26: 6.53 | Y26: 6.53 | Z26: 6.53 | AA26: 0.1 | AB26: 0.1 | AC26: 0.1 | AD26: 0.1 | AE26: 0.1 | AF26: 0.1 | AG26: 0.1 | AH26: 0.1 | AI26: 0.1 | AJ26: 0.1 | AK26: 0.1 | AL26: 0.1 | AM26: 0.1 | AN26: 0 | AO26: =AB26*AN26 -> 0 | AP26: 120 | AQ26: =AC26*AP26 -> 12 | AR26: 0 | AS26: =AD26*AR26 -> 0 | AT26: 0 | AU26: =AE26*AT26 -> 0 | AV26: 0 | AW26: =AF26*AV26 -> 0 | AY26: =AG26*AX26 -> 0 | AZ26: 0 | BA26: =AH26*AZ26 -> 0 | BB26: 0 | BC26: =AI26*BB26 -> 0 | BD26: 0 | BE26: =AJ26*BD26 -> 0 | BF26: 0 | BG26: =AK26*BF26 -> 0 | BH26: 0 | BI26: =AL26*BH26 -> 0 | BJ26: 0 | BK26: =AM26*BJ26 -> 0
A27: FY23 | B27: Chris Chang | C27: SUNREX | E27: NB | G27: 2021 | H27: STARFOX | I27: CLICKPAD | J27: 13 | K27: PIKE SILVER/SLATE BLUE | L27: W China | M27: INVENTEC | N27: 8.18 | O27: 8.18 | P27: 8.18 | Q27: 8.18 | R27: 8.18 | S27: 8.18 | T27: 8.18 | U27: 8.18 | V27: 8.18 | W27: 8.18 | X27: 8.18 | Y27: 8.18 | Z27: 8.18 | AA27: 0 | AB27: 0.25 | AC27: 0.25 | AD27: 0.25 | AE27: 0.31 | AF27: 0.31 | AG27: 0.31 | AH27: 0.31 | AI27: 0.31 | AJ27: 0.31 | AK27: 0.31 | AL27: 0.31 | AM27: 0.31 | AN27: 6908 | AO27: =AB27*AN27 -> 1727 | AP27: 4800 | AQ27: =AC27*AP27 -> 1200 | AR27: 10600 | AS27: =AD27*AR27 -> 2650 | AT27: 7200 | AU27: =AE27*AT27 -> 2232 | AV27: 9393 | AW27: =AF27*AV27 -> 2911.83 | AX27: 3096 | AY27: =AG27*AX27 -> 959.76 | AZ27: 10800 | BA27: =AH27*AZ27 -> 3348 | BB27: 9800 | BC27: =AI27*BB27 -> 3038 | BD27: 13324 | BE27: =AJ27*BD27 -> 4130.44 | BF27: 13416 | BG27: =AK27*BF27 -> 4158.96 | BH27: 25400 | BI27: =AL27*BH27 -> 7874 | BJ27: 12184 | BK27: =AM27*BJ27 -> 3777.04
A28: FY23 | C28: SUNREX | E28: NB | AO28: =AB28*AN28 -> 0 | AQ28: =AC28*AP28 -> 0 | AS28: =AD28*AR28 -> 0 | AU28: =AE28*AT28 -> 0 | AW28: =AF28*AV28 -> 0 | AY28: =AG28*AX28 -> 0 | BA28: =AH28*AZ28 -> 0 | BB28: 0 | BC28: =AI28*BB28 -> 0 | BD28: 0 | BE28: =AJ28*BD28 -> 0 | BF28: 0 | BG28: =AK28*BF28 -> 0 | BH28: 0 | BI28: =AL28*BH28 -> 0 | BJ28: 0 | BK28: =AM28*BJ28 -> 0
A29: FY23 | B29: Chris Chang | C29: SUNREX | E29: NB | F29: Probook | G29: 2020 | H29: GRIZZLY | I29: CLICKPAD | J29: 13 | K29: PIKE SILVER | L29: W China | M29: INVENTEC | N29: 6.69 | O29: 6.69 | P29: 6.69 | Q29: 6.69 | R29: 6.69 | S29: 6.69 | T29: 6.69 | U29: 6.69 | V29: 6.69 | W29: 6.69 | X29: 6.69 | Y29: 6.69 | Z29: 6.69 | AA29: 0.1 | AB29: 0.1 | AC29: 0.1 | AD29: 0.1 | AE29: 0.1 | AF29: 0.1 | AG29: 0.1 | AH29: 0.1 | AI29: 0.1 | AJ29: 0.1 | AK29: 0.1 | AL29: 0.1 | AM29: 0.1 | AN29: 3600 | AO29: =AB29*AN29 -> 360 | AP29: 3960 | AQ29: =AC29*AP29 -> 396 | AR29: 8400 | AS29: =AD29*AR29 -> 840 | AT29: 10212 | AU29: =AE29*AT29 -> 1021.2 | AV29: 9791 | AW29: =AF29*AV29 -> 979.1 | AX29: 1494 | AY29: =AG29*AX29 -> 149.4 | AZ29: 13083 | BA29: =AH29*AZ29 -> 1308.3 | BB29: 3488 | BC29: =AI29*BB29 -> 348.8 | BD29: 3293 | BE29: =AJ29*BD29 -> 329.3 | BF29: 9680 | BG29: =AK29*BF29 -> 968 | BH29: 1680 | BI29: =AL29*BH29 -> 168 | BJ29: 1200 | BK29: =AM29*BJ29 -> 120
A30: FY23 | C30: SUNREX | E30: NB | AO30: =AB30*AN30 -> 0 | AQ30: =AC30*AP30 -> 0 | AS30: =AD30*AR30 -> 0 | AU30: =AE30*AT30 -> 0 | AW30: =AF30*AV30 -> 0 | AY30: =AG30*AX30 -> 0 | BA30: =AH30*AZ30 -> 0 | BB30: 0 | BC30: =AI30*BB30 -> 0 | BE30: =AJ30*BD30 -> 0 | BF30: 0 | BG30: =AK30*BF30 -> 0 | BI30: =AL30*BH30 -> 0 | BK30: =AM30*BJ30 -> 0
A31: FY23 | C31: SUNREX | E31: NB | F31: Education | AO31: =AB31*AN31 -> 0 | AQ31: =AC31*AP31 -> 0 | AS31: =AD31*AR31 -> 0 | AU31: =AE31*AT31 -> 0 | AW31: =AF31*AV31 -> 0 | AY31: =AG31*AX31 -> 0 | BA31: =AH31*AZ31 -> 0 | BC31: =AI31*BB31 -> 0 | BE31: =AJ31*BD31 -> 0 | BF31: 0 | BG31: =AK31*BF31 -> 0 | BI31: =AL31*BH31 -> 0 | BK31: =AM31*BJ31 -> 0
A32: FY23 | C32: SUNREX | E32: NB | AO32: =AB32*AN32 -> 0 | AQ32: =AC32*AP32 -> 0 | AS32: =AD32*AR32 -> 0 | AU32: =AE32*AT32 -> 0 | AW32: =AF32*AV32 -> 0 | AY32: =AG32*AX32 -> 0 | BA32: =AH32*AZ32 -> 0 | BC32: =AI32*BB32 -> 0 | BE32: =AJ32*BD32 -> 0 | BF32: 0 | BG32: =AK32*BF32 -> 0 | BI32: =AL32*BH32 -> 0 | BK32: =AM32*BJ32 -> 0
A33: FY23 | C33: SUNREX | E33: NB | F33: MWS (Workstation) | AO33: =AB33*AN33 -> 0 | AQ33: =AC33*AP33 -> 0 | AS33: =AD33*AR33 -> 0 | AU33: =AE33*AT33 -> 0 | AW33: =AF33*AV33 -> 0 | AY33: =AG33*AX33 -> 0 | BA33: =AH33*AZ33 -> 0 | BC33: =AI33*BB33 -> 0 | BE33: =AJ33*BD33 -> 0 | BF33: 0 | BG33: =AK33*BF33 -> 0 | BI33: =AL33*BH33 -> 0 | BK33: =AM33*BJ33 -> 0
A34: FY23 | C34: SUNREX | E34: NB | AO34: =AB34*AN34 -> 0 | AQ34: =AC34*AP34 -> 0 | AS34: =AD34*AR34 -> 0 | AU34: =AE34*AT34 -> 0 | AW34: =AF34*AV34 -> 0 | AY34: =AG34*AX34 -> 0 | BA34: =AH34*AZ34 -> 0 | BC34: =AI34*BB34 -> 0 | BE34: =AJ34*BD34 -> 0 | BF34: 0 | BG34: =AK34*BF34 -> 0 | BI34: =AL34*BH34 -> 0 | BK34: =AM34*BJ34 -> 0
A35: FY23 | C35: SUNREX | E35: NB | F35: Soft Keyboard | AO35: =AB35*AN35 -> 0 | AQ35: =AC35*AP35 -> 0 | AS35: =AD35*AR35 -> 0 | AU35: =AE35*AT35 -> 0 | AW35: =AF35*AV35 -> 0 | AY35: =AG35*AX35 -> 0 | BA35: =AH35*AZ35 -> 0 | BC35: =AI35*BB35 -> 0 | BE35: =AJ35*BD35 -> 0 | BF35: 0 | BG35: =AK35*BF35 -> 0 | BI35: =AL35*BH35 -> 0 | BK35: =AM35*BJ35 -> 0
A36: FY23 | C36: SUNREX | E36: NB | AO36: =AB36*AN36 -> 0 | AQ36: =AC36*AP36 -> 0 | AS36: =AD36*AR36 -> 0 | AU36: =AE36*AT36 -> 0 | AW36: =AF36*AV36 -> 0 | AY36: =AG36*AX36 -> 0 | BA36: =AH36*AZ36 -> 0 | BC36: =AI36*BB36 -> 0 | BE36: =AJ36*BD36 -> 0 | BF36: 0 | BG36: =AK36*BF36 -> 0 | BI36: =AL36*BH36 -> 0 | BK36: =AM36*BJ36 -> 0
A37: FY23 | B37: Iris Huang | C37: SUNREX | E37: NB | F37: Chromebook | G37: 2020 | H37: AIRES | I37: NBL KB | J37: 14 | K37: JET BLACK/SNOW WHITE/DARKER LIGHT TEAL | L37: W China | M37: QUANTA | N37: 3.5 | O37: 3.5 | P37: 3.5 | Q37: 3.5 | R37: 3.5 | S37: 3.5 | T37: 3.5 | U37: 3.5 | V37: 3.5 | W37: 3.5 | X37: 3.5 | Y37: 3.5 | Z37: 3.5 | AA37: 0.77 | AB37: 0.77 | AC37: 0.77 | AD37: 0.77 | AE37: 0.77 | AF37: 0.77 | AG37: 0.77 | AH37: 0.77 | AI37: 0.77 | AJ37: 0.77 | AK37: 0.77 | AL37: 0.77 | AM37: 0.77 | AN37: 5557 | AO37: =AB37*AN37 -> 4278.89 | AP37: 1200 | AQ37: =AC37*AP37 -> 924 | AR37: 238 | AS37: =AD37*AR37 -> 183.26 | AT37: 4520 | AU37: =AE37*AT37 -> 3480.4 | AV37: 879 | AW37: =AF37*AV37 -> 676.83 | AX37: 3220 | AY37: =AG37*AX37 -> 2479.4 | AZ37: 1599 | BA37: =AH37*AZ37 -> 1231.23 | BB37: 2199 | BC37: =AI37*BB37 -> 1693.23 | BD37: 4113 | BE37: =AJ37*BD37 -> 3167.01 | BF37: 6478 | BG37: =AK37*BF37 -> 4988.06 | BH37: 0 | BI37: =AL37*BH37 -> 0 | BJ37: 3999 | BK37: =AM37*BJ37 -> 3079.23
A38: FY23 | B38: Iris Huang | C38: SUNREX | E38: NB | G38: 2020 | H38: AIRES | I38: BL KB | J38: 14 | K38: JET BLACK | L38: W China | M38: QUANTA | N38: 11.45 | O38: 11.45 | P38: 11.45 | Q38: 11.45 | R38: 11.45 | S38: 11.45 | T38: 11.45 | U38: 11.45 | V38: 11.45 | W38: 11.45 | X38: 11.45 | Y38: 11.45 | Z38: 11.45 | AA38: 2.2 | AB38: 2.2 | AC38: 2.2 | AD38: 2.2 | AE38: 2.2 | AF38: 2.2 | AG38: 2.2 | AH38: 2.2 | AI38: 2.2 | AJ38: 2.2 | AK38: 2.8 | AL38: 2.8 | AM38: 2.8 | AN38: 200 | AO38: =AB38*AN38 -> 440 | AP38: 0 | AQ38: =AC38*AP38 -> 0 | AR38: 40 | AS38: =AD38*AR38 -> 88 | AT38: 0 | AU38: =AE38*AT38 -> 0 | AV38: 0 | AW38: =AF38*AV38 -> 0 | AX38: 40 | AY38: =AG38*AX38 -> 88 | AZ38: 2720 | BA38: =AH38*AZ38 -> 5984 | BB38: 720 | BC38: =AI38*BB38 -> 1584 | BD38: 1079 | BE38: =AJ38*BD38 -> 2373.8 | BF38: 1865 | BG38: =AK38*BF38 -> 5222 | BH38: 0 | BI38: =AL38*BH38 -> 0 | BJ38: 2359 | BK38: =AM38*BJ38 -> 6605.2
A39: FY23 | B39: Iris Huang | C39: SUNREX | E39: NB | G39: 2020 | H39: AIRES | I39: BL KB | J39: 14 | K39: CERAMIC WHITE/DARKER LIGHT TEAL | L39: W China | M39: QUANTA | N39: 12.15 | O39: 12.15 | P39: 12.15 | Q39: 12.15 | R39: 12.15 | S39: 12.15 | T39: 12.15 | U39: 12.15 | V39: 12.15 | W39: 12.15 | X39: 12.15 | Y39: 12.15 | Z39: 12.15 | AA39: 2.2 | AB39: 2.2 | AC39: 2.2 | AD39: 2.2 | AE39: 2.2 | AF39: 2.2 | AG39: 2.2 | AH39: 2.2 | AI39: 2.2 | AJ39: 2.2 | AK39: 2.8 | AL39: 2.8 | AM39: 2.8 | AN39: 80 | AO39: =AB39*AN39 -> 176 | AP39: 0 | AQ39: =AC39*AP39 -> 0 | AR39: 0 | AS39: =AD39*AR39 -> 0 | AT39: 0 | AU39: =AE39*AT39 -> 0 | AV39: 0 | AW39: =AF39*AV39 -> 0 | AX39: 0 | AY39: =AG39*AX39 -> 0 | AZ39: 0 | BA39: =AH39*AZ39 -> 0 | BB39: 0 | BC39: =AI39*BB39 -> 0 | BD39: 0 | BE39: =AJ39*BD39 -> 0 | BF39: 0 | BG39: =AK39*BF39 -> 0 | BH39: 0 | BI39: =AL39*BH39 -> 0 | BJ39: 0 | BK39: =AM39*BJ39 -> 0
A40: FY23 | B40: Iris Huang | C40: SUNREX | E40: NB | G40: 2020 | H40: B52CHB/LEPUS | I40: NBL KB | J40: 14 | K40: SNOW WHITE/ASH GRAY /JACK BLACK | L40: W China | M40: QUANTA | N40: 3.5 | O40: 3.5 | P40: 3.5 | Q40: 3.5 | R40: 3.5 | S40: 3.5 | T40: 3.5 | U40: 3.5 | V40: 3.5 | W40: 3.5 | X40: 3.5 | Y40: 3.5 | Z40: 3.5 | AA40: 0.5 | AB40: 0.52 | AC40: 0.52 | AD40: 0.52 | AE40: 0.52 | AF40: 0.52 | AG40: 0.52 | AH40: 0.52 | AI40: 0.52 | AJ40: 0.52 | AK40: 0.52 | AL40: 0.52 | AM40: 0.52 | AN40: 2126 | AO40: =AB40*AN40 -> 1105.52 | AP40: 400 | AQ40: =AC40*AP40 -> 208 | AR40: 3101 | AS40: =AD40*AR40 -> 1612.52 | AT40: 200 | AU40: =AE40*AT40 -> 104 | AV40: 6398 | AW40: =AF40*AV40 -> 3326.96 | AX40: 6058 | AY40: =AG40*AX40 -> 3150.16 | AZ40: 8800 | BA40: =AH40*AZ40 -> 4576 | BB40: 1842 | BC40: =AI40*BB40 -> 957.84 | BD40: 5720 | BE40: =AJ40*BD40 -> 2974.4 | BF40: 8500 | BG40: =AK40*BF40 -> 4420 | BH40: 10449 | BI40: =AL40*BH40 -> 5433.48 | BJ40: 5049 | BK40: =AM40*BJ40 -> 2625.48
...

Sheet FY24 Summary_1
B3: Supplier's name | C3: 2023 11 | D3: 2023 12 | E3: 2024 01 | F3: Total Q1
B4: Rebate amount | C4: ='FY24'!AP1 -> 1067282.4 | D4: ='FY24'!AR1 -> 1488022.6 | E4: ='FY24'!AT1 -> 1241429.6 | F4: =SUM(C4:E4) -> 3796734.5
B5: E&O reduction | D5: 8663.94 | F5: =SUM(C5:E5) -> 8663.94
B6: Complexity reduction | F6: =SUM(C6:E6) -> 0 | H6: 1. 新增Summary_1, 原先的Summary重新命名為Summary_2
B7: Total amount | C7: =SUM(C4:C6) -> 1067282.4 | D7: =SUM(D4:D6) -> 1496686.5 | E7: =SUM(E4:E6) -> 1241429.6 | F7: =SUM(F4:F6) -> 3805398.4
H8: 2.黃色部位為貴司名稱, 請整份報告都跟檔名貴司名稱撰寫方式一致
B10: Supplier's name | C10: 2024 02 | D10: 2024 03 | E10: 2024 04 | F10: Total Q2 | H10: 3. 這些欄位一定要固定, B3-B28, C3-C28, D3-D28, E3-E28, F3-F28都有賦予定義
B11: Rebate amount | C11: ='FY24'!AV1 -> 1004453.2 | D11: ='FY24'!AX1 -> 1603764.8 | E11: ='FY24'!AZ1 -> 1390474 | F11: =SUM(C11:E11) -> 3998692
B12: E&O reduction | F12: =SUM(C12:E12) -> 0 | H12: 4. Rebate amount 指得是summary_2的page金額 (就是我們一直以來收集的金額)
B13: Complexity reduction | F13: =SUM(C13:E13) -> 0
B14: Total amount | C14: =SUM(C11:C13) -> 1004453.2 | D14: =SUM(D11:D13) -> 1603764.8 | E14: =SUM(E11:E13) -> 1390474 | F14: =SUM(F11:F13) -> 3998692 | H14: 5. 新增 E&O reduction 及complexity reduction品項, 先留足空間
H15: 若目前還未有此款項存在都先填0
B17: Supplier's name | C17: 2024 05 | D17: 2024 06 | E17: 2024 07 | F17: Total Q3 | H17: 6. 金額都放未經調整後的真實數字, 分析才具意義
B18: Rebate amount | C18: ='FY24'!BB1 -> 1367766.7 | D18: ='FY24'!BD1 -> 1210926.6 | E18: ='FY24'!BF1 -> 1197384.4 | F18: =SUM(C18:E18) -> 3776077.7
B19: E&O reduction | F19: =SUM(C19:E19) -> 0
B20: Complexity reduction | F20: =SUM(C20:E20) -> 0
B21: Total amount | C21: =SUM(C18:C20) -> 1367766.7 | D21: =SUM(D18:D20) -> 1210926.6 | E21: =SUM(E18:E20) -> 1197384.4 | F21: =SUM(F18:F20) -> 3776077.7
B24: Supplier's name | C24: 2024 08 | D24: 2024 09 | E24: 2024 10 | F24: Total Q4
B25: Rebate amount | C25: ='FY24'!BH1 -> 1179530.1 | D25: ='FY24'!BJ1 -> 1052763.2 | E25: ='FY24'!BL1 -> 829727.83 | F25: =SUM(C25:E25) -> 3062021.1
B26: E&O reduction | C26: 65640.07 | F26: =SUM(C26:E26) -> 65640.07
B27: Complexity reduction | F27: =SUM(C27:E27) -> 0
B28: Total amount | C28: =SUM(C25:C27) -> 1245170.2 | D28: =SUM(D25:D27) -> 1052763.2 | E28: =SUM(E25:E27) -> 829727.83 | F28: =SUM(F25:F27) -> 3127661.2

Sheet FY24 Summary_2
B3: Q1 Actual by Segment
C4: Segment | D4: 45231 | E4: 45261 | F4: 45292 | G4: Total Rebate in Q1 2024 (US$)
B5: CMIT Input Devices | C5: 200 series (6U) | D5: 10828.4 | E5: 16396.55 | F5: 10844.75 | G5: =SUM(D5:F5) -> 38069.7
C6: 400 series (S) | D6: 528543.24 | E6: 782115.18 | F6: 694863.35 | G6: =SUM(D6:F6) -> 2005521.8
C7: 600 series (B) | D7: 132135.81 | E7: 195528.8 | F7: 173715.84 | G7: =SUM(D7:F7) -> 501380.44
C8: 800 series (P) | G8: =SUM(D8:F8) -> 0
C9: 1000 series (M | G9: =SUM(D9:F9) -> 0
C10: MWS (Workstation) | G10: =SUM(D10:F10) -> 0
C11: Soft Keyboard | G11: =SUM(D11:F11) -> 0
C12: Chrome Book | D12: 24638.48 | E12: 91228.87 | F12: 32565.39 | G12: =SUM(D12:F12) -> 148432.74
C13: Clickpad | D13: 92993.66 | E13: 67906.52 | F13: 64922.26 | G13: =SUM(D13:F13) -> 225822.44
C14: Education | G14: =SUM(D14:F14) -> 0
C15: Peripherals/AMO | D15: 22489.6 | E15: 14423.8 | F15: 20067.8 | G15: =SUM(D15:F15) -> 56981.2
C16: Desktop | G16: =SUM(D16:F16) -> 0
B17: Consumer Input Devices | C17: OPP | D17: 78321.2 | E17: 96409.75 | F17: 95240.75 | G17: =SUM(D17:F17) -> 269971.7
C18: Chrome Book | G18: =SUM(D18:F18) -> 0
C19: Pavilion | D19: 159487 | E19: 205770.44 | F19: 137426.59 | G19: =SUM(D19:F19) -> 502684.03
C20: Spectre | G20: =SUM(D20:F20) -> 0
C21: Envy | D21: 13283.5 | E21: 8746.14 | F21: 4717.32 | G21: =SUM(D21:F21) -> 26746.96
C22: Stream | G22: =SUM(D22:F22) -> 0
C23: Omen | D23: 4561.5 | E23: 9496.5 | F23: 7065.5 | G23: =SUM(D23:F23) -> 21123.5
C24: Peripherals/AMO | G24: =SUM(D24:F24) -> 0
C25: Desktop | G25: =SUM(D25:F25) -> 0
G26: =SUM(G5:G25) -> 3796734.5
B28: Q1 Actual by Segment
C29: Supplier | D29: 45231 | E29: 45261 | F29: 45292 | G29: Total Rebate in Q1 2024 (US$)
B30: Input Devices | C30: Chicony
C31: Darfon
C32: Liteon
C33: Primax
C34: Sunrex | D34: =SUM(D5:D25) -> 1067282.4 | E34: =SUM(E5:E25) -> 1488022.6 | F34: =SUM(F5:F25) -> 1241429.6 | G34: =SUM(D34:F34) -> 3796734.5
B35: reserved | E35: 277191.56 | F35: 427802.33 | G35: =SUM(C35:F35) -> 704993.89
B36: E&O incentive | C36: Irwin | G36: 8663.94
C37: Total Q1 Rebate Amount Afer Adjustment | G37: =G34-G35+G36 -> 3100404.5
B39: Q2 Actual by Segment
C40: Segment | D40: 45323 | E40: 45352 | F40: 45383 | G40: Total Rebate in Q2 2024 (US$)
B41: CMIT Input Devices | C41: 200 series (6U) | D41: 26828.025 | E41: 36721.65 | F41: 28012.875 | G41: =SUM(D41:F41) -> 91562.55
C42: 400 series (S) | D42: 509203.67 | E42: 785199.8 | F42: 752750.62 | G42: =SUM(D42:F42) -> 2047154.1
C43: 600 series (B) | D43: 127300.92 | E43: 196299.95 | F43: 188187.65 | G43: =SUM(D43:F43) -> 511788.52
C44: 800 series (P) | G44: =SUM(D44:F44) -> 0
...

Sheet FY24
D1: Consumer/Commercial/ Peripheral | E1: NB/DT/Peripherals/Chromebook | G1: 2020/2021/2022 | H1: Remove Size/Color, define Platform naming Hagrid/Hedwig/Granger/Ashmore/Ramla (follow naming rule of product list) | I1: NBL KB/BL KB/Mouse /Combo/Clickpad/Others | J1: NA/ | K1: NA/ | L1: (E China/W China/S China/NMC) | M1: COMPAL/ QUANTA /INVENTEC /WISTRON/ FOXCONN/ OTHERS | AC1: =SUM(AC3:AC148) -> 271.91 | AD1: =SUM(AD3:AD148) -> 291.5 | AE1: =SUM(AE3:AE148) -> 291.5 | AF1: =SUM(AF3:AF148) -> 295.1 | AG1: =SUM(AG3:AG148) -> 297.05 | AH1: =SUM(AH3:AH148) -> 304.75 | AI1: =SUM(AI3:AI148) -> 337.33 | AJ1: =SUM(AJ3:AJ148) -> 337.33 | ... AN1: =SUM(AN3:AN148) -> 339.51 | AP1: =SUM(AP3:AP1036) -> 1067282.4 | AR1: =SUM(AR3:AR1036) -> 1488022.6 | AT1: =SUM(AT3:AT1036) -> 1241429.6 | AV1: =SUM(AV3:AV1036) -> 1004453.2 | AX1: =SUM(AX3:AX1036) -> 1603764.8 | AZ1: =SUM(AZ3:AZ1036) -> 1390474 | BB1: =SUM(BB3:BB1036) -> 1367766.7 | BD1: =SUM(BD3:BD1036) -> 1210926.6 | BF1: =SUM(BF3:BF1036) -> 1197384.4 | BH1: =SUM(BH3:BH1036) -> 1179530.1 | BJ1: =SUM(BJ3:BJ1036) -> 1052763.2 | BL1: =SUM(BL3:BL1036) -> 829727.83 | BO1: NA/EMEA/APJ/OTHER
A2: FY24 | B2: SPM (Project Owner) | C2: GTK Suppliers | D2: Category | E2: Segment | F2: Series | G2: Production Year | H2: Platforms | I2: Product | J2: Size | K2: Color | L2: Location | M2: ODM | N2: RFQ Final Cost | O2: The lowest unit table price (ODM cost) | P2: Table Price Nov | Q2: Table Price Dec | R2: Table Price Jan | S2: Table Price Feb | T2: Table Price Mar | U2: Table Price Apr | V2: Table Price May | W2: Table Price Jun | X2: Table Price Jul | Y2: Table Price Aug | Z2: Table Price Sep | AA2: Table Price Oct | AB2: The lowest unit rebate cost | AC2: Unit Rebate Nov | AD2: Unit Rebate Dec | AE2: Unit Rebate Jan | AF2: Unit Rebate Feb | AG2: Unit Rebate Mar | AH2: Unit Rebate Apr | AI2: Unit Rebate May | AJ2: Unit Rebate Jun | AK2: Unit Rebate Jul | AL2: Unit Rebate Aug | AM2: Unit Rebate Sep | AN2: Unit Rebate Oct | AO2: Nov Q'ty | AP2: Nov Rebate Amount | AQ2: Dec Q'ty | AR2: Dec Rebate Amount | AS2: Jan Q'ty | AT2: Jan Rebate Amount | AU2: Feb Q'ty | AV2: Feb Rebate Amount | AW2: Mar Q'ty | AX2: Mar Rebate Amount | AY2: Apr Q'ty | AZ2: Apr Rebate Amount | BA2: May Q'ty | BB2: May Rebate Amount | BC2: Jun Q'ty | BD2: Jun Rebate Amount | BE2: Jul Q'ty | BF2: Jul Rebate Amount | BG2: Aug Q'ty | BH2: Aug Rebate Amount | BI2: Sep Q'ty | BJ2: Sep Rebate Amount | BK2: Oct Q'ty | BL2: Oct Rebate Amount | BM2: Supplier Part# | BN2: Comment | BO2: Region
A3: FY24 | C3: SUNREX | D3: Commercial | E3: NB | F3: 200 | AP3: =AC3*AO3 -> 0 | AR3: =AD3*AQ3 -> 0 | AT3: =AE3*AS3 -> 0 | AV3: =AF3*AU3 -> 0 | AX3: =AG3*AW3 -> 0 | AZ3: =AH3*AY3 -> 0 | BB3: =AI3*BA3 -> 0 | BD3: =AJ3*BC3 -> 0 | BF3: =AK3*BE3 -> 0 | BH3: =AL3*BG3 -> 0 | BJ3: =AM3*BI3 -> 0 | BL3: =AN3*BK3 -> 0
A4: FY24 | C4: SUNREX | E4: NB | AP4: =AC4*AO4 -> 0 | AR4: =AD4*AQ4 -> 0 | AT4: =AE4*AS4 -> 0 | AV4: =AF4*AU4 -> 0 | AX4: =AG4*AW4 -> 0 | AZ4: =AH4*AY4 -> 0 | BB4: =AI4*BA4 -> 0 | BD4: =AJ4*BC4 -> 0 | BF4: =AK4*BE4 -> 0 | BH4: =AL4*BG4 -> 0 | BJ4: =AM4*BI4 -> 0 | BL4: =AN4*BK4 -> 0
A5: FY24 | B5: Sandy Lu | C5: SUNREX | E5: NB | F5: 400/600 | G5: 2021 | H5: PRIMROSE/PEPPER/PIXIE/PAX | I5: NBL KB | J5: 13 | K5: FLINT OPAQUE | L5: W China | M5: INVENTEC | N5: 3.25 | O5: 4.4 | P5: 4.4 | Q5: 4.4 | R5: 4.4 | S5: 4.4 | T5: 4.4 | U5: 4.4 | V5: 4.31 | W5: 4.31 | X5: 4.31 | Y5: 4.31 | Z5: 4.31 | AA5: 4.31 | AB5: 0.73 | AC5: 0.73 | AD5: 0.73 | AE5: 0.73 | AF5: 0.73 | AG5: 0.73 | AH5: 0.73 | AI5: 1.07 | AJ5: 1.07 | AK5: 1.07 | AL5: 1.07 | AM5: 1.07 | AN5: 1.07 | AO5: 3721 | AP5: =AC5*AO5 -> 2716.33 | AQ5: 2920 | AR5: =AD5*AQ5 -> 2131.6 | AS5: 2440 | AT5: =AE5*AS5 -> 1781.2 | AU5: 2840 | AV5: =AF5*AU5 -> 2073.2 | AW5: 3580 | AX5: =AG5*AW5 -> 2613.4 | AY5: 3200 | AZ5: =AH5*AY5 -> 2336 | BA5: 6680 | BB5: =AI5*BA5 -> 7147.6 | BC5: 3760 | BD5: =AJ5*BC5 -> 4023.2 | BE5: 2520 | BF5: =AK5*BE5 -> 2696.4 | BG5: 2100 | BH5: =AL5*BG5 -> 2247 | BI5: 2760 | BJ5: =AM5*BI5 -> 2953.2 | BK5: 3200 | BL5: =AN5*BK5 -> 3424
A6: FY24 | B6: Sandy Lu | C6: SUNREX | E6: NB | G6: 2021 | H6: PRIMROSE/PEPPER/PIXIE/PAX | I6: BL KB | J6: 13 | K6: FLINT OPAQUE | L6: W China | M6: INVENTEC | N6: 8.95 | O6: 14.9 | P6: 14.9 | Q6: 14.9 | R6: 14.9 | S6: 14.9 | T6: 14.9 | U6: 14.9 | V6: 13.04 | W6: 13.04 | X6: 13.04 | Y6: 13.04 | Z6: 13.04 | AA6: 13.04 | AB6: 6.79 | AC6: 6.79 | AD6: 6.79 | AE6: 6.79 | AF6: 6.79 | AG6: 6.79 | AH6: 6.79 | AI6: 4.99 | AJ6: 4.99 | AK6: 4.99 | AL6: 4.99 | AM6: 4.99 | AN6: 4.99 | AO6: 3479 | AP6: =AC6*AO6 -> 23622.41 | AQ6: 1399 | AR6: =AD6*AQ6 -> 9499.21 | AS6: 1039 | AT6: =AE6*AS6 -> 7054.81 | AU6: 759 | AV6: =AF6*AU6 -> 5153.61 | AW6: 1180 | AX6: =AG6*AW6 -> 8012.2 | AY6: 1720 | AZ6: =AH6*AY6 -> 11678.8 | BA6: 960 | BB6: =AI6*BA6 -> 4790.4 | BC6: 2518 | BD6: =AJ6*BC6 -> 12564.82 | BE6: 1080 | BF6: =AK6*BE6 -> 5389.2 | BG6: 1100 | BH6: =AL6*BG6 -> 5489 | BI6: 1559 | BJ6: =AM6*BI6 -> 7779.41 | BK6: 1920 | BL6: =AN6*BK6 -> 9580.8
A7: FY24 | B7: Sandy Lu | C7: SUNREX | E7: NB | G7: 2020 | H7: DIANSHAN/REEDS/IONIAN/KRAKEN | I7: NBL KB | J7: 13 | K7: FLINT OPAQUE | L7: W China | M7: QUANTA | N7: 3.25 | O7: 4.4 | P7: 4.4 | Q7: 4.4 | R7: 4.4 | S7: 4.4 | T7: 4.4 | U7: 4.4 | V7: 4.31 | W7: 4.31 | X7: 4.31 | Y7: 4.31 | Z7: 4.31 | AA7: 4.31 | AB7: 0.2 | AC7: 0.25 | AD7: 0.25 | AE7: 0.25 | AF7: 0.25 | AG7: 0.25 | AH7: 0.25 | AI7: 1.07 | AJ7: 1.07 | AK7: 1.07 | AL7: 1.07 | AM7: 1.07 | AN7: 1.07 | AO7: 45982 | AP7: =AC7*AO7 -> 11495.5 | AQ7: 9350 | AR7: =AD7*AQ7 -> 2337.5 | AS7: 29425 | AT7: =AE7*AS7 -> 7356.25 | AU7: 11502 | AV7: =AF7*AU7 -> 2875.5 | AW7: 15142 | AX7: =AG7*AW7 -> 3785.5 | AY7: 8060 | AZ7: =AH7*AY7 -> 2015 | BA7: 13683 | BB7: =AI7*BA7 -> 14640.81 | BC7: 16080 | BD7: =AJ7*BC7 -> 17205.6 | BE7: 10837 | BF7: =AK7*BE7 -> 11595.59 | BG7: 13240 | BH7: =AL7*BG7 -> 14166.8 | BI7: 12880 | BJ7: =AM7*BI7 -> 13781.6 | BK7: 28108 | BL7: =AN7*BK7 -> 30075.56
A8: FY24 | B8: Sandy Lu | C8: SUNREX | E8: NB | G8: 2020 | H8: DIANSHAN/REEDS/IONIAN/KRAKEN | I8: BL KB | J8: 13 | K8: FLINT OPAQUE | L8: W China | M8: QUANTA | N8: 8.95 | O8: 14.9 | P8: 14.9 | Q8: 14.9 | R8: 14.9 | S8: 14.9 | T8: 14.9 | U8: 14.9 | V8: 13.04 | W8: 13.04 | X8: 13.04 | Y8: 13.04 | Z8: 13.04 | AA8: 13.04 | AB8: 4.5 | AC8: 5.22 | AD8: 5.22 | AE8: 5.22 | AF8: 5.22 | AG8: 5.22 | AH8: 5.22 | AI8: 4.99 | AJ8: 4.99 | AK8: 4.99 | AL8: 4.99 | AM8: 4.99 | AN8: 4.99 | AO8: 9605 | AP8: =AC8*AO8 -> 50138.1 | AQ8: 8328 | AR8: =AD8*AQ8 -> 43472.16 | AS8: 25353 | AT8: =AE8*AS8 -> 132342.66 | AU8: 3203 | AV8: =AF8*AU8 -> 16719.66 | AW8: 9258 | AX8: =AG8*AW8 -> 48326.76 | AY8: 9885 | AZ8: =AH8*AY8 -> 51599.7 | BA8: 7203 | BB8: =AI8*BA8 -> 35942.97 | BC8: 5720 | BD8: =AJ8*BC8 -> 28542.8 | BE8: 4884 | BF8: =AK8*BE8 -> 24371.16 | BG8: 1680 | BH8: =AL8*BG8 -> 8383.2 | BI8: 3120 | BJ8: =AM8*BI8 -> 15568.8 | BK8: 3394 | BL8: =AN8*BK8 -> 16936.06
A9: FY24 | B9: Sandy Lu | C9: SUNREX | E9: NB | G9: 2020 | H9: DONGQIAN/DIANSHAN/PETROF/RABON/IONIAN/IRONOAK/KRAKEN/ROC/XUANWU/KNUCKER/PAN | I9: NBL KB | J9: 14 | K9: FLINT OPAQUE | L9: W China | M9: QUANTA | N9: 3.64 | O9: 4.4 | P9: 4.4 | Q9: 4.4 | R9: 4.4 | S9: 4.4 | T9: 4.4 | U9: 4.4 | V9: 4.31 | W9: 4.31 | X9: 4.31 | Y9: 4.31 | Z9: 4.31 | AA9: 4.31 | AB9: 0.6 | AC9: 0.76 | AD9: 0.76 | AE9: 0.76 | AF9: 0.76 | AG9: 0.76 | AH9: 0.76 | AI9: 0.69 | AJ9: 0.69 | AK9: 0.69 | AL9: 0.69 | AM9: 0.69 | AN9: 0.69 | AO9: 127260 | AP9: =AC9*AO9 -> 96717.6 | AQ9: 81205 | AR9: =AD9*AQ9 -> 61715.8 | AS9: 83101 | AT9: =AE9*AS9 -> 63156.76 | AU9: 66282 | AV9: =AF9*AU9 -> 50374.32 | AW9: 104309 | AX9: =AG9*AW9 -> 79274.84 | AY9: 119396 | AZ9: =AH9*AY9 -> 90740.96 | BA9: 96626 | BB9: =AI9*BA9 -> 66671.94 | BC9: 71903 | BD9: =AJ9*BC9 -> 49613.07 | BE9: 107308 | BF9: =AK9*BE9 -> 74042.52 | BG9: 71845 | BH9: =AL9*BG9 -> 49573.05 | BI9: 66879 | BJ9: =AM9*BI9 -> 46146.51 | BK9: 66711 | BL9: =AN9*BK9 -> 46030.59
A10: FY24 | B10: Sandy Lu | C10: SUNREX | E10: NB | G10: 2020 | H10: DONGQIAN/DIANSHAN/PETROF/RABON/IONIAN/IRONOAK/KRAKEN/ROC/XUANWU/KNUCKER/PAN | I10: BL KB | J10: 14 | K10: FLINT OPAQUE | L10: W China | M10: QUANTA | N10: 8.73 | O10: 14.9 | P10: 14.9 | Q10: 14.9 | R10: 14.9 | S10: 14.9 | T10: 14.9 | U10: 14.9 | V10: 13.04 | W10: 13.04 | X10: 13.04 | Y10: 13.04 | Z10: 13.04 | AA10: 13.04 | AB10: 5 | AC10: 6.17 | AD10: 6.17 | AE10: 6.17 | AF10: 6.17 | AG10: 6.17 | AH10: 6.17 | AI10: 5.06 | AJ10: 5.06 | AK10: 5.06 | AL10: 5.06 | AM10: 5.06 | AN10: 5.06 | AO10: 60032 | AP10: =AC10*AO10 -> 370397.44 | AQ10: 104211 | AR10: =AD10*AQ10 -> 642981.87 | AS10: 83046 | AT10: =AE10*AS10 -> 512393.82 | AU10: 63598 | AV10: =AF10*AU10 -> 392399.66 | AW10: 100314 | AX10: =AG10*AW10 -> 618937.38 | AY10: 106745 | AZ10: =AH10*AY10 -> 658616.65 | BA10: 97052 | BB10: =AI10*BA10 -> 491083.12 | BC10: 70993 | BD10: =AJ10*BC10 -> 359224.58 | BE10: 121070 | BF10: =AK10*BE10 -> 612614.2 | BG10: 76791 | BH10: =AL10*BG10 -> 388562.46 | BI10: 53509 | BJ10: =AM10*BI10 -> 270755.54 | BK10: 53471 | BL10: =AN10*BK10 -> 270563.26
A11: FY24 | B11: Sandy Lu | C11: SUNREX | E11: NB | G11: 2020 | H11: DIANSHAN/PECONIC/RARITAN/IONIAN/IRONOAK/KRAKEN/ROC/XUANWU/KNUCKER/PAN | I11: NBL KB | J11: 15 | K11: FLINT OPAQUE | L11: W China | M11: QUANTA | N11: 3.69 | O11: 4.5 | P11: 4.5 | Q11: 4.5 | R11: 4.5 | S11: 4.5 | T11: 4.5 | U11: 4.5 | V11: 4.41 | W11: 4.41 | X11: 4.41 | Y11: 4.41 | Z11: 4.41 | AA11: 4.41 | AB11: 0.8 | AC11: 0.81 | AD11: 0.81 | AE11: 0.81 | AF11: 0.81 | AG11: 0.81 | AH11: 0.81 | AI11: 0.74 | AJ11: 0.74 | AK11: 0.74 | AL11: 0.74 | AM11: 0.74 | AN11: 0.74 | AO11: 36007 | AP11: =AC11*AO11 -> 29165.67 | AQ11: 26528 | AR11: =AD11*AQ11 -> 21487.68 | AS11: 18271 | AT11: =AE11*AS11 -> 14799.51 | AU11: 19644 | AV11: =AF11*AU11 -> 15911.64 | AW11: 25473 | AX11: =AG11*AW11 -> 20633.13 | AY11: 19986 | AZ11: =AH11*AY11 -> 16188.66 | BA11: 18416 | BB11: =AI11*BA11 -> 13627.84 | BC11: 12109 | BD11: =AJ11*BC11 -> 8960.66 | BE11: 7030 | BF11: =AK11*BE11 -> 5202.2 | BG11: 27996 | BH11: =AL11*BG11 -> 20717.04 | BI11: 14118 | BJ11: =AM11*BI11 -> 10447.32 | BK11: 15796 | BL11: =AN11*BK11 -> 11689.04
A12: FY24 | B12: Sandy Lu | C12: SUNREX | E12: NB | G12: 2020 | H12: DIANSHAN/PECONIC/RARITAN/IONIAN/IRONOAK/KRAKEN/ROC/XUANWU/KNUCKER/PAN | I12: BL KB | J12: 15 | K12: FLINT OPAQUE | L12: W China | M12: QUANTA | N12: 8.78 | O12: 16.2 | P12: 16.2 | Q12: 16.2 | R12: 16.2 | S12: 16.2 | T12: 16.2 | U12: 16.2 | V12: 14.18 | W12: 14.18 | X12: 14.18 | Y12: 14.18 | Z12: 14.18 | AA12: 14.18 | AB12: 6 | AC12: 7.42 | AD12: 7.42 | AE12: 7.42 | AF12: 7.42 | AG12: 7.42 | AH12: 7.42 | AI12: 5.97 | AJ12: 5.97 | AK12: 5.97 | AL12: 5.97 | AM12: 5.97 | AN12: 5.97 | AO12: 10300 | AP12: =AC12*AO12 -> 76426 | AQ12: 26148 | AR12: =AD12*AQ12 -> 194018.16 | AS12: 17479 | AT12: =AE12*AS12 -> 129694.18 | AU12: 20350 | AV12: =AF12*AU12 -> 150997 | AW12: 13692 | AX12: =AG12*AW12 -> 101594.64 | AY12: 7895 | AZ12: =AH12*AY12 -> 58580.9 | BA12: 5255 | BB12: =AI12*BA12 -> 31372.35 | BC12: 3920 | BD12: =AJ12*BC12 -> 23402.4 | BE12: 2320 | BF12: =AK12*BE12 -> 13850.4 | BG12: 3282 | BH12: =AL12*BG12 -> 19593.54 | BI12: 4069 | BJ12: =AM12*BI12 -> 24291.93 | BK12: 5792 | BL12: =AN12*BK12 -> 34578.24
A13: FY24 | B13: Sandy Lu | C13: SUNREX | E13: NB | G13: 2020 | H13: DIANSHAN/PECONIC/RARITAN/IONIAN/IRONOAK/KRAKEN/ROC/XUANWU/KNUCKER/PAN | I13: NBL KB | J13: 15 | K13: FLINT OPAQUE | L13: NMC | M13: QUANTA | N13: 3.69 | O13: 4.5 | P13: 4.5 | Q13: 4.5 | R13: 4.5 | S13: 4.5 | T13: 4.5 | U13: 4.5 | V13: 4.41 | W13: 4.41 | X13: 4.41 | Y13: 4.41 | Z13: 4.41 | AA13: 4.41 | AB13: =0.81-0.39 -> 0.42 | AC13: 0 | AD13: 0.42 | AE13: 0.42 | AF13: 0.42 | AG13: 0.81 | AH13: 0.81 | AI13: 0.74 | AJ13: 0.74 | AK13: 0.74 | AL13: 0.74 | AM13: 0.74 | AN13: 0.74 | AO13: 0 | AP13: =AC13*AO13 -> 0 | AQ13: 0 | AR13: =AD13*AQ13 -> 0 | AS13: 0 | AT13: =AE13*AS13 -> 0 | AU13: 0 | AV13: =AF13*AU13 -> 0 | AW13: 5230 | AX13: =AG13*AW13 -> 4236.3 | AY13: 8320 | AZ13: =AH13*AY13 -> 6739.2 | BA13: 6680 | BB13: =AI13*BA13 -> 4943.2 | BC13: 6318 | BD13: =AJ13*BC13 -> 4675.32 | BE13: 12988 | BF13: =AK13*BE13 -> 9611.12 | BG13: 2555 | BH13: =AL13*BG13 -> 1890.7 | BI13: 1880 | BJ13: =AM13*BI13 -> 1391.2 | BK13: 0 | BL13: =AN13*BK13 -> 0
A14: FY24 | B14: Sandy Lu | C14: SUNREX | E14: NB | G14: 2020 | H14: DIANSHAN/PECONIC/RARITAN/IONIAN/IRONOAK/KRAKEN/ROC/XUANWU/KNUCKER/PAN | I14: BL KB | J14: 15 | K14: FLINT OPAQUE | L14: NMC | M14: QUANTA | N14: 8.78 | O14: 16.2 | P14: 16.2 | Q14: 16.2 | R14: 16.2 | S14: 16.2 | T14: 16.2 | U14: 16.2 | V14: 14.18 | W14: 14.18 | X14: 14.18 | Y14: 14.18 | Z14: 14.18 | AA14: 14.18 | AB14: =7.42-0.39 -> 7.03 | AC14: 0 | AD14: 7.03 | AE14: 7.03 | AF14: 7.03 | AG14: 7.42 | AH14: 7.42 | AI14: 5.97 | AJ14: 5.97 | AK14: 5.97 | AL14: 5.97 | AM14: 5.97 | AN14: 5.97 | AO14: 0 | AP14: =AC14*AO14 -> 0 | AQ14: 0 | AR14: =AD14*AQ14 -> 0 | AS14: 0 | AT14: =AE14*AS14 -> 0 | AU14: 0 | AV14: =AF14*AU14 -> 0 | AW14: 12680 | AX14: =AG14*AW14 -> 94085.6 | AY14: 5720 | AZ14: =AH14*AY14 -> 42442.4 | BA14: 7440 | BB14: =AI14*BA14 -> 44416.8 | BC14: 10120 | BD14: =AJ14*BC14 -> 60416.4 | BE14: 5740 | BF14: =AK14*BE14 -> 34267.8 | BG14: 4333 | BH14: =AL14*BG14 -> 25868.01 | BI14: 0 | BJ14: =AM14*BI14 -> 0 | BK14: 0 | BL14: =AN14*BK14 -> 0
A15: FY24 | B15: Mandy Yu | C15: SUNREX | E15: NB | G15: 2020 | H15: IONIAN/RABON/PRTROF/REEDS/DONGQIAN/DIANSHAN | I15: CLICKPAD | J15: 13/14 | K15: PIKE SILVER | L15: W China | M15: QUANTA | N15: 4.38 | O15: 4.46 | P15: 4.46 | Q15: 4.46 | R15: 4.46 | S15: 4.46 | T15: 4.46 | U15: 4.46 | V15: 4.46 | W15: 4.46 | X15: 4.46 | Y15: 4.46 | Z15: 4.46 | AA15: 4.46 | AB15: 0.05 | AC15: 0.05 | AD15: 0.05 | AE15: 0.05 | AF15: 0.05 | AG15: 0.05 | AH15: 0.05 | AI15: 0.05 | AJ15: 0.05 | AK15: 0.05 | AL15: 0.05 | AM15: 0.05 | AN15: 0.05 | AO15: 720 | AP15: =AC15*AO15 -> 36 | AQ15: 600 | AR15: =AD15*AQ15 -> 30 | AS15: 600 | AT15: =AE15*AS15 -> 30 | AU15: 480 | AV15: =AF15*AU15 -> 24 | AW15: 0 | AX15: =AG15*AW15 -> 0 | AY15: 600 | AZ15: =AH15*AY15 -> 30 | BA15: 840 | BB15: =AI15*BA15 -> 42 | BC15: 0 | BD15: =AJ15*BC15 -> 0 | BE15: 0 | BF15: =AK15*BE15 -> 0 | BG15: 0 | BH15: =AL15*BG15 -> 0 | BI15: 0 | BJ15: =AM15*BI15 -> 0 | BK15: 0 | BL15: =AN15*BK15 -> 0
A16: FY24 | B16: Mandy Yu | C16: SUNREX | E16: NB | G16: 2020 | H16: IONIAN/RABON/PRTROF/REEDS | I16: CLICKPAD | J16: 13/14 | K16: PIKE SILVER | L16: W China | M16: QUANTA | N16: 4.42 | O16: 4.5 | P16: 4.5 | Q16: 4.5 | R16: 4.5 | S16: 4.5 | T16: 4.5 | U16: 4.5 | V16: 4.5 | W16: 4.5 | X16: 4.5 | Y16: 4.5 | Z16: 4.5 | AA16: 4.5 | AB16: 0.05 | AC16: 0.05 | AD16: 0.05 | AE16: 0.05 | AF16: 0.05 | AG16: 0.05 | AH16: 0.05 | AI16: 0.05 | AJ16: 0.05 | AK16: 0.05 | AL16: 0.05 | AM16: 0.05 | AN16: 0.05 | AO16: 0 | AP16: =AC16*AO16 -> 0 | AQ16: 440 | AR16: =AD16*AQ16 -> 22 | AS16: 550 | AT16: =AE16*AS16 -> 27.5 | AU16: 1100 | AV16: =AF16*AU16 -> 55 | AW16: 0 | AX16: =AG16*AW16 -> 0 | AY16: 220 | AZ16: =AH16*AY16 -> 11 | BA16: 220 | BB16: =AI16*BA16 -> 11 | BC16: 0 | BD16: =AJ16*BC16 -> 0 | BE16: 0 | BF16: =AK16*BE16 -> 0 | BG16: 0 | BH16: =AL16*BG16 -> 0 | BI16: 0 | BJ16: =AM16*BI16 -> 0 | BK16: 0 | BL16: =AN16*BK16 -> 0
A17: FY24 | B17: Mandy Yu | C17: SUNREX | E17: NB | G17: 2023 | H17: KRAKEN/PAN/ROC/KNUCKER/KRAKEN/XUANWU | I17: CLICKPAD | J17: 13/14 | K17: PIKE SILVER | L17: W China | M17: QUANTA | N17: 4.42 | O17: 4.62 | P17: 4.62 | Q17: 4.62 | R17: 4.62 | S17: 4.62 | T17: 4.62 | U17: 4.62 | V17: 4.62 | W17: 4.62 | X17: 4.62 | Y17: 4.62 | Z17: 4.62 | AA17: 4.62 | AB17: 0.05 | AC17: 0.05 | AD17: 0.05 | AE17: 0.05 | AF17: 0.05 | AG17: 0.05 | AH17: 0.05 | AI17: 0.05 | AJ17: 0.05 | AK17: 0.05 | AL17: 0.05 | AM17: 0.05 | AN17: 0.05 | AO17: 25140 | AP17: =AC17*AO17 -> 1257 | AQ17: 9900 | AR17: =AD17*AQ17 -> 495 | AS17: 4620 | AT17: =AE17*AS17 -> 231 | AU17: 18810 | AV17: =AF17*AU17 -> 940.5 | AW17: 11770 | AX17: =AG17*AW17 -> 588.5 | AY17: 9900 | AZ17: =AH17*AY17 -> 495 | BA17: 17620 | BB17: =AI17*BA17 -> 881 | BC17: 3850 | BD17: =AJ17*BC17 -> 192.5 | BE17: 6820 | BF17: =AK17*BE17 -> 341 | BG17: 2860 | BH17: =AL17*BG17 -> 143 | BI17: 6159 | BJ17: =AM17*BI17 -> 307.95 | BK17: 1540 | BL17: =AN17*BK17 -> 77
A18: FY24 | B18: Mandy Yu | C18: SUNREX | E18: NB | G18: 2022 | H18: THANS/THUNDRA/RONIN/PRIMA/DOOP/REDSTART/DARKSTAR | I18: CLICKPAD | J18: 13/14 | K18: PIKE SILVER | L18: W China | M18: QUANTA | N18: 4.38 | O18: 4.46 | P18: 4.46 | Q18: 4.46 | R18: 4.46 | S18: 4.46 | T18: 4.46 | U18: 4.46 | V18: 4.46 | W18: 4.46 | X18: 4.46 | Y18: 4.46 | Z18: 4.46 | AA18: 4.46 | AB18: 0.05 | AC18: 0.05 | AD18: 0.05 | AE18: 0.05 | AF18: 0.05 | AG18: 0.05 | AH18: 0.05 | AI18: 0.05 | AJ18: 0.05 | AK18: 0.05 | AL18: 0.05 | AM18: 0.05 | AN18: 0.05 | AO18: 146764 | AP18: =AC18*AO18 -> 7338.2 | AQ18: 136020 | AR18: =AD18*AQ18 -> 6801 | AS18: 94360 | AT18: =AE18*AS18 -> 4718 | AU18: 104250 | AV18: =AF18*AU18 -> 5212.5 | AW18: 86220 | AX18: =AG18*AW18 -> 4311 | AY18: 43010 | AZ18: =AH18*AY18 -> 2150.5 | BA18: 34980 | BB18: =AI18*BA18 -> 1749 | BC18: 13090 | BD18: =AJ18*BC18 -> 654.5 | BE18: 108050 | BF18: =AK18*BE18 -> 5402.5 | BG18: 29260 | BH18: =AL18*BG18 -> 1463 | BI18: 8156 | BJ18: =AM18*BI18 -> 407.8 | BK18: 0 | BL18: =AN18*BK18 -> 0
